Workbook
Name bev: INDIRECT(Hibak!$Z$122):INDIRECT(Hibak!$Z$123)
Name beva: INDIRECT(Hibak!$AA$122):INDIRECT(Hibak!$AA$123)
Name bevb: INDIRECT(Hibak!$AB$122):INDIRECT(Hibak!$AB$123)
Name bevc: INDIRECT(Hibak!$AC$122):INDIRECT(Hibak!$AC$123)
Name bevd: INDIRECT(Hibak!$AD$122):INDIRECT(Hibak!$AD$123)
Name beve: INDIRECT(Hibak!$AE$122):INDIRECT(Hibak!$AE$123)
Name bevf: INDIRECT(Hibak!$AF$122):INDIRECT(Hibak!$AF$123)
Name bevg: INDIRECT(Hibak!$AG$122):INDIRECT(Hibak!$AG$123)
Name bevh: INDIRECT(Hibak!$AH$122):INDIRECT(Hibak!$AH$123)
Name bevi: INDIRECT(Hibak!$AI$122):INDIRECT(Hibak!$AI$123)
Name bevj: INDIRECT(Hibak!$AJ$122):INDIRECT(Hibak!$AJ$123)
Name bevk: INDIRECT(Hibak!$AK$122):INDIRECT(Hibak!$AK$123)
Name bevl: INDIRECT(Hibak!$AL$122):INDIRECT(Hibak!$AL$123)
Name bevm: INDIRECT(Hibak!$AM$122):INDIRECT(Hibak!$AM$123)
Name bevn: INDIRECT(Hibak!$AN$122):INDIRECT(Hibak!$AN$123)
Name bevo: INDIRECT(Hibak!$AO$122):INDIRECT(Hibak!$AO$123)
Name bevp: INDIRECT(Hibak!$AP$122):INDIRECT(Hibak!$AP$123)
Name bevq: INDIRECT(Hibak!$AQ$122):INDIRECT(Hibak!$AQ$123)
Name bevr: INDIRECT(Hibak!$AR$122):INDIRECT(Hibak!$AR$123)
Name bevs: INDIRECT(Hibak!$AS$122):INDIRECT(Hibak!$AS$123)
Name bevt: INDIRECT(Hibak!$AT$122):INDIRECT(Hibak!$AT$123)
Name fi: Hibak!$C$198:$D$1131
Name fif: Hibak!$C$51:$H$1040
Name kiad: INDIRECT(Hibak!$AZ$122):INDIRECT(Hibak!$AZ$123)
Name kiada: INDIRECT(Hibak!$BA$122):INDIRECT(Hibak!$BA$123)
Name kiadb: INDIRECT(Hibak!$BB$122):INDIRECT(Hibak!$BB$123)
Name kiadc: INDIRECT(Hibak!$BC$122):INDIRECT(Hibak!$BC$123)
Name kiadd: INDIRECT(Hibak!$BD$122):INDIRECT(Hibak!$BD$123)
Name kiade: INDIRECT(Hibak!$BE$122):INDIRECT(Hibak!$BE$123)
Name kiadf: INDIRECT(Hibak!$BF$122):INDIRECT(Hibak!$BF$123)
Name kiadg: INDIRECT(Hibak!$BG$122):INDIRECT(Hibak!$BG$123)
Name kiadh: INDIRECT(Hibak!$BH$122):INDIRECT(Hibak!$BH$123)
Name kiadi: INDIRECT(Hibak!$BI$122):INDIRECT(Hibak!$BI$123)
Name kiadj: INDIRECT(Hibak!$BJ$122):INDIRECT(Hibak!$BJ$123)
Name kiadk: INDIRECT(Hibak!$BK$122):INDIRECT(Hibak!$BK$123)
Name kiadl: INDIRECT(Hibak!$BL$122):INDIRECT(Hibak!$BL$123)
Name kiadm: INDIRECT(Hibak!$BM$122):INDIRECT(Hibak!$BM$123)
Name kiadn: INDIRECT(Hibak!$BN$122):INDIRECT(Hibak!$BN$123)
Name kiado: INDIRECT(Hibak!$BO$122):INDIRECT(Hibak!$BO$123)
Name kiadp: INDIRECT(Hibak!$BP$122):INDIRECT(Hibak!$BP$123)
Name kiadq: INDIRECT(Hibak!$BQ$122):INDIRECT(Hibak!$BQ$123)
Name kiadr: INDIRECT(Hibak!$BR$122):INDIRECT(Hibak!$BR$123)
Name kiads: INDIRECT(Hibak!$BS$122):INDIRECT(Hibak!$BS$123)
Name kiadt: INDIRECT(Hibak!$BT$122):INDIRECT(Hibak!$BT$123)
Name Nap: Kasszakonyv!$BC$1:INDEX(Kasszakonyv!$BC:$BC,Kasszakonyv!$AX$1)

Sheet Monetar
E1: Különbség
B2: Kasszaegyenleg: | D2: =ROUND(Kassza!H3,2) -> 0 | E2: =D3-D2 -> 0
B3: Készpénzegyenleg összesen: | D3: =ROUND(SUM(D5:D16),2) -> 0
B4: Pénznemek | C4: Darabszám | D4: Összeg
B5: 500 | D5: =B5*C5 -> 0
B6: 200 | D6: =B6*C6 -> 0
B7: 100 | D7: =B7*C7 -> 0
B8: 50 | D8: =B8*C8 -> 0
B9: 20 | D9: =B9*C9 -> 0
B10: 10 | D10: =B10*C10 -> 0
B11: 5 | D11: =B11*C11 -> 0
B12: 1 | D12: =B12*C12 -> 0
B13: 0.5 | D13: =B13*C13 -> 0
B14: 0.1 | D14: =B14*C14 -> 0
B15: 0.05 | D15: =B15*C15 -> 0
B16: 0.01 | D16: =B16*C16 -> 0

Sheet Kassza
C1: =DATE(Hibak!$A$1,1,1) -> 46023 | D1: =TRIM(Koltsegvetes!B79&Koltsegvetes!V1) -> Református Egyházközség | G1: Napi bevétel: | H1: =SUMIF($C$7:$C$10000,$C$2,$H$7:$H$10000) -> 0 | J1: =C2 -> 46023 | N1: A másolás, kivágás, beillesztés
C2: =IF(MAX(C7:C10000)>C1,MAX(C7:C10000),C1) -> 46023 | G2: Napi kiadás: | H2: =SUMIF($C$7:$C$10000,$C$2,$J$7:$J$10000) -> 0 | I2: =IF(H3>50000,"Az egyenleg meghaladta a kasszaplafont. Le kell tenni a készpénzt a bankszámlánkra!!!","") | N2: műveleteket lehetoleg ne használd!
C3: =DATE(Hibak!$A$1,12,31) -> 46387 | D3: Készpénz könyvelése | G3: Egyenleg: | H3: =SUM(SUM(H6:H10000),-SUM(J7:J10000)) -> 0
D4: =Hibak!Z3 | N4: Költségvetési
D5: Dátum | E5: Iratszám | F5: Irattip. | G5: Név | H5: Bev. - Összeg | I5: Bevétel - Költ.vet. név | J5: Kiad. - Összeg | K5: Kiadás - költ.vet. név | L5: Megjegyzés | M5: Magyarázat | N5: szám
B6: q | G6: Előző évi készpénzegyenleg:
B7: =IF(C7=1,"",IF(Kasszakonyv!$K$2>C7,"q",IF(Kasszakonyv!$K$2=C7,COUNTIF($C$7:C7,C7),""))) | C7: =IF(AND(D7<>0,D7>=$C$1,D7<=$C$3),D7,IF(SUM(H7:J17)<>0,C1,1)) -> 1 | M7: =IF(I7&K7<>"",VLOOKUP(I7&K7,fif,3,FALSE),"") | N7: =IF(I7&K7<>"",VLOOKUP(I7&K7,fi,2,FALSE),"")
B8: =IF(C8=1,"",IF(Kasszakonyv!$K$2>C8,"q",IF(Kasszakonyv!$K$2=C8,COUNTIF($C$7:C8,C8),""))) | C8: =IF(AND(D8<>0,D8>=$C$1,D8<=$C$3),D8,IF(SUM(H8:J18)<>0,C7,1)) -> 1 | M8: =IF(I8&K8<>"",VLOOKUP(I8&K8,fif,3,FALSE),"") | N8: =IF(I8&K8<>"",VLOOKUP(I8&K8,fi,2,FALSE),"")
B9: =IF(C9=1,"",IF(Kasszakonyv!$K$2>C9,"q",IF(Kasszakonyv!$K$2=C9,COUNTIF($C$7:C9,C9),""))) | C9: =IF(AND(D9<>0,D9>=$C$1,D9<=$C$3),D9,IF(SUM(H9:J19)<>0,C8,1)) -> 1 | M9: =IF(I9&K9<>"",VLOOKUP(I9&K9,fif,3,FALSE),"") | N9: =IF(I9&K9<>"",VLOOKUP(I9&K9,fi,2,FALSE),"")
B10: =IF(C10=1,"",IF(Kasszakonyv!$K$2>C10,"q",IF(Kasszakonyv!$K$2=C10,COUNTIF($C$7:C10,C10),""))) | C10: =IF(AND(D10<>0,D10>=$C$1,D10<=$C$3),D10,IF(SUM(H10:J20)<>0,C9,1)) -> 1 | M10: =IF(I10&K10<>"",VLOOKUP(I10&K10,fif,3,FALSE),"") | N10: =IF(I10&K10<>"",VLOOKUP(I10&K10,fi,2,FALSE),"")
B11: =IF(C11=1,"",IF(Kasszakonyv!$K$2>C11,"q",IF(Kasszakonyv!$K$2=C11,COUNTIF($C$7:C11,C11),""))) | C11: =IF(AND(D11<>0,D11>=$C$1,D11<=$C$3),D11,IF(SUM(H11:J21)<>0,C10,1)) -> 1 | M11: =IF(I11&K11<>"",VLOOKUP(I11&K11,fif,3,FALSE),"") | N11: =IF(I11&K11<>"",VLOOKUP(I11&K11,fi,2,FALSE),"")
B12: =IF(C12=1,"",IF(Kasszakonyv!$K$2>C12,"q",IF(Kasszakonyv!$K$2=C12,COUNTIF($C$7:C12,C12),""))) | C12: =IF(AND(D12<>0,D12>=$C$1,D12<=$C$3),D12,IF(SUM(H12:J22)<>0,C11,1)) -> 1 | M12: =IF(I12&K12<>"",VLOOKUP(I12&K12,fif,3,FALSE),"") | N12: =IF(I12&K12<>"",VLOOKUP(I12&K12,fi,2,FALSE),"")
B13: =IF(C13=1,"",IF(Kasszakonyv!$K$2>C13,"q",IF(Kasszakonyv!$K$2=C13,COUNTIF($C$7:C13,C13),""))) | C13: =IF(AND(D13<>0,D13>=$C$1,D13<=$C$3),D13,IF(SUM(H13:J23)<>0,C12,1)) -> 1 | M13: =IF(I13&K13<>"",VLOOKUP(I13&K13,fif,3,FALSE),"") | N13: =IF(I13&K13<>"",VLOOKUP(I13&K13,fi,2,FALSE),"")
B14: =IF(C14=1,"",IF(Kasszakonyv!$K$2>C14,"q",IF(Kasszakonyv!$K$2=C14,COUNTIF($C$7:C14,C14),""))) | C14: =IF(AND(D14<>0,D14>=$C$1,D14<=$C$3),D14,IF(SUM(H14:J24)<>0,C13,1)) -> 1 | M14: =IF(I14&K14<>"",VLOOKUP(I14&K14,fif,3,FALSE),"") | N14: =IF(I14&K14<>"",VLOOKUP(I14&K14,fi,2,FALSE),"")
B15: =IF(C15=1,"",IF(Kasszakonyv!$K$2>C15,"q",IF(Kasszakonyv!$K$2=C15,COUNTIF($C$7:C15,C15),""))) | C15: =IF(AND(D15<>0,D15>=$C$1,D15<=$C$3),D15,IF(SUM(H15:J25)<>0,C14,1)) -> 1 | M15: =IF(I15&K15<>"",VLOOKUP(I15&K15,fif,3,FALSE),"") | N15: =IF(I15&K15<>"",VLOOKUP(I15&K15,fi,2,FALSE),"")
B16: =IF(C16=1,"",IF(Kasszakonyv!$K$2>C16,"q",IF(Kasszakonyv!$K$2=C16,COUNTIF($C$7:C16,C16),""))) | C16: =IF(AND(D16<>0,D16>=$C$1,D16<=$C$3),D16,IF(SUM(H16:J26)<>0,C15,1)) -> 1 | M16: =IF(I16&K16<>"",VLOOKUP(I16&K16,fif,3,FALSE),"") | N16: =IF(I16&K16<>"",VLOOKUP(I16&K16,fi,2,FALSE),"")
B17: =IF(C17=1,"",IF(Kasszakonyv!$K$2>C17,"q",IF(Kasszakonyv!$K$2=C17,COUNTIF($C$7:C17,C17),""))) | C17: =IF(AND(D17<>0,D17>=$C$1,D17<=$C$3),D17,IF(SUM(H17:J27)<>0,C16,1)) -> 1 | M17: =IF(I17&K17<>"",VLOOKUP(I17&K17,fif,3,FALSE),"") | N17: =IF(I17&K17<>"",VLOOKUP(I17&K17,fi,2,FALSE),"")
B18: =IF(C18=1,"",IF(Kasszakonyv!$K$2>C18,"q",IF(Kasszakonyv!$K$2=C18,COUNTIF($C$7:C18,C18),""))) | C18: =IF(AND(D18<>0,D18>=$C$1,D18<=$C$3),D18,IF(SUM(H18:J28)<>0,C17,1)) -> 1 | M18: =IF(I18&K18<>"",VLOOKUP(I18&K18,fif,3,FALSE),"") | N18: =IF(I18&K18<>"",VLOOKUP(I18&K18,fi,2,FALSE),"")
B19: =IF(C19=1,"",IF(Kasszakonyv!$K$2>C19,"q",IF(Kasszakonyv!$K$2=C19,COUNTIF($C$7:C19,C19),""))) | C19: =IF(AND(D19<>0,D19>=$C$1,D19<=$C$3),D19,IF(SUM(H19:J29)<>0,C18,1)) -> 1 | M19: =IF(I19&K19<>"",VLOOKUP(I19&K19,fif,3,FALSE),"") | N19: =IF(I19&K19<>"",VLOOKUP(I19&K19,fi,2,FALSE),"")
... B4000: =IF(C4000=1,"",IF(Kasszakonyv!$K$2>C4000,"q",IF(Kasszakonyv!$K$2=C4000,COUNTIF($C$7:C4000,C4000),""))) | C4000: =IF(AND(D4000<>0,D4000>=$C$1,D4000<=$C$3),D4000,IF(SUM(H4000:J4010)<>0,C3999,1)) -> 1 | M4000: =IF(I4000&K4000<>"",VLOOKUP(I4000&K4000,fif,3,FALSE),"") | N4000: =IF(I4000&K4000<>"",VLOOKUP(I4000&K4000,fi,2,FALSE),"")

Sheet Kasszakonyv
A1: A jobboldali, zöld cellában lehet kiválasztani a lenyílóból a korábbi kasszakönyvi lapokat. A lenyílóban csak azok a napok jelennek meg, amikor volt mozgás a kasszában. Ha a cella üres, vagy értéke 0 (nulla), akkor a legutolsó kasszakönyvi lapot listázza. | J1: A A | K1: =IF(AND(G1<>0,G1<>"",ISERROR(VLOOKUP(G1,BC1:BD366,2,FALSE))<>TRUE),G1,MAX(BC1:BC366)) -> 0 | L1: Ezen a napon összesen | M1: =MAX(Kassza!B7:B10000) -> 0 | P1: Előző egyleg | Q1: =SUMIF(Kassza!$B$6:$B$10000,"q",Kassza!$H$6:$H$10000)-SUMIF(Kassza!$B$7:$B$10000,"q",Kassza!$J$7:$J$10000) -> 0 | R1: ="<="&M8 -> <=0 | T1: Sold ziua precedentă - Előző napi egyenleg: | AW1: =Kasszakonyv!$BC$1:INDEX(Kasszakonyv!$BC:$BC,Kasszakonyv!$AX$1) -> 0 | AX1: =IF(MATCH(0,BC1:BC367,0)>1,MATCH(0,BC1:BC367,0)-1,1) -> 1 | BA1: 1 | BC1: =IF(ISERROR(VLOOKUP(BA1,$BD$1:$BE$366,2,FALSE))=FALSE,VLOOKUP(BA1,$BD$1:$BE$366,2,FALSE),0) -> 0 | BD1: =IF(COUNTIF(Kassza!$C$7:$C$10000,BE1)<>0,1,0) -> 0 | BE1: =DATE(Hibak!A1,1,1) -> 46023 | BF1: =ROUNDUP(COUNTIF(Kassza!$C$7:$C$10000,BE1)/30,0) -> 0 | BK1: 1 | BL1: Jan.
A2: =IF(M2>1,L1&M2&L2&M3&L3,"") | J2: A A | K2: =DATE(Hibak!A1,MONTH(K1),DAY(K1)) -> 46022 | L2: kasszakönyvi lap van. Ebből jelenleg a(z) | M2: =ROUNDUP(M1/30,0) -> 0 | Q2: =SUMIF(Kassza!$B$7:$B$10000,$R$1,Kassza!$H$7:$H$10000) -> 0 | R2: =SUMIF(Kassza!$B$7:$B$10000,$R$1,Kassza!$J$7:$J$10000) -> 0 | T2: Report din pagina precedentă - Áthozat az előző lapról: | BA2: 2 | BC2: =IF(ISERROR(VLOOKUP(BA2,$BD$1:$BE$366,2,FALSE))=FALSE,VLOOKUP(BA2,$BD$1:$BE$366,2,FALSE),0) -> 0 | BD2: =IF(COUNTIF(Kassza!$C$7:$C$10000,BE2)<>0,BD1+1,BD1) -> 0 | BE2: =BE1+1 -> 46024 | BF2: =ROUNDUP(COUNTIF(Kassza!$C$7:$C$10000,BE2)/30,0) -> 0 | BG2: =SUM($BF$1:BF1) -> 0 | BK2: 2 | BL2: Febr.
K3: =IF(MONTH(K2)<10,0,"") | L3: . látszik. A jobboldali, zöld cellában lehet megadni a listázni kívánt lapszámot. | M3: =IF(OR(G2=0,G2>M2,G2=""),1,G2) -> 1 | T3: Total - Összesen: | BA3: 3 | BC3: =IF(ISERROR(VLOOKUP(BA3,$BD$1:$BE$366,2,FALSE))=FALSE,VLOOKUP(BA3,$BD$1:$BE$366,2,FALSE),0) -> 0 | BD3: =IF(COUNTIF(Kassza!$C$7:$C$10000,BE3)<>0,BD2+1,BD2) -> 0 | BE3: =BE2+1 -> 46025 | BF3: =ROUNDUP(COUNTIF(Kassza!$C$7:$C$10000,BE3)/30,0) -> 0 | BG3: =SUM($BF$1:BF2) -> 0 | BK3: 3 | BL3: Márc.
A4: =IF(Koltsegvetes!B79<>0,Koltsegvetes!B79,"") | D4: REGISTRU DE CASĂ KASSZAKÖNYV | G4: =YEAR(K2)&"."&K3&MONTH(K2)&"."&K4&DAY(K2)&"." -> 2025.12.31. | K4: =IF(DAY(K2)<10,0,"") | M4: =IF(ISERROR(VLOOKUP(K2,BE1:BG366,3,FALSE))=FALSE,VLOOKUP(K2,BE1:BG366,3,FALSE)+M3,1) -> 1 | T4: Sold zi - Napi egyenleg - | BA4: 4 | BC4: =IF(ISERROR(VLOOKUP(BA4,$BD$1:$BE$366,2,FALSE))=FALSE,VLOOKUP(BA4,$BD$1:$BE$366,2,FALSE),0) -> 0 | BD4: =IF(COUNTIF(Kassza!$C$7:$C$10000,BE4)<>0,BD3+1,BD3) -> 0 | BE4: =BE3+1 -> 46026 | BF4: =ROUNDUP(COUNTIF(Kassza!$C$7:$C$10000,BE4)/30,0) -> 0 | BG4: =SUM($BF$1:BF3) -> 0 | BK4: 4 | BL4: Ápr.
A5: =Koltsegvetes!V2 -> Ref. Egyházközség | T5: De reportat pagina - Átvitel: | BA5: 5 | BC5: =IF(ISERROR(VLOOKUP(BA5,$BD$1:$BE$366,2,FALSE))=FALSE,VLOOKUP(BA5,$BD$1:$BE$366,2,FALSE),0) -> 0 | BD5: =IF(COUNTIF(Kassza!$C$7:$C$10000,BE5)<>0,BD4+1,BD4) -> 0 | BE5: =BE4+1 -> 46027 | BF5: =ROUNDUP(COUNTIF(Kassza!$C$7:$C$10000,BE5)/30,0) -> 0 | BG5: =SUM($BF$1:BF4) -> 0 | BK5: 5 | BL5: Máj.
A6: (unitate - egység) | G6: A/L/Z/ - É/H/N | BA6: 6 | BC6: =IF(ISERROR(VLOOKUP(BA6,$BD$1:$BE$366,2,FALSE))=FALSE,VLOOKUP(BA6,$BD$1:$BE$366,2,FALSE),0) -> 0 | BD6: =IF(COUNTIF(Kassza!$C$7:$C$10000,BE6)<>0,BD5+1,BD5) -> 0 | BE6: =BE5+1 -> 46028 | BF6: =ROUNDUP(COUNTIF(Kassza!$C$7:$C$10000,BE6)/30,0) -> 0 | BG6: =SUM($BF$1:BF5) -> 0 | BK6: 6 | BL6: Jún.
A7: Nr.crt S.sz. | B7: Nr.act.casă Iratszám | C7: Act Irat | D7: Explicaţia - Magyarázat | E7: Încasări Bevételek | F7: Plăţi Kiadások | G7: Simbol cont. Költségv.sz. | BA7: 7 | BC7: =IF(ISERROR(VLOOKUP(BA7,$BD$1:$BE$366,2,FALSE))=FALSE,VLOOKUP(BA7,$BD$1:$BE$366,2,FALSE),0) -> 0 | BD7: =IF(COUNTIF(Kassza!$C$7:$C$10000,BE7)<>0,BD6+1,BD6) -> 0 | BE7: =BE6+1 -> 46029 | BF7: =ROUNDUP(COUNTIF(Kassza!$C$7:$C$10000,BE7)/30,0) -> 0 | BG7: =SUM($BF$1:BF6) -> 0 | BK7: 7 | BL7: Júl.
D8: =IF(M3=1,T1,T2) -> Sold ziua precedentă - Előző napi egyenleg: | E8: =SUM(Q1:Q2) -> 0 | F8: =IF(M3>1,R2,"") | M8: =ROUND(SUM(M3,-1)*30,0) -> 0 | O8: 12 | Q8: 11 | BA8: 8 | BC8: =IF(ISERROR(VLOOKUP(BA8,$BD$1:$BE$366,2,FALSE))=FALSE,VLOOKUP(BA8,$BD$1:$BE$366,2,FALSE),0) -> 0 | BD8: =IF(COUNTIF(Kassza!$C$7:$C$10000,BE8)<>0,BD7+1,BD7) -> 0 | BE8: =BE7+1 -> 46030 | BF8: =ROUNDUP(COUNTIF(Kassza!$C$7:$C$10000,BE8)/30,0) -> 0 | BG8: =SUM($BF$1:BF7) -> 0 | BK8: 8 | BL8: Aug.
A9: =IF($M$1>=M9,M9,"") | B9: =IF($M$1>=M9,TRIM(VLOOKUP(M9,Kassza!$B$7:$N$10000,4,FALSE)),"") | C9: =IF($M$1>=M9,TRIM(VLOOKUP(M9,Kassza!$B$7:$N$10000,5,FALSE)),"") | D9: =TRIM(IF($M$1>=M9,O9&" "&P9&" "&Q9,IF($M$1=M8,$T$3,IF($M$1=M7,$T$4&G4,"")))) -> Total - Összesen: | E9: =IF($M$1>=M9,IF(VLOOKUP(M9,Kassza!$B$7:$N$10000,7,FALSE)<>0,VLOOKUP(M9,Kassza!$B$7:$N$10000,7,FALSE),""),IF($M$1=M8,SUM($E$8:E8),IF($M$1=M7,SUM(E8,-F8),""))) -> 0 | F9: =IF($M$1>=M9,IF(VLOOKUP(M9,Kassza!$B$7:$N$10000,9,FALSE)<>0,VLOOKUP(M9,Kassza!$B$7:$N$10000,9,FALSE),""),IF($M$1=M8,SUM($F$8:F8),"")) -> 0 | G9: =IF($M$1>=M9,TRIM(VLOOKUP(M9,Kassza!$B$7:$N$10000,13,FALSE)),"") | M9: =M8+1 -> 1 | O9: =IF($M$1>=M9,TRIM(VLOOKUP(M9,Kassza!$B$7:$N$10000,12,FALSE)),"") | P9: =IF($M$1>=M9,TRIM(VLOOKUP(M9,Kassza!$B$7:$N$10000,6,FALSE)),"") | Q9: =IF($M$1>=M9,TRIM(VLOOKUP(M9,Kassza!$B$7:$N$10000,11,FALSE)),"") | BA9: 9 | BC9: =IF(ISERROR(VLOOKUP(BA9,$BD$1:$BE$366,2,FALSE))=FALSE,VLOOKUP(BA9,$BD$1:$BE$366,2,FALSE),0) -> 0 | BD9: =IF(COUNTIF(Kassza!$C$7:$C$10000,BE9)<>0,BD8+1,BD8) -> 0 | BE9: =BE8+1 -> 46031 | BF9: =ROUNDUP(COUNTIF(Kassza!$C$7:$C$10000,BE9)/30,0) -> 0 | BG9: =SUM($BF$1:BF8) -> 0 | BK9: 9 | BL9: Szept.
A10: =IF($M$1>=M10,M10,"") | B10: =IF($M$1>=M10,TRIM(VLOOKUP(M10,Kassza!$B$7:$N$10000,4,FALSE)),"") | C10: =IF($M$1>=M10,TRIM(VLOOKUP(M10,Kassza!$B$7:$N$10000,5,FALSE)),"") | D10: =TRIM(IF($M$1>=M10,O10&" "&P10&" "&Q10,IF($M$1=M9,$T$3,IF($M$1=M8,$T$4&G4,"")))) -> Sold zi - Napi egyenleg - 2025.12.31. | E10: =IF($M$1>=M10,IF(VLOOKUP(M10,Kassza!$B$7:$N$10000,7,FALSE)<>0,VLOOKUP(M10,Kassza!$B$7:$N$10000,7,FALSE),""),IF($M$1=M9,SUM($E$8:E9),IF($M$1=M8,SUM(E9,-F9),""))) -> 0 | F10: =IF($M$1>=M10,IF(VLOOKUP(M10,Kassza!$B$7:$N$10000,9,FALSE)<>0,VLOOKUP(M10,Kassza!$B$7:$N$10000,9,FALSE),""),IF($M$1=M9,SUM($F$8:F9),"")) | G10: =IF($M$1>=M10,TRIM(VLOOKUP(M10,Kassza!$B$7:$N$10000,13,FALSE)),"") | M10: =M9+1 -> 2 | O10: =IF($M$1>=M10,TRIM(VLOOKUP(M10,Kassza!$B$7:$N$10000,12,FALSE)),"") | P10: =IF($M$1>=M10,TRIM(VLOOKUP(M10,Kassza!$B$7:$N$10000,6,FALSE)),"") | Q10: =IF($M$1>=M10,TRIM(VLOOKUP(M10,Kassza!$B$7:$N$10000,11,FALSE)),"") | BA10: 10 | BC10: =IF(ISERROR(VLOOKUP(BA10,$BD$1:$BE$366,2,FALSE))=FALSE,VLOOKUP(BA10,$BD$1:$BE$366,2,FALSE),0) -> 0 | BD10: =IF(COUNTIF(Kassza!$C$7:$C$10000,BE10)<>0,BD9+1,BD9) -> 0 | BE10: =BE9+1 -> 46032 | BF10: =ROUNDUP(COUNTIF(Kassza!$C$7:$C$10000,BE10)/30,0) -> 0 | BG10: =SUM($BF$1:BF9) -> 0 | BK10: 10 | BL10: Okt.
A11: =IF($M$1>=M11,M11,"") | B11: =IF($M$1>=M11,TRIM(VLOOKUP(M11,Kassza!$B$7:$N$10000,4,FALSE)),"") | C11: =IF($M$1>=M11,TRIM(VLOOKUP(M11,Kassza!$B$7:$N$10000,5,FALSE)),"") | D11: =TRIM(IF($M$1>=M11,O11&" "&P11&" "&Q11,IF($M$1=M10,$T$3,IF($M$1=M9,$T$4&G4,"")))) | E11: =IF($M$1>=M11,IF(VLOOKUP(M11,Kassza!$B$7:$N$10000,7,FALSE)<>0,VLOOKUP(M11,Kassza!$B$7:$N$10000,7,FALSE),""),IF($M$1=M10,SUM($E$8:E10),IF($M$1=M9,SUM(E10,-F10),""))) | F11: =IF($M$1>=M11,IF(VLOOKUP(M11,Kassza!$B$7:$N$10000,9,FALSE)<>0,VLOOKUP(M11,Kassza!$B$7:$N$10000,9,FALSE),""),IF($M$1=M10,SUM($F$8:F10),"")) | G11: =IF($M$1>=M11,TRIM(VLOOKUP(M11,Kassza!$B$7:$N$10000,13,FALSE)),"") | M11: =M10+1 -> 3 | O11: =IF($M$1>=M11,TRIM(VLOOKUP(M11,Kassza!$B$7:$N$10000,12,FALSE)),"") | P11: =IF($M$1>=M11,TRIM(VLOOKUP(M11,Kassza!$B$7:$N$10000,6,FALSE)),"") | Q11: =IF($M$1>=M11,TRIM(VLOOKUP(M11,Kassza!$B$7:$N$10000,11,FALSE)),"") | BA11: 11 | BC11: =IF(ISERROR(VLOOKUP(BA11,$BD$1:$BE$366,2,FALSE))=FALSE,VLOOKUP(BA11,$BD$1:$BE$366,2,FALSE),0) -> 0 | BD11: =IF(COUNTIF(Kassza!$C$7:$C$10000,BE11)<>0,BD10+1,BD10) -> 0 | BE11: =BE10+1 -> 46033 | BF11: =ROUNDUP(COUNTIF(Kassza!$C$7:$C$10000,BE11)/30,0) -> 0 | BG11: =SUM($BF$1:BF10) -> 0 | BK11: 11 | BL11: Nov.
A12: =IF($M$1>=M12,M12,"") | B12: =IF($M$1>=M12,TRIM(VLOOKUP(M12,Kassza!$B$7:$N$10000,4,FALSE)),"") | C12: =IF($M$1>=M12,TRIM(VLOOKUP(M12,Kassza!$B$7:$N$10000,5,FALSE)),"") | D12: =TRIM(IF($M$1>=M12,O12&" "&P12&" "&Q12,IF($M$1=M11,$T$3,IF($M$1=M10,$T$4&G4,"")))) | E12: =IF($M$1>=M12,IF(VLOOKUP(M12,Kassza!$B$7:$N$10000,7,FALSE)<>0,VLOOKUP(M12,Kassza!$B$7:$N$10000,7,FALSE),""),IF($M$1=M11,SUM($E$8:E11),IF($M$1=M10,SUM(E11,-F11),""))) | F12: =IF($M$1>=M12,IF(VLOOKUP(M12,Kassza!$B$7:$N$10000,9,FALSE)<>0,VLOOKUP(M12,Kassza!$B$7:$N$10000,9,FALSE),""),IF($M$1=M11,SUM($F$8:F11),"")) | G12: =IF($M$1>=M12,TRIM(VLOOKUP(M12,Kassza!$B$7:$N$10000,13,FALSE)),"") | M12: =M11+1 -> 4 | O12: =IF($M$1>=M12,TRIM(VLOOKUP(M12,Kassza!$B$7:$N$10000,12,FALSE)),"") | P12: =IF($M$1>=M12,TRIM(VLOOKUP(M12,Kassza!$B$7:$N$10000,6,FALSE)),"") | Q12: =IF($M$1>=M12,TRIM(VLOOKUP(M12,Kassza!$B$7:$N$10000,11,FALSE)),"") | BA12: 12 | BC12: =IF(ISERROR(VLOOKUP(BA12,$BD$1:$BE$366,2,FALSE))=FALSE,VLOOKUP(BA12,$BD$1:$BE$366,2,FALSE),0) -> 0 | BD12: =IF(COUNTIF(Kassza!$C$7:$C$10000,BE12)<>0,BD11+1,BD11) -> 0 | BE12: =BE11+1 -> 46034 | BF12: =ROUNDUP(COUNTIF(Kassza!$C$7:$C$10000,BE12)/30,0) -> 0 | BG12: =SUM($BF$1:BF11) -> 0 | BK12: 12 | BL12: Dec.
A13: =IF($M$1>=M13,M13,"") | B13: =IF($M$1>=M13,TRIM(VLOOKUP(M13,Kassza!$B$7:$N$10000,4,FALSE)),"") | C13: =IF($M$1>=M13,TRIM(VLOOKUP(M13,Kassza!$B$7:$N$10000,5,FALSE)),"") | D13: =TRIM(IF($M$1>=M13,O13&" "&P13&" "&Q13,IF($M$1=M12,$T$3,IF($M$1=M11,$T$4&G4,"")))) | E13: =IF($M$1>=M13,IF(VLOOKUP(M13,Kassza!$B$7:$N$10000,7,FALSE)<>0,VLOOKUP(M13,Kassza!$B$7:$N$10000,7,FALSE),""),IF($M$1=M12,SUM($E$8:E12),IF($M$1=M11,SUM(E12,-F12),""))) | F13: =IF($M$1>=M13,IF(VLOOKUP(M13,Kassza!$B$7:$N$10000,9,FALSE)<>0,VLOOKUP(M13,Kassza!$B$7:$N$10000,9,FALSE),""),IF($M$1=M12,SUM($F$8:F12),"")) | G13: =IF($M$1>=M13,TRIM(VLOOKUP(M13,Kassza!$B$7:$N$10000,13,FALSE)),"") | M13: =M12+1 -> 5 | O13: =IF($M$1>=M13,TRIM(VLOOKUP(M13,Kassza!$B$7:$N$10000,12,FALSE)),"") | P13: =IF($M$1>=M13,TRIM(VLOOKUP(M13,Kassza!$B$7:$N$10000,6,FALSE)),"") | Q13: =IF($M$1>=M13,TRIM(VLOOKUP(M13,Kassza!$B$7:$N$10000,11,FALSE)),"") | BA13: 13 | BC13: =IF(ISERROR(VLOOKUP(BA13,$BD$1:$BE$366,2,FALSE))=FALSE,VLOOKUP(BA13,$BD$1:$BE$366,2,FALSE),0) -> 0 | BD13: =IF(COUNTIF(Kassza!$C$7:$C$10000,BE13)<>0,BD12+1,BD12) -> 0 | BE13: =BE12+1 -> 46035 | BF13: =ROUNDUP(COUNTIF(Kassza!$C$7:$C$10000,BE13)/30,0) -> 0 | BG13: =SUM($BF$1:BF12) -> 0
A14: =IF($M$1>=M14,M14,"") | B14: =IF($M$1>=M14,TRIM(VLOOKUP(M14,Kassza!$B$7:$N$10000,4,FALSE)),"") | C14: =IF($M$1>=M14,TRIM(VLOOKUP(M14,Kassza!$B$7:$N$10000,5,FALSE)),"") | D14: =TRIM(IF($M$1>=M14,O14&" "&P14&" "&Q14,IF($M$1=M13,$T$3,IF($M$1=M12,$T$4&G4,"")))) | E14: =IF($M$1>=M14,IF(VLOOKUP(M14,Kassza!$B$7:$N$10000,7,FALSE)<>0,VLOOKUP(M14,Kassza!$B$7:$N$10000,7,FALSE),""),IF($M$1=M13,SUM($E$8:E13),IF($M$1=M12,SUM(E13,-F13),""))) | F14: =IF($M$1>=M14,IF(VLOOKUP(M14,Kassza!$B$7:$N$10000,9,FALSE)<>0,VLOOKUP(M14,Kassza!$B$7:$N$10000,9,FALSE),""),IF($M$1=M13,SUM($F$8:F13),"")) | G14: =IF($M$1>=M14,TRIM(VLOOKUP(M14,Kassza!$B$7:$N$10000,13,FALSE)),"") | M14: =M13+1 -> 6 | O14: =IF($M$1>=M14,TRIM(VLOOKUP(M14,Kassza!$B$7:$N$10000,12,FALSE)),"") | P14: =IF($M$1>=M14,TRIM(VLOOKUP(M14,Kassza!$B$7:$N$10000,6,FALSE)),"") | Q14: =IF($M$1>=M14,TRIM(VLOOKUP(M14,Kassza!$B$7:$N$10000,11,FALSE)),"") | BA14: 14 | BC14: =IF(ISERROR(VLOOKUP(BA14,$BD$1:$BE$366,2,FALSE))=FALSE,VLOOKUP(BA14,$BD$1:$BE$366,2,FALSE),0) -> 0 | BD14: =IF(COUNTIF(Kassza!$C$7:$C$10000,BE14)<>0,BD13+1,BD13) -> 0 | BE14: =BE13+1 -> 46036 | BF14: =ROUNDUP(COUNTIF(Kassza!$C$7:$C$10000,BE14)/30,0) -> 0 | BG14: =SUM($BF$1:BF13) -> 0
A15: =IF($M$1>=M15,M15,"") | B15: =IF($M$1>=M15,TRIM(VLOOKUP(M15,Kassza!$B$7:$N$10000,4,FALSE)),"") | C15: =IF($M$1>=M15,TRIM(VLOOKUP(M15,Kassza!$B$7:$N$10000,5,FALSE)),"") | D15: =TRIM(IF($M$1>=M15,O15&" "&P15&" "&Q15,IF($M$1=M14,$T$3,IF($M$1=M13,$T$4&G4,"")))) | E15: =IF($M$1>=M15,IF(VLOOKUP(M15,Kassza!$B$7:$N$10000,7,FALSE)<>0,VLOOKUP(M15,Kassza!$B$7:$N$10000,7,FALSE),""),IF($M$1=M14,SUM($E$8:E14),IF($M$1=M13,SUM(E14,-F14),""))) | F15: =IF($M$1>=M15,IF(VLOOKUP(M15,Kassza!$B$7:$N$10000,9,FALSE)<>0,VLOOKUP(M15,Kassza!$B$7:$N$10000,9,FALSE),""),IF($M$1=M14,SUM($F$8:F14),"")) | G15: =IF($M$1>=M15,TRIM(VLOOKUP(M15,Kassza!$B$7:$N$10000,13,FALSE)),"") | M15: =M14+1 -> 7 | O15: =IF($M$1>=M15,TRIM(VLOOKUP(M15,Kassza!$B$7:$N$10000,12,FALSE)),"") | P15: =IF($M$1>=M15,TRIM(VLOOKUP(M15,Kassza!$B$7:$N$10000,6,FALSE)),"") | Q15: =IF($M$1>=M15,TRIM(VLOOKUP(M15,Kassza!$B$7:$N$10000,11,FALSE)),"") | BA15: 15 | BC15: =IF(ISERROR(VLOOKUP(BA15,$BD$1:$BE$366,2,FALSE))=FALSE,VLOOKUP(BA15,$BD$1:$BE$366,2,FALSE),0) -> 0 | BD15: =IF(COUNTIF(Kassza!$C$7:$C$10000,BE15)<>0,BD14+1,BD14) -> 0 | BE15: =BE14+1 -> 46037 | BF15: =ROUNDUP(COUNTIF(Kassza!$C$7:$C$10000,BE15)/30,0) -> 0 | BG15: =SUM($BF$1:BF14) -> 0
A16: =IF($M$1>=M16,M16,"") | B16: =IF($M$1>=M16,TRIM(VLOOKUP(M16,Kassza!$B$7:$N$10000,4,FALSE)),"") | C16: =IF($M$1>=M16,TRIM(VLOOKUP(M16,Kassza!$B$7:$N$10000,5,FALSE)),"") | D16: =TRIM(IF($M$1>=M16,O16&" "&P16&" "&Q16,IF($M$1=M15,$T$3,IF($M$1=M14,$T$4&G4,"")))) | E16: =IF($M$1>=M16,IF(VLOOKUP(M16,Kassza!$B$7:$N$10000,7,FALSE)<>0,VLOOKUP(M16,Kassza!$B$7:$N$10000,7,FALSE),""),IF($M$1=M15,SUM($E$8:E15),IF($M$1=M14,SUM(E15,-F15),""))) | F16: =IF($M$1>=M16,IF(VLOOKUP(M16,Kassza!$B$7:$N$10000,9,FALSE)<>0,VLOOKUP(M16,Kassza!$B$7:$N$10000,9,FALSE),""),IF($M$1=M15,SUM($F$8:F15),"")) | G16: =IF($M$1>=M16,TRIM(VLOOKUP(M16,Kassza!$B$7:$N$10000,13,FALSE)),"") | M16: =M15+1 -> 8 | O16: =IF($M$1>=M16,TRIM(VLOOKUP(M16,Kassza!$B$7:$N$10000,12,FALSE)),"") | P16: =IF($M$1>=M16,TRIM(VLOOKUP(M16,Kassza!$B$7:$N$10000,6,FALSE)),"") | Q16: =IF($M$1>=M16,TRIM(VLOOKUP(M16,Kassza!$B$7:$N$10000,11,FALSE)),"") | BA16: 16 | BC16: =IF(ISERROR(VLOOKUP(BA16,$BD$1:$BE$366,2,FALSE))=FALSE,VLOOKUP(BA16,$BD$1:$BE$366,2,FALSE),0) -> 0 | BD16: =IF(COUNTIF(Kassza!$C$7:$C$10000,BE16)<>0,BD15+1,BD15) -> 0 | BE16: =BE15+1 -> 46038 | BF16: =ROUNDUP(COUNTIF(Kassza!$C$7:$C$10000,BE16)/30,0) -> 0 | BG16: =SUM($BF$1:BF15) -> 0
A17: =IF($M$1>=M17,M17,"") | B17: =IF($M$1>=M17,TRIM(VLOOKUP(M17,Kassza!$B$7:$N$10000,4,FALSE)),"") | C17: =IF($M$1>=M17,TRIM(VLOOKUP(M17,Kassza!$B$7:$N$10000,5,FALSE)),"") | D17: =TRIM(IF($M$1>=M17,O17&" "&P17&" "&Q17,IF($M$1=M16,$T$3,IF($M$1=M15,$T$4&G4,"")))) | E17: =IF($M$1>=M17,IF(VLOOKUP(M17,Kassza!$B$7:$N$10000,7,FALSE)<>0,VLOOKUP(M17,Kassza!$B$7:$N$10000,7,FALSE),""),IF($M$1=M16,SUM($E$8:E16),IF($M$1=M15,SUM(E16,-F16),""))) | F17: =IF($M$1>=M17,IF(VLOOKUP(M17,Kassza!$B$7:$N$10000,9,FALSE)<>0,VLOOKUP(M17,Kassza!$B$7:$N$10000,9,FALSE),""),IF($M$1=M16,SUM($F$8:F16),"")) | G17: =IF($M$1>=M17,TRIM(VLOOKUP(M17,Kassza!$B$7:$N$10000,13,FALSE)),"") | M17: =M16+1 -> 9 | O17: =IF($M$1>=M17,TRIM(VLOOKUP(M17,Kassza!$B$7:$N$10000,12,FALSE)),"") | P17: =IF($M$1>=M17,TRIM(VLOOKUP(M17,Kassza!$B$7:$N$10000,6,FALSE)),"") | Q17: =IF($M$1>=M17,TRIM(VLOOKUP(M17,Kassza!$B$7:$N$10000,11,FALSE)),"") | BA17: 17 | BC17: =IF(ISERROR(VLOOKUP(BA17,$BD$1:$BE$366,2,FALSE))=FALSE,VLOOKUP(BA17,$BD$1:$BE$366,2,FALSE),0) -> 0 | BD17: =IF(COUNTIF(Kassza!$C$7:$C$10000,BE17)<>0,BD16+1,BD16) -> 0 | BE17: =BE16+1 -> 46039 | BF17: =ROUNDUP(COUNTIF(Kassza!$C$7:$C$10000,BE17)/30,0) -> 0 | BG17: =SUM($BF$1:BF16) -> 0
A18: =IF($M$1>=M18,M18,"") | B18: =IF($M$1>=M18,TRIM(VLOOKUP(M18,Kassza!$B$7:$N$10000,4,FALSE)),"") | C18: =IF($M$1>=M18,TRIM(VLOOKUP(M18,Kassza!$B$7:$N$10000,5,FALSE)),"") | D18: =TRIM(IF($M$1>=M18,O18&" "&P18&" "&Q18,IF($M$1=M17,$T$3,IF($M$1=M16,$T$4&G4,"")))) | E18: =IF($M$1>=M18,IF(VLOOKUP(M18,Kassza!$B$7:$N$10000,7,FALSE)<>0,VLOOKUP(M18,Kassza!$B$7:$N$10000,7,FALSE),""),IF($M$1=M17,SUM($E$8:E17),IF($M$1=M16,SUM(E17,-F17),""))) | F18: =IF($M$1>=M18,IF(VLOOKUP(M18,Kassza!$B$7:$N$10000,9,FALSE)<>0,VLOOKUP(M18,Kassza!$B$7:$N$10000,9,FALSE),""),IF($M$1=M17,SUM($F$8:F17),"")) | G18: =IF($M$1>=M18,TRIM(VLOOKUP(M18,Kassza!$B$7:$N$10000,13,FALSE)),"") | M18: =M17+1 -> 10 | O18: =IF($M$1>=M18,TRIM(VLOOKUP(M18,Kassza!$B$7:$N$10000,12,FALSE)),"") | P18: =IF($M$1>=M18,TRIM(VLOOKUP(M18,Kassza!$B$7:$N$10000,6,FALSE)),"") | Q18: =IF($M$1>=M18,TRIM(VLOOKUP(M18,Kassza!$B$7:$N$10000,11,FALSE)),"") | BA18: 18 | BC18: =IF(ISERROR(VLOOKUP(BA18,$BD$1:$BE$366,2,FALSE))=FALSE,VLOOKUP(BA18,$BD$1:$BE$366,2,FALSE),0) -> 0 | BD18: =IF(COUNTIF(Kassza!$C$7:$C$10000,BE18)<>0,BD17+1,BD17) -> 0 | BE18: =BE17+1 -> 46040 | BF18: =ROUNDUP(COUNTIF(Kassza!$C$7:$C$10000,BE18)/30,0) -> 0 | BG18: =SUM($BF$1:BF17) -> 0
A19: =IF($M$1>=M19,M19,"") | B19: =IF($M$1>=M19,TRIM(VLOOKUP(M19,Kassza!$B$7:$N$10000,4,FALSE)),"") | C19: =IF($M$1>=M19,TRIM(VLOOKUP(M19,Kassza!$B$7:$N$10000,5,FALSE)),"") | D19: =TRIM(IF($M$1>=M19,O19&" "&P19&" "&Q19,IF($M$1=M18,$T$3,IF($M$1=M17,$T$4&G4,"")))) | E19: =IF($M$1>=M19,IF(VLOOKUP(M19,Kassza!$B$7:$N$10000,7,FALSE)<>0,VLOOKUP(M19,Kassza!$B$7:$N$10000,7,FALSE),""),IF($M$1=M18,SUM($E$8:E18),IF($M$1=M17,SUM(E18,-F18),""))) | F19: =IF($M$1>=M19,IF(VLOOKUP(M19,Kassza!$B$7:$N$10000,9,FALSE)<>0,VLOOKUP(M19,Kassza!$B$7:$N$10000,9,FALSE),""),IF($M$1=M18,SUM($F$8:F18),"")) | G19: =IF($M$1>=M19,TRIM(VLOOKUP(M19,Kassza!$B$7:$N$10000,13,FALSE)),"") | M19: =M18+1 -> 11 | O19: =IF($M$1>=M19,TRIM(VLOOKUP(M19,Kassza!$B$7:$N$10000,12,FALSE)),"") | P19: =IF($M$1>=M19,TRIM(VLOOKUP(M19,Kassza!$B$7:$N$10000,6,FALSE)),"") | Q19: =IF($M$1>=M19,TRIM(VLOOKUP(M19,Kassza!$B$7:$N$10000,11,FALSE)),"") | BA19: 19 | BC19: =IF(ISERROR(VLOOKUP(BA19,$BD$1:$BE$366,2,FALSE))=FALSE,VLOOKUP(BA19,$BD$1:$BE$366,2,FALSE),0) -> 0 | BD19: =IF(COUNTIF(Kassza!$C$7:$C$10000,BE19)<>0,BD18+1,BD18) -> 0 | BE19: =BE18+1 -> 46041 | BF19: =ROUNDUP(COUNTIF(Kassza!$C$7:$C$10000,BE19)/30,0) -> 0 | BG19: =SUM($BF$1:BF18) -> 0
A20: =IF($M$1>=M20,M20,"") | B20: =IF($M$1>=M20,TRIM(VLOOKUP(M20,Kassza!$B$7:$N$10000,4,FALSE)),"") | C20: =IF($M$1>=M20,TRIM(VLOOKUP(M20,Kassza!$B$7:$N$10000,5,FALSE)),"") | D20: =TRIM(IF($M$1>=M20,O20&" "&P20&" "&Q20,IF($M$1=M19,$T$3,IF($M$1=M18,$T$4&G4,"")))) | E20: =IF($M$1>=M20,IF(VLOOKUP(M20,Kassza!$B$7:$N$10000,7,FALSE)<>0,VLOOKUP(M20,Kassza!$B$7:$N$10000,7,FALSE),""),IF($M$1=M19,SUM($E$8:E19),IF($M$1=M18,SUM(E19,-F19),""))) | F20: =IF($M$1>=M20,IF(VLOOKUP(M20,Kassza!$B$7:$N$10000,9,FALSE)<>0,VLOOKUP(M20,Kassza!$B$7:$N$10000,9,FALSE),""),IF($M$1=M19,SUM($F$8:F19),"")) | G20: =IF($M$1>=M20,TRIM(VLOOKUP(M20,Kassza!$B$7:$N$10000,13,FALSE)),"") | M20: =M19+1 -> 12 | O20: =IF($M$1>=M20,TRIM(VLOOKUP(M20,Kassza!$B$7:$N$10000,12,FALSE)),"") | P20: =IF($M$1>=M20,TRIM(VLOOKUP(M20,Kassza!$B$7:$N$10000,6,FALSE)),"") | Q20: =IF($M$1>=M20,TRIM(VLOOKUP(M20,Kassza!$B$7:$N$10000,11,FALSE)),"") | BA20: 20 | BC20: =IF(ISERROR(VLOOKUP(BA20,$BD$1:$BE$366,2,FALSE))=FALSE,VLOOKUP(BA20,$BD$1:$BE$366,2,FALSE),0) -> 0 | BD20: =IF(COUNTIF(Kassza!$C$7:$C$10000,BE20)<>0,BD19+1,BD19) -> 0 | BE20: =BE19+1 -> 46042 | BF20: =ROUNDUP(COUNTIF(Kassza!$C$7:$C$10000,BE20)/30,0) -> 0 | BG20: =SUM($BF$1:BF19) -> 0
A21: =IF($M$1>=M21,M21,"") | B21: =IF($M$1>=M21,TRIM(VLOOKUP(M21,Kassza!$B$7:$N$10000,4,FALSE)),"") | C21: =IF($M$1>=M21,TRIM(VLOOKUP(M21,Kassza!$B$7:$N$10000,5,FALSE)),"") | D21: =TRIM(IF($M$1>=M21,O21&" "&P21&" "&Q21,IF($M$1=M20,$T$3,IF($M$1=M19,$T$4&G4,"")))) | E21: =IF($M$1>=M21,IF(VLOOKUP(M21,Kassza!$B$7:$N$10000,7,FALSE)<>0,VLOOKUP(M21,Kassza!$B$7:$N$10000,7,FALSE),""),IF($M$1=M20,SUM($E$8:E20),IF($M$1=M19,SUM(E20,-F20),""))) | F21: =IF($M$1>=M21,IF(VLOOKUP(M21,Kassza!$B$7:$N$10000,9,FALSE)<>0,VLOOKUP(M21,Kassza!$B$7:$N$10000,9,FALSE),""),IF($M$1=M20,SUM($F$8:F20),"")) | G21: =IF($M$1>=M21,TRIM(VLOOKUP(M21,Kassza!$B$7:$N$10000,13,FALSE)),"") | M21: =M20+1 -> 13 | O21: =IF($M$1>=M21,TRIM(VLOOKUP(M21,Kassza!$B$7:$N$10000,12,FALSE)),"") | P21: =IF($M$1>=M21,TRIM(VLOOKUP(M21,Kassza!$B$7:$N$10000,6,FALSE)),"") | Q21: =IF($M$1>=M21,TRIM(VLOOKUP(M21,Kassza!$B$7:$N$10000,11,FALSE)),"") | BA21: 21 | BC21: =IF(ISERROR(VLOOKUP(BA21,$BD$1:$BE$366,2,FALSE))=FALSE,VLOOKUP(BA21,$BD$1:$BE$366,2,FALSE),0) -> 0 | BD21: =IF(COUNTIF(Kassza!$C$7:$C$10000,BE21)<>0,BD20+1,BD20) -> 0 | BE21: =BE20+1 -> 46043 | BF21: =ROUNDUP(COUNTIF(Kassza!$C$7:$C$10000,BE21)/30,0) -> 0 | BG21: =SUM($BF$1:BF20) -> 0
A22: =IF($M$1>=M22,M22,"") | B22: =IF($M$1>=M22,TRIM(VLOOKUP(M22,Kassza!$B$7:$N$10000,4,FALSE)),"") | C22: =IF($M$1>=M22,TRIM(VLOOKUP(M22,Kassza!$B$7:$N$10000,5,FALSE)),"") | D22: =TRIM(IF($M$1>=M22,O22&" "&P22&" "&Q22,IF($M$1=M21,$T$3,IF($M$1=M20,$T$4&G4,"")))) | E22: =IF($M$1>=M22,IF(VLOOKUP(M22,Kassza!$B$7:$N$10000,7,FALSE)<>0,VLOOKUP(M22,Kassza!$B$7:$N$10000,7,FALSE),""),IF($M$1=M21,SUM($E$8:E21),IF($M$1=M20,SUM(E21,-F21),""))) | F22: =IF($M$1>=M22,IF(VLOOKUP(M22,Kassza!$B$7:$N$10000,9,FALSE)<>0,VLOOKUP(M22,Kassza!$B$7:$N$10000,9,FALSE),""),IF($M$1=M21,SUM($F$8:F21),"")) | G22: =IF($M$1>=M22,TRIM(VLOOKUP(M22,Kassza!$B$7:$N$10000,13,FALSE)),"") | M22: =M21+1 -> 14 | O22: =IF($M$1>=M22,TRIM(VLOOKUP(M22,Kassza!$B$7:$N$10000,12,FALSE)),"") | P22: =IF($M$1>=M22,TRIM(VLOOKUP(M22,Kassza!$B$7:$N$10000,6,FALSE)),"") | Q22: =IF($M$1>=M22,TRIM(VLOOKUP(M22,Kassza!$B$7:$N$10000,11,FALSE)),"") | BA22: 22 | BC22: =IF(ISERROR(VLOOKUP(BA22,$BD$1:$BE$366,2,FALSE))=FALSE,VLOOKUP(BA22,$BD$1:$BE$366,2,FALSE),0) -> 0 | BD22: =IF(COUNTIF(Kassza!$C$7:$C$10000,BE22)<>0,BD21+1,BD21) -> 0 | BE22: =BE21+1 -> 46044 | BF22: =ROUNDUP(COUNTIF(Kassza!$C$7:$C$10000,BE22)/30,0) -> 0 | BG22: =SUM($BF$1:BF21) -> 0
A23: =IF($M$1>=M23,M23,"") | B23: =IF($M$1>=M23,TRIM(VLOOKUP(M23,Kassza!$B$7:$N$10000,4,FALSE)),"") | C23: =IF($M$1>=M23,TRIM(VLOOKUP(M23,Kassza!$B$7:$N$10000,5,FALSE)),"") | D23: =TRIM(IF($M$1>=M23,O23&" "&P23&" "&Q23,IF($M$1=M22,$T$3,IF($M$1=M21,$T$4&G4,"")))) | E23: =IF($M$1>=M23,IF(VLOOKUP(M23,Kassza!$B$7:$N$10000,7,FALSE)<>0,VLOOKUP(M23,Kassza!$B$7:$N$10000,7,FALSE),""),IF($M$1=M22,SUM($E$8:E22),IF($M$1=M21,SUM(E22,-F22),""))) | F23: =IF($M$1>=M23,IF(VLOOKUP(M23,Kassza!$B$7:$N$10000,9,FALSE)<>0,VLOOKUP(M23,Kassza!$B$7:$N$10000,9,FALSE),""),IF($M$1=M22,SUM($F$8:F22),"")) | G23: =IF($M$1>=M23,TRIM(VLOOKUP(M23,Kassza!$B$7:$N$10000,13,FALSE)),"") | M23: =M22+1 -> 15 | O23: =IF($M$1>=M23,TRIM(VLOOKUP(M23,Kassza!$B$7:$N$10000,12,FALSE)),"") | P23: =IF($M$1>=M23,TRIM(VLOOKUP(M23,Kassza!$B$7:$N$10000,6,FALSE)),"") | Q23: =IF($M$1>=M23,TRIM(VLOOKUP(M23,Kassza!$B$7:$N$10000,11,FALSE)),"") | BA23: 23 | BC23: =IF(ISERROR(VLOOKUP(BA23,$BD$1:$BE$366,2,FALSE))=FALSE,VLOOKUP(BA23,$BD$1:$BE$366,2,FALSE),0) -> 0 | BD23: =IF(COUNTIF(Kassza!$C$7:$C$10000,BE23)<>0,BD22+1,BD22) -> 0 | BE23: =BE22+1 -> 46045 | BF23: =ROUNDUP(COUNTIF(Kassza!$C$7:$C$10000,BE23)/30,0) -> 0 | BG23: =SUM($BF$1:BF22) -> 0
A24: =IF($M$1>=M24,M24,"") | B24: =IF($M$1>=M24,TRIM(VLOOKUP(M24,Kassza!$B$7:$N$10000,4,FALSE)),"") | C24: =IF($M$1>=M24,TRIM(VLOOKUP(M24,Kassza!$B$7:$N$10000,5,FALSE)),"") | D24: =TRIM(IF($M$1>=M24,O24&" "&P24&" "&Q24,IF($M$1=M23,$T$3,IF($M$1=M22,$T$4&G4,"")))) | E24: =IF($M$1>=M24,IF(VLOOKUP(M24,Kassza!$B$7:$N$10000,7,FALSE)<>0,VLOOKUP(M24,Kassza!$B$7:$N$10000,7,FALSE),""),IF($M$1=M23,SUM($E$8:E23),IF($M$1=M22,SUM(E23,-F23),""))) | F24: =IF($M$1>=M24,IF(VLOOKUP(M24,Kassza!$B$7:$N$10000,9,FALSE)<>0,VLOOKUP(M24,Kassza!$B$7:$N$10000,9,FALSE),""),IF($M$1=M23,SUM($F$8:F23),"")) | G24: =IF($M$1>=M24,TRIM(VLOOKUP(M24,Kassza!$B$7:$N$10000,13,FALSE)),"") | M24: =M23+1 -> 16 | O24: =IF($M$1>=M24,TRIM(VLOOKUP(M24,Kassza!$B$7:$N$10000,12,FALSE)),"") | P24: =IF($M$1>=M24,TRIM(VLOOKUP(M24,Kassza!$B$7:$N$10000,6,FALSE)),"") | Q24: =IF($M$1>=M24,TRIM(VLOOKUP(M24,Kassza!$B$7:$N$10000,11,FALSE)),"") | BA24: 24 | BC24: =IF(ISERROR(VLOOKUP(BA24,$BD$1:$BE$366,2,FALSE))=FALSE,VLOOKUP(BA24,$BD$1:$BE$366,2,FALSE),0) -> 0 | BD24: =IF(COUNTIF(Kassza!$C$7:$C$10000,BE24)<>0,BD23+1,BD23) -> 0 | BE24: =BE23+1 -> 46046 | BF24: =ROUNDUP(COUNTIF(Kassza!$C$7:$C$10000,BE24)/30,0) -> 0 | BG24: =SUM($BF$1:BF23) -> 0
A25: =IF($M$1>=M25,M25,"") | B25: =IF($M$1>=M25,TRIM(VLOOKUP(M25,Kassza!$B$7:$N$10000,4,FALSE)),"") | C25: =IF($M$1>=M25,TRIM(VLOOKUP(M25,Kassza!$B$7:$N$10000,5,FALSE)),"") | D25: =TRIM(IF($M$1>=M25,O25&" "&P25&" "&Q25,IF($M$1=M24,$T$3,IF($M$1=M23,$T$4&G4,"")))) | E25: =IF($M$1>=M25,IF(VLOOKUP(M25,Kassza!$B$7:$N$10000,7,FALSE)<>0,VLOOKUP(M25,Kassza!$B$7:$N$10000,7,FALSE),""),IF($M$1=M24,SUM($E$8:E24),IF($M$1=M23,SUM(E24,-F24),""))) | F25: =IF($M$1>=M25,IF(VLOOKUP(M25,Kassza!$B$7:$N$10000,9,FALSE)<>0,VLOOKUP(M25,Kassza!$B$7:$N$10000,9,FALSE),""),IF($M$1=M24,SUM($F$8:F24),"")) | G25: =IF($M$1>=M25,TRIM(VLOOKUP(M25,Kassza!$B$7:$N$10000,13,FALSE)),"") | M25: =M24+1 -> 17 | O25: =IF($M$1>=M25,TRIM(VLOOKUP(M25,Kassza!$B$7:$N$10000,12,FALSE)),"") | P25: =IF($M$1>=M25,TRIM(VLOOKUP(M25,Kassza!$B$7:$N$10000,6,FALSE)),"") | Q25: =IF($M$1>=M25,TRIM(VLOOKUP(M25,Kassza!$B$7:$N$10000,11,FALSE)),"") | BA25: 25 | BC25: =IF(ISERROR(VLOOKUP(BA25,$BD$1:$BE$366,2,FALSE))=FALSE,VLOOKUP(BA25,$BD$1:$BE$366,2,FALSE),0) -> 0 | BD25: =IF(COUNTIF(Kassza!$C$7:$C$10000,BE25)<>0,BD24+1,BD24) -> 0 | BE25: =BE24+1 -> 46047 | BF25: =ROUNDUP(COUNTIF(Kassza!$C$7:$C$10000,BE25)/30,0) -> 0 | BG25: =SUM($BF$1:BF24) -> 0
A26: =IF($M$1>=M26,M26,"") | B26: =IF($M$1>=M26,TRIM(VLOOKUP(M26,Kassza!$B$7:$N$10000,4,FALSE)),"") | C26: =IF($M$1>=M26,TRIM(VLOOKUP(M26,Kassza!$B$7:$N$10000,5,FALSE)),"") | D26: =TRIM(IF($M$1>=M26,O26&" "&P26&" "&Q26,IF($M$1=M25,$T$3,IF($M$1=M24,$T$4&G4,"")))) | E26: =IF($M$1>=M26,IF(VLOOKUP(M26,Kassza!$B$7:$N$10000,7,FALSE)<>0,VLOOKUP(M26,Kassza!$B$7:$N$10000,7,FALSE),""),IF($M$1=M25,SUM($E$8:E25),IF($M$1=M24,SUM(E25,-F25),""))) | F26: =IF($M$1>=M26,IF(VLOOKUP(M26,Kassza!$B$7:$N$10000,9,FALSE)<>0,VLOOKUP(M26,Kassza!$B$7:$N$10000,9,FALSE),""),IF($M$1=M25,SUM($F$8:F25),"")) | G26: =IF($M$1>=M26,TRIM(VLOOKUP(M26,Kassza!$B$7:$N$10000,13,FALSE)),"") | M26: =M25+1 -> 18 | O26: =IF($M$1>=M26,TRIM(VLOOKUP(M26,Kassza!$B$7:$N$10000,12,FALSE)),"") | P26: =IF($M$1>=M26,TRIM(VLOOKUP(M26,Kassza!$B$7:$N$10000,6,FALSE)),"") | Q26: =IF($M$1>=M26,TRIM(VLOOKUP(M26,Kassza!$B$7:$N$10000,11,FALSE)),"") | BA26: 26 | BC26: =IF(ISERROR(VLOOKUP(BA26,$BD$1:$BE$366,2,FALSE))=FALSE,VLOOKUP(BA26,$BD$1:$BE$366,2,FALSE),0) -> 0 | BD26: =IF(COUNTIF(Kassza!$C$7:$C$10000,BE26)<>0,BD25+1,BD25) -> 0 | BE26: =BE25+1 -> 46048 | BF26: =ROUNDUP(COUNTIF(Kassza!$C$7:$C$10000,BE26)/30,0) -> 0 | BG26: =SUM($BF$1:BF25) -> 0
A27: =IF($M$1>=M27,M27,"") | B27: =IF($M$1>=M27,TRIM(VLOOKUP(M27,Kassza!$B$7:$N$10000,4,FALSE)),"") | C27: =IF($M$1>=M27,TRIM(VLOOKUP(M27,Kassza!$B$7:$N$10000,5,FALSE)),"") | D27: =TRIM(IF($M$1>=M27,O27&" "&P27&" "&Q27,IF($M$1=M26,$T$3,IF($M$1=M25,$T$4&G4,"")))) | E27: =IF($M$1>=M27,IF(VLOOKUP(M27,Kassza!$B$7:$N$10000,7,FALSE)<>0,VLOOKUP(M27,Kassza!$B$7:$N$10000,7,FALSE),""),IF($M$1=M26,SUM($E$8:E26),IF($M$1=M25,SUM(E26,-F26),""))) | F27: =IF($M$1>=M27,IF(VLOOKUP(M27,Kassza!$B$7:$N$10000,9,FALSE)<>0,VLOOKUP(M27,Kassza!$B$7:$N$10000,9,FALSE),""),IF($M$1=M26,SUM($F$8:F26),"")) | G27: =IF($M$1>=M27,TRIM(VLOOKUP(M27,Kassza!$B$7:$N$10000,13,FALSE)),"") | M27: =M26+1 -> 19 | O27: =IF($M$1>=M27,TRIM(VLOOKUP(M27,Kassza!$B$7:$N$10000,12,FALSE)),"") | P27: =IF($M$1>=M27,TRIM(VLOOKUP(M27,Kassza!$B$7:$N$10000,6,FALSE)),"") | Q27: =IF($M$1>=M27,TRIM(VLOOKUP(M27,Kassza!$B$7:$N$10000,11,FALSE)),"") | BA27: 27 | BC27: =IF(ISERROR(VLOOKUP(BA27,$BD$1:$BE$366,2,FALSE))=FALSE,VLOOKUP(BA27,$BD$1:$BE$366,2,FALSE),0) -> 0 | BD27: =IF(COUNTIF(Kassza!$C$7:$C$10000,BE27)<>0,BD26+1,BD26) -> 0 | BE27: =BE26+1 -> 46049 | BF27: =ROUNDUP(COUNTIF(Kassza!$C$7:$C$10000,BE27)/30,0) -> 0 | BG27: =SUM($BF$1:BF26) -> 0
A28: =IF($M$1>=M28,M28,"") | B28: =IF($M$1>=M28,TRIM(VLOOKUP(M28,Kassza!$B$7:$N$10000,4,FALSE)),"") | C28: =IF($M$1>=M28,TRIM(VLOOKUP(M28,Kassza!$B$7:$N$10000,5,FALSE)),"") | D28: =TRIM(IF($M$1>=M28,O28&" "&P28&" "&Q28,IF($M$1=M27,$T$3,IF($M$1=M26,$T$4&G4,"")))) | E28: =IF($M$1>=M28,IF(VLOOKUP(M28,Kassza!$B$7:$N$10000,7,FALSE)<>0,VLOOKUP(M28,Kassza!$B$7:$N$10000,7,FALSE),""),IF($M$1=M27,SUM($E$8:E27),IF($M$1=M26,SUM(E27,-F27),""))) | F28: =IF($M$1>=M28,IF(VLOOKUP(M28,Kassza!$B$7:$N$10000,9,FALSE)<>0,VLOOKUP(M28,Kassza!$B$7:$N$10000,9,FALSE),""),IF($M$1=M27,SUM($F$8:F27),"")) | G28: =IF($M$1>=M28,TRIM(VLOOKUP(M28,Kassza!$B$7:$N$10000,13,FALSE)),"") | M28: =M27+1 -> 20 | O28: =IF($M$1>=M28,TRIM(VLOOKUP(M28,Kassza!$B$7:$N$10000,12,FALSE)),"") | P28: =IF($M$1>=M28,TRIM(VLOOKUP(M28,Kassza!$B$7:$N$10000,6,FALSE)),"") | Q28: =IF($M$1>=M28,TRIM(VLOOKUP(M28,Kassza!$B$7:$N$10000,11,FALSE)),"") | BA28: 28 | BC28: =IF(ISERROR(VLOOKUP(BA28,$BD$1:$BE$366,2,FALSE))=FALSE,VLOOKUP(BA28,$BD$1:$BE$366,2,FALSE),0) -> 0 | BD28: =IF(COUNTIF(Kassza!$C$7:$C$10000,BE28)<>0,BD27+1,BD27) -> 0 | BE28: =BE27+1 -> 46050 | BF28: =ROUNDUP(COUNTIF(Kassza!$C$7:$C$10000,BE28)/30,0) -> 0 | BG28: =SUM($BF$1:BF27) -> 0
A29: =IF($M$1>=M29,M29,"") | B29: =IF($M$1>=M29,TRIM(VLOOKUP(M29,Kassza!$B$7:$N$10000,4,FALSE)),"") | C29: =IF($M$1>=M29,TRIM(VLOOKUP(M29,Kassza!$B$7:$N$10000,5,FALSE)),"") | D29: =TRIM(IF($M$1>=M29,O29&" "&P29&" "&Q29,IF($M$1=M28,$T$3,IF($M$1=M27,$T$4&G4,"")))) | E29: =IF($M$1>=M29,IF(VLOOKUP(M29,Kassza!$B$7:$N$10000,7,FALSE)<>0,VLOOKUP(M29,Kassza!$B$7:$N$10000,7,FALSE),""),IF($M$1=M28,SUM($E$8:E28),IF($M$1=M27,SUM(E28,-F28),""))) | F29: =IF($M$1>=M29,IF(VLOOKUP(M29,Kassza!$B$7:$N$10000,9,FALSE)<>0,VLOOKUP(M29,Kassza!$B$7:$N$10000,9,FALSE),""),IF($M$1=M28,SUM($F$8:F28),"")) | G29: =IF($M$1>=M29,TRIM(VLOOKUP(M29,Kassza!$B$7:$N$10000,13,FALSE)),"") | M29: =M28+1 -> 21 | O29: =IF($M$1>=M29,TRIM(VLOOKUP(M29,Kassza!$B$7:$N$10000,12,FALSE)),"") | P29: =IF($M$1>=M29,TRIM(VLOOKUP(M29,Kassza!$B$7:$N$10000,6,FALSE)),"") | Q29: =IF($M$1>=M29,TRIM(VLOOKUP(M29,Kassza!$B$7:$N$10000,11,FALSE)),"") | BA29: 29 | BC29: =IF(ISERROR(VLOOKUP(BA29,$BD$1:$BE$366,2,FALSE))=FALSE,VLOOKUP(BA29,$BD$1:$BE$366,2,FALSE),0) -> 0 | BD29: =IF(COUNTIF(Kassza!$C$7:$C$10000,BE29)<>0,BD28+1,BD28) -> 0 | BE29: =BE28+1 -> 46051 | BF29: =ROUNDUP(COUNTIF(Kassza!$C$7:$C$10000,BE29)/30,0) -> 0 | BG29: =SUM($BF$1:BF28) -> 0
A30: =IF($M$1>=M30,M30,"") | B30: =IF($M$1>=M30,TRIM(VLOOKUP(M30,Kassza!$B$7:$N$10000,4,FALSE)),"") | C30: =IF($M$1>=M30,TRIM(VLOOKUP(M30,Kassza!$B$7:$N$10000,5,FALSE)),"") | D30: =TRIM(IF($M$1>=M30,O30&" "&P30&" "&Q30,IF($M$1=M29,$T$3,IF($M$1=M28,$T$4&G4,"")))) | E30: =IF($M$1>=M30,IF(VLOOKUP(M30,Kassza!$B$7:$N$10000,7,FALSE)<>0,VLOOKUP(M30,Kassza!$B$7:$N$10000,7,FALSE),""),IF($M$1=M29,SUM($E$8:E29),IF($M$1=M28,SUM(E29,-F29),""))) | F30: =IF($M$1>=M30,IF(VLOOKUP(M30,Kassza!$B$7:$N$10000,9,FALSE)<>0,VLOOKUP(M30,Kassza!$B$7:$N$10000,9,FALSE),""),IF($M$1=M29,SUM($F$8:F29),"")) | G30: =IF($M$1>=M30,TRIM(VLOOKUP(M30,Kassza!$B$7:$N$10000,13,FALSE)),"") | M30: =M29+1 -> 22 | O30: =IF($M$1>=M30,TRIM(VLOOKUP(M30,Kassza!$B$7:$N$10000,12,FALSE)),"") | P30: =IF($M$1>=M30,TRIM(VLOOKUP(M30,Kassza!$B$7:$N$10000,6,FALSE)),"") | Q30: =IF($M$1>=M30,TRIM(VLOOKUP(M30,Kassza!$B$7:$N$10000,11,FALSE)),"") | BA30: 30 | BC30: =IF(ISERROR(VLOOKUP(BA30,$BD$1:$BE$366,2,FALSE))=FALSE,VLOOKUP(BA30,$BD$1:$BE$366,2,FALSE),0) -> 0 | BD30: =IF(COUNTIF(Kassza!$C$7:$C$10000,BE30)<>0,BD29+1,BD29) -> 0 | BE30: =BE29+1 -> 46052 | BF30: =ROUNDUP(COUNTIF(Kassza!$C$7:$C$10000,BE30)/30,0) -> 0 | BG30: =SUM($BF$1:BF29) -> 0
A31: =IF($M$1>=M31,M31,"") | B31: =IF($M$1>=M31,TRIM(VLOOKUP(M31,Kassza!$B$7:$N$10000,4,FALSE)),"") | C31: =IF($M$1>=M31,TRIM(VLOOKUP(M31,Kassza!$B$7:$N$10000,5,FALSE)),"") | D31: =TRIM(IF($M$1>=M31,O31&" "&P31&" "&Q31,IF($M$1=M30,$T$3,IF($M$1=M29,$T$4&G4,"")))) | E31: =IF($M$1>=M31,IF(VLOOKUP(M31,Kassza!$B$7:$N$10000,7,FALSE)<>0,VLOOKUP(M31,Kassza!$B$7:$N$10000,7,FALSE),""),IF($M$1=M30,SUM($E$8:E30),IF($M$1=M29,SUM(E30,-F30),""))) | F31: =IF($M$1>=M31,IF(VLOOKUP(M31,Kassza!$B$7:$N$10000,9,FALSE)<>0,VLOOKUP(M31,Kassza!$B$7:$N$10000,9,FALSE),""),IF($M$1=M30,SUM($F$8:F30),"")) | G31: =IF($M$1>=M31,TRIM(VLOOKUP(M31,Kassza!$B$7:$N$10000,13,FALSE)),"") | M31: =M30+1 -> 23 | O31: =IF($M$1>=M31,TRIM(VLOOKUP(M31,Kassza!$B$7:$N$10000,12,FALSE)),"") | P31: =IF($M$1>=M31,TRIM(VLOOKUP(M31,Kassza!$B$7:$N$10000,6,FALSE)),"") | Q31: =IF($M$1>=M31,TRIM(VLOOKUP(M31,Kassza!$B$7:$N$10000,11,FALSE)),"") | BA31: 31 | BC31: =IF(ISERROR(VLOOKUP(BA31,$BD$1:$BE$366,2,FALSE))=FALSE,VLOOKUP(BA31,$BD$1:$BE$366,2,FALSE),0) -> 0 | BD31: =IF(COUNTIF(Kassza!$C$7:$C$10000,BE31)<>0,BD30+1,BD30) -> 0 | BE31: =BE30+1 -> 46053 | BF31: =ROUNDUP(COUNTIF(Kassza!$C$7:$C$10000,BE31)/30,0) -> 0 | BG31: =SUM($BF$1:BF30) -> 0
A32: =IF($M$1>=M32,M32,"") | B32: =IF($M$1>=M32,TRIM(VLOOKUP(M32,Kassza!$B$7:$N$10000,4,FALSE)),"") | C32: =IF($M$1>=M32,TRIM(VLOOKUP(M32,Kassza!$B$7:$N$10000,5,FALSE)),"") | D32: =TRIM(IF($M$1>=M32,O32&" "&P32&" "&Q32,IF($M$1=M31,$T$3,IF($M$1=M30,$T$4&G4,"")))) | E32: =IF($M$1>=M32,IF(VLOOKUP(M32,Kassza!$B$7:$N$10000,7,FALSE)<>0,VLOOKUP(M32,Kassza!$B$7:$N$10000,7,FALSE),""),IF($M$1=M31,SUM($E$8:E31),IF($M$1=M30,SUM(E31,-F31),""))) | F32: =IF($M$1>=M32,IF(VLOOKUP(M32,Kassza!$B$7:$N$10000,9,FALSE)<>0,VLOOKUP(M32,Kassza!$B$7:$N$10000,9,FALSE),""),IF($M$1=M31,SUM($F$8:F31),"")) | G32: =IF($M$1>=M32,TRIM(VLOOKUP(M32,Kassza!$B$7:$N$10000,13,FALSE)),"") | M32: =M31+1 -> 24 | O32: =IF($M$1>=M32,TRIM(VLOOKUP(M32,Kassza!$B$7:$N$10000,12,FALSE)),"") | P32: =IF($M$1>=M32,TRIM(VLOOKUP(M32,Kassza!$B$7:$N$10000,6,FALSE)),"") | Q32: =IF($M$1>=M32,TRIM(VLOOKUP(M32,Kassza!$B$7:$N$10000,11,FALSE)),"") | BA32: 32 | BC32: =IF(ISERROR(VLOOKUP(BA32,$BD$1:$BE$366,2,FALSE))=FALSE,VLOOKUP(BA32,$BD$1:$BE$366,2,FALSE),0) -> 0 | BD32: =IF(COUNTIF(Kassza!$C$7:$C$10000,BE32)<>0,BD31+1,BD31) -> 0 | BE32: =BE31+1 -> 46054 | BF32: =ROUNDUP(COUNTIF(Kassza!$C$7:$C$10000,BE32)/30,0) -> 0 | BG32: =SUM($BF$1:BF31) -> 0
A33: =IF($M$1>=M33,M33,"") | B33: =IF($M$1>=M33,TRIM(VLOOKUP(M33,Kassza!$B$7:$N$10000,4,FALSE)),"") | C33: =IF($M$1>=M33,TRIM(VLOOKUP(M33,Kassza!$B$7:$N$10000,5,FALSE)),"") | D33: =TRIM(IF($M$1>=M33,O33&" "&P33&" "&Q33,IF($M$1=M32,$T$3,IF($M$1=M31,$T$4&G4,"")))) | E33: =IF($M$1>=M33,IF(VLOOKUP(M33,Kassza!$B$7:$N$10000,7,FALSE)<>0,VLOOKUP(M33,Kassza!$B$7:$N$10000,7,FALSE),""),IF($M$1=M32,SUM($E$8:E32),IF($M$1=M31,SUM(E32,-F32),""))) | F33: =IF($M$1>=M33,IF(VLOOKUP(M33,Kassza!$B$7:$N$10000,9,FALSE)<>0,VLOOKUP(M33,Kassza!$B$7:$N$10000,9,FALSE),""),IF($M$1=M32,SUM($F$8:F32),"")) | G33: =IF($M$1>=M33,TRIM(VLOOKUP(M33,Kassza!$B$7:$N$10000,13,FALSE)),"") | M33: =M32+1 -> 25 | O33: =IF($M$1>=M33,TRIM(VLOOKUP(M33,Kassza!$B$7:$N$10000,12,FALSE)),"") | P33: =IF($M$1>=M33,TRIM(VLOOKUP(M33,Kassza!$B$7:$N$10000,6,FALSE)),"") | Q33: =IF($M$1>=M33,TRIM(VLOOKUP(M33,Kassza!$B$7:$N$10000,11,FALSE)),"") | BA33: 33 | BC33: =IF(ISERROR(VLOOKUP(BA33,$BD$1:$BE$366,2,FALSE))=FALSE,VLOOKUP(BA33,$BD$1:$BE$366,2,FALSE),0) -> 0 | BD33: =IF(COUNTIF(Kassza!$C$7:$C$10000,BE33)<>0,BD32+1,BD32) -> 0 | BE33: =BE32+1 -> 46055 | BF33: =ROUNDUP(COUNTIF(Kassza!$C$7:$C$10000,BE33)/30,0) -> 0 | BG33: =SUM($BF$1:BF32) -> 0
A34: =IF($M$1>=M34,M34,"") | B34: =IF($M$1>=M34,TRIM(VLOOKUP(M34,Kassza!$B$7:$N$10000,4,FALSE)),"") | C34: =IF($M$1>=M34,TRIM(VLOOKUP(M34,Kassza!$B$7:$N$10000,5,FALSE)),"") | D34: =TRIM(IF($M$1>=M34,O34&" "&P34&" "&Q34,IF($M$1=M33,$T$3,IF($M$1=M32,$T$4&G4,"")))) | E34: =IF($M$1>=M34,IF(VLOOKUP(M34,Kassza!$B$7:$N$10000,7,FALSE)<>0,VLOOKUP(M34,Kassza!$B$7:$N$10000,7,FALSE),""),IF($M$1=M33,SUM($E$8:E33),IF($M$1=M32,SUM(E33,-F33),""))) | F34: =IF($M$1>=M34,IF(VLOOKUP(M34,Kassza!$B$7:$N$10000,9,FALSE)<>0,VLOOKUP(M34,Kassza!$B$7:$N$10000,9,FALSE),""),IF($M$1=M33,SUM($F$8:F33),"")) | G34: =IF($M$1>=M34,TRIM(VLOOKUP(M34,Kassza!$B$7:$N$10000,13,FALSE)),"") | M34: =M33+1 -> 26 | O34: =IF($M$1>=M34,TRIM(VLOOKUP(M34,Kassza!$B$7:$N$10000,12,FALSE)),"") | P34: =IF($M$1>=M34,TRIM(VLOOKUP(M34,Kassza!$B$7:$N$10000,6,FALSE)),"") | Q34: =IF($M$1>=M34,TRIM(VLOOKUP(M34,Kassza!$B$7:$N$10000,11,FALSE)),"") | BA34: 34 | BC34: =IF(ISERROR(VLOOKUP(BA34,$BD$1:$BE$366,2,FALSE))=FALSE,VLOOKUP(BA34,$BD$1:$BE$366,2,FALSE),0) -> 0 | BD34: =IF(COUNTIF(Kassza!$C$7:$C$10000,BE34)<>0,BD33+1,BD33) -> 0 | BE34: =BE33+1 -> 46056 | BF34: =ROUNDUP(COUNTIF(Kassza!$C$7:$C$10000,BE34)/30,0) -> 0 | BG34: =SUM($BF$1:BF33) -> 0
A35: =IF($M$1>=M35,M35,"") | B35: =IF($M$1>=M35,TRIM(VLOOKUP(M35,Kassza!$B$7:$N$10000,4,FALSE)),"") | C35: =IF($M$1>=M35,TRIM(VLOOKUP(M35,Kassza!$B$7:$N$10000,5,FALSE)),"") | D35: =TRIM(IF($M$1>=M35,O35&" "&P35&" "&Q35,IF($M$1=M34,$T$3,IF($M$1=M33,$T$4&G4,"")))) | E35: =IF($M$1>=M35,IF(VLOOKUP(M35,Kassza!$B$7:$N$10000,7,FALSE)<>0,VLOOKUP(M35,Kassza!$B$7:$N$10000,7,FALSE),""),IF($M$1=M34,SUM($E$8:E34),IF($M$1=M33,SUM(E34,-F34),""))) | F35: =IF($M$1>=M35,IF(VLOOKUP(M35,Kassza!$B$7:$N$10000,9,FALSE)<>0,VLOOKUP(M35,Kassza!$B$7:$N$10000,9,FALSE),""),IF($M$1=M34,SUM($F$8:F34),"")) | G35: =IF($M$1>=M35,TRIM(VLOOKUP(M35,Kassza!$B$7:$N$10000,13,FALSE)),"") | M35: =M34+1 -> 27 | O35: =IF($M$1>=M35,TRIM(VLOOKUP(M35,Kassza!$B$7:$N$10000,12,FALSE)),"") | P35: =IF($M$1>=M35,TRIM(VLOOKUP(M35,Kassza!$B$7:$N$10000,6,FALSE)),"") | Q35: =IF($M$1>=M35,TRIM(VLOOKUP(M35,Kassza!$B$7:$N$10000,11,FALSE)),"") | BA35: 35 | BC35: =IF(ISERROR(VLOOKUP(BA35,$BD$1:$BE$366,2,FALSE))=FALSE,VLOOKUP(BA35,$BD$1:$BE$366,2,FALSE),0) -> 0 | BD35: =IF(COUNTIF(Kassza!$C$7:$C$10000,BE35)<>0,BD34+1,BD34) -> 0 | BE35: =BE34+1 -> 46057 | BF35: =ROUNDUP(COUNTIF(Kassza!$C$7:$C$10000,BE35)/30,0) -> 0 | BG35: =SUM($BF$1:BF34) -> 0
A36: =IF($M$1>=M36,M36,"") | B36: =IF($M$1>=M36,TRIM(VLOOKUP(M36,Kassza!$B$7:$N$10000,4,FALSE)),"") | C36: =IF($M$1>=M36,TRIM(VLOOKUP(M36,Kassza!$B$7:$N$10000,5,FALSE)),"") | D36: =TRIM(IF($M$1>=M36,O36&" "&P36&" "&Q36,IF($M$1=M35,$T$3,IF($M$1=M34,$T$4&G4,"")))) | E36: =IF($M$1>=M36,IF(VLOOKUP(M36,Kassza!$B$7:$N$10000,7,FALSE)<>0,VLOOKUP(M36,Kassza!$B$7:$N$10000,7,FALSE),""),IF($M$1=M35,SUM($E$8:E35),IF($M$1=M34,SUM(E35,-F35),""))) | F36: =IF($M$1>=M36,IF(VLOOKUP(M36,Kassza!$B$7:$N$10000,9,FALSE)<>0,VLOOKUP(M36,Kassza!$B$7:$N$10000,9,FALSE),""),IF($M$1=M35,SUM($F$8:F35),"")) | G36: =IF($M$1>=M36,TRIM(VLOOKUP(M36,Kassza!$B$7:$N$10000,13,FALSE)),"") | M36: =M35+1 -> 28 | O36: =IF($M$1>=M36,TRIM(VLOOKUP(M36,Kassza!$B$7:$N$10000,12,FALSE)),"") | P36: =IF($M$1>=M36,TRIM(VLOOKUP(M36,Kassza!$B$7:$N$10000,6,FALSE)),"") | Q36: =IF($M$1>=M36,TRIM(VLOOKUP(M36,Kassza!$B$7:$N$10000,11,FALSE)),"") | BA36: 36 | BC36: =IF(ISERROR(VLOOKUP(BA36,$BD$1:$BE$366,2,FALSE))=FALSE,VLOOKUP(BA36,$BD$1:$BE$366,2,FALSE),0) -> 0 | BD36: =IF(COUNTIF(Kassza!$C$7:$C$10000,BE36)<>0,BD35+1,BD35) -> 0 | BE36: =BE35+1 -> 46058 | BF36: =ROUNDUP(COUNTIF(Kassza!$C$7:$C$10000,BE36)/30,0) -> 0 | BG36: =SUM($BF$1:BF35) -> 0
A37: =IF($M$1>=M37,M37,"") | B37: =IF($M$1>=M37,TRIM(VLOOKUP(M37,Kassza!$B$7:$N$10000,4,FALSE)),"") | C37: =IF($M$1>=M37,TRIM(VLOOKUP(M37,Kassza!$B$7:$N$10000,5,FALSE)),"") | D37: =TRIM(IF($M$1>=M37,O37&" "&P37&" "&Q37,IF($M$1=M36,$T$3,IF($M$1=M35,$T$4&G4,"")))) | E37: =IF($M$1>=M37,IF(VLOOKUP(M37,Kassza!$B$7:$N$10000,7,FALSE)<>0,VLOOKUP(M37,Kassza!$B$7:$N$10000,7,FALSE),""),IF($M$1=M36,SUM($E$8:E36),IF($M$1=M35,SUM(E36,-F36),""))) | F37: =IF($M$1>=M37,IF(VLOOKUP(M37,Kassza!$B$7:$N$10000,9,FALSE)<>0,VLOOKUP(M37,Kassza!$B$7:$N$10000,9,FALSE),""),IF($M$1=M36,SUM($F$8:F36),"")) | G37: =IF($M$1>=M37,TRIM(VLOOKUP(M37,Kassza!$B$7:$N$10000,13,FALSE)),"") | M37: =M36+1 -> 29 | O37: =IF($M$1>=M37,TRIM(VLOOKUP(M37,Kassza!$B$7:$N$10000,12,FALSE)),"") | P37: =IF($M$1>=M37,TRIM(VLOOKUP(M37,Kassza!$B$7:$N$10000,6,FALSE)),"") | Q37: =IF($M$1>=M37,TRIM(VLOOKUP(M37,Kassza!$B$7:$N$10000,11,FALSE)),"") | BA37: 37 | BC37: =IF(ISERROR(VLOOKUP(BA37,$BD$1:$BE$366,2,FALSE))=FALSE,VLOOKUP(BA37,$BD$1:$BE$366,2,FALSE),0) -> 0 | BD37: =IF(COUNTIF(Kassza!$C$7:$C$10000,BE37)<>0,BD36+1,BD36) -> 0 | BE37: =BE36+1 -> 46059 | BF37: =ROUNDUP(COUNTIF(Kassza!$C$7:$C$10000,BE37)/30,0) -> 0 | BG37: =SUM($BF$1:BF36) -> 0
A38: =IF($M$1>=M38,M38,"") | B38: =IF($M$1>=M38,TRIM(VLOOKUP(M38,Kassza!$B$7:$N$10000,4,FALSE)),"") | C38: =IF($M$1>=M38,TRIM(VLOOKUP(M38,Kassza!$B$7:$N$10000,5,FALSE)),"") | D38: =TRIM(IF($M$1>=M38,O38&" "&P38&" "&Q38,IF($M$1=M37,$T$3,IF($M$1=M36,$T$4&G4,"")))) | E38: =IF($M$1>=M38,IF(VLOOKUP(M38,Kassza!$B$7:$N$10000,7,FALSE)<>0,VLOOKUP(M38,Kassza!$B$7:$N$10000,7,FALSE),""),IF($M$1=M37,SUM($E$8:E37),IF($M$1=M36,SUM(E37,-F37),""))) | F38: =IF($M$1>=M38,IF(VLOOKUP(M38,Kassza!$B$7:$N$10000,9,FALSE)<>0,VLOOKUP(M38,Kassza!$B$7:$N$10000,9,FALSE),""),IF($M$1=M37,SUM($F$8:F37),"")) | G38: =IF($M$1>=M38,TRIM(VLOOKUP(M38,Kassza!$B$7:$N$10000,13,FALSE)),"") | M38: =M37+1 -> 30 | O38: =IF($M$1>=M38,TRIM(VLOOKUP(M38,Kassza!$B$7:$N$10000,12,FALSE)),"") | P38: =IF($M$1>=M38,TRIM(VLOOKUP(M38,Kassza!$B$7:$N$10000,6,FALSE)),"") | Q38: =IF($M$1>=M38,TRIM(VLOOKUP(M38,Kassza!$B$7:$N$10000,11,FALSE)),"") | BA38: 38 | BC38: =IF(ISERROR(VLOOKUP(BA38,$BD$1:$BE$366,2,FALSE))=FALSE,VLOOKUP(BA38,$BD$1:$BE$366,2,FALSE),0) -> 0 | BD38: =IF(COUNTIF(Kassza!$C$7:$C$10000,BE38)<>0,BD37+1,BD37) -> 0 | BE38: =BE37+1 -> 46060 | BF38: =ROUNDUP(COUNTIF(Kassza!$C$7:$C$10000,BE38)/30,0) -> 0 | BG38: =SUM($BF$1:BF37) -> 0
D39: =TRIM(IF($M$1>M38,$T$5,IF($M$1=M38,$T$3,IF($M$1=M37,$T$2,"")))) | E39: =IF($M$1>M38,SUM(E8:E38),IF($M$1=M38,SUM($E$8:E38),IF($M$1=M37,SUM(E38,-F38),""))) | F39: =IF($M$1>M38,SUM(F8:F38),IF($M$1=M38,SUM($F$8:F38),"")) | BA39: 39 | BC39: =IF(ISERROR(VLOOKUP(BA39,$BD$1:$BE$366,2,FALSE))=FALSE,VLOOKUP(BA39,$BD$1:$BE$366,2,FALSE),0) -> 0 | BD39: =IF(COUNTIF(Kassza!$C$7:$C$10000,BE39)<>0,BD38+1,BD38) -> 0 | BE39: =BE38+1 -> 46061 | BF39: =ROUNDUP(COUNTIF(Kassza!$C$7:$C$10000,BE39)/30,0) -> 0 | BG39: =SUM($BF$1:BF38) -> 0
D40: =TRIM(IF($M$1=M38,$T$4&G4,"")) | E40: =IF($M$1=M38,SUM(E39,-F39),"") | BA40: 40 | BC40: =IF(ISERROR(VLOOKUP(BA40,$BD$1:$BE$366,2,FALSE))=FALSE,VLOOKUP(BA40,$BD$1:$BE$366,2,FALSE),0) -> 0 | BD40: =IF(COUNTIF(Kassza!$C$7:$C$10000,BE40)<>0,BD39+1,BD39) -> 0 | BE40: =BE39+1 -> 46062 | BF40: =ROUNDUP(COUNTIF(Kassza!$C$7:$C$10000,BE40)/30,0) -> 0 | BG40: =SUM($BF$1:BF39) -> 0
...

Sheet A
C1: =DATE(Hibak!$A$1,1,1) -> 46023 | D1: =TRIM(Koltsegvetes!B79&Koltsegvetes!V1) -> Református Egyházközség | G1: Napi bevétel: | H1: =SUMIF($C$7:$C$10000,$C$2,$H$7:$H$10000) -> 0 | J1: =C2 -> 46023 | N1: A másolás, kivágás, beillesztés
C2: =IF(MAX(C7:C10000)>C1,MAX(C7:C10000),C1) -> 46023 | G2: Napi kiadás: | H2: =SUMIF($C$7:$C$10000,$C$2,$J$7:$J$10000) -> 0 | N2: műveleteket lehetőleg ne használd!
C3: =DATE(Hibak!$A$1,12,31) -> 46387 | G3: Egyenleg: | H3: =SUM(SUM(H6:H10000),-SUM(J7:J10000)) -> 0
D4: =Hibak!AA3 | N4: Költségvetési
D5: Dátum | E5: Iratszám | F5: Irattip. | G5: Név | H5: Bev. - Összeg | I5: Bevétel - Költ.vet. név | J5: Kiad. - Összeg | K5: Kiadás - költ.vet. név | L5: Megjegyzés | M5: Magyarázat | N5: szám
G6: Előző évi egyenleg:
C7: =IF(AND(D7<>0,D7>=$C$1,D7<=$C$3),D7,IF(SUM(H7:J17)<>0,C1,1)) -> 1 | M7: =IF(I7&K7<>"",VLOOKUP(I7&K7,fif,3,FALSE),"") | N7: =IF(I7&K7<>"",VLOOKUP(I7&K7,fi,2,FALSE),"")
C8: =IF(AND(D8<>0,D8>=$C$1,D8<=$C$3),D8,IF(SUM(H8:J18)<>0,C7,1)) -> 1 | M8: =IF(I8&K8<>"",VLOOKUP(I8&K8,fif,3,FALSE),"") | N8: =IF(I8&K8<>"",VLOOKUP(I8&K8,fi,2,FALSE),"")
C9: =IF(AND(D9<>0,D9>=$C$1,D9<=$C$3),D9,IF(SUM(H9:J19)<>0,C8,1)) -> 1 | M9: =IF(I9&K9<>"",VLOOKUP(I9&K9,fif,3,FALSE),"") | N9: =IF(I9&K9<>"",VLOOKUP(I9&K9,fi,2,FALSE),"")
C10: =IF(AND(D10<>0,D10>=$C$1,D10<=$C$3),D10,IF(SUM(H10:J20)<>0,C9,1)) -> 1 | M10: =IF(I10&K10<>"",VLOOKUP(I10&K10,fif,3,FALSE),"") | N10: =IF(I10&K10<>"",VLOOKUP(I10&K10,fi,2,FALSE),"")
C11: =IF(AND(D11<>0,D11>=$C$1,D11<=$C$3),D11,IF(SUM(H11:J21)<>0,C10,1)) -> 1 | M11: =IF(I11&K11<>"",VLOOKUP(I11&K11,fif,3,FALSE),"") | N11: =IF(I11&K11<>"",VLOOKUP(I11&K11,fi,2,FALSE),"")
C12: =IF(AND(D12<>0,D12>=$C$1,D12<=$C$3),D12,IF(SUM(H12:J22)<>0,C11,1)) -> 1 | M12: =IF(I12&K12<>"",VLOOKUP(I12&K12,fif,3,FALSE),"") | N12: =IF(I12&K12<>"",VLOOKUP(I12&K12,fi,2,FALSE),"")
C13: =IF(AND(D13<>0,D13>=$C$1,D13<=$C$3),D13,IF(SUM(H13:J23)<>0,C12,1)) -> 1 | M13: =IF(I13&K13<>"",VLOOKUP(I13&K13,fif,3,FALSE),"") | N13: =IF(I13&K13<>"",VLOOKUP(I13&K13,fi,2,FALSE),"")
C14: =IF(AND(D14<>0,D14>=$C$1,D14<=$C$3),D14,IF(SUM(H14:J24)<>0,C13,1)) -> 1 | M14: =IF(I14&K14<>"",VLOOKUP(I14&K14,fif,3,FALSE),"") | N14: =IF(I14&K14<>"",VLOOKUP(I14&K14,fi,2,FALSE),"")
C15: =IF(AND(D15<>0,D15>=$C$1,D15<=$C$3),D15,IF(SUM(H15:J25)<>0,C14,1)) -> 1 | M15: =IF(I15&K15<>"",VLOOKUP(I15&K15,fif,3,FALSE),"") | N15: =IF(I15&K15<>"",VLOOKUP(I15&K15,fi,2,FALSE),"")
C16: =IF(AND(D16<>0,D16>=$C$1,D16<=$C$3),D16,IF(SUM(H16:J26)<>0,C15,1)) -> 1 | M16: =IF(I16&K16<>"",VLOOKUP(I16&K16,fif,3,FALSE),"") | N16: =IF(I16&K16<>"",VLOOKUP(I16&K16,fi,2,FALSE),"")
C17: =IF(AND(D17<>0,D17>=$C$1,D17<=$C$3),D17,IF(SUM(H17:J27)<>0,C16,1)) -> 1 | M17: =IF(I17&K17<>"",VLOOKUP(I17&K17,fif,3,FALSE),"") | N17: =IF(I17&K17<>"",VLOOKUP(I17&K17,fi,2,FALSE),"")
C18: =IF(AND(D18<>0,D18>=$C$1,D18<=$C$3),D18,IF(SUM(H18:J28)<>0,C17,1)) -> 1 | M18: =IF(I18&K18<>"",VLOOKUP(I18&K18,fif,3,FALSE),"") | N18: =IF(I18&K18<>"",VLOOKUP(I18&K18,fi,2,FALSE),"")
C19: =IF(AND(D19<>0,D19>=$C$1,D19<=$C$3),D19,IF(SUM(H19:J29)<>0,C18,1)) -> 1 | M19: =IF(I19&K19<>"",VLOOKUP(I19&K19,fif,3,FALSE),"") | N19: =IF(I19&K19<>"",VLOOKUP(I19&K19,fi,2,FALSE),"")
... C1000: =IF(AND(D1000<>0,D1000>=$C$1,D1000<=$C$3),D1000,IF(SUM(H1000:J1010)<>0,C999,1)) -> 1 | M1000: =IF(I1000&K1000<>"",VLOOKUP(I1000&K1000,fif,3,FALSE),"") | N1000: =IF(I1000&K1000<>"",VLOOKUP(I1000&K1000,fi,2,FALSE),"")

Sheet B
C1: =DATE(Hibak!$A$1,1,1) -> 46023 | D1: =A!D1 -> Református Egyházközség | G1: Napi bevétel: | H1: =SUMIF($C$7:$C$10000,$C$2,$H$7:$H$10000) -> 0 | J1: =C2 -> 46023 | N1: A másolás, kivágás, beillesztés
C2: =IF(MAX(C7:C10000)>C1,MAX(C7:C10000),C1) -> 46023 | G2: Napi kiadás: | H2: =SUMIF($C$7:$C$10000,$C$2,$J$7:$J$10000) -> 0 | N2: műveleteket lehetőleg ne használd!
C3: =DATE(Hibak!$A$1,12,31) -> 46387 | G3: Egyenleg: | H3: =SUM(SUM(H6:H10000),-SUM(J7:J10000)) -> 0
D4: =Hibak!AB3 | N4: Költségvetési
D5: Dátum | E5: Iratszám | F5: Irattip. | G5: Név | H5: Bev. - Összeg | I5: Bevétel - Költ.vet. név | J5: Kiad. - Összeg | K5: Kiadás - költ.vet. név | L5: Megjegyzés | M5: Magyarázat | N5: szám
G6: Előző évi egyenleg:
C7: =IF(AND(D7<>0,D7>=$C$1,D7<=$C$3),D7,IF(SUM(H7:J17)<>0,C1,1)) -> 1 | M7: =IF(I7&K7<>"",VLOOKUP(I7&K7,fif,3,FALSE),"") | N7: =IF(I7&K7<>"",VLOOKUP(I7&K7,fi,2,FALSE),"")
C8: =IF(AND(D8<>0,D8>=$C$1,D8<=$C$3),D8,IF(SUM(H8:J18)<>0,C7,1)) -> 1 | M8: =IF(I8&K8<>"",VLOOKUP(I8&K8,fif,3,FALSE),"") | N8: =IF(I8&K8<>"",VLOOKUP(I8&K8,fi,2,FALSE),"")
C9: =IF(AND(D9<>0,D9>=$C$1,D9<=$C$3),D9,IF(SUM(H9:J19)<>0,C8,1)) -> 1 | M9: =IF(I9&K9<>"",VLOOKUP(I9&K9,fif,3,FALSE),"") | N9: =IF(I9&K9<>"",VLOOKUP(I9&K9,fi,2,FALSE),"")
C10: =IF(AND(D10<>0,D10>=$C$1,D10<=$C$3),D10,IF(SUM(H10:J20)<>0,C9,1)) -> 1 | M10: =IF(I10&K10<>"",VLOOKUP(I10&K10,fif,3,FALSE),"") | N10: =IF(I10&K10<>"",VLOOKUP(I10&K10,fi,2,FALSE),"")
C11: =IF(AND(D11<>0,D11>=$C$1,D11<=$C$3),D11,IF(SUM(H11:J21)<>0,C10,1)) -> 1 | M11: =IF(I11&K11<>"",VLOOKUP(I11&K11,fif,3,FALSE),"") | N11: =IF(I11&K11<>"",VLOOKUP(I11&K11,fi,2,FALSE),"")
C12: =IF(AND(D12<>0,D12>=$C$1,D12<=$C$3),D12,IF(SUM(H12:J22)<>0,C11,1)) -> 1 | M12: =IF(I12&K12<>"",VLOOKUP(I12&K12,fif,3,FALSE),"") | N12: =IF(I12&K12<>"",VLOOKUP(I12&K12,fi,2,FALSE),"")
C13: =IF(AND(D13<>0,D13>=$C$1,D13<=$C$3),D13,IF(SUM(H13:J23)<>0,C12,1)) -> 1 | M13: =IF(I13&K13<>"",VLOOKUP(I13&K13,fif,3,FALSE),"") | N13: =IF(I13&K13<>"",VLOOKUP(I13&K13,fi,2,FALSE),"")
C14: =IF(AND(D14<>0,D14>=$C$1,D14<=$C$3),D14,IF(SUM(H14:J24)<>0,C13,1)) -> 1 | M14: =IF(I14&K14<>"",VLOOKUP(I14&K14,fif,3,FALSE),"") | N14: =IF(I14&K14<>"",VLOOKUP(I14&K14,fi,2,FALSE),"")
C15: =IF(AND(D15<>0,D15>=$C$1,D15<=$C$3),D15,IF(SUM(H15:J25)<>0,C14,1)) -> 1 | M15: =IF(I15&K15<>"",VLOOKUP(I15&K15,fif,3,FALSE),"") | N15: =IF(I15&K15<>"",VLOOKUP(I15&K15,fi,2,FALSE),"")
C16: =IF(AND(D16<>0,D16>=$C$1,D16<=$C$3),D16,IF(SUM(H16:J26)<>0,C15,1)) -> 1 | M16: =IF(I16&K16<>"",VLOOKUP(I16&K16,fif,3,FALSE),"") | N16: =IF(I16&K16<>"",VLOOKUP(I16&K16,fi,2,FALSE),"")
C17: =IF(AND(D17<>0,D17>=$C$1,D17<=$C$3),D17,IF(SUM(H17:J27)<>0,C16,1)) -> 1 | M17: =IF(I17&K17<>"",VLOOKUP(I17&K17,fif,3,FALSE),"") | N17: =IF(I17&K17<>"",VLOOKUP(I17&K17,fi,2,FALSE),"")
C18: =IF(AND(D18<>0,D18>=$C$1,D18<=$C$3),D18,IF(SUM(H18:J28)<>0,C17,1)) -> 1 | M18: =IF(I18&K18<>"",VLOOKUP(I18&K18,fif,3,FALSE),"") | N18: =IF(I18&K18<>"",VLOOKUP(I18&K18,fi,2,FALSE),"")
C19: =IF(AND(D19<>0,D19>=$C$1,D19<=$C$3),D19,IF(SUM(H19:J29)<>0,C18,1)) -> 1 | M19: =IF(I19&K19<>"",VLOOKUP(I19&K19,fif,3,FALSE),"") | N19: =IF(I19&K19<>"",VLOOKUP(I19&K19,fi,2,FALSE),"")
... C500: =IF(AND(D500<>0,D500>=$C$1,D500<=$C$3),D500,IF(SUM(H500:J510)<>0,C499,1)) -> 1 | M500: =IF(I500&K500<>"",VLOOKUP(I500&K500,fif,3,FALSE),"") | N500: =IF(I500&K500<>"",VLOOKUP(I500&K500,fi,2,FALSE),"")

Sheet C
C1: =DATE(Hibak!$A$1,1,1) -> 46023 | D1: =A!D1 -> Református Egyházközség | G1: Napi bevétel: | H1: =SUMIF($C$7:$C$10000,$C$2,$H$7:$H$10000) -> 0 | J1: =C2 -> 46023 | N1: A másolás, kivágás, beillesztés
C2: =IF(MAX(C7:C10000)>C1,MAX(C7:C10000),C1) -> 46023 | G2: Napi kiadás: | H2: =SUMIF($C$7:$C$10000,$C$2,$J$7:$J$10000) -> 0 | N2: műveleteket lehetőleg ne használd!
C3: =DATE(Hibak!$A$1,12,31) -> 46387 | G3: Egyenleg: | H3: =SUM(SUM(H6:H10000),-SUM(J7:J10000)) -> 0
D4: =Hibak!AC3 | N4: Költségvetési
D5: Dátum | E5: Iratszám | F5: Irattip. | G5: Név | H5: Bev. - Összeg | I5: Bevétel - Költ.vet. név | J5: Kiad. - Összeg | K5: Kiadás - költ.vet. név | L5: Megjegyzés | M5: Magyarázat | N5: szám
G6: Előző évi egyenleg:
C7: =IF(AND(D7<>0,D7>=$C$1,D7<=$C$3),D7,IF(SUM(H7:J17)<>0,C1,1)) -> 1 | M7: =IF(I7&K7<>"",VLOOKUP(I7&K7,fif,3,FALSE),"") | N7: =IF(I7&K7<>"",VLOOKUP(I7&K7,fi,2,FALSE),"")
C8: =IF(AND(D8<>0,D8>=$C$1,D8<=$C$3),D8,IF(SUM(H8:J18)<>0,C7,1)) -> 1 | M8: =IF(I8&K8<>"",VLOOKUP(I8&K8,fif,3,FALSE),"") | N8: =IF(I8&K8<>"",VLOOKUP(I8&K8,fi,2,FALSE),"")
C9: =IF(AND(D9<>0,D9>=$C$1,D9<=$C$3),D9,IF(SUM(H9:J19)<>0,C8,1)) -> 1 | M9: =IF(I9&K9<>"",VLOOKUP(I9&K9,fif,3,FALSE),"") | N9: =IF(I9&K9<>"",VLOOKUP(I9&K9,fi,2,FALSE),"")
C10: =IF(AND(D10<>0,D10>=$C$1,D10<=$C$3),D10,IF(SUM(H10:J20)<>0,C9,1)) -> 1 | M10: =IF(I10&K10<>"",VLOOKUP(I10&K10,fif,3,FALSE),"") | N10: =IF(I10&K10<>"",VLOOKUP(I10&K10,fi,2,FALSE),"")
C11: =IF(AND(D11<>0,D11>=$C$1,D11<=$C$3),D11,IF(SUM(H11:J21)<>0,C10,1)) -> 1 | M11: =IF(I11&K11<>"",VLOOKUP(I11&K11,fif,3,FALSE),"") | N11: =IF(I11&K11<>"",VLOOKUP(I11&K11,fi,2,FALSE),"")
C12: =IF(AND(D12<>0,D12>=$C$1,D12<=$C$3),D12,IF(SUM(H12:J22)<>0,C11,1)) -> 1 | M12: =IF(I12&K12<>"",VLOOKUP(I12&K12,fif,3,FALSE),"") | N12: =IF(I12&K12<>"",VLOOKUP(I12&K12,fi,2,FALSE),"")
C13: =IF(AND(D13<>0,D13>=$C$1,D13<=$C$3),D13,IF(SUM(H13:J23)<>0,C12,1)) -> 1 | M13: =IF(I13&K13<>"",VLOOKUP(I13&K13,fif,3,FALSE),"") | N13: =IF(I13&K13<>"",VLOOKUP(I13&K13,fi,2,FALSE),"")
C14: =IF(AND(D14<>0,D14>=$C$1,D14<=$C$3),D14,IF(SUM(H14:J24)<>0,C13,1)) -> 1 | M14: =IF(I14&K14<>"",VLOOKUP(I14&K14,fif,3,FALSE),"") | N14: =IF(I14&K14<>"",VLOOKUP(I14&K14,fi,2,FALSE),"")
C15: =IF(AND(D15<>0,D15>=$C$1,D15<=$C$3),D15,IF(SUM(H15:J25)<>0,C14,1)) -> 1 | M15: =IF(I15&K15<>"",VLOOKUP(I15&K15,fif,3,FALSE),"") | N15: =IF(I15&K15<>"",VLOOKUP(I15&K15,fi,2,FALSE),"")
C16: =IF(AND(D16<>0,D16>=$C$1,D16<=$C$3),D16,IF(SUM(H16:J26)<>0,C15,1)) -> 1 | M16: =IF(I16&K16<>"",VLOOKUP(I16&K16,fif,3,FALSE),"") | N16: =IF(I16&K16<>"",VLOOKUP(I16&K16,fi,2,FALSE),"")
C17: =IF(AND(D17<>0,D17>=$C$1,D17<=$C$3),D17,IF(SUM(H17:J27)<>0,C16,1)) -> 1 | M17: =IF(I17&K17<>"",VLOOKUP(I17&K17,fif,3,FALSE),"") | N17: =IF(I17&K17<>"",VLOOKUP(I17&K17,fi,2,FALSE),"")
C18: =IF(AND(D18<>0,D18>=$C$1,D18<=$C$3),D18,IF(SUM(H18:J28)<>0,C17,1)) -> 1 | M18: =IF(I18&K18<>"",VLOOKUP(I18&K18,fif,3,FALSE),"") | N18: =IF(I18&K18<>"",VLOOKUP(I18&K18,fi,2,FALSE),"")
C19: =IF(AND(D19<>0,D19>=$C$1,D19<=$C$3),D19,IF(SUM(H19:J29)<>0,C18,1)) -> 1 | M19: =IF(I19&K19<>"",VLOOKUP(I19&K19,fif,3,FALSE),"") | N19: =IF(I19&K19<>"",VLOOKUP(I19&K19,fi,2,FALSE),"")
... C500: =IF(AND(D500<>0,D500>=$C$1,D500<=$C$3),D500,IF(SUM(H500:J510)<>0,C499,1)) -> 1 | M500: =IF(I500&K500<>"",VLOOKUP(I500&K500,fif,3,FALSE),"") | N500: =IF(I500&K500<>"",VLOOKUP(I500&K500,fi,2,FALSE),"")

Sheet D
C1: =DATE(Hibak!$A$1,1,1) -> 46023 | D1: =A!D1 -> Református Egyházközség | G1: Napi bevétel: | H1: =SUMIF($C$7:$C$10000,$C$2,$H$7:$H$10000) -> 0 | J1: =C2 -> 46023 | N1: A másolás, kivágás, beillesztés
