Workbook
Name ab: [1]A!$C$6:$M$1000
Name bb: [1]B!$C$6:$M$500
Name bev: [1]Hibak!$Z$61:$Z$120
Name beva: [1]Hibak!$AA$61:$AA$120
Name bevb: [1]Hibak!$AB$61:$AB$120
Name bevc: [1]Hibak!$AC$61:$AC$120
Name bevd: [1]Hibak!$AD$61:$AD$120
Name beve: [1]Hibak!$AE$61:$AE$120
Name bevf: [1]Hibak!$AF$61:$AF$120
Name bevg: [1]Hibak!$AG$61:$AG$120
Name bevh: [1]Hibak!$AH$61:$AH$120
Name bevi: [1]Hibak!$AI$61:$AI$120
Name bevj: [1]Hibak!$AJ$61:$AJ$120
Name bevk: [1]Hibak!$AK$61:$AK$120
Name bevl: [1]Hibak!$AL$61:$AL$120
Name bevm: [1]Hibak!$AM$61:$AM$120
Name bevn: [1]Hibak!$AN$61:$AN$120
Name bevo: [1]Hibak!$AO$61:$AO$120
Name bevp: [1]Hibak!$AP$61:$AP$120
Name bevq: [1]Hibak!$AQ$61:$AQ$120
Name bevr: [1]Hibak!$AR$61:$AR$120
Name bevs: [1]Hibak!$AS$61:$AS$120
Name bevt: [1]Hibak!$AT$61:$AT$120
Name cb: [1]C!$C$6:$M$500
Name Csfi: [1]Hibak!$C$198:$D$1131
Name CSnaploSz: Csoportnaplo!$AZ$1:INDEX(Csoportnaplo!$AZ:$AZ,Csoportnaplo!$AW$1)
Name CsNapNY: Csoportnaplo!$A$4:INDEX(Csoportnaplo!$H:$H,Csoportnaplo!$M$1)
Name db: [1]D!$C$6:$M$200
Name eb: [1]E!$C$6:$M$200
Name fb: [1]F!$C$6:$M$200
Name fi: [1]Hibak!$C$198:$D$1131
Name gb: [1]G!$C$6:$M$200
Name hb: [1]H!$C$6:$M$100
Name ib: [1]I!$C$6:$M$100
Name jb: [1]J!$C$6:$M$100
Name Kassza: [1]Kassza!$C$6:$M$4000
Name kb: [1]K!$C$6:$M$100
Name kiad: [1]Hibak!$AZ$50:$AZ$120
Name kiada: [1]Hibak!$BA$50:$BA$120
Name kiadb: [1]Hibak!$BB$50:$BB$120
Name kiadc: [1]Hibak!$BC$50:$BC$120
Name kiadd: [1]Hibak!$BD$50:$BD$120
Name kiade: [1]Hibak!$BE$50:$BE$120
Name kiadf: [1]Hibak!$BF$50:$BF$120
Name kiadg: [1]Hibak!$BG$50:$BG$120
Name kiadh: [1]Hibak!$BH$50:$BH$120
Name kiadi: [1]Hibak!$BI$50:$BI$120
Name kiadj: [1]Hibak!$BJ$50:$BJ$120
Name kiadk: [1]Hibak!$BK$50:$BK$120
Name kiadl: [1]Hibak!$BL$50:$BL$120
Name kiadm: [1]Hibak!$BM$50:$BM$120
Name kiadn: [1]Hibak!$BN$50:$BN$120
Name kiado: [1]Hibak!$BO$50:$BO$120
Name kiadp: [1]Hibak!$BP$50:$BP$120
Name kiadq: [1]Hibak!$BQ$50:$BQ$120
Name kiadr: [1]Hibak!$BR$50:$BR$120
Name kiads: [1]Hibak!$BS$50:$BS$120
Name kiadt: [1]Hibak!$BT$50:$BT$120
Name Kisiv: Cs!$CW$40:$CX$88
Name KKNap: Kiadasi_kiseroiv!$BC$1:INDEX(Kiadasi_kiseroiv!$BC:$BC,Kiadasi_kiseroiv!$AX$1)

Sheet Cs
BT1: Több kiadás | BU1: =Kiadasi_kiseroiv!P2 -> kassza | BW1: résszámadás | BX1: =Csoportnaplo!A3 -> Egyházfenntartói járulék | BZ1: Napló | CA1: Napló szám | CB1: Naploregiszter | CJ1: =[1]Hibak!$A$1 -> 2026 | CK1: =[1]Koltsegvetes!$B$79 -> 0 | CL1: =[1]Koltsegvetes!$V$2 -> Ref. Egyházközség | CP1: kassza | CQ1: =INDEX(Kassza,1,6) -> 0 | CU1: =[1]Hibak!E1041 -> Contribuţia anuală a credincioşilor | CV1: =INDEX(Csfi,CZ1,1) -> Egyházfenntartói járulék | CW1: =CV52 -> Karbantartási kiadások | CZ1: 844 | DD1: Kassza | DE1: kassza | DF1: =IF(ISERROR(VLOOKUP(DD1,Resz_szamadas!$H$1:$I$21,2,FALSE))=FALSE,1,0) -> 0
BW2: w | BX2: =Csoportnaplo!H2 -> 0 | BZ2: =Naplo!O1 -> 46023 | CC2: 1 | CD2: 55153 | CP2: ab | CQ2: =INDEX(ab,1,6) -> 0 | CR2: =[1]A!$D$3 -> 0 | CU2: =[1]Hibak!E1042 -> Contribuţii pt. diverse servicii religioase | CV2: =INDEX(Csfi,CZ2,1) -> Bevételek a különböző egyházi szolgálatokért | CZ2: 845 | DD2: A - számla | DE2: ab | DF2: =IF(ISERROR(VLOOKUP(DD2,Resz_szamadas!$H$1:$I$21,2,FALSE))=FALSE,1,0) -> 0
BZ3: =Naplo!P1 -> 46053 | CJ3: 5 | CK3: 10 | CL3: 11 | CP3: bb | CQ3: =INDEX(bb,1,6) -> 0 | CR3: =[1]B!$D$3 -> 0 | CU3: =[1]Hibak!E1043 -> Contribuţii în lăcaşuri de cult - colecta | CV3: =INDEX(Csfi,CZ3,1) -> Perselypénz | CZ3: 846 | DD3: B - számla | DE3: bb | DF3: =IF(ISERROR(VLOOKUP(DD3,Resz_szamadas!$H$1:$I$21,2,FALSE))=FALSE,1,0) -> 0
BS4: Több kiadás | BT4: =Kiadasi_kiseroiv!P2 -> kassza | BU4: kiadási kísérőív | BW4: résszámadás | BX4: Csnapl | BY4: Csnapl sz | BZ4: =Naplo!O2 -> kassza | CC4: Dátum | CD4: Sorszám | CE4: Bevétel | CF4: Kiadás | CG4: Tétel | CH4: Szám | CI4: Név | CJ4: Név | CK4: Megjegyzés | CL4: Román magyarázat | CM4: Irat | CN4: Szám | CP4: cb | CQ4: =INDEX(cb,1,6) -> 0 | CR4: =[1]C!$D$3 -> 0 | CU4: =[1]Hibak!E1044 -> Ajutoare primite de la credincioşi şi organizaţii religioase | CV4: =INDEX(Csfi,CZ4,1) -> Adományok hívektől, egyházi intézményektől | CZ4: 847 | DD4: C - számla | DE4: cb | DF4: =IF(ISERROR(VLOOKUP(DD4,Resz_szamadas!$H$1:$I$21,2,FALSE))=FALSE,1,0) -> 0
BZ5: t | CP5: db | CQ5: =INDEX(db,1,6) -> 0 | CR5: =[1]D!$D$3 -> 0 | CU5: =[1]Hibak!E1045 -> Donații pt. masa domnului | CV5: =INDEX(Csfi,CZ5,1) -> Úrasztali adományok | CZ5: 848 | DD5: D - számla | DE5: db | DF5: =IF(ISERROR(VLOOKUP(DD5,Resz_szamadas!$H$1:$I$21,2,FALSE))=FALSE,1,0) -> 0
B6: Ez a csatolás munkalap. | CH6: 1 | CJ6: 10 | CK6: 5 | CL6: 11 | CP6: eb | CQ6: =INDEX(eb,1,6) -> 0 | CR6: =[1]E!$D$3 -> 0 | CU6: =[1]Hibak!E1046 -> Cont. pt. concesionarea şi îngrijirea locurilor din cimitire | CV6: =INDEX(Csfi,CZ6,1) -> Sírhelyek eladásából, bérleti díjából, gondozásából származó bevételek | CZ6: 849 | DD6: E - számla | DE6: eb | DF6: =IF(ISERROR(VLOOKUP(DD6,Resz_szamadas!$H$1:$I$21,2,FALSE))=FALSE,1,0) -> 0
B7: Itt lehet megadni, hogy hol találja meg az Adatok_2026.xlsx munkafüzetet. | BS7: =IF(Kiadasi_kiseroiv!$K$2=BT7,BV7,"") | BT7: =IF(AND($BT$4=CI7,BU7<>""),CC7,"") | BU7: =IF(AND($BU$1=CI7,ISERROR(VLOOKUP(CG7,Kisiv,2,FALSE))=FALSE),CB7,"") | BV7: =IF(BU7<>"",RANK(BU7,$BU$7:$BU$33000,1),"") | BW7: =IF(CC7<min,$BW$2,IF(CC7<=max,CG7,"")) | BX7: =IF(AND(OR($BX$1=0,$BX$1=CG7),OR($BX$2=0,IF(ISERROR(SEARCH($BX$2,CJ7&CK7&CL7,1)),FALSE,TRUE))),CB7,"") | BY7: =IF(AND(BX7<>"",CC7<>$CD$2),RANK(BX7,$BX$7:$BX$33000,1),"") | BZ7: =IF(AND(CC7<$BZ$2,CI7=$BZ$4),$BZ$5,IF(AND(CC7<=$BZ$3,CI7=$BZ$4),CB7,"")) | CA7: =IF(AND(BZ7<>"",BZ7<>$BZ$5),RANK(BZ7,$BZ$7:$BZ$33000,1),"") | CB7: =IF(COUNTIF($CD$7:CD7,CD7)=1,CD7,CD7+COUNTIF($CD$6:CD6,CD7)) -> 55153 | CC7: =IF(INDEX(Kassza,CH7,1)<>1,INDEX(Kassza,CH7,1),$CD$2) -> 55153 | CD7: =IF(CC7<>$CD$2,RANK(CC7,$CC$7:$CC$33000,1),$CD$2) -> 55153 | CE7: =INDEX(Kassza,CH7,6) -> 0 | CF7: =INDEX(Kassza,CH7,8) -> 0 | CG7: =INDEX(Kassza,CH7,7)&INDEX(Kassza,CH7,9) | CH7: 2 | CI7: Kassza | CJ7: =IF(INDEX(Kassza,CH7,5)<>0,INDEX(Kassza,CH7,5),"") | CK7: =IF(INDEX(Kassza,CH7,10)<>0,INDEX(Kassza,CH7,10),"") | CL7: =IF(INDEX(Kassza,CH7,11)<>0,INDEX(Kassza,CH7,11),"") | CM7: =IF(INDEX(Kassza,CH7,4)<>0,INDEX(Kassza,CH7,4),"") | CN7: =IF(INDEX(Kassza,CH7,3)<>0,INDEX(Kassza,CH7,3),"") | CP7: fb | CQ7: =INDEX(fb,1,6) -> 0 | CR7: =[1]F!$D$3 -> 0 | CU7: =[1]Hibak!E1047 -> Contribuţia pt. susţinerea unit. Ierarhic superioare* | CV7: =INDEX(Csfi,CZ7,1) -> Központi járulékok - egyházmegyei bevétel | CZ7: 850 | DD7: F - számla | DE7: fb | DF7: =IF(ISERROR(VLOOKUP(DD7,Resz_szamadas!$H$1:$I$21,2,FALSE))=FALSE,1,0) -> 0
B8: Teendők: | BS8: =IF(Kiadasi_kiseroiv!$K$2=BT8,BV8,"") | BT8: =IF(AND($BT$4=CI8,BU8<>""),CC8,"") | BU8: =IF(AND($BU$1=CI8,ISERROR(VLOOKUP(CG8,Kisiv,2,FALSE))=FALSE),CB8,"") | BV8: =IF(BU8<>"",RANK(BU8,$BU$7:$BU$33000,1),"") | BW8: =IF(CC8<min,$BW$2,IF(CC8<=max,CG8,"")) | BX8: =IF(AND(OR($BX$1=0,$BX$1=CG8),OR($BX$2=0,IF(ISERROR(SEARCH($BX$2,CJ8&CK8&CL8,1)),FALSE,TRUE))),CB8,"") | BY8: =IF(AND(BX8<>"",CC8<>$CD$2),RANK(BX8,$BX$7:$BX$33000,1),"") | BZ8: =IF(AND(CC8<$BZ$2,CI8=$BZ$4),$BZ$5,IF(AND(CC8<=$BZ$3,CI8=$BZ$4),CB8,"")) | CA8: =IF(AND(BZ8<>"",BZ8<>$BZ$5),RANK(BZ8,$BZ$7:$BZ$33000,1),"") | CB8: =IF(COUNTIF($CD$7:CD8,CD8)=1,CD8,CD8+COUNTIF($CD$6:CD7,CD8)) -> 55154 | CC8: =IF(INDEX(Kassza,CH8,1)<>1,INDEX(Kassza,CH8,1),$CD$2) -> 55153 | CD8: =IF(CC8<>$CD$2,RANK(CC8,$CC$7:$CC$33000,1),$CD$2) -> 55153 | CE8: =INDEX(Kassza,CH8,6) -> 0 | CF8: =INDEX(Kassza,CH8,8) -> 0 | CG8: =INDEX(Kassza,CH8,7)&INDEX(Kassza,CH8,9) | CH8: 3 | CI8: Kassza | CJ8: =IF(INDEX(Kassza,CH8,5)<>0,INDEX(Kassza,CH8,5),"") | CK8: =IF(INDEX(Kassza,CH8,10)<>0,INDEX(Kassza,CH8,10),"") | CL8: =IF(INDEX(Kassza,CH8,11)<>0,INDEX(Kassza,CH8,11),"") | CM8: =IF(INDEX(Kassza,CH8,4)<>0,INDEX(Kassza,CH8,4),"") | CN8: =IF(INDEX(Kassza,CH8,3)<>0,INDEX(Kassza,CH8,3),"") | CP8: gb | CQ8: =INDEX(gb,1,6) -> 0 | CR8: =[1]G!$D$3 -> 0 | CU8: =[1]Hibak!E1048 -> Contr. pentru prestări servicii la parohii* | CV8: =INDEX(Csfi,CZ8,1) -> Egyházközségek fizetésalapja - emei bevétel | CZ8: 851 | DD8: G - számla | DE8: gb | DF8: =IF(ISERROR(VLOOKUP(DD8,Resz_szamadas!$H$1:$I$21,2,FALSE))=FALSE,1,0) -> 0
BS9: =IF(Kiadasi_kiseroiv!$K$2=BT9,BV9,"") | BT9: =IF(AND($BT$4=CI9,BU9<>""),CC9,"") | BU9: =IF(AND($BU$1=CI9,ISERROR(VLOOKUP(CG9,Kisiv,2,FALSE))=FALSE),CB9,"") | BV9: =IF(BU9<>"",RANK(BU9,$BU$7:$BU$33000,1),"") | BW9: =IF(CC9<min,$BW$2,IF(CC9<=max,CG9,"")) | BX9: =IF(AND(OR($BX$1=0,$BX$1=CG9),OR($BX$2=0,IF(ISERROR(SEARCH($BX$2,CJ9&CK9&CL9,1)),FALSE,TRUE))),CB9,"") | BY9: =IF(AND(BX9<>"",CC9<>$CD$2),RANK(BX9,$BX$7:$BX$33000,1),"") | BZ9: =IF(AND(CC9<$BZ$2,CI9=$BZ$4),$BZ$5,IF(AND(CC9<=$BZ$3,CI9=$BZ$4),CB9,"")) | CA9: =IF(AND(BZ9<>"",BZ9<>$BZ$5),RANK(BZ9,$BZ$7:$BZ$33000,1),"") | CB9: =IF(COUNTIF($CD$7:CD9,CD9)=1,CD9,CD9+COUNTIF($CD$6:CD8,CD9)) -> 55155 | CC9: =IF(INDEX(Kassza,CH9,1)<>1,INDEX(Kassza,CH9,1),$CD$2) -> 55153 | CD9: =IF(CC9<>$CD$2,RANK(CC9,$CC$7:$CC$33000,1),$CD$2) -> 55153 | CE9: =INDEX(Kassza,CH9,6) -> 0 | CF9: =INDEX(Kassza,CH9,8) -> 0 | CG9: =INDEX(Kassza,CH9,7)&INDEX(Kassza,CH9,9) | CH9: 4 | CI9: Kassza | CJ9: =IF(INDEX(Kassza,CH9,5)<>0,INDEX(Kassza,CH9,5),"") | CK9: =IF(INDEX(Kassza,CH9,10)<>0,INDEX(Kassza,CH9,10),"") | CL9: =IF(INDEX(Kassza,CH9,11)<>0,INDEX(Kassza,CH9,11),"") | CM9: =IF(INDEX(Kassza,CH9,4)<>0,INDEX(Kassza,CH9,4),"") | CN9: =IF(INDEX(Kassza,CH9,3)<>0,INDEX(Kassza,CH9,3),"") | CP9: hb | CQ9: =INDEX(hb,1,6) -> 0 | CR9: =[1]H!$D$3 -> 0 | CU9: =[1]Hibak!E1049 -> Venituri cu scop misionar - tineret | CV9: =INDEX(Csfi,CZ9,1) -> Gyerek és ifjúsági tevékenységek bevételei | CZ9: 852 | DD9: H - számla | DE9: hb | DF9: =IF(ISERROR(VLOOKUP(DD9,Resz_szamadas!$H$1:$I$21,2,FALSE))=FALSE,1,0) -> 0
B10: 1 | C10: Adatok | D10: Data | E10: menü | BS10: =IF(Kiadasi_kiseroiv!$K$2=BT10,BV10,"") | BT10: =IF(AND($BT$4=CI10,BU10<>""),CC10,"") | BU10: =IF(AND($BU$1=CI10,ISERROR(VLOOKUP(CG10,Kisiv,2,FALSE))=FALSE),CB10,"") | BV10: =IF(BU10<>"",RANK(BU10,$BU$7:$BU$33000,1),"") | BW10: =IF(CC10<min,$BW$2,IF(CC10<=max,CG10,"")) | BX10: =IF(AND(OR($BX$1=0,$BX$1=CG10),OR($BX$2=0,IF(ISERROR(SEARCH($BX$2,CJ10&CK10&CL10,1)),FALSE,TRUE))),CB10,"") | BY10: =IF(AND(BX10<>"",CC10<>$CD$2),RANK(BX10,$BX$7:$BX$33000,1),"") | BZ10: =IF(AND(CC10<$BZ$2,CI10=$BZ$4),$BZ$5,IF(AND(CC10<=$BZ$3,CI10=$BZ$4),CB10,"")) | CA10: =IF(AND(BZ10<>"",BZ10<>$BZ$5),RANK(BZ10,$BZ$7:$BZ$33000,1),"") | CB10: =IF(COUNTIF($CD$7:CD10,CD10)=1,CD10,CD10+COUNTIF($CD$6:CD9,CD10)) -> 55156 | CC10: =IF(INDEX(Kassza,CH10,1)<>1,INDEX(Kassza,CH10,1),$CD$2) -> 55153 | CD10: =IF(CC10<>$CD$2,RANK(CC10,$CC$7:$CC$33000,1),$CD$2) -> 55153 | CE10: =INDEX(Kassza,CH10,6) -> 0 | CF10: =INDEX(Kassza,CH10,8) -> 0 | CG10: =INDEX(Kassza,CH10,7)&INDEX(Kassza,CH10,9) | CH10: 5 | CI10: Kassza | CJ10: =IF(INDEX(Kassza,CH10,5)<>0,INDEX(Kassza,CH10,5),"") | CK10: =IF(INDEX(Kassza,CH10,10)<>0,INDEX(Kassza,CH10,10),"") | CL10: =IF(INDEX(Kassza,CH10,11)<>0,INDEX(Kassza,CH10,11),"") | CM10: =IF(INDEX(Kassza,CH10,4)<>0,INDEX(Kassza,CH10,4),"") | CN10: =IF(INDEX(Kassza,CH10,3)<>0,INDEX(Kassza,CH10,3),"") | CP10: ib | CQ10: =INDEX(ib,1,6) -> 0 | CR10: =[1]I!$D$3 -> 0 | CU10: =[1]Hibak!E1050 -> Venituri cu scop misionar - asoc. femeilor crestine | CV10: =INDEX(Csfi,CZ10,1) -> Nőszövetségi tevékenységek bevételei | CZ10: 853 | DD10: I - számla | DE10: ib | DF10: =IF(ISERROR(VLOOKUP(DD10,Resz_szamadas!$H$1:$I$21,2,FALSE))=FALSE,1,0) -> 0
B11: 2 | C11: Csatolások szerkesztése | D11: Edit links | E11: almenü | BS11: =IF(Kiadasi_kiseroiv!$K$2=BT11,BV11,"") | BT11: =IF(AND($BT$4=CI11,BU11<>""),CC11,"") | BU11: =IF(AND($BU$1=CI11,ISERROR(VLOOKUP(CG11,Kisiv,2,FALSE))=FALSE),CB11,"") | BV11: =IF(BU11<>"",RANK(BU11,$BU$7:$BU$33000,1),"") | BW11: =IF(CC11<min,$BW$2,IF(CC11<=max,CG11,"")) | BX11: =IF(AND(OR($BX$1=0,$BX$1=CG11),OR($BX$2=0,IF(ISERROR(SEARCH($BX$2,CJ11&CK11&CL11,1)),FALSE,TRUE))),CB11,"") | BY11: =IF(AND(BX11<>"",CC11<>$CD$2),RANK(BX11,$BX$7:$BX$33000,1),"") | BZ11: =IF(AND(CC11<$BZ$2,CI11=$BZ$4),$BZ$5,IF(AND(CC11<=$BZ$3,CI11=$BZ$4),CB11,"")) | CA11: =IF(AND(BZ11<>"",BZ11<>$BZ$5),RANK(BZ11,$BZ$7:$BZ$33000,1),"") | CB11: =IF(COUNTIF($CD$7:CD11,CD11)=1,CD11,CD11+COUNTIF($CD$6:CD10,CD11)) -> 55157 | CC11: =IF(INDEX(Kassza,CH11,1)<>1,INDEX(Kassza,CH11,1),$CD$2) -> 55153 | CD11: =IF(CC11<>$CD$2,RANK(CC11,$CC$7:$CC$33000,1),$CD$2) -> 55153 | CE11: =INDEX(Kassza,CH11,6) -> 0 | CF11: =INDEX(Kassza,CH11,8) -> 0 | CG11: =INDEX(Kassza,CH11,7)&INDEX(Kassza,CH11,9) | CH11: 6 | CI11: Kassza | CJ11: =IF(INDEX(Kassza,CH11,5)<>0,INDEX(Kassza,CH11,5),"") | CK11: =IF(INDEX(Kassza,CH11,10)<>0,INDEX(Kassza,CH11,10),"") | CL11: =IF(INDEX(Kassza,CH11,11)<>0,INDEX(Kassza,CH11,11),"") | CM11: =IF(INDEX(Kassza,CH11,4)<>0,INDEX(Kassza,CH11,4),"") | CN11: =IF(INDEX(Kassza,CH11,3)<>0,INDEX(Kassza,CH11,3),"") | CP11: jb | CQ11: =INDEX(jb,1,6) -> 0 | CR11: =[1]J!$D$3 -> 0 | CU11: =[1]Hibak!E1051 -> Venituri cu scop misionar - asoc. presbiterilor | CV11: =INDEX(Csfi,CZ11,1) -> Presbiterszövetségi tevékenységek bevételei | CZ11: 854 | DD11: J - számla | DE11: jb | DF11: =IF(ISERROR(VLOOKUP(DD11,Resz_szamadas!$H$1:$I$21,2,FALSE))=FALSE,1,0) -> 0
C12: 3 | D12: Váltás | E12: Change source | F12: gomb | BS12: =IF(Kiadasi_kiseroiv!$K$2=BT12,BV12,"") | BT12: =IF(AND($BT$4=CI12,BU12<>""),CC12,"") | BU12: =IF(AND($BU$1=CI12,ISERROR(VLOOKUP(CG12,Kisiv,2,FALSE))=FALSE),CB12,"") | BV12: =IF(BU12<>"",RANK(BU12,$BU$7:$BU$33000,1),"") | BW12: =IF(CC12<min,$BW$2,IF(CC12<=max,CG12,"")) | BX12: =IF(AND(OR($BX$1=0,$BX$1=CG12),OR($BX$2=0,IF(ISERROR(SEARCH($BX$2,CJ12&CK12&CL12,1)),FALSE,TRUE))),CB12,"") | BY12: =IF(AND(BX12<>"",CC12<>$CD$2),RANK(BX12,$BX$7:$BX$33000,1),"") | BZ12: =IF(AND(CC12<$BZ$2,CI12=$BZ$4),$BZ$5,IF(AND(CC12<=$BZ$3,CI12=$BZ$4),CB12,"")) | CA12: =IF(AND(BZ12<>"",BZ12<>$BZ$5),RANK(BZ12,$BZ$7:$BZ$33000,1),"") | CB12: =IF(COUNTIF($CD$7:CD12,CD12)=1,CD12,CD12+COUNTIF($CD$6:CD11,CD12)) -> 55158 | CC12: =IF(INDEX(Kassza,CH12,1)<>1,INDEX(Kassza,CH12,1),$CD$2) -> 55153 | CD12: =IF(CC12<>$CD$2,RANK(CC12,$CC$7:$CC$33000,1),$CD$2) -> 55153 | CE12: =INDEX(Kassza,CH12,6) -> 0 | CF12: =INDEX(Kassza,CH12,8) -> 0 | CG12: =INDEX(Kassza,CH12,7)&INDEX(Kassza,CH12,9) | CH12: 7 | CI12: Kassza | CJ12: =IF(INDEX(Kassza,CH12,5)<>0,INDEX(Kassza,CH12,5),"") | CK12: =IF(INDEX(Kassza,CH12,10)<>0,INDEX(Kassza,CH12,10),"") | CL12: =IF(INDEX(Kassza,CH12,11)<>0,INDEX(Kassza,CH12,11),"") | CM12: =IF(INDEX(Kassza,CH12,4)<>0,INDEX(Kassza,CH12,4),"") | CN12: =IF(INDEX(Kassza,CH12,3)<>0,INDEX(Kassza,CH12,3),"") | CP12: kb | CQ12: =INDEX(kb,1,6) -> 0 | CR12: =[1]K!$D$3 -> 0 | CU12: =[1]Hibak!E1052 -> Donaţii pentru scopuri diaconice | CV12: =INDEX(Csfi,CZ12,1) -> Diakóniai célú adományok | CZ12: 855 | DD12: K - számla | DE12: kb | DF12: =IF(ISERROR(VLOOKUP(DD12,Resz_szamadas!$H$1:$I$21,2,FALSE))=FALSE,1,0) -> 0
C13: 4 | D13: A megjelenő böngészőben kiválasztani azt az állományt, amelybe a könyvelési adatokat irtuk majd egy OK | BS13: =IF(Kiadasi_kiseroiv!$K$2=BT13,BV13,"") | BT13: =IF(AND($BT$4=CI13,BU13<>""),CC13,"") | BU13: =IF(AND($BU$1=CI13,ISERROR(VLOOKUP(CG13,Kisiv,2,FALSE))=FALSE),CB13,"") | BV13: =IF(BU13<>"",RANK(BU13,$BU$7:$BU$33000,1),"") | BW13: =IF(CC13<min,$BW$2,IF(CC13<=max,CG13,"")) | BX13: =IF(AND(OR($BX$1=0,$BX$1=CG13),OR($BX$2=0,IF(ISERROR(SEARCH($BX$2,CJ13&CK13&CL13,1)),FALSE,TRUE))),CB13,"") | BY13: =IF(AND(BX13<>"",CC13<>$CD$2),RANK(BX13,$BX$7:$BX$33000,1),"") | BZ13: =IF(AND(CC13<$BZ$2,CI13=$BZ$4),$BZ$5,IF(AND(CC13<=$BZ$3,CI13=$BZ$4),CB13,"")) | CA13: =IF(AND(BZ13<>"",BZ13<>$BZ$5),RANK(BZ13,$BZ$7:$BZ$33000,1),"") | CB13: =IF(COUNTIF($CD$7:CD13,CD13)=1,CD13,CD13+COUNTIF($CD$6:CD12,CD13)) -> 55159 | CC13: =IF(INDEX(Kassza,CH13,1)<>1,INDEX(Kassza,CH13,1),$CD$2) -> 55153 | CD13: =IF(CC13<>$CD$2,RANK(CC13,$CC$7:$CC$33000,1),$CD$2) -> 55153 | CE13: =INDEX(Kassza,CH13,6) -> 0 | CF13: =INDEX(Kassza,CH13,8) -> 0 | CG13: =INDEX(Kassza,CH13,7)&INDEX(Kassza,CH13,9) | CH13: 8 | CI13: Kassza | CJ13: =IF(INDEX(Kassza,CH13,5)<>0,INDEX(Kassza,CH13,5),"") | CK13: =IF(INDEX(Kassza,CH13,10)<>0,INDEX(Kassza,CH13,10),"") | CL13: =IF(INDEX(Kassza,CH13,11)<>0,INDEX(Kassza,CH13,11),"") | CM13: =IF(INDEX(Kassza,CH13,4)<>0,INDEX(Kassza,CH13,4),"") | CN13: =IF(INDEX(Kassza,CH13,3)<>0,INDEX(Kassza,CH13,3),"") | CP13: lb | CQ13: =INDEX(lb,1,6) -> 0 | CR13: =[1]L!$D$3 -> 0 | CU13: =[1]Hibak!E1053 -> Donatii pt scopuri misionare | CV13: =INDEX(Csfi,CZ13,1) -> Missziós célú adományok | CZ13: 856 | DD13: L - számla | DE13: lb | DF13: =IF(ISERROR(VLOOKUP(DD13,Resz_szamadas!$H$1:$I$21,2,FALSE))=FALSE,1,0) -> 0
C14: 5 | D14: Megvárni amig befejezi a csatolást (kisebb teljesítményu gépeknél ez pár percet is igénybe vehet), majd bezárás | BS14: =IF(Kiadasi_kiseroiv!$K$2=BT14,BV14,"") | BT14: =IF(AND($BT$4=CI14,BU14<>""),CC14,"") | BU14: =IF(AND($BU$1=CI14,ISERROR(VLOOKUP(CG14,Kisiv,2,FALSE))=FALSE),CB14,"") | BV14: =IF(BU14<>"",RANK(BU14,$BU$7:$BU$33000,1),"") | BW14: =IF(CC14<min,$BW$2,IF(CC14<=max,CG14,"")) | BX14: =IF(AND(OR($BX$1=0,$BX$1=CG14),OR($BX$2=0,IF(ISERROR(SEARCH($BX$2,CJ14&CK14&CL14,1)),FALSE,TRUE))),CB14,"") | BY14: =IF(AND(BX14<>"",CC14<>$CD$2),RANK(BX14,$BX$7:$BX$33000,1),"") | BZ14: =IF(AND(CC14<$BZ$2,CI14=$BZ$4),$BZ$5,IF(AND(CC14<=$BZ$3,CI14=$BZ$4),CB14,"")) | CA14: =IF(AND(BZ14<>"",BZ14<>$BZ$5),RANK(BZ14,$BZ$7:$BZ$33000,1),"") | CB14: =IF(COUNTIF($CD$7:CD14,CD14)=1,CD14,CD14+COUNTIF($CD$6:CD13,CD14)) -> 55160 | CC14: =IF(INDEX(Kassza,CH14,1)<>1,INDEX(Kassza,CH14,1),$CD$2) -> 55153 | CD14: =IF(CC14<>$CD$2,RANK(CC14,$CC$7:$CC$33000,1),$CD$2) -> 55153 | CE14: =INDEX(Kassza,CH14,6) -> 0 | CF14: =INDEX(Kassza,CH14,8) -> 0 | CG14: =INDEX(Kassza,CH14,7)&INDEX(Kassza,CH14,9) | CH14: 9 | CI14: Kassza | CJ14: =IF(INDEX(Kassza,CH14,5)<>0,INDEX(Kassza,CH14,5),"") | CK14: =IF(INDEX(Kassza,CH14,10)<>0,INDEX(Kassza,CH14,10),"") | CL14: =IF(INDEX(Kassza,CH14,11)<>0,INDEX(Kassza,CH14,11),"") | CM14: =IF(INDEX(Kassza,CH14,4)<>0,INDEX(Kassza,CH14,4),"") | CN14: =IF(INDEX(Kassza,CH14,3)<>0,INDEX(Kassza,CH14,3),"") | CP14: mb | CU14: =[1]Hibak!E1054 -> Donatii pt studenti de la teologie | CV14: =INDEX(Csfi,CZ14,1) -> Legátumok - adományok teológiai hallgatók támogatására | CZ14: 857 | DD14: M - számla | DE14: mb | DF14: =IF(ISERROR(VLOOKUP(DD14,Resz_szamadas!$H$1:$I$21,2,FALSE))=FALSE,1,0) -> 0
BS15: =IF(Kiadasi_kiseroiv!$K$2=BT15,BV15,"") | BT15: =IF(AND($BT$4=CI15,BU15<>""),CC15,"") | BU15: =IF(AND($BU$1=CI15,ISERROR(VLOOKUP(CG15,Kisiv,2,FALSE))=FALSE),CB15,"") | BV15: =IF(BU15<>"",RANK(BU15,$BU$7:$BU$33000,1),"") | BW15: =IF(CC15<min,$BW$2,IF(CC15<=max,CG15,"")) | BX15: =IF(AND(OR($BX$1=0,$BX$1=CG15),OR($BX$2=0,IF(ISERROR(SEARCH($BX$2,CJ15&CK15&CL15,1)),FALSE,TRUE))),CB15,"") | BY15: =IF(AND(BX15<>"",CC15<>$CD$2),RANK(BX15,$BX$7:$BX$33000,1),"") | BZ15: =IF(AND(CC15<$BZ$2,CI15=$BZ$4),$BZ$5,IF(AND(CC15<=$BZ$3,CI15=$BZ$4),CB15,"")) | CA15: =IF(AND(BZ15<>"",BZ15<>$BZ$5),RANK(BZ15,$BZ$7:$BZ$33000,1),"") | CB15: =IF(COUNTIF($CD$7:CD15,CD15)=1,CD15,CD15+COUNTIF($CD$6:CD14,CD15)) -> 55161 | CC15: =IF(INDEX(Kassza,CH15,1)<>1,INDEX(Kassza,CH15,1),$CD$2) -> 55153 | CD15: =IF(CC15<>$CD$2,RANK(CC15,$CC$7:$CC$33000,1),$CD$2) -> 55153 | CE15: =INDEX(Kassza,CH15,6) -> 0 | CF15: =INDEX(Kassza,CH15,8) -> 0 | CG15: =INDEX(Kassza,CH15,7)&INDEX(Kassza,CH15,9) | CH15: 10 | CI15: Kassza | CJ15: =IF(INDEX(Kassza,CH15,5)<>0,INDEX(Kassza,CH15,5),"") | CK15: =IF(INDEX(Kassza,CH15,10)<>0,INDEX(Kassza,CH15,10),"") | CL15: =IF(INDEX(Kassza,CH15,11)<>0,INDEX(Kassza,CH15,11),"") | CM15: =IF(INDEX(Kassza,CH15,4)<>0,INDEX(Kassza,CH15,4),"") | CN15: =IF(INDEX(Kassza,CH15,3)<>0,INDEX(Kassza,CH15,3),"") | CP15: nb | CU15: =[1]Hibak!E1055 -> Alte donaţii | CV15: =INDEX(Csfi,CZ15,1) -> Segélyszervezetektől, alapítványoktól, helyi szervezetektől származó adományok | CZ15: 858 | DD15: N - számla | DE15: nb | DF15: =IF(ISERROR(VLOOKUP(DD15,Resz_szamadas!$H$1:$I$21,2,FALSE))=FALSE,1,0) -> 0
BS16: =IF(Kiadasi_kiseroiv!$K$2=BT16,BV16,"") | BT16: =IF(AND($BT$4=CI16,BU16<>""),CC16,"") | BU16: =IF(AND($BU$1=CI16,ISERROR(VLOOKUP(CG16,Kisiv,2,FALSE))=FALSE),CB16,"") | BV16: =IF(BU16<>"",RANK(BU16,$BU$7:$BU$33000,1),"") | BW16: =IF(CC16<min,$BW$2,IF(CC16<=max,CG16,"")) | BX16: =IF(AND(OR($BX$1=0,$BX$1=CG16),OR($BX$2=0,IF(ISERROR(SEARCH($BX$2,CJ16&CK16&CL16,1)),FALSE,TRUE))),CB16,"") | BY16: =IF(AND(BX16<>"",CC16<>$CD$2),RANK(BX16,$BX$7:$BX$33000,1),"") | BZ16: =IF(AND(CC16<$BZ$2,CI16=$BZ$4),$BZ$5,IF(AND(CC16<=$BZ$3,CI16=$BZ$4),CB16,"")) | CA16: =IF(AND(BZ16<>"",BZ16<>$BZ$5),RANK(BZ16,$BZ$7:$BZ$33000,1),"") | CB16: =IF(COUNTIF($CD$7:CD16,CD16)=1,CD16,CD16+COUNTIF($CD$6:CD15,CD16)) -> 55162 | CC16: =IF(INDEX(Kassza,CH16,1)<>1,INDEX(Kassza,CH16,1),$CD$2) -> 55153 | CD16: =IF(CC16<>$CD$2,RANK(CC16,$CC$7:$CC$33000,1),$CD$2) -> 55153 | CE16: =INDEX(Kassza,CH16,6) -> 0 | CF16: =INDEX(Kassza,CH16,8) -> 0 | CG16: =INDEX(Kassza,CH16,7)&INDEX(Kassza,CH16,9) | CH16: 11 | CI16: Kassza | CJ16: =IF(INDEX(Kassza,CH16,5)<>0,INDEX(Kassza,CH16,5),"") | CK16: =IF(INDEX(Kassza,CH16,10)<>0,INDEX(Kassza,CH16,10),"") | CL16: =IF(INDEX(Kassza,CH16,11)<>0,INDEX(Kassza,CH16,11),"") | CM16: =IF(INDEX(Kassza,CH16,4)<>0,INDEX(Kassza,CH16,4),"") | CN16: =IF(INDEX(Kassza,CH16,3)<>0,INDEX(Kassza,CH16,3),"") | CP16: ob | CU16: =[1]Hibak!E1056 -> Incasări proiecte | CV16: =INDEX(Csfi,CZ16,1) -> Pályázatokból | CZ16: 859 | DD16: O - számla | DE16: ob | DF16: =IF(ISERROR(VLOOKUP(DD16,Resz_szamadas!$H$1:$I$21,2,FALSE))=FALSE,1,0) -> 0
BS17: =IF(Kiadasi_kiseroiv!$K$2=BT17,BV17,"") | BT17: =IF(AND($BT$4=CI17,BU17<>""),CC17,"") | BU17: =IF(AND($BU$1=CI17,ISERROR(VLOOKUP(CG17,Kisiv,2,FALSE))=FALSE),CB17,"") | BV17: =IF(BU17<>"",RANK(BU17,$BU$7:$BU$33000,1),"") | BW17: =IF(CC17<min,$BW$2,IF(CC17<=max,CG17,"")) | BX17: =IF(AND(OR($BX$1=0,$BX$1=CG17),OR($BX$2=0,IF(ISERROR(SEARCH($BX$2,CJ17&CK17&CL17,1)),FALSE,TRUE))),CB17,"") | BY17: =IF(AND(BX17<>"",CC17<>$CD$2),RANK(BX17,$BX$7:$BX$33000,1),"") | BZ17: =IF(AND(CC17<$BZ$2,CI17=$BZ$4),$BZ$5,IF(AND(CC17<=$BZ$3,CI17=$BZ$4),CB17,"")) | CA17: =IF(AND(BZ17<>"",BZ17<>$BZ$5),RANK(BZ17,$BZ$7:$BZ$33000,1),"") | CB17: =IF(COUNTIF($CD$7:CD17,CD17)=1,CD17,CD17+COUNTIF($CD$6:CD16,CD17)) -> 55163 | CC17: =IF(INDEX(Kassza,CH17,1)<>1,INDEX(Kassza,CH17,1),$CD$2) -> 55153 | CD17: =IF(CC17<>$CD$2,RANK(CC17,$CC$7:$CC$33000,1),$CD$2) -> 55153 | CE17: =INDEX(Kassza,CH17,6) -> 0 | CF17: =INDEX(Kassza,CH17,8) -> 0 | CG17: =INDEX(Kassza,CH17,7)&INDEX(Kassza,CH17,9) | CH17: 12 | CI17: Kassza | CJ17: =IF(INDEX(Kassza,CH17,5)<>0,INDEX(Kassza,CH17,5),"") | CK17: =IF(INDEX(Kassza,CH17,10)<>0,INDEX(Kassza,CH17,10),"") | CL17: =IF(INDEX(Kassza,CH17,11)<>0,INDEX(Kassza,CH17,11),"") | CM17: =IF(INDEX(Kassza,CH17,4)<>0,INDEX(Kassza,CH17,4),"") | CN17: =IF(INDEX(Kassza,CH17,3)<>0,INDEX(Kassza,CH17,3),"") | CP17: pb | CU17: =[1]Hibak!E1057 -> Din alte surse | CV17: =INDEX(Csfi,CZ17,1) -> Más bevételek | CZ17: 860 | DD17: P - számla | DE17: pb | DF17: =IF(ISERROR(VLOOKUP(DD17,Resz_szamadas!$H$1:$I$21,2,FALSE))=FALSE,1,0) -> 0
BS18: =IF(Kiadasi_kiseroiv!$K$2=BT18,BV18,"") | BT18: =IF(AND($BT$4=CI18,BU18<>""),CC18,"") | BU18: =IF(AND($BU$1=CI18,ISERROR(VLOOKUP(CG18,Kisiv,2,FALSE))=FALSE),CB18,"") | BV18: =IF(BU18<>"",RANK(BU18,$BU$7:$BU$33000,1),"") | BW18: =IF(CC18<min,$BW$2,IF(CC18<=max,CG18,"")) | BX18: =IF(AND(OR($BX$1=0,$BX$1=CG18),OR($BX$2=0,IF(ISERROR(SEARCH($BX$2,CJ18&CK18&CL18,1)),FALSE,TRUE))),CB18,"") | BY18: =IF(AND(BX18<>"",CC18<>$CD$2),RANK(BX18,$BX$7:$BX$33000,1),"") | BZ18: =IF(AND(CC18<$BZ$2,CI18=$BZ$4),$BZ$5,IF(AND(CC18<=$BZ$3,CI18=$BZ$4),CB18,"")) | CA18: =IF(AND(BZ18<>"",BZ18<>$BZ$5),RANK(BZ18,$BZ$7:$BZ$33000,1),"") | CB18: =IF(COUNTIF($CD$7:CD18,CD18)=1,CD18,CD18+COUNTIF($CD$6:CD17,CD18)) -> 55164 | CC18: =IF(INDEX(Kassza,CH18,1)<>1,INDEX(Kassza,CH18,1),$CD$2) -> 55153 | CD18: =IF(CC18<>$CD$2,RANK(CC18,$CC$7:$CC$33000,1),$CD$2) -> 55153 | CE18: =INDEX(Kassza,CH18,6) -> 0 | CF18: =INDEX(Kassza,CH18,8) -> 0 | CG18: =INDEX(Kassza,CH18,7)&INDEX(Kassza,CH18,9) | CH18: 13 | CI18: Kassza | CJ18: =IF(INDEX(Kassza,CH18,5)<>0,INDEX(Kassza,CH18,5),"") | CK18: =IF(INDEX(Kassza,CH18,10)<>0,INDEX(Kassza,CH18,10),"") | CL18: =IF(INDEX(Kassza,CH18,11)<>0,INDEX(Kassza,CH18,11),"") | CM18: =IF(INDEX(Kassza,CH18,4)<>0,INDEX(Kassza,CH18,4),"") | CN18: =IF(INDEX(Kassza,CH18,3)<>0,INDEX(Kassza,CH18,3),"") | CP18: qb | CU18: =[1]Hibak!E1058 -> Dobândă bancară, diferentă curs valutar, venituri din dividende si obligatiuni | CV18: =INDEX(Csfi,CZ18,1) -> Banki kamatok, árfolyam nyereségek, kötvények jövedelme, osztalékok | CZ18: 861 | DD18: Q - számla | DE18: qb | DF18: =IF(ISERROR(VLOOKUP(DD18,Resz_szamadas!$H$1:$I$21,2,FALSE))=FALSE,1,0) -> 0
BS19: =IF(Kiadasi_kiseroiv!$K$2=BT19,BV19,"") | BT19: =IF(AND($BT$4=CI19,BU19<>""),CC19,"") | BU19: =IF(AND($BU$1=CI19,ISERROR(VLOOKUP(CG19,Kisiv,2,FALSE))=FALSE),CB19,"") | BV19: =IF(BU19<>"",RANK(BU19,$BU$7:$BU$33000,1),"") | BW19: =IF(CC19<min,$BW$2,IF(CC19<=max,CG19,"")) | BX19: =IF(AND(OR($BX$1=0,$BX$1=CG19),OR($BX$2=0,IF(ISERROR(SEARCH($BX$2,CJ19&CK19&CL19,1)),FALSE,TRUE))),CB19,"") | BY19: =IF(AND(BX19<>"",CC19<>$CD$2),RANK(BX19,$BX$7:$BX$33000,1),"") | BZ19: =IF(AND(CC19<$BZ$2,CI19=$BZ$4),$BZ$5,IF(AND(CC19<=$BZ$3,CI19=$BZ$4),CB19,"")) | CA19: =IF(AND(BZ19<>"",BZ19<>$BZ$5),RANK(BZ19,$BZ$7:$BZ$33000,1),"") | CB19: =IF(COUNTIF($CD$7:CD19,CD19)=1,CD19,CD19+COUNTIF($CD$6:CD18,CD19)) -> 55165 | CC19: =IF(INDEX(Kassza,CH19,1)<>1,INDEX(Kassza,CH19,1),$CD$2) -> 55153 | CD19: =IF(CC19<>$CD$2,RANK(CC19,$CC$7:$CC$33000,1),$CD$2) -> 55153 | CE19: =INDEX(Kassza,CH19,6) -> 0 | CF19: =INDEX(Kassza,CH19,8) -> 0 | CG19: =INDEX(Kassza,CH19,7)&INDEX(Kassza,CH19,9) | CH19: 14 | CI19: Kassza | CJ19: =IF(INDEX(Kassza,CH19,5)<>0,INDEX(Kassza,CH19,5),"") | CK19: =IF(INDEX(Kassza,CH19,10)<>0,INDEX(Kassza,CH19,10),"") | CL19: =IF(INDEX(Kassza,CH19,11)<>0,INDEX(Kassza,CH19,11),"") | CM19: =IF(INDEX(Kassza,CH19,4)<>0,INDEX(Kassza,CH19,4),"") | CN19: =IF(INDEX(Kassza,CH19,3)<>0,INDEX(Kassza,CH19,3),"") | CP19: rb | CU19: =[1]Hibak!E1059 -> Pt. participare la conferinţe | CV19: =INDEX(Csfi,CZ19,1) -> Hozzájárulás konferenciák és szeretetvendégségek szervezéséhez | CZ19: 862 | DD19: R - számla | DE19: rb | DF19: =IF(ISERROR(VLOOKUP(DD19,Resz_szamadas!$H$1:$I$21,2,FALSE))=FALSE,1,0) -> 0
BS20: =IF(Kiadasi_kiseroiv!$K$2=BT20,BV20,"") | BT20: =IF(AND($BT$4=CI20,BU20<>""),CC20,"") | BU20: =IF(AND($BU$1=CI20,ISERROR(VLOOKUP(CG20,Kisiv,2,FALSE))=FALSE),CB20,"") | BV20: =IF(BU20<>"",RANK(BU20,$BU$7:$BU$33000,1),"") | BW20: =IF(CC20<min,$BW$2,IF(CC20<=max,CG20,"")) | BX20: =IF(AND(OR($BX$1=0,$BX$1=CG20),OR($BX$2=0,IF(ISERROR(SEARCH($BX$2,CJ20&CK20&CL20,1)),FALSE,TRUE))),CB20,"") | BY20: =IF(AND(BX20<>"",CC20<>$CD$2),RANK(BX20,$BX$7:$BX$33000,1),"") | BZ20: =IF(AND(CC20<$BZ$2,CI20=$BZ$4),$BZ$5,IF(AND(CC20<=$BZ$3,CI20=$BZ$4),CB20,"")) | CA20: =IF(AND(BZ20<>"",BZ20<>$BZ$5),RANK(BZ20,$BZ$7:$BZ$33000,1),"") | CB20: =IF(COUNTIF($CD$7:CD20,CD20)=1,CD20,CD20+COUNTIF($CD$6:CD19,CD20)) -> 55166 | CC20: =IF(INDEX(Kassza,CH20,1)<>1,INDEX(Kassza,CH20,1),$CD$2) -> 55153 | CD20: =IF(CC20<>$CD$2,RANK(CC20,$CC$7:$CC$33000,1),$CD$2) -> 55153 | CE20: =INDEX(Kassza,CH20,6) -> 0 | CF20: =INDEX(Kassza,CH20,8) -> 0 | CG20: =INDEX(Kassza,CH20,7)&INDEX(Kassza,CH20,9) | CH20: 15 | CI20: Kassza | CJ20: =IF(INDEX(Kassza,CH20,5)<>0,INDEX(Kassza,CH20,5),"") | CK20: =IF(INDEX(Kassza,CH20,10)<>0,INDEX(Kassza,CH20,10),"") | CL20: =IF(INDEX(Kassza,CH20,11)<>0,INDEX(Kassza,CH20,11),"") | CM20: =IF(INDEX(Kassza,CH20,4)<>0,INDEX(Kassza,CH20,4),"") | CN20: =IF(INDEX(Kassza,CH20,3)<>0,INDEX(Kassza,CH20,3),"") | CP20: sb | CU20: =[1]Hibak!E1060 -> Distribuirea tipăriturilor | CV20: =INDEX(Csfi,CZ20,1) -> Iratterjesztés - bevétel | CZ20: 863 | DD20: S - számla | DE20: sb | DF20: =IF(ISERROR(VLOOKUP(DD20,Resz_szamadas!$H$1:$I$21,2,FALSE))=FALSE,1,0) -> 0
BS21: =IF(Kiadasi_kiseroiv!$K$2=BT21,BV21,"") | BT21: =IF(AND($BT$4=CI21,BU21<>""),CC21,"") | BU21: =IF(AND($BU$1=CI21,ISERROR(VLOOKUP(CG21,Kisiv,2,FALSE))=FALSE),CB21,"") | BV21: =IF(BU21<>"",RANK(BU21,$BU$7:$BU$33000,1),"") | BW21: =IF(CC21<min,$BW$2,IF(CC21<=max,CG21,"")) | BX21: =IF(AND(OR($BX$1=0,$BX$1=CG21),OR($BX$2=0,IF(ISERROR(SEARCH($BX$2,CJ21&CK21&CL21,1)),FALSE,TRUE))),CB21,"") | BY21: =IF(AND(BX21<>"",CC21<>$CD$2),RANK(BX21,$BX$7:$BX$33000,1),"") | BZ21: =IF(AND(CC21<$BZ$2,CI21=$BZ$4),$BZ$5,IF(AND(CC21<=$BZ$3,CI21=$BZ$4),CB21,"")) | CA21: =IF(AND(BZ21<>"",BZ21<>$BZ$5),RANK(BZ21,$BZ$7:$BZ$33000,1),"") | CB21: =IF(COUNTIF($CD$7:CD21,CD21)=1,CD21,CD21+COUNTIF($CD$6:CD20,CD21)) -> 55167 | CC21: =IF(INDEX(Kassza,CH21,1)<>1,INDEX(Kassza,CH21,1),$CD$2) -> 55153 | CD21: =IF(CC21<>$CD$2,RANK(CC21,$CC$7:$CC$33000,1),$CD$2) -> 55153 | CE21: =INDEX(Kassza,CH21,6) -> 0 | CF21: =INDEX(Kassza,CH21,8) -> 0 | CG21: =INDEX(Kassza,CH21,7)&INDEX(Kassza,CH21,9) | CH21: 16 | CI21: Kassza | CJ21: =IF(INDEX(Kassza,CH21,5)<>0,INDEX(Kassza,CH21,5),"") | CK21: =IF(INDEX(Kassza,CH21,10)<>0,INDEX(Kassza,CH21,10),"") | CL21: =IF(INDEX(Kassza,CH21,11)<>0,INDEX(Kassza,CH21,11),"") | CM21: =IF(INDEX(Kassza,CH21,4)<>0,INDEX(Kassza,CH21,4),"") | CN21: =IF(INDEX(Kassza,CH21,3)<>0,INDEX(Kassza,CH21,3),"") | CP21: tb | CU21: =[1]Hibak!E1061 -> Din valorificarea unor bunuri si vânzare unori actiuni | CV21: =INDEX(Csfi,CZ21,1) -> Javak és részvények értékesítéséből | CZ21: 864 | DD21: T - számla | DE21: tb | DF21: =IF(ISERROR(VLOOKUP(DD21,Resz_szamadas!$H$1:$I$21,2,FALSE))=FALSE,1,0) -> 0
BS22: =IF(Kiadasi_kiseroiv!$K$2=BT22,BV22,"") | BT22: =IF(AND($BT$4=CI22,BU22<>""),CC22,"") | BU22: =IF(AND($BU$1=CI22,ISERROR(VLOOKUP(CG22,Kisiv,2,FALSE))=FALSE),CB22,"") | BV22: =IF(BU22<>"",RANK(BU22,$BU$7:$BU$33000,1),"") | BW22: =IF(CC22<min,$BW$2,IF(CC22<=max,CG22,"")) | BX22: =IF(AND(OR($BX$1=0,$BX$1=CG22),OR($BX$2=0,IF(ISERROR(SEARCH($BX$2,CJ22&CK22&CL22,1)),FALSE,TRUE))),CB22,"") | BY22: =IF(AND(BX22<>"",CC22<>$CD$2),RANK(BX22,$BX$7:$BX$33000,1),"") | BZ22: =IF(AND(CC22<$BZ$2,CI22=$BZ$4),$BZ$5,IF(AND(CC22<=$BZ$3,CI22=$BZ$4),CB22,"")) | CA22: =IF(AND(BZ22<>"",BZ22<>$BZ$5),RANK(BZ22,$BZ$7:$BZ$33000,1),"") | CB22: =IF(COUNTIF($CD$7:CD22,CD22)=1,CD22,CD22+COUNTIF($CD$6:CD21,CD22)) -> 55168 | CC22: =IF(INDEX(Kassza,CH22,1)<>1,INDEX(Kassza,CH22,1),$CD$2) -> 55153 | CD22: =IF(CC22<>$CD$2,RANK(CC22,$CC$7:$CC$33000,1),$CD$2) -> 55153 | CE22: =INDEX(Kassza,CH22,6) -> 0 | CF22: =INDEX(Kassza,CH22,8) -> 0 | CG22: =INDEX(Kassza,CH22,7)&INDEX(Kassza,CH22,9) | CH22: 17 | CI22: Kassza | CJ22: =IF(INDEX(Kassza,CH22,5)<>0,INDEX(Kassza,CH22,5),"") | CK22: =IF(INDEX(Kassza,CH22,10)<>0,INDEX(Kassza,CH22,10),"") | CL22: =IF(INDEX(Kassza,CH22,11)<>0,INDEX(Kassza,CH22,11),"") | CM22: =IF(INDEX(Kassza,CH22,4)<>0,INDEX(Kassza,CH22,4),"") | CN22: =IF(INDEX(Kassza,CH22,3)<>0,INDEX(Kassza,CH22,3),"") | CU22: =[1]Hibak!E1062 -> Rambursări | CV22: =INDEX(Csfi,CZ22,1) -> Számlavisszatérítések | CZ22: 865
BS23: =IF(Kiadasi_kiseroiv!$K$2=BT23,BV23,"") | BT23: =IF(AND($BT$4=CI23,BU23<>""),CC23,"") | BU23: =IF(AND($BU$1=CI23,ISERROR(VLOOKUP(CG23,Kisiv,2,FALSE))=FALSE),CB23,"") | BV23: =IF(BU23<>"",RANK(BU23,$BU$7:$BU$33000,1),"") | BW23: =IF(CC23<min,$BW$2,IF(CC23<=max,CG23,"")) | BX23: =IF(AND(OR($BX$1=0,$BX$1=CG23),OR($BX$2=0,IF(ISERROR(SEARCH($BX$2,CJ23&CK23&CL23,1)),FALSE,TRUE))),CB23,"") | BY23: =IF(AND(BX23<>"",CC23<>$CD$2),RANK(BX23,$BX$7:$BX$33000,1),"") | BZ23: =IF(AND(CC23<$BZ$2,CI23=$BZ$4),$BZ$5,IF(AND(CC23<=$BZ$3,CI23=$BZ$4),CB23,"")) | CA23: =IF(AND(BZ23<>"",BZ23<>$BZ$5),RANK(BZ23,$BZ$7:$BZ$33000,1),"") | CB23: =IF(COUNTIF($CD$7:CD23,CD23)=1,CD23,CD23+COUNTIF($CD$6:CD22,CD23)) -> 55169 | CC23: =IF(INDEX(Kassza,CH23,1)<>1,INDEX(Kassza,CH23,1),$CD$2) -> 55153 | CD23: =IF(CC23<>$CD$2,RANK(CC23,$CC$7:$CC$33000,1),$CD$2) -> 55153 | CE23: =INDEX(Kassza,CH23,6) -> 0 | CF23: =INDEX(Kassza,CH23,8) -> 0 | CG23: =INDEX(Kassza,CH23,7)&INDEX(Kassza,CH23,9) | CH23: 18 | CI23: Kassza | CJ23: =IF(INDEX(Kassza,CH23,5)<>0,INDEX(Kassza,CH23,5),"") | CK23: =IF(INDEX(Kassza,CH23,10)<>0,INDEX(Kassza,CH23,10),"") | CL23: =IF(INDEX(Kassza,CH23,11)<>0,INDEX(Kassza,CH23,11),"") | CM23: =IF(INDEX(Kassza,CH23,4)<>0,INDEX(Kassza,CH23,4),"") | CN23: =IF(INDEX(Kassza,CH23,3)<>0,INDEX(Kassza,CH23,3),"") | CU23: =[1]Hibak!E1063 -> Din sponsorizări | CV23: =INDEX(Csfi,CZ23,1) -> Szponzortámogatások, adók 3,5 %-a | CZ23: 866
BS24: =IF(Kiadasi_kiseroiv!$K$2=BT24,BV24,"") | BT24: =IF(AND($BT$4=CI24,BU24<>""),CC24,"") | BU24: =IF(AND($BU$1=CI24,ISERROR(VLOOKUP(CG24,Kisiv,2,FALSE))=FALSE),CB24,"") | BV24: =IF(BU24<>"",RANK(BU24,$BU$7:$BU$33000,1),"") | BW24: =IF(CC24<min,$BW$2,IF(CC24<=max,CG24,"")) | BX24: =IF(AND(OR($BX$1=0,$BX$1=CG24),OR($BX$2=0,IF(ISERROR(SEARCH($BX$2,CJ24&CK24&CL24,1)),FALSE,TRUE))),CB24,"") | BY24: =IF(AND(BX24<>"",CC24<>$CD$2),RANK(BX24,$BX$7:$BX$33000,1),"") | BZ24: =IF(AND(CC24<$BZ$2,CI24=$BZ$4),$BZ$5,IF(AND(CC24<=$BZ$3,CI24=$BZ$4),CB24,"")) | CA24: =IF(AND(BZ24<>"",BZ24<>$BZ$5),RANK(BZ24,$BZ$7:$BZ$33000,1),"") | CB24: =IF(COUNTIF($CD$7:CD24,CD24)=1,CD24,CD24+COUNTIF($CD$6:CD23,CD24)) -> 55170 | CC24: =IF(INDEX(Kassza,CH24,1)<>1,INDEX(Kassza,CH24,1),$CD$2) -> 55153 | CD24: =IF(CC24<>$CD$2,RANK(CC24,$CC$7:$CC$33000,1),$CD$2) -> 55153 | CE24: =INDEX(Kassza,CH24,6) -> 0 | CF24: =INDEX(Kassza,CH24,8) -> 0 | CG24: =INDEX(Kassza,CH24,7)&INDEX(Kassza,CH24,9) | CH24: 19 | CI24: Kassza | CJ24: =IF(INDEX(Kassza,CH24,5)<>0,INDEX(Kassza,CH24,5),"") | CK24: =IF(INDEX(Kassza,CH24,10)<>0,INDEX(Kassza,CH24,10),"") | CL24: =IF(INDEX(Kassza,CH24,11)<>0,INDEX(Kassza,CH24,11),"") | CM24: =IF(INDEX(Kassza,CH24,4)<>0,INDEX(Kassza,CH24,4),"") | CN24: =IF(INDEX(Kassza,CH24,3)<>0,INDEX(Kassza,CH24,3),"") | CU24: =[1]Hibak!E1064 -> Activităţi agricole | CV24: =INDEX(Csfi,CZ24,1) -> Mezőgazdasági jövedelem | CZ24: 867
BS25: =IF(Kiadasi_kiseroiv!$K$2=BT25,BV25,"") | BT25: =IF(AND($BT$4=CI25,BU25<>""),CC25,"") | BU25: =IF(AND($BU$1=CI25,ISERROR(VLOOKUP(CG25,Kisiv,2,FALSE))=FALSE),CB25,"") | BV25: =IF(BU25<>"",RANK(BU25,$BU$7:$BU$33000,1),"") | BW25: =IF(CC25<min,$BW$2,IF(CC25<=max,CG25,"")) | BX25: =IF(AND(OR($BX$1=0,$BX$1=CG25),OR($BX$2=0,IF(ISERROR(SEARCH($BX$2,CJ25&CK25&CL25,1)),FALSE,TRUE))),CB25,"") | BY25: =IF(AND(BX25<>"",CC25<>$CD$2),RANK(BX25,$BX$7:$BX$33000,1),"") | BZ25: =IF(AND(CC25<$BZ$2,CI25=$BZ$4),$BZ$5,IF(AND(CC25<=$BZ$3,CI25=$BZ$4),CB25,"")) | CA25: =IF(AND(BZ25<>"",BZ25<>$BZ$5),RANK(BZ25,$BZ$7:$BZ$33000,1),"") | CB25: =IF(COUNTIF($CD$7:CD25,CD25)=1,CD25,CD25+COUNTIF($CD$6:CD24,CD25)) -> 55171 | CC25: =IF(INDEX(Kassza,CH25,1)<>1,INDEX(Kassza,CH25,1),$CD$2) -> 55153 | CD25: =IF(CC25<>$CD$2,RANK(CC25,$CC$7:$CC$33000,1),$CD$2) -> 55153 | CE25: =INDEX(Kassza,CH25,6) -> 0 | CF25: =INDEX(Kassza,CH25,8) -> 0 | CG25: =INDEX(Kassza,CH25,7)&INDEX(Kassza,CH25,9) | CH25: 20 | CI25: Kassza | CJ25: =IF(INDEX(Kassza,CH25,5)<>0,INDEX(Kassza,CH25,5),"") | CK25: =IF(INDEX(Kassza,CH25,10)<>0,INDEX(Kassza,CH25,10),"") | CL25: =IF(INDEX(Kassza,CH25,11)<>0,INDEX(Kassza,CH25,11),"") | CM25: =IF(INDEX(Kassza,CH25,4)<>0,INDEX(Kassza,CH25,4),"") | CN25: =IF(INDEX(Kassza,CH25,3)<>0,INDEX(Kassza,CH25,3),"") | CU25: =[1]Hibak!E1065 -> Activităţi silvice | CV25: =INDEX(Csfi,CZ25,1) -> Erdőgazdálkodási jövedelem | CZ25: 868
BS26: =IF(Kiadasi_kiseroiv!$K$2=BT26,BV26,"") | BT26: =IF(AND($BT$4=CI26,BU26<>""),CC26,"") | BU26: =IF(AND($BU$1=CI26,ISERROR(VLOOKUP(CG26,Kisiv,2,FALSE))=FALSE),CB26,"") | BV26: =IF(BU26<>"",RANK(BU26,$BU$7:$BU$33000,1),"") | BW26: =IF(CC26<min,$BW$2,IF(CC26<=max,CG26,"")) | BX26: =IF(AND(OR($BX$1=0,$BX$1=CG26),OR($BX$2=0,IF(ISERROR(SEARCH($BX$2,CJ26&CK26&CL26,1)),FALSE,TRUE))),CB26,"") | BY26: =IF(AND(BX26<>"",CC26<>$CD$2),RANK(BX26,$BX$7:$BX$33000,1),"") | BZ26: =IF(AND(CC26<$BZ$2,CI26=$BZ$4),$BZ$5,IF(AND(CC26<=$BZ$3,CI26=$BZ$4),CB26,"")) | CA26: =IF(AND(BZ26<>"",BZ26<>$BZ$5),RANK(BZ26,$BZ$7:$BZ$33000,1),"") | CB26: =IF(COUNTIF($CD$7:CD26,CD26)=1,CD26,CD26+COUNTIF($CD$6:CD25,CD26)) -> 55172 | CC26: =IF(INDEX(Kassza,CH26,1)<>1,INDEX(Kassza,CH26,1),$CD$2) -> 55153 | CD26: =IF(CC26<>$CD$2,RANK(CC26,$CC$7:$CC$33000,1),$CD$2) -> 55153 | CE26: =INDEX(Kassza,CH26,6) -> 0 | CF26: =INDEX(Kassza,CH26,8) -> 0 | CG26: =INDEX(Kassza,CH26,7)&INDEX(Kassza,CH26,9) | CH26: 21 | CI26: Kassza | CJ26: =IF(INDEX(Kassza,CH26,5)<>0,INDEX(Kassza,CH26,5),"") | CK26: =IF(INDEX(Kassza,CH26,10)<>0,INDEX(Kassza,CH26,10),"") | CL26: =IF(INDEX(Kassza,CH26,11)<>0,INDEX(Kassza,CH26,11),"") | CM26: =IF(INDEX(Kassza,CH26,4)<>0,INDEX(Kassza,CH26,4),"") | CN26: =IF(INDEX(Kassza,CH26,3)<>0,INDEX(Kassza,CH26,3),"") | CU26: =[1]Hibak!E1066 -> Alte venituri din activităţi anexe | CV26: =INDEX(Csfi,CZ26,1) -> Más gazdasági bevételek | CZ26: 869
BS27: =IF(Kiadasi_kiseroiv!$K$2=BT27,BV27,"") | BT27: =IF(AND($BT$4=CI27,BU27<>""),CC27,"") | BU27: =IF(AND($BU$1=CI27,ISERROR(VLOOKUP(CG27,Kisiv,2,FALSE))=FALSE),CB27,"") | BV27: =IF(BU27<>"",RANK(BU27,$BU$7:$BU$33000,1),"") | BW27: =IF(CC27<min,$BW$2,IF(CC27<=max,CG27,"")) | BX27: =IF(AND(OR($BX$1=0,$BX$1=CG27),OR($BX$2=0,IF(ISERROR(SEARCH($BX$2,CJ27&CK27&CL27,1)),FALSE,TRUE))),CB27,"") | BY27: =IF(AND(BX27<>"",CC27<>$CD$2),RANK(BX27,$BX$7:$BX$33000,1),"") | BZ27: =IF(AND(CC27<$BZ$2,CI27=$BZ$4),$BZ$5,IF(AND(CC27<=$BZ$3,CI27=$BZ$4),CB27,"")) | CA27: =IF(AND(BZ27<>"",BZ27<>$BZ$5),RANK(BZ27,$BZ$7:$BZ$33000,1),"") | CB27: =IF(COUNTIF($CD$7:CD27,CD27)=1,CD27,CD27+COUNTIF($CD$6:CD26,CD27)) -> 55173 | CC27: =IF(INDEX(Kassza,CH27,1)<>1,INDEX(Kassza,CH27,1),$CD$2) -> 55153 | CD27: =IF(CC27<>$CD$2,RANK(CC27,$CC$7:$CC$33000,1),$CD$2) -> 55153 | CE27: =INDEX(Kassza,CH27,6) -> 0 | CF27: =INDEX(Kassza,CH27,8) -> 0 | CG27: =INDEX(Kassza,CH27,7)&INDEX(Kassza,CH27,9) | CH27: 22 | CI27: Kassza | CJ27: =IF(INDEX(Kassza,CH27,5)<>0,INDEX(Kassza,CH27,5),"") | CK27: =IF(INDEX(Kassza,CH27,10)<>0,INDEX(Kassza,CH27,10),"") | CL27: =IF(INDEX(Kassza,CH27,11)<>0,INDEX(Kassza,CH27,11),"") | CM27: =IF(INDEX(Kassza,CH27,4)<>0,INDEX(Kassza,CH27,4),"") | CN27: =IF(INDEX(Kassza,CH27,3)<>0,INDEX(Kassza,CH27,3),"") | CU27: =[1]Hibak!E1067 -> Venit din închirierea clădirilor | CV27: =INDEX(Csfi,CZ27,1) -> Épületek bérjövedelme | CZ27: 870
BS28: =IF(Kiadasi_kiseroiv!$K$2=BT28,BV28,"") | BT28: =IF(AND($BT$4=CI28,BU28<>""),CC28,"") | BU28: =IF(AND($BU$1=CI28,ISERROR(VLOOKUP(CG28,Kisiv,2,FALSE))=FALSE),CB28,"") | BV28: =IF(BU28<>"",RANK(BU28,$BU$7:$BU$33000,1),"") | BW28: =IF(CC28<min,$BW$2,IF(CC28<=max,CG28,"")) | BX28: =IF(AND(OR($BX$1=0,$BX$1=CG28),OR($BX$2=0,IF(ISERROR(SEARCH($BX$2,CJ28&CK28&CL28,1)),FALSE,TRUE))),CB28,"") | BY28: =IF(AND(BX28<>"",CC28<>$CD$2),RANK(BX28,$BX$7:$BX$33000,1),"") | BZ28: =IF(AND(CC28<$BZ$2,CI28=$BZ$4),$BZ$5,IF(AND(CC28<=$BZ$3,CI28=$BZ$4),CB28,"")) | CA28: =IF(AND(BZ28<>"",BZ28<>$BZ$5),RANK(BZ28,$BZ$7:$BZ$33000,1),"") | CB28: =IF(COUNTIF($CD$7:CD28,CD28)=1,CD28,CD28+COUNTIF($CD$6:CD27,CD28)) -> 55174 | CC28: =IF(INDEX(Kassza,CH28,1)<>1,INDEX(Kassza,CH28,1),$CD$2) -> 55153 | CD28: =IF(CC28<>$CD$2,RANK(CC28,$CC$7:$CC$33000,1),$CD$2) -> 55153 | CE28: =INDEX(Kassza,CH28,6) -> 0 | CF28: =INDEX(Kassza,CH28,8) -> 0 | CG28: =INDEX(Kassza,CH28,7)&INDEX(Kassza,CH28,9) | CH28: 23 | CI28: Kassza | CJ28: =IF(INDEX(Kassza,CH28,5)<>0,INDEX(Kassza,CH28,5),"") | CK28: =IF(INDEX(Kassza,CH28,10)<>0,INDEX(Kassza,CH28,10),"") | CL28: =IF(INDEX(Kassza,CH28,11)<>0,INDEX(Kassza,CH28,11),"") | CM28: =IF(INDEX(Kassza,CH28,4)<>0,INDEX(Kassza,CH28,4),"") | CN28: =IF(INDEX(Kassza,CH28,3)<>0,INDEX(Kassza,CH28,3),"") | CU28: =[1]Hibak!E1068 -> Venit din închirierea terenurilor | CV28: =INDEX(Csfi,CZ28,1) -> Területek bérjövedelme | CZ28: 871
BS29: =IF(Kiadasi_kiseroiv!$K$2=BT29,BV29,"") | BT29: =IF(AND($BT$4=CI29,BU29<>""),CC29,"") | BU29: =IF(AND($BU$1=CI29,ISERROR(VLOOKUP(CG29,Kisiv,2,FALSE))=FALSE),CB29,"") | BV29: =IF(BU29<>"",RANK(BU29,$BU$7:$BU$33000,1),"") | BW29: =IF(CC29<min,$BW$2,IF(CC29<=max,CG29,"")) | BX29: =IF(AND(OR($BX$1=0,$BX$1=CG29),OR($BX$2=0,IF(ISERROR(SEARCH($BX$2,CJ29&CK29&CL29,1)),FALSE,TRUE))),CB29,"") | BY29: =IF(AND(BX29<>"",CC29<>$CD$2),RANK(BX29,$BX$7:$BX$33000,1),"") | BZ29: =IF(AND(CC29<$BZ$2,CI29=$BZ$4),$BZ$5,IF(AND(CC29<=$BZ$3,CI29=$BZ$4),CB29,"")) | CA29: =IF(AND(BZ29<>"",BZ29<>$BZ$5),RANK(BZ29,$BZ$7:$BZ$33000,1),"") | CB29: =IF(COUNTIF($CD$7:CD29,CD29)=1,CD29,CD29+COUNTIF($CD$6:CD28,CD29)) -> 55175 | CC29: =IF(INDEX(Kassza,CH29,1)<>1,INDEX(Kassza,CH29,1),$CD$2) -> 55153 | CD29: =IF(CC29<>$CD$2,RANK(CC29,$CC$7:$CC$33000,1),$CD$2) -> 55153 | CE29: =INDEX(Kassza,CH29,6) -> 0 | CF29: =INDEX(Kassza,CH29,8) -> 0 | CG29: =INDEX(Kassza,CH29,7)&INDEX(Kassza,CH29,9) | CH29: 24 | CI29: Kassza | CJ29: =IF(INDEX(Kassza,CH29,5)<>0,INDEX(Kassza,CH29,5),"") | CK29: =IF(INDEX(Kassza,CH29,10)<>0,INDEX(Kassza,CH29,10),"") | CL29: =IF(INDEX(Kassza,CH29,11)<>0,INDEX(Kassza,CH29,11),"") | CM29: =IF(INDEX(Kassza,CH29,4)<>0,INDEX(Kassza,CH29,4),"") | CN29: =IF(INDEX(Kassza,CH29,3)<>0,INDEX(Kassza,CH29,3),"") | CU29: =[1]Hibak!E1069 -> De la unităţi din cadrul cultului | CV29: =INDEX(Csfi,CZ29,1) -> Más egyházi intézményektől kapott támogatás | CZ29: 872
BS30: =IF(Kiadasi_kiseroiv!$K$2=BT30,BV30,"") | BT30: =IF(AND($BT$4=CI30,BU30<>""),CC30,"") | BU30: =IF(AND($BU$1=CI30,ISERROR(VLOOKUP(CG30,Kisiv,2,FALSE))=FALSE),CB30,"") | BV30: =IF(BU30<>"",RANK(BU30,$BU$7:$BU$33000,1),"") | BW30: =IF(CC30<min,$BW$2,IF(CC30<=max,CG30,"")) | BX30: =IF(AND(OR($BX$1=0,$BX$1=CG30),OR($BX$2=0,IF(ISERROR(SEARCH($BX$2,CJ30&CK30&CL30,1)),FALSE,TRUE))),CB30,"") | BY30: =IF(AND(BX30<>"",CC30<>$CD$2),RANK(BX30,$BX$7:$BX$33000,1),"") | BZ30: =IF(AND(CC30<$BZ$2,CI30=$BZ$4),$BZ$5,IF(AND(CC30<=$BZ$3,CI30=$BZ$4),CB30,"")) | CA30: =IF(AND(BZ30<>"",BZ30<>$BZ$5),RANK(BZ30,$BZ$7:$BZ$33000,1),"") | CB30: =IF(COUNTIF($CD$7:CD30,CD30)=1,CD30,CD30+COUNTIF($CD$6:CD29,CD30)) -> 55176 | CC30: =IF(INDEX(Kassza,CH30,1)<>1,INDEX(Kassza,CH30,1),$CD$2) -> 55153 | CD30: =IF(CC30<>$CD$2,RANK(CC30,$CC$7:$CC$33000,1),$CD$2) -> 55153 | CE30: =INDEX(Kassza,CH30,6) -> 0 | CF30: =INDEX(Kassza,CH30,8) -> 0 | CG30: =INDEX(Kassza,CH30,7)&INDEX(Kassza,CH30,9) | CH30: 25 | CI30: Kassza | CJ30: =IF(INDEX(Kassza,CH30,5)<>0,INDEX(Kassza,CH30,5),"") | CK30: =IF(INDEX(Kassza,CH30,10)<>0,INDEX(Kassza,CH30,10),"") | CL30: =IF(INDEX(Kassza,CH30,11)<>0,INDEX(Kassza,CH30,11),"") | CM30: =IF(INDEX(Kassza,CH30,4)<>0,INDEX(Kassza,CH30,4),"") | CN30: =IF(INDEX(Kassza,CH30,3)<>0,INDEX(Kassza,CH30,3),"") | CU30: =[1]Hibak!E1070 -> Subvenţii de la stat | CV30: =INDEX(Csfi,CZ30,1) -> Állami intézménytől kapott támogatás (APIA, stb.) | CZ30: 873
BS31: =IF(Kiadasi_kiseroiv!$K$2=BT31,BV31,"") | BT31: =IF(AND($BT$4=CI31,BU31<>""),CC31,"") | BU31: =IF(AND($BU$1=CI31,ISERROR(VLOOKUP(CG31,Kisiv,2,FALSE))=FALSE),CB31,"") | BV31: =IF(BU31<>"",RANK(BU31,$BU$7:$BU$33000,1),"") | BW31: =IF(CC31<min,$BW$2,IF(CC31<=max,CG31,"")) | BX31: =IF(AND(OR($BX$1=0,$BX$1=CG31),OR($BX$2=0,IF(ISERROR(SEARCH($BX$2,CJ31&CK31&CL31,1)),FALSE,TRUE))),CB31,"") | BY31: =IF(AND(BX31<>"",CC31<>$CD$2),RANK(BX31,$BX$7:$BX$33000,1),"") | BZ31: =IF(AND(CC31<$BZ$2,CI31=$BZ$4),$BZ$5,IF(AND(CC31<=$BZ$3,CI31=$BZ$4),CB31,"")) | CA31: =IF(AND(BZ31<>"",BZ31<>$BZ$5),RANK(BZ31,$BZ$7:$BZ$33000,1),"") | CB31: =IF(COUNTIF($CD$7:CD31,CD31)=1,CD31,CD31+COUNTIF($CD$6:CD30,CD31)) -> 55177 | CC31: =IF(INDEX(Kassza,CH31,1)<>1,INDEX(Kassza,CH31,1),$CD$2) -> 55153 | CD31: =IF(CC31<>$CD$2,RANK(CC31,$CC$7:$CC$33000,1),$CD$2) -> 55153 | CE31: =INDEX(Kassza,CH31,6) -> 0 | CF31: =INDEX(Kassza,CH31,8) -> 0 | CG31: =INDEX(Kassza,CH31,7)&INDEX(Kassza,CH31,9) | CH31: 26 | CI31: Kassza | CJ31: =IF(INDEX(Kassza,CH31,5)<>0,INDEX(Kassza,CH31,5),"") | CK31: =IF(INDEX(Kassza,CH31,10)<>0,INDEX(Kassza,CH31,10),"") | CL31: =IF(INDEX(Kassza,CH31,11)<>0,INDEX(Kassza,CH31,11),"") | CM31: =IF(INDEX(Kassza,CH31,4)<>0,INDEX(Kassza,CH31,4),"") | CN31: =IF(INDEX(Kassza,CH31,3)<>0,INDEX(Kassza,CH31,3),"") | CU31: =[1]Hibak!E1071 -> Subvenţii primite pt. salarii* | CV31: =INDEX(Csfi,CZ31,1) -> Kongrua és járulékai | CZ31: 874
BS32: =IF(Kiadasi_kiseroiv!$K$2=BT32,BV32,"") | BT32: =IF(AND($BT$4=CI32,BU32<>""),CC32,"") | BU32: =IF(AND($BU$1=CI32,ISERROR(VLOOKUP(CG32,Kisiv,2,FALSE))=FALSE),CB32,"") | BV32: =IF(BU32<>"",RANK(BU32,$BU$7:$BU$33000,1),"") | BW32: =IF(CC32<min,$BW$2,IF(CC32<=max,CG32,"")) | BX32: =IF(AND(OR($BX$1=0,$BX$1=CG32),OR($BX$2=0,IF(ISERROR(SEARCH($BX$2,CJ32&CK32&CL32,1)),FALSE,TRUE))),CB32,"") | BY32: =IF(AND(BX32<>"",CC32<>$CD$2),RANK(BX32,$BX$7:$BX$33000,1),"") | BZ32: =IF(AND(CC32<$BZ$2,CI32=$BZ$4),$BZ$5,IF(AND(CC32<=$BZ$3,CI32=$BZ$4),CB32,"")) | CA32: =IF(AND(BZ32<>"",BZ32<>$BZ$5),RANK(BZ32,$BZ$7:$BZ$33000,1),"") | CB32: =IF(COUNTIF($CD$7:CD32,CD32)=1,CD32,CD32+COUNTIF($CD$6:CD31,CD32)) -> 55178 | CC32: =IF(INDEX(Kassza,CH32,1)<>1,INDEX(Kassza,CH32,1),$CD$2) -> 55153 | CD32: =IF(CC32<>$CD$2,RANK(CC32,$CC$7:$CC$33000,1),$CD$2) -> 55153 | CE32: =INDEX(Kassza,CH32,6) -> 0 | CF32: =INDEX(Kassza,CH32,8) -> 0 | CG32: =INDEX(Kassza,CH32,7)&INDEX(Kassza,CH32,9) | CH32: 27 | CI32: Kassza | CJ32: =IF(INDEX(Kassza,CH32,5)<>0,INDEX(Kassza,CH32,5),"") | CK32: =IF(INDEX(Kassza,CH32,10)<>0,INDEX(Kassza,CH32,10),"") | CL32: =IF(INDEX(Kassza,CH32,11)<>0,INDEX(Kassza,CH32,11),"") | CM32: =IF(INDEX(Kassza,CH32,4)<>0,INDEX(Kassza,CH32,4),"") | CN32: =IF(INDEX(Kassza,CH32,3)<>0,INDEX(Kassza,CH32,3),"") | CU32: =[1]Hibak!E1072 -> Alte încasări | CV32: =INDEX(Csfi,CZ32,1) -> Bevételek más egyházi intézmények részére | CZ32: 875
BS33: =IF(Kiadasi_kiseroiv!$K$2=BT33,BV33,"") | BT33: =IF(AND($BT$4=CI33,BU33<>""),CC33,"") | BU33: =IF(AND($BU$1=CI33,ISERROR(VLOOKUP(CG33,Kisiv,2,FALSE))=FALSE),CB33,"") | BV33: =IF(BU33<>"",RANK(BU33,$BU$7:$BU$33000,1),"") | BW33: =IF(CC33<min,$BW$2,IF(CC33<=max,CG33,"")) | BX33: =IF(AND(OR($BX$1=0,$BX$1=CG33),OR($BX$2=0,IF(ISERROR(SEARCH($BX$2,CJ33&CK33&CL33,1)),FALSE,TRUE))),CB33,"") | BY33: =IF(AND(BX33<>"",CC33<>$CD$2),RANK(BX33,$BX$7:$BX$33000,1),"") | BZ33: =IF(AND(CC33<$BZ$2,CI33=$BZ$4),$BZ$5,IF(AND(CC33<=$BZ$3,CI33=$BZ$4),CB33,"")) | CA33: =IF(AND(BZ33<>"",BZ33<>$BZ$5),RANK(BZ33,$BZ$7:$BZ$33000,1),"") | CB33: =IF(COUNTIF($CD$7:CD33,CD33)=1,CD33,CD33+COUNTIF($CD$6:CD32,CD33)) -> 55179 | CC33: =IF(INDEX(Kassza,CH33,1)<>1,INDEX(Kassza,CH33,1),$CD$2) -> 55153 | CD33: =IF(CC33<>$CD$2,RANK(CC33,$CC$7:$CC$33000,1),$CD$2) -> 55153 | CE33: =INDEX(Kassza,CH33,6) -> 0 | CF33: =INDEX(Kassza,CH33,8) -> 0 | CG33: =INDEX(Kassza,CH33,7)&INDEX(Kassza,CH33,9) | CH33: 28 | CI33: Kassza | CJ33: =IF(INDEX(Kassza,CH33,5)<>0,INDEX(Kassza,CH33,5),"") | CK33: =IF(INDEX(Kassza,CH33,10)<>0,INDEX(Kassza,CH33,10),"") | CL33: =IF(INDEX(Kassza,CH33,11)<>0,INDEX(Kassza,CH33,11),"") | CM33: =IF(INDEX(Kassza,CH33,4)<>0,INDEX(Kassza,CH33,4),"") | CN33: =IF(INDEX(Kassza,CH33,3)<>0,INDEX(Kassza,CH33,3),"") | CU33: =[1]Hibak!E1073 -> Asigurari* | CV33: =INDEX(Csfi,CZ33,1) -> Biztosítások - bevétel | CZ33: 876
... BS39: =IF(Kiadasi_kiseroiv!$K$2=BT39,BV39,"") | BT39: =IF(AND($BT$4=CI39,BU39<>""),CC39,"") | BU39: =IF(AND($BU$1=CI39,ISERROR(VLOOKUP(CG39,Kisiv,2,FALSE))=FALSE),CB39,"") | BV39: =IF(BU39<>"",RANK(BU39,$BU$7:$BU$33000,1),"") | BW39: =IF(CC39<min,$BW$2,IF(CC39<=max,CG39,"")) | BX39: =IF(AND(OR($BX$1=0,$BX$1=CG39),OR($BX$2=0,IF(ISERROR(SEARCH($BX$2,CJ39&CK39&CL39,1)),FALSE,TRUE))),CB39,"") | BY39: =IF(AND(BX39<>"",CC39<>$CD$2),RANK(BX39,$BX$7:$BX$33000,1),"") | BZ39: =IF(AND(CC39<$BZ$2,CI39=$BZ$4),$BZ$5,IF(AND(CC39<=$BZ$3,CI39=$BZ$4),CB39,"")) | CA39: =IF(AND(BZ39<>"",BZ39<>$BZ$5),RANK(BZ39,$BZ$7:$BZ$33000,1),"") | CB39: =IF(COUNTIF($CD$7:CD39,CD39)=1,CD39,CD39+COUNTIF($CD$6:CD38,CD39)) -> 55185 | CC39: =IF(INDEX(Kassza,CH39,1)<>1,INDEX(Kassza,CH39,1),$CD$2) -> 55153 | CD39: =IF(CC39<>$CD$2,RANK(CC39,$CC$7:$CC$33000,1),$CD$2) -> 55153 | CE39: =INDEX(Kassza,CH39,6) -> 0 | CF39: =INDEX(Kassza,CH39,8) -> 0 | CG39: =INDEX(Kassza,CH39,7)&INDEX(Kassza,CH39,9) | CH39: 34 | CI39: Kassza | CJ39: =IF(INDEX(Kassza,CH39,5)<>0,INDEX(Kassza,CH39,5),"") | CK39: =IF(INDEX(Kassza,CH39,10)<>0,INDEX(Kassza,CH39,10),"") | CL39: =IF(INDEX(Kassza,CH39,11)<>0,INDEX(Kassza,CH39,11),"") | CM39: =IF(INDEX(Kassza,CH39,4)<>0,INDEX(Kassza,CH39,4),"") | CN39: =IF(INDEX(Kassza,CH39,3)<>0,INDEX(Kassza,CH39,3),"") | CU39: =[1]Hibak!E1079 -> Restituiri din credite | CV39: =INDEX(Csfi,CZ39,1) -> Visszakapott hitelek | CZ39: 882
BS40: =IF(Kiadasi_kiseroiv!$K$2=BT40,BV40,"") | BT40: =IF(AND($BT$4=CI40,BU40<>""),CC40,"") | BU40: =IF(AND($BU$1=CI40,ISERROR(VLOOKUP(CG40,Kisiv,2,FALSE))=FALSE),CB40,"") | BV40: =IF(BU40<>"",RANK(BU40,$BU$7:$BU$33000,1),"") | BW40: =IF(CC40<min,$BW$2,IF(CC40<=max,CG40,"")) | BX40: =IF(AND(OR($BX$1=0,$BX$1=CG40),OR($BX$2=0,IF(ISERROR(SEARCH($BX$2,CJ40&CK40&CL40,1)),FALSE,TRUE))),CB40,"") | BY40: =IF(AND(BX40<>"",CC40<>$CD$2),RANK(BX40,$BX$7:$BX$33000,1),"") | BZ40: =IF(AND(CC40<$BZ$2,CI40=$BZ$4),$BZ$5,IF(AND(CC40<=$BZ$3,CI40=$BZ$4),CB40,"")) | CA40: =IF(AND(BZ40<>"",BZ40<>$BZ$5),RANK(BZ40,$BZ$7:$BZ$33000,1),"") | CB40: =IF(COUNTIF($CD$7:CD40,CD40)=1,CD40,CD40+COUNTIF($CD$6:CD39,CD40)) -> 55186 | CC40: =IF(INDEX(Kassza,CH40,1)<>1,INDEX(Kassza,CH40,1),$CD$2) -> 55153 | CD40: =IF(CC40<>$CD$2,RANK(CC40,$CC$7:$CC$33000,1),$CD$2) -> 55153 | CE40: =INDEX(Kassza,CH40,6) -> 0 | CF40: =INDEX(Kassza,CH40,8) -> 0 | CG40: =INDEX(Kassza,CH40,7)&INDEX(Kassza,CH40,9) | CH40: 35 | CI40: Kassza | CJ40: =IF(INDEX(Kassza,CH40,5)<>0,INDEX(Kassza,CH40,5),"") | CK40: =IF(INDEX(Kassza,CH40,10)<>0,INDEX(Kassza,CH40,10),"") | CL40: =IF(INDEX(Kassza,CH40,11)<>0,INDEX(Kassza,CH40,11),"") | CM40: =IF(INDEX(Kassza,CH40,4)<>0,INDEX(Kassza,CH40,4),"") | CN40: =IF(INDEX(Kassza,CH40,3)<>0,INDEX(Kassza,CH40,3),"") | CU40: =[1]Hibak!E1080 -> Contr. pentru prestări servicii efectuate către protopopiat | CV40: =INDEX(Csfi,CZ40,1) -> Fizetés alap | CW40: =CV40 -> Fizetés alap | CZ40: 883
BS41: =IF(Kiadasi_kiseroiv!$K$2=BT41,BV41,"") | BT41: =IF(AND($BT$4=CI41,BU41<>""),CC41,"") | BU41: =IF(AND($BU$1=CI41,ISERROR(VLOOKUP(CG41,Kisiv,2,FALSE))=FALSE),CB41,"") | BV41: =IF(BU41<>"",RANK(BU41,$BU$7:$BU$33000,1),"") | BW41: =IF(CC41<min,$BW$2,IF(CC41<=max,CG41,"")) | BX41: =IF(AND(OR($BX$1=0,$BX$1=CG41),OR($BX$2=0,IF(ISERROR(SEARCH($BX$2,CJ41&CK41&CL41,1)),FALSE,TRUE))),CB41,"") | BY41: =IF(AND(BX41<>"",CC41<>$CD$2),RANK(BX41,$BX$7:$BX$33000,1),"") | BZ41: =IF(AND(CC41<$BZ$2,CI41=$BZ$4),$BZ$5,IF(AND(CC41<=$BZ$3,CI41=$BZ$4),CB41,"")) | CA41: =IF(AND(BZ41<>"",BZ41<>$BZ$5),RANK(BZ41,$BZ$7:$BZ$33000,1),"") | CB41: =IF(COUNTIF($CD$7:CD41,CD41)=1,CD41,CD41+COUNTIF($CD$6:CD40,CD41)) -> 55187 | CC41: =IF(INDEX(Kassza,CH41,1)<>1,INDEX(Kassza,CH41,1),$CD$2) -> 55153 | CD41: =IF(CC41<>$CD$2,RANK(CC41,$CC$7:$CC$33000,1),$CD$2) -> 55153 | CE41: =INDEX(Kassza,CH41,6) -> 0 | CF41: =INDEX(Kassza,CH41,8) -> 0 | CG41: =INDEX(Kassza,CH41,7)&INDEX(Kassza,CH41,9) | CH41: 36 | CI41: Kassza | CJ41: =IF(INDEX(Kassza,CH41,5)<>0,INDEX(Kassza,CH41,5),"") | CK41: =IF(INDEX(Kassza,CH41,10)<>0,INDEX(Kassza,CH41,10),"") | CL41: =IF(INDEX(Kassza,CH41,11)<>0,INDEX(Kassza,CH41,11),"") | CM41: =IF(INDEX(Kassza,CH41,4)<>0,INDEX(Kassza,CH41,4),"") | CN41: =IF(INDEX(Kassza,CH41,3)<>0,INDEX(Kassza,CH41,3),"") | CU41: =[1]Hibak!E1081 -> Cheltuieli de întreţinere (încălzire iluminat apă etc.) | CV41: =INDEX(Csfi,CZ41,1) -> Közköltségek (fűtés, világítás, víz stb.) | CW41: =CV41 -> Közköltségek (fűtés, világítás, víz stb.) | CZ41: 884
BS42: =IF(Kiadasi_kiseroiv!$K$2=BT42,BV42,"") | BT42: =IF(AND($BT$4=CI42,BU42<>""),CC42,"") | BU42: =IF(AND($BU$1=CI42,ISERROR(VLOOKUP(CG42,Kisiv,2,FALSE))=FALSE),CB42,"") | BV42: =IF(BU42<>"",RANK(BU42,$BU$7:$BU$33000,1),"") | BW42: =IF(CC42<min,$BW$2,IF(CC42<=max,CG42,"")) | BX42: =IF(AND(OR($BX$1=0,$BX$1=CG42),OR($BX$2=0,IF(ISERROR(SEARCH($BX$2,CJ42&CK42&CL42,1)),FALSE,TRUE))),CB42,"") | BY42: =IF(AND(BX42<>"",CC42<>$CD$2),RANK(BX42,$BX$7:$BX$33000,1),"") | BZ42: =IF(AND(CC42<$BZ$2,CI42=$BZ$4),$BZ$5,IF(AND(CC42<=$BZ$3,CI42=$BZ$4),CB42,"")) | CA42: =IF(AND(BZ42<>"",BZ42<>$BZ$5),RANK(BZ42,$BZ$7:$BZ$33000,1),"") | CB42: =IF(COUNTIF($CD$7:CD42,CD42)=1,CD42,CD42+COUNTIF($CD$6:CD41,CD42)) -> 55188 | CC42: =IF(INDEX(Kassza,CH42,1)<>1,INDEX(Kassza,CH42,1),$CD$2) -> 55153 | CD42: =IF(CC42<>$CD$2,RANK(CC42,$CC$7:$CC$33000,1),$CD$2) -> 55153 | CE42: =INDEX(Kassza,CH42,6) -> 0 | CF42: =INDEX(Kassza,CH42,8) -> 0 | CG42: =INDEX(Kassza,CH42,7)&INDEX(Kassza,CH42,9) | CH42: 37 | CI42: Kassza | CJ42: =IF(INDEX(Kassza,CH42,5)<>0,INDEX(Kassza,CH42,5),"") | CK42: =IF(INDEX(Kassza,CH42,10)<>0,INDEX(Kassza,CH42,10),"") | CL42: =IF(INDEX(Kassza,CH42,11)<>0,INDEX(Kassza,CH42,11),"") | CM42: =IF(INDEX(Kassza,CH42,4)<>0,INDEX(Kassza,CH42,4),"") | CN42: =IF(INDEX(Kassza,CH42,3)<>0,INDEX(Kassza,CH42,3),"") | CU42: =[1]Hibak!E1082 -> Chirii | CV42: =INDEX(Csfi,CZ42,1) -> Házbérek | CW42: =CV42 -> Házbérek | CZ42: 885
BS43: =IF(Kiadasi_kiseroiv!$K$2=BT43,BV43,"") | BT43: =IF(AND($BT$4=CI43,BU43<>""),CC43,"") | BU43: =IF(AND($BU$1=CI43,ISERROR(VLOOKUP(CG43,Kisiv,2,FALSE))=FALSE),CB43,"") | BV43: =IF(BU43<>"",RANK(BU43,$BU$7:$BU$33000,1),"") | BW43: =IF(CC43<min,$BW$2,IF(CC43<=max,CG43,"")) | BX43: =IF(AND(OR($BX$1=0,$BX$1=CG43),OR($BX$2=0,IF(ISERROR(SEARCH($BX$2,CJ43&CK43&CL43,1)),FALSE,TRUE))),CB43,"") | BY43: =IF(AND(BX43<>"",CC43<>$CD$2),RANK(BX43,$BX$7:$BX$33000,1),"") | BZ43: =IF(AND(CC43<$BZ$2,CI43=$BZ$4),$BZ$5,IF(AND(CC43<=$BZ$3,CI43=$BZ$4),CB43,"")) | CA43: =IF(AND(BZ43<>"",BZ43<>$BZ$5),RANK(BZ43,$BZ$7:$BZ$33000,1),"") | CB43: =IF(COUNTIF($CD$7:CD43,CD43)=1,CD43,CD43+COUNTIF($CD$6:CD42,CD43)) -> 55189 | CC43: =IF(INDEX(Kassza,CH43,1)<>1,INDEX(Kassza,CH43,1),$CD$2) -> 55153 | CD43: =IF(CC43<>$CD$2,RANK(CC43,$CC$7:$CC$33000,1),$CD$2) -> 55153 | CE43: =INDEX(Kassza,CH43,6) -> 0 | CF43: =INDEX(Kassza,CH43,8) -> 0 | CG43: =INDEX(Kassza,CH43,7)&INDEX(Kassza,CH43,9) | CH43: 38 | CI43: Kassza | CJ43: =IF(INDEX(Kassza,CH43,5)<>0,INDEX(Kassza,CH43,5),"") | CK43: =IF(INDEX(Kassza,CH43,10)<>0,INDEX(Kassza,CH43,10),"") | CL43: =IF(INDEX(Kassza,CH43,11)<>0,INDEX(Kassza,CH43,11),"") | CM43: =IF(INDEX(Kassza,CH43,4)<>0,INDEX(Kassza,CH43,4),"") | CN43: =IF(INDEX(Kassza,CH43,3)<>0,INDEX(Kassza,CH43,3),"") | CU43: =[1]Hibak!E1083 -> Impozite, taxe, şi asigurări ADAS | CV43: =INDEX(Csfi,CZ43,1) -> Épületadó, földadó biztosítás | CW43: =CV43 -> Épületadó, földadó biztosítás | CZ43: 886
BS44: =IF(Kiadasi_kiseroiv!$K$2=BT44,BV44,"") | BT44: =IF(AND($BT$4=CI44,BU44<>""),CC44,"") | BU44: =IF(AND($BU$1=CI44,ISERROR(VLOOKUP(CG44,Kisiv,2,FALSE))=FALSE),CB44,"") | BV44: =IF(BU44<>"",RANK(BU44,$BU$7:$BU$33000,1),"") | BW44: =IF(CC44<min,$BW$2,IF(CC44<=max,CG44,"")) | BX44: =IF(AND(OR($BX$1=0,$BX$1=CG44),OR($BX$2=0,IF(ISERROR(SEARCH($BX$2,CJ44&CK44&CL44,1)),FALSE,TRUE))),CB44,"") | BY44: =IF(AND(BX44<>"",CC44<>$CD$2),RANK(BX44,$BX$7:$BX$33000,1),"") | BZ44: =IF(AND(CC44<$BZ$2,CI44=$BZ$4),$BZ$5,IF(AND(CC44<=$BZ$3,CI44=$BZ$4),CB44,"")) | CA44: =IF(AND(BZ44<>"",BZ44<>$BZ$5),RANK(BZ44,$BZ$7:$BZ$33000,1),"") | CB44: =IF(COUNTIF($CD$7:CD44,CD44)=1,CD44,CD44+COUNTIF($CD$6:CD43,CD44)) -> 55190 | CC44: =IF(INDEX(Kassza,CH44,1)<>1,INDEX(Kassza,CH44,1),$CD$2) -> 55153 | CD44: =IF(CC44<>$CD$2,RANK(CC44,$CC$7:$CC$33000,1),$CD$2) -> 55153 | CE44: =INDEX(Kassza,CH44,6) -> 0 | CF44: =INDEX(Kassza,CH44,8) -> 0 | CG44: =INDEX(Kassza,CH44,7)&INDEX(Kassza,CH44,9) | CH44: 39 | CI44: Kassza | CJ44: =IF(INDEX(Kassza,CH44,5)<>0,INDEX(Kassza,CH44,5),"") | CK44: =IF(INDEX(Kassza,CH44,10)<>0,INDEX(Kassza,CH44,10),"") | CL44: =IF(INDEX(Kassza,CH44,11)<>0,INDEX(Kassza,CH44,11),"") | CM44: =IF(INDEX(Kassza,CH44,4)<>0,INDEX(Kassza,CH44,4),"") | CN44: =IF(INDEX(Kassza,CH44,3)<>0,INDEX(Kassza,CH44,3),"") | CU44: =[1]Hibak!E1084 -> Mijloace de transport | CV44: =INDEX(Csfi,CZ44,1) -> Szállítóeszközök üzemeltetési költségei | CW44: =CV44 -> Szállítóeszközök üzemeltetési költségei | CZ44: 887
BS45: =IF(Kiadasi_kiseroiv!$K$2=BT45,BV45,"") | BT45: =IF(AND($BT$4=CI45,BU45<>""),CC45,"") | BU45: =IF(AND($BU$1=CI45,ISERROR(VLOOKUP(CG45,Kisiv,2,FALSE))=FALSE),CB45,"") | BV45: =IF(BU45<>"",RANK(BU45,$BU$7:$BU$33000,1),"") | BW45: =IF(CC45<min,$BW$2,IF(CC45<=max,CG45,"")) | BX45: =IF(AND(OR($BX$1=0,$BX$1=CG45),OR($BX$2=0,IF(ISERROR(SEARCH($BX$2,CJ45&CK45&CL45,1)),FALSE,TRUE))),CB45,"") | BY45: =IF(AND(BX45<>"",CC45<>$CD$2),RANK(BX45,$BX$7:$BX$33000,1),"") | BZ45: =IF(AND(CC45<$BZ$2,CI45=$BZ$4),$BZ$5,IF(AND(CC45<=$BZ$3,CI45=$BZ$4),CB45,"")) | CA45: =IF(AND(BZ45<>"",BZ45<>$BZ$5),RANK(BZ45,$BZ$7:$BZ$33000,1),"") | CB45: =IF(COUNTIF($CD$7:CD45,CD45)=1,CD45,CD45+COUNTIF($CD$6:CD44,CD45)) -> 55191 | CC45: =IF(INDEX(Kassza,CH45,1)<>1,INDEX(Kassza,CH45,1),$CD$2) -> 55153 | CD45: =IF(CC45<>$CD$2,RANK(CC45,$CC$7:$CC$33000,1),$CD$2) -> 55153 | CE45: =INDEX(Kassza,CH45,6) -> 0 | CF45: =INDEX(Kassza,CH45,8) -> 0 | CG45: =INDEX(Kassza,CH45,7)&INDEX(Kassza,CH45,9) | CH45: 40 | CI45: Kassza | CJ45: =IF(INDEX(Kassza,CH45,5)<>0,INDEX(Kassza,CH45,5),"") | CK45: =IF(INDEX(Kassza,CH45,10)<>0,INDEX(Kassza,CH45,10),"") | CL45: =IF(INDEX(Kassza,CH45,11)<>0,INDEX(Kassza,CH45,11),"") | CM45: =IF(INDEX(Kassza,CH45,4)<>0,INDEX(Kassza,CH45,4),"") | CN45: =IF(INDEX(Kassza,CH45,3)<>0,INDEX(Kassza,CH45,3),"") | CU45: =[1]Hibak!E1085 -> Diurnă, cheltuieli de deplasare | CV45: =INDEX(Csfi,CZ45,1) -> Napidíj, utazási költségek | CW45: =CV45 -> Napidíj, utazási költségek | CZ45: 888
...

Sheet Kiadasi_kiseroiv
A1: A jobboldali, zöld cellában lehet kiválasztani a lenyílóból a kasszát illetve a számlákat. Ha a cella üres, vagy értéke 0 (nulla), akkor alapértelmezettként a kasszát listázza. | F1: Kassza | J1: A A a | K1: =IF(AND(F3<>0,F3<>"",ISERROR(VLOOKUP(F3,BC1:BD366,2,FALSE))<>TRUE),F3,MAX(BC1:BC367)) -> 46023 | L1: Ezen a napon összesen | M1: =MAX(Cs!BS7:BS33000) -> 0 | N1: =MIN(Cs!BS7:BS33000) -> 0 | O1: =SUM(M1,-N1,1) -> 1 | T1: =IF(VLOOKUP(P2,AO1:AR21,4,FALSE)<>"",VLOOKUP(P2,AO1:AR21,4,FALSE)&" "&IF(F1<>AN1,F1,""),F1) -> Kasszakönyv | U1: =IF(AND(T1<>R1,AND(ISERROR(SEARCH("száml",T1,1)),ISERROR(SEARCH("kassz",T1,1))))," számla","") | AN1: Kassza | AO1: kassza | AP1: kassza | AQ1: =Cs!CQ1 -> 0 | AR1: Kasszakönyv | AW1: =Kiadasi_kiseroiv!$BC$1:INDEX(Kiadasi_kiseroiv!$BC:$BC,Kiadasi_kiseroiv!$AX$1) -> 0 | AX1: =IF(MATCH(0,BC1:BC367,0)>1,MATCH(0,BC1:BC367,0)-1,1) -> 1 | BA1: 1 | BB1: =IF(BC1<>0,VLOOKUP(MONTH(BC1),$BK$1:$BL$12,2,FALSE)&DAY(BC1),"--") -> -- | BC1: =IF(ISERROR(VLOOKUP(BA1,$BD$1:$BE$366,2,FALSE))=FALSE,VLOOKUP(BA1,$BD$1:$BE$366,2,FALSE),0) -> 0 | BD1: =IF(COUNTIF(Cs!$BT$7:$BT$33000,BE1)<>0,1,0) -> 0 | BE1: =DATE(Cs!CJ1,1,1) -> 46023 | BF1: =ROUNDUP(COUNTIF(Cs!$BT$7:$BT$33000,BE1)/20,0) -> 0 | BK1: 1 | BL1: Jan.
A2: =IF(M2>1,L1&M2&L2&M3&L3,"") | F2: 1 | J2: A A a | K2: =DATE(Cs!CJ1,MONTH(K1),DAY(K1)) -> 46023 | L2: kiadási kísérőív lap van. Ebből jelenleg a(z) | M2: =ROUNDUP(O1/20,0) -> 1 | P2: =IF(ISERROR(VLOOKUP(F1,AN1:AP21,2,FALSE))=FALSE,VLOOKUP(F1,AN1:AP21,2,FALSE),AN1) -> kassza | AN2: A - számla | AO2: ab | AP2: a | AQ2: =Cs!CQ2 -> 0 | AR2: =IF(Cs!CR2<>0,Cs!CR2&" /","") | BA2: 2 | BB2: =IF(BC2<>0,VLOOKUP(MONTH(BC2),$BK$1:$BL$12,2,FALSE)&DAY(BC2),"--") -> -- | BC2: =IF(ISERROR(VLOOKUP(BA2,$BD$1:$BE$366,2,FALSE))=FALSE,VLOOKUP(BA2,$BD$1:$BE$366,2,FALSE),0) -> 0 | BD2: =IF(COUNTIF(Cs!$BT$7:$BT$33000,BE2)<>0,BD1+1,BD1) -> 0 | BE2: =BE1+1 -> 46024 | BF2: =ROUNDUP(COUNTIF(Cs!$BT$7:$BT$33000,BE2)/20,0) -> 0 | BG2: =SUM($BF$1:BF1) -> 0 | BK2: 2 | BL2: Febr.
A3: A jobboldali, zöld cellában lehet kiválasztani a dátumot. A lenyílóban csak azok a napok jelennek meg, amikor kiadás volt a kasszában, illetve a bankszámlán. Ha a cella üres, vagy értéke 0 (nulla), akkor a legutolsó kiadási kísérőlapot listázza. | J3: A A a | K3: =IF(MONTH(K2)<10,0,"") -> 0 | L3: . látszik. A jobboldali, zöld cellában lehet megadni a listázni kívánt lapszámot. | M3: =IF(OR(F2=0,F2>M2,F2=""),1,F2) -> 1 | T3: ="Összesen kiadás - "&F6 -> Összesen kiadás - 2026.01.01. | AN3: B - számla | AO3: bb | AP3: b | AQ3: =Cs!CQ3 -> 0 | AR3: =IF(Cs!CR3<>0,Cs!CR3&" /","") | BA3: 3 | BB3: =IF(BC3<>0,VLOOKUP(MONTH(BC3),$BK$1:$BL$12,2,FALSE)&DAY(BC3),"--") -> -- | BC3: =IF(ISERROR(VLOOKUP(BA3,$BD$1:$BE$366,2,FALSE))=FALSE,VLOOKUP(BA3,$BD$1:$BE$366,2,FALSE),0) -> 0 | BD3: =IF(COUNTIF(Cs!$BT$7:$BT$33000,BE3)<>0,BD2+1,BD2) -> 0 | BE3: =BE2+1 -> 46025 | BF3: =ROUNDUP(COUNTIF(Cs!$BT$7:$BT$33000,BE3)/20,0) -> 0 | BG3: =SUM($BF$1:BF2) -> 0 | BK3: 3 | BL3: Márc.
