Workbook
Name cimbev: Vagyonleltar_jelentes!$Z$1:INDEX(Vagyonleltar_jelentes!$Z:$Z,Vagyonleltar_jelentes!$Y$1)
Name cimkiad: Vagyonleltar_jelentes!$AB$1:INDEX(Vagyonleltar_jelentes!$AB:$AB,Vagyonleltar_jelentes!$Y$2)
Name kkezd: Keszlet!$K$1
Name kvegez: Keszlet!$K$2
Name q: Anyagraktar_iv!$O$1

Sheet Keszlet
K1: =DATE(L1,1,1) -> 45658 | L1: 2025
K2: =DATE(L1+25,12,31) -> 55153
C3: zzzzzzzzzzz | E3: A jobboldali, zöld cellába kell beírni az egyházközség (egyházmegye) teljes megnevezését. (pl: Zabolai Református Egyházközség) | R3: a a
C4: =IF(E4<>0,IF(F4<>0,TRIM(E4&" - "&F4),E4),"") -> Anyag megnevezése - Megjegyzés | D4: S.sz | E4: Anyag megnevezése | F4: Megjegyzés | G4: Egységár | H4: Mérték-egység | I4: Készleten levő mennyiség | J4: Érték | N4: Bevétel | O4: Kiadás | R4: egyenleg | S4: Bevétel | T4: kiadás | U4: érték
A5: =IF(C5<>$C$3,A4+1,A4) -> 0 | B5: =IF(AND(R5<>0,R5<>""),B4+1,B4) -> 0 | C5: =IF(E5<>0,TRIM(D5&" - "&E5&IF(F5<>0," - "&F5,"")&" - "&L5&","&M5&" lej/"&H5),$C$3) -> zzzzzzzzzzz | D5: 1 | I5: =IF(C5<>"",N5-O5,"") -> 0 | J5: =IF(I5<>"",G5*I5,"") -> 0 | L5: =ROUNDDOWN(G5,0) -> 0 | M5: =IF(SUM(G5,-L5)*100<=9,"0"&SUM(G5,-L5)*100,SUM(G5,-L5)*100) -> 00 | N5: =SUMIF(Bevetel!$G$6:$G$1000,C5,Bevetel!$I$6:$I$1000) -> 0 | O5: =SUMIF(Kiadas!$G$1006:$G$10000,C5,Kiadas!$I$1006:$I$10000) -> 0 | R5: =IF(C5<>"",S5-T5,"") -> 0 | S5: =SUMIF(Kiadas!$G$6:$G$1000,C5,Kiadas!$BA$6:$BA$1000) -> 0 | T5: =SUMIF(Kiadas!$G$1006:$G$10000,C5,Kiadas!$BA$1006:$BA$10000) -> 0 | U5: =PRODUCT(G5*R5) -> 0
A6: =IF(C6<>$C$3,A5+1,A5) -> 0 | B6: =IF(AND(R6<>0,R6<>""),B5+1,B5) -> 0 | C6: =IF(E6<>0,TRIM(D6&" - "&E6&IF(F6<>0," - "&F6,"")&" - "&L6&","&M6&" lej/"&H6),$C$3) -> zzzzzzzzzzz | D6: 2 | I6: =IF(C6<>"",N6-O6,"") -> 0 | J6: =IF(I6<>"",G6*I6,"") -> 0 | L6: =ROUNDDOWN(G6,0) -> 0 | M6: =IF(SUM(G6,-L6)*100<=9,"0"&SUM(G6,-L6)*100,SUM(G6,-L6)*100) -> 00 | N6: =SUMIF(Bevetel!$G$6:$G$1000,C6,Bevetel!$I$6:$I$1000) -> 0 | O6: =SUMIF(Kiadas!$G$1006:$G$10000,C6,Kiadas!$I$1006:$I$10000) -> 0 | R6: =IF(C6<>"",S6-T6,"") -> 0 | S6: =SUMIF(Kiadas!$G$6:$G$1000,C6,Kiadas!$BA$6:$BA$1000) -> 0 | T6: =SUMIF(Kiadas!$G$1006:$G$10000,C6,Kiadas!$BA$1006:$BA$10000) -> 0 | U6: =PRODUCT(G6*R6) -> 0
A7: =IF(C7<>$C$3,A6+1,A6) -> 0 | B7: =IF(AND(R7<>0,R7<>""),B6+1,B6) -> 0 | C7: =IF(E7<>0,TRIM(D7&" - "&E7&IF(F7<>0," - "&F7,"")&" - "&L7&","&M7&" lej/"&H7),$C$3) -> zzzzzzzzzzz | D7: 3 | I7: =IF(C7<>"",N7-O7,"") -> 0 | J7: =IF(I7<>"",G7*I7,"") -> 0 | L7: =ROUNDDOWN(G7,0) -> 0 | M7: =IF(SUM(G7,-L7)*100<=9,"0"&SUM(G7,-L7)*100,SUM(G7,-L7)*100) -> 00 | N7: =SUMIF(Bevetel!$G$6:$G$1000,C7,Bevetel!$I$6:$I$1000) -> 0 | O7: =SUMIF(Kiadas!$G$1006:$G$10000,C7,Kiadas!$I$1006:$I$10000) -> 0 | R7: =IF(C7<>"",S7-T7,"") -> 0 | S7: =SUMIF(Kiadas!$G$6:$G$1000,C7,Kiadas!$BA$6:$BA$1000) -> 0 | T7: =SUMIF(Kiadas!$G$1006:$G$10000,C7,Kiadas!$BA$1006:$BA$10000) -> 0 | U7: =PRODUCT(G7*R7) -> 0
A8: =IF(C8<>$C$3,A7+1,A7) -> 0 | B8: =IF(AND(R8<>0,R8<>""),B7+1,B7) -> 0 | C8: =IF(E8<>0,TRIM(D8&" - "&E8&IF(F8<>0," - "&F8,"")&" - "&L8&","&M8&" lej/"&H8),$C$3) -> zzzzzzzzzzz | D8: 4 | I8: =IF(C8<>"",N8-O8,"") -> 0 | J8: =IF(I8<>"",G8*I8,"") -> 0 | L8: =ROUNDDOWN(G8,0) -> 0 | M8: =IF(SUM(G8,-L8)*100<=9,"0"&SUM(G8,-L8)*100,SUM(G8,-L8)*100) -> 00 | N8: =SUMIF(Bevetel!$G$6:$G$1000,C8,Bevetel!$I$6:$I$1000) -> 0 | O8: =SUMIF(Kiadas!$G$1006:$G$10000,C8,Kiadas!$I$1006:$I$10000) -> 0 | R8: =IF(C8<>"",S8-T8,"") -> 0 | S8: =SUMIF(Kiadas!$G$6:$G$1000,C8,Kiadas!$BA$6:$BA$1000) -> 0 | T8: =SUMIF(Kiadas!$G$1006:$G$10000,C8,Kiadas!$BA$1006:$BA$10000) -> 0 | U8: =PRODUCT(G8*R8) -> 0
A9: =IF(C9<>$C$3,A8+1,A8) -> 0 | B9: =IF(AND(R9<>0,R9<>""),B8+1,B8) -> 0 | C9: =IF(E9<>0,TRIM(D9&" - "&E9&IF(F9<>0," - "&F9,"")&" - "&L9&","&M9&" lej/"&H9),$C$3) -> zzzzzzzzzzz | D9: 5 | I9: =IF(C9<>"",N9-O9,"") -> 0 | J9: =IF(I9<>"",G9*I9,"") -> 0 | L9: =ROUNDDOWN(G9,0) -> 0 | M9: =IF(SUM(G9,-L9)*100<=9,"0"&SUM(G9,-L9)*100,SUM(G9,-L9)*100) -> 00 | N9: =SUMIF(Bevetel!$G$6:$G$1000,C9,Bevetel!$I$6:$I$1000) -> 0 | O9: =SUMIF(Kiadas!$G$1006:$G$10000,C9,Kiadas!$I$1006:$I$10000) -> 0 | R9: =IF(C9<>"",S9-T9,"") -> 0 | S9: =SUMIF(Kiadas!$G$6:$G$1000,C9,Kiadas!$BA$6:$BA$1000) -> 0 | T9: =SUMIF(Kiadas!$G$1006:$G$10000,C9,Kiadas!$BA$1006:$BA$10000) -> 0 | U9: =PRODUCT(G9*R9) -> 0
A10: =IF(C10<>$C$3,A9+1,A9) -> 0 | B10: =IF(AND(R10<>0,R10<>""),B9+1,B9) -> 0 | C10: =IF(E10<>0,TRIM(D10&" - "&E10&IF(F10<>0," - "&F10,"")&" - "&L10&","&M10&" lej/"&H10),$C$3) -> zzzzzzzzzzz | D10: 6 | I10: =IF(C10<>"",N10-O10,"") -> 0 | J10: =IF(I10<>"",G10*I10,"") -> 0 | L10: =ROUNDDOWN(G10,0) -> 0 | M10: =IF(SUM(G10,-L10)*100<=9,"0"&SUM(G10,-L10)*100,SUM(G10,-L10)*100) -> 00 | N10: =SUMIF(Bevetel!$G$6:$G$1000,C10,Bevetel!$I$6:$I$1000) -> 0 | O10: =SUMIF(Kiadas!$G$1006:$G$10000,C10,Kiadas!$I$1006:$I$10000) -> 0 | R10: =IF(C10<>"",S10-T10,"") -> 0 | S10: =SUMIF(Kiadas!$G$6:$G$1000,C10,Kiadas!$BA$6:$BA$1000) -> 0 | T10: =SUMIF(Kiadas!$G$1006:$G$10000,C10,Kiadas!$BA$1006:$BA$10000) -> 0 | U10: =PRODUCT(G10*R10) -> 0
A11: =IF(C11<>$C$3,A10+1,A10) -> 0 | B11: =IF(AND(R11<>0,R11<>""),B10+1,B10) -> 0 | C11: =IF(E11<>0,TRIM(D11&" - "&E11&IF(F11<>0," - "&F11,"")&" - "&L11&","&M11&" lej/"&H11),$C$3) -> zzzzzzzzzzz | D11: 7 | I11: =IF(C11<>"",N11-O11,"") -> 0 | J11: =IF(I11<>"",G11*I11,"") -> 0 | L11: =ROUNDDOWN(G11,0) -> 0 | M11: =IF(SUM(G11,-L11)*100<=9,"0"&SUM(G11,-L11)*100,SUM(G11,-L11)*100) -> 00 | N11: =SUMIF(Bevetel!$G$6:$G$1000,C11,Bevetel!$I$6:$I$1000) -> 0 | O11: =SUMIF(Kiadas!$G$1006:$G$10000,C11,Kiadas!$I$1006:$I$10000) -> 0 | R11: =IF(C11<>"",S11-T11,"") -> 0 | S11: =SUMIF(Kiadas!$G$6:$G$1000,C11,Kiadas!$BA$6:$BA$1000) -> 0 | T11: =SUMIF(Kiadas!$G$1006:$G$10000,C11,Kiadas!$BA$1006:$BA$10000) -> 0 | U11: =PRODUCT(G11*R11) -> 0
A12: =IF(C12<>$C$3,A11+1,A11) -> 0 | B12: =IF(AND(R12<>0,R12<>""),B11+1,B11) -> 0 | C12: =IF(E12<>0,TRIM(D12&" - "&E12&IF(F12<>0," - "&F12,"")&" - "&L12&","&M12&" lej/"&H12),$C$3) -> zzzzzzzzzzz | D12: 8 | I12: =IF(C12<>"",N12-O12,"") -> 0 | J12: =IF(I12<>"",G12*I12,"") -> 0 | L12: =ROUNDDOWN(G12,0) -> 0 | M12: =IF(SUM(G12,-L12)*100<=9,"0"&SUM(G12,-L12)*100,SUM(G12,-L12)*100) -> 00 | N12: =SUMIF(Bevetel!$G$6:$G$1000,C12,Bevetel!$I$6:$I$1000) -> 0 | O12: =SUMIF(Kiadas!$G$1006:$G$10000,C12,Kiadas!$I$1006:$I$10000) -> 0 | R12: =IF(C12<>"",S12-T12,"") -> 0 | S12: =SUMIF(Kiadas!$G$6:$G$1000,C12,Kiadas!$BA$6:$BA$1000) -> 0 | T12: =SUMIF(Kiadas!$G$1006:$G$10000,C12,Kiadas!$BA$1006:$BA$10000) -> 0 | U12: =PRODUCT(G12*R12) -> 0
A13: =IF(C13<>$C$3,A12+1,A12) -> 0 | B13: =IF(AND(R13<>0,R13<>""),B12+1,B12) -> 0 | C13: =IF(E13<>0,TRIM(D13&" - "&E13&IF(F13<>0," - "&F13,"")&" - "&L13&","&M13&" lej/"&H13),$C$3) -> zzzzzzzzzzz | D13: 9 | I13: =IF(C13<>"",N13-O13,"") -> 0 | J13: =IF(I13<>"",G13*I13,"") -> 0 | L13: =ROUNDDOWN(G13,0) -> 0 | M13: =IF(SUM(G13,-L13)*100<=9,"0"&SUM(G13,-L13)*100,SUM(G13,-L13)*100) -> 00 | N13: =SUMIF(Bevetel!$G$6:$G$1000,C13,Bevetel!$I$6:$I$1000) -> 0 | O13: =SUMIF(Kiadas!$G$1006:$G$10000,C13,Kiadas!$I$1006:$I$10000) -> 0 | R13: =IF(C13<>"",S13-T13,"") -> 0 | S13: =SUMIF(Kiadas!$G$6:$G$1000,C13,Kiadas!$BA$6:$BA$1000) -> 0 | T13: =SUMIF(Kiadas!$G$1006:$G$10000,C13,Kiadas!$BA$1006:$BA$10000) -> 0 | U13: =PRODUCT(G13*R13) -> 0
A14: =IF(C14<>$C$3,A13+1,A13) -> 0 | B14: =IF(AND(R14<>0,R14<>""),B13+1,B13) -> 0 | C14: =IF(E14<>0,TRIM(D14&" - "&E14&IF(F14<>0," - "&F14,"")&" - "&L14&","&M14&" lej/"&H14),$C$3) -> zzzzzzzzzzz | D14: 10 | I14: =IF(C14<>"",N14-O14,"") -> 0 | J14: =IF(I14<>"",G14*I14,"") -> 0 | L14: =ROUNDDOWN(G14,0) -> 0 | M14: =IF(SUM(G14,-L14)*100<=9,"0"&SUM(G14,-L14)*100,SUM(G14,-L14)*100) -> 00 | N14: =SUMIF(Bevetel!$G$6:$G$1000,C14,Bevetel!$I$6:$I$1000) -> 0 | O14: =SUMIF(Kiadas!$G$1006:$G$10000,C14,Kiadas!$I$1006:$I$10000) -> 0 | R14: =IF(C14<>"",S14-T14,"") -> 0 | S14: =SUMIF(Kiadas!$G$6:$G$1000,C14,Kiadas!$BA$6:$BA$1000) -> 0 | T14: =SUMIF(Kiadas!$G$1006:$G$10000,C14,Kiadas!$BA$1006:$BA$10000) -> 0 | U14: =PRODUCT(G14*R14) -> 0
A15: =IF(C15<>$C$3,A14+1,A14) -> 0 | B15: =IF(AND(R15<>0,R15<>""),B14+1,B14) -> 0 | C15: =IF(E15<>0,TRIM(D15&" - "&E15&IF(F15<>0," - "&F15,"")&" - "&L15&","&M15&" lej/"&H15),$C$3) -> zzzzzzzzzzz | D15: 11 | I15: =IF(C15<>"",N15-O15,"") -> 0 | J15: =IF(I15<>"",G15*I15,"") -> 0 | L15: =ROUNDDOWN(G15,0) -> 0 | M15: =IF(SUM(G15,-L15)*100<=9,"0"&SUM(G15,-L15)*100,SUM(G15,-L15)*100) -> 00 | N15: =SUMIF(Bevetel!$G$6:$G$1000,C15,Bevetel!$I$6:$I$1000) -> 0 | O15: =SUMIF(Kiadas!$G$1006:$G$10000,C15,Kiadas!$I$1006:$I$10000) -> 0 | R15: =IF(C15<>"",S15-T15,"") -> 0 | S15: =SUMIF(Kiadas!$G$6:$G$1000,C15,Kiadas!$BA$6:$BA$1000) -> 0 | T15: =SUMIF(Kiadas!$G$1006:$G$10000,C15,Kiadas!$BA$1006:$BA$10000) -> 0 | U15: =PRODUCT(G15*R15) -> 0
A16: =IF(C16<>$C$3,A15+1,A15) -> 0 | B16: =IF(AND(R16<>0,R16<>""),B15+1,B15) -> 0 | C16: =IF(E16<>0,TRIM(D16&" - "&E16&IF(F16<>0," - "&F16,"")&" - "&L16&","&M16&" lej/"&H16),$C$3) -> zzzzzzzzzzz | D16: 12 | I16: =IF(C16<>"",N16-O16,"") -> 0 | J16: =IF(I16<>"",G16*I16,"") -> 0 | L16: =ROUNDDOWN(G16,0) -> 0 | M16: =IF(SUM(G16,-L16)*100<=9,"0"&SUM(G16,-L16)*100,SUM(G16,-L16)*100) -> 00 | N16: =SUMIF(Bevetel!$G$6:$G$1000,C16,Bevetel!$I$6:$I$1000) -> 0 | O16: =SUMIF(Kiadas!$G$1006:$G$10000,C16,Kiadas!$I$1006:$I$10000) -> 0 | R16: =IF(C16<>"",S16-T16,"") -> 0 | S16: =SUMIF(Kiadas!$G$6:$G$1000,C16,Kiadas!$BA$6:$BA$1000) -> 0 | T16: =SUMIF(Kiadas!$G$1006:$G$10000,C16,Kiadas!$BA$1006:$BA$10000) -> 0 | U16: =PRODUCT(G16*R16) -> 0
... A200: =IF(C200<>$C$3,A199+1,A199) -> 0 | B200: =IF(AND(R200<>0,R200<>""),B199+1,B199) -> 0 | C200: =IF(E200<>0,TRIM(D200&" - "&E200&IF(F200<>0," - "&F200,"")&" - "&L200&","&M200&" lej/"&H200),$C$3) -> zzzzzzzzzzz | D200: 196 | I200: =IF(C200<>"",N200-O200,"") -> 0 | J200: =IF(I200<>"",G200*I200,"") -> 0 | L200: =ROUNDDOWN(G200,0) -> 0 | M200: =IF(SUM(G200,-L200)*100<=9,"0"&SUM(G200,-L200)*100,SUM(G200,-L200)*100) -> 00 | N200: =SUMIF(Bevetel!$G$6:$G$1000,C200,Bevetel!$I$6:$I$1000) -> 0 | O200: =SUMIF(Kiadas!$G$1006:$G$10000,C200,Kiadas!$I$1006:$I$10000) -> 0 | R200: =IF(C200<>"",S200-T200,"") -> 0 | S200: =SUMIF(Kiadas!$G$6:$G$1000,C200,Kiadas!$BA$6:$BA$1000) -> 0 | T200: =SUMIF(Kiadas!$G$1006:$G$10000,C200,Kiadas!$BA$1006:$BA$10000) -> 0 | U200: =PRODUCT(G200*R200) -> 0
A201: =IF(C201<>$C$3,A200+1,A200) -> 0 | C201: =IF(E201<>0,TRIM(D201&" - "&E201&IF(F201<>0," - "&F201,"")&" - "&G201&" lej/"&H201),$C$3) -> zzzzzzzzzzz
C202: 0
C203: ""
C204: =""

Sheet Bevetel
E1: =IF(MAX(E6:E1000)>kkezd,MAX(E6:E1000),kkezd) -> 45658
D3: Iratszám | E3: Dátum | F3: Kinek adtuk ki | G3: Megjegyzés | H3: Anyag megnevezése | I3: Mennyiség | K3: Egységár | L3: Érték
E4: ANYAGRAKTÁR - BEVÉTEL
D5: Iratszám | E5: Dátum | F5: Kitől vettük be | G5: Anyag megnevezése | H5: Megjegyzés | I5: Mennyiség | J5: M.egység | K5: Egységár | L5: Érték
D6: =IF(AND(OR(Kiadas!C5<>Kiadas!C6,Kiadas!C6=1),SUM(Kiadas!L6:L26)<>0),YEAR(Kiadas!W6)&"/"&Kiadas!C6,"") | J6: =IF(AND(G6<>"",ISERROR(VLOOKUP(G6,Keszlet!$C$5:$H$200,6,FALSE))=FALSE),VLOOKUP(G6,Keszlet!$C$5:$H$200,6,FALSE),"") | K6: =IF(AND(G6<>"",ISERROR(VLOOKUP(G6,Keszlet!$C$5:$G$200,5,FALSE))=FALSE),VLOOKUP(G6,Keszlet!$C$5:$G$200,5,FALSE),"") | L6: =IF(AND(G6<>0,K6<>""),I6*K6,"") | T6: =IF(OR(E6<>0,F6<>0,SUM(L6:L26)=0),E6&F6,0) | BA6: =IF(E6<=Leltar_iv!$Y$1,I6,0) -> 0
D7: =IF(AND(OR(Kiadas!C6<>Kiadas!C7,Kiadas!C7=1),SUM(Kiadas!L7:L27)<>0),YEAR(Kiadas!W7)&"/"&Kiadas!C7,"") | J7: =IF(AND(G7<>"",ISERROR(VLOOKUP(G7,Keszlet!$C$5:$H$200,6,FALSE))=FALSE),VLOOKUP(G7,Keszlet!$C$5:$H$200,6,FALSE),"") | K7: =IF(AND(G7<>"",ISERROR(VLOOKUP(G7,Keszlet!$C$5:$G$200,5,FALSE))=FALSE),VLOOKUP(G7,Keszlet!$C$5:$G$200,5,FALSE),"") | L7: =IF(AND(G7<>0,K7<>""),I7*K7,"") | T7: =IF(OR(E7<>0,F7<>0,SUM(L7:L27)=0),E7&F7,0) | BA7: =IF(E7<=Leltar_iv!$Y$1,I7,0) -> 0
D8: =IF(AND(OR(Kiadas!C7<>Kiadas!C8,Kiadas!C8=1),SUM(Kiadas!L8:L28)<>0),YEAR(Kiadas!W8)&"/"&Kiadas!C8,"") | J8: =IF(AND(G8<>"",ISERROR(VLOOKUP(G8,Keszlet!$C$5:$H$200,6,FALSE))=FALSE),VLOOKUP(G8,Keszlet!$C$5:$H$200,6,FALSE),"") | K8: =IF(AND(G8<>"",ISERROR(VLOOKUP(G8,Keszlet!$C$5:$G$200,5,FALSE))=FALSE),VLOOKUP(G8,Keszlet!$C$5:$G$200,5,FALSE),"") | L8: =IF(AND(G8<>0,K8<>""),I8*K8,"") | T8: =IF(OR(E8<>0,F8<>0,SUM(L8:L28)=0),E8&F8,0) | BA8: =IF(E8<=Leltar_iv!$Y$1,I8,0) -> 0
D9: =IF(AND(OR(Kiadas!C8<>Kiadas!C9,Kiadas!C9=1),SUM(Kiadas!L9:L29)<>0),YEAR(Kiadas!W9)&"/"&Kiadas!C9,"") | J9: =IF(AND(G9<>"",ISERROR(VLOOKUP(G9,Keszlet!$C$5:$H$200,6,FALSE))=FALSE),VLOOKUP(G9,Keszlet!$C$5:$H$200,6,FALSE),"") | K9: =IF(AND(G9<>"",ISERROR(VLOOKUP(G9,Keszlet!$C$5:$G$200,5,FALSE))=FALSE),VLOOKUP(G9,Keszlet!$C$5:$G$200,5,FALSE),"") | L9: =IF(AND(G9<>0,K9<>""),I9*K9,"") | T9: =IF(OR(E9<>0,F9<>0,SUM(L9:L29)=0),E9&F9,0) | BA9: =IF(E9<=Leltar_iv!$Y$1,I9,0) -> 0
D10: =IF(AND(OR(Kiadas!C9<>Kiadas!C10,Kiadas!C10=1),SUM(Kiadas!L10:L30)<>0),YEAR(Kiadas!W10)&"/"&Kiadas!C10,"") | J10: =IF(AND(G10<>"",ISERROR(VLOOKUP(G10,Keszlet!$C$5:$H$200,6,FALSE))=FALSE),VLOOKUP(G10,Keszlet!$C$5:$H$200,6,FALSE),"") | K10: =IF(AND(G10<>"",ISERROR(VLOOKUP(G10,Keszlet!$C$5:$G$200,5,FALSE))=FALSE),VLOOKUP(G10,Keszlet!$C$5:$G$200,5,FALSE),"") | L10: =IF(AND(G10<>0,K10<>""),I10*K10,"") | T10: =IF(OR(E10<>0,F10<>0,SUM(L10:L30)=0),E10&F10,0) | BA10: =IF(E10<=Leltar_iv!$Y$1,I10,0) -> 0
D11: =IF(AND(OR(Kiadas!C10<>Kiadas!C11,Kiadas!C11=1),SUM(Kiadas!L11:L31)<>0),YEAR(Kiadas!W11)&"/"&Kiadas!C11,"") | J11: =IF(AND(G11<>"",ISERROR(VLOOKUP(G11,Keszlet!$C$5:$H$200,6,FALSE))=FALSE),VLOOKUP(G11,Keszlet!$C$5:$H$200,6,FALSE),"") | K11: =IF(AND(G11<>"",ISERROR(VLOOKUP(G11,Keszlet!$C$5:$G$200,5,FALSE))=FALSE),VLOOKUP(G11,Keszlet!$C$5:$G$200,5,FALSE),"") | L11: =IF(AND(G11<>0,K11<>""),I11*K11,"") | T11: =IF(OR(E11<>0,COUNTIF(T2:T10,0)=9,F11<>0,SUM(L11:L31)=0),E11&F11,0) | BA11: =IF(E11<=Leltar_iv!$Y$1,I11,0) -> 0
D12: =IF(AND(OR(Kiadas!C11<>Kiadas!C12,Kiadas!C12=1),SUM(Kiadas!L12:L32)<>0),YEAR(Kiadas!W12)&"/"&Kiadas!C12,"") | J12: =IF(AND(G12<>"",ISERROR(VLOOKUP(G12,Keszlet!$C$5:$H$200,6,FALSE))=FALSE),VLOOKUP(G12,Keszlet!$C$5:$H$200,6,FALSE),"") | K12: =IF(AND(G12<>"",ISERROR(VLOOKUP(G12,Keszlet!$C$5:$G$200,5,FALSE))=FALSE),VLOOKUP(G12,Keszlet!$C$5:$G$200,5,FALSE),"") | L12: =IF(AND(G12<>0,K12<>""),I12*K12,"") | T12: =IF(OR(E12<>0,COUNTIF(T3:T11,0)=9,F12<>0,SUM(L12:L32)=0),E12&F12,0) | BA12: =IF(E12<=Leltar_iv!$Y$1,I12,0) -> 0
D13: =IF(AND(OR(Kiadas!C12<>Kiadas!C13,Kiadas!C13=1),SUM(Kiadas!L13:L33)<>0),YEAR(Kiadas!W13)&"/"&Kiadas!C13,"") | J13: =IF(AND(G13<>"",ISERROR(VLOOKUP(G13,Keszlet!$C$5:$H$200,6,FALSE))=FALSE),VLOOKUP(G13,Keszlet!$C$5:$H$200,6,FALSE),"") | K13: =IF(AND(G13<>"",ISERROR(VLOOKUP(G13,Keszlet!$C$5:$G$200,5,FALSE))=FALSE),VLOOKUP(G13,Keszlet!$C$5:$G$200,5,FALSE),"") | L13: =IF(AND(G13<>0,K13<>""),I13*K13,"") | T13: =IF(OR(E13<>0,COUNTIF(T4:T12,0)=9,F13<>0,SUM(L13:L33)=0),E13&F13,0) | BA13: =IF(E13<=Leltar_iv!$Y$1,I13,0) -> 0
D14: =IF(AND(OR(Kiadas!C13<>Kiadas!C14,Kiadas!C14=1),SUM(Kiadas!L14:L34)<>0),YEAR(Kiadas!W14)&"/"&Kiadas!C14,"") | J14: =IF(AND(G14<>"",ISERROR(VLOOKUP(G14,Keszlet!$C$5:$H$200,6,FALSE))=FALSE),VLOOKUP(G14,Keszlet!$C$5:$H$200,6,FALSE),"") | K14: =IF(AND(G14<>"",ISERROR(VLOOKUP(G14,Keszlet!$C$5:$G$200,5,FALSE))=FALSE),VLOOKUP(G14,Keszlet!$C$5:$G$200,5,FALSE),"") | L14: =IF(AND(G14<>0,K14<>""),I14*K14,"") | T14: =IF(OR(E14<>0,COUNTIF(T5:T13,0)=9,F14<>0,SUM(L14:L34)=0),E14&F14,0) | BA14: =IF(E14<=Leltar_iv!$Y$1,I14,0) -> 0
D15: =IF(AND(OR(Kiadas!C14<>Kiadas!C15,Kiadas!C15=1),SUM(Kiadas!L15:L35)<>0),YEAR(Kiadas!W15)&"/"&Kiadas!C15,"") | J15: =IF(AND(G15<>"",ISERROR(VLOOKUP(G15,Keszlet!$C$5:$H$200,6,FALSE))=FALSE),VLOOKUP(G15,Keszlet!$C$5:$H$200,6,FALSE),"") | K15: =IF(AND(G15<>"",ISERROR(VLOOKUP(G15,Keszlet!$C$5:$G$200,5,FALSE))=FALSE),VLOOKUP(G15,Keszlet!$C$5:$G$200,5,FALSE),"") | L15: =IF(AND(G15<>0,K15<>""),I15*K15,"") | T15: =IF(OR(E15<>0,COUNTIF(T6:T14,0)=9,F15<>0,SUM(L15:L35)=0),E15&F15,0) | BA15: =IF(E15<=Leltar_iv!$Y$1,I15,0) -> 0
D16: =IF(AND(OR(Kiadas!C15<>Kiadas!C16,Kiadas!C16=1),SUM(Kiadas!L16:L36)<>0),YEAR(Kiadas!W16)&"/"&Kiadas!C16,"") | J16: =IF(AND(G16<>"",ISERROR(VLOOKUP(G16,Keszlet!$C$5:$H$200,6,FALSE))=FALSE),VLOOKUP(G16,Keszlet!$C$5:$H$200,6,FALSE),"") | K16: =IF(AND(G16<>"",ISERROR(VLOOKUP(G16,Keszlet!$C$5:$G$200,5,FALSE))=FALSE),VLOOKUP(G16,Keszlet!$C$5:$G$200,5,FALSE),"") | L16: =IF(AND(G16<>0,K16<>""),I16*K16,"") | T16: =IF(OR(E16<>0,COUNTIF(T7:T15,0)=9,F16<>0,SUM(L16:L36)=0),E16&F16,0) | BA16: =IF(E16<=Leltar_iv!$Y$1,I16,0) -> 0
D17: =IF(AND(OR(Kiadas!C16<>Kiadas!C17,Kiadas!C17=1),SUM(Kiadas!L17:L37)<>0),YEAR(Kiadas!W17)&"/"&Kiadas!C17,"") | J17: =IF(AND(G17<>"",ISERROR(VLOOKUP(G17,Keszlet!$C$5:$H$200,6,FALSE))=FALSE),VLOOKUP(G17,Keszlet!$C$5:$H$200,6,FALSE),"") | K17: =IF(AND(G17<>"",ISERROR(VLOOKUP(G17,Keszlet!$C$5:$G$200,5,FALSE))=FALSE),VLOOKUP(G17,Keszlet!$C$5:$G$200,5,FALSE),"") | L17: =IF(AND(G17<>0,K17<>""),I17*K17,"") | T17: =IF(OR(E17<>0,COUNTIF(T8:T16,0)=9,F17<>0,SUM(L17:L37)=0),E17&F17,0) | BA17: =IF(E17<=Leltar_iv!$Y$1,I17,0) -> 0
D18: =IF(AND(OR(Kiadas!C17<>Kiadas!C18,Kiadas!C18=1),SUM(Kiadas!L18:L38)<>0),YEAR(Kiadas!W18)&"/"&Kiadas!C18,"") | J18: =IF(AND(G18<>"",ISERROR(VLOOKUP(G18,Keszlet!$C$5:$H$200,6,FALSE))=FALSE),VLOOKUP(G18,Keszlet!$C$5:$H$200,6,FALSE),"") | K18: =IF(AND(G18<>"",ISERROR(VLOOKUP(G18,Keszlet!$C$5:$G$200,5,FALSE))=FALSE),VLOOKUP(G18,Keszlet!$C$5:$G$200,5,FALSE),"") | L18: =IF(AND(G18<>0,K18<>""),I18*K18,"") | T18: =IF(OR(E18<>0,COUNTIF(T9:T17,0)=9,F18<>0,SUM(L18:L38)=0),E18&F18,0) | BA18: =IF(E18<=Leltar_iv!$Y$1,I18,0) -> 0
D19: =IF(AND(OR(Kiadas!C18<>Kiadas!C19,Kiadas!C19=1),SUM(Kiadas!L19:L39)<>0),YEAR(Kiadas!W19)&"/"&Kiadas!C19,"") | J19: =IF(AND(G19<>"",ISERROR(VLOOKUP(G19,Keszlet!$C$5:$H$200,6,FALSE))=FALSE),VLOOKUP(G19,Keszlet!$C$5:$H$200,6,FALSE),"") | K19: =IF(AND(G19<>"",ISERROR(VLOOKUP(G19,Keszlet!$C$5:$G$200,5,FALSE))=FALSE),VLOOKUP(G19,Keszlet!$C$5:$G$200,5,FALSE),"") | L19: =IF(AND(G19<>0,K19<>""),I19*K19,"") | T19: =IF(OR(E19<>0,COUNTIF(T10:T18,0)=9,F19<>0,SUM(L19:L39)=0),E19&F19,0) | BA19: =IF(E19<=Leltar_iv!$Y$1,I19,0) -> 0
D20: =IF(AND(OR(Kiadas!C19<>Kiadas!C20,Kiadas!C20=1),SUM(Kiadas!L20:L40)<>0),YEAR(Kiadas!W20)&"/"&Kiadas!C20,"") | J20: =IF(AND(G20<>"",ISERROR(VLOOKUP(G20,Keszlet!$C$5:$H$200,6,FALSE))=FALSE),VLOOKUP(G20,Keszlet!$C$5:$H$200,6,FALSE),"") | K20: =IF(AND(G20<>"",ISERROR(VLOOKUP(G20,Keszlet!$C$5:$G$200,5,FALSE))=FALSE),VLOOKUP(G20,Keszlet!$C$5:$G$200,5,FALSE),"") | L20: =IF(AND(G20<>0,K20<>""),I20*K20,"") | T20: =IF(OR(E20<>0,COUNTIF(T11:T19,0)=9,F20<>0,SUM(L20:L40)=0),E20&F20,0) | BA20: =IF(E20<=Leltar_iv!$Y$1,I20,0) -> 0
D21: =IF(AND(OR(Kiadas!C20<>Kiadas!C21,Kiadas!C21=1),SUM(Kiadas!L21:L41)<>0),YEAR(Kiadas!W21)&"/"&Kiadas!C21,"") | J21: =IF(AND(G21<>"",ISERROR(VLOOKUP(G21,Keszlet!$C$5:$H$200,6,FALSE))=FALSE),VLOOKUP(G21,Keszlet!$C$5:$H$200,6,FALSE),"") | K21: =IF(AND(G21<>"",ISERROR(VLOOKUP(G21,Keszlet!$C$5:$G$200,5,FALSE))=FALSE),VLOOKUP(G21,Keszlet!$C$5:$G$200,5,FALSE),"") | L21: =IF(AND(G21<>0,K21<>""),I21*K21,"") | T21: =IF(OR(E21<>0,COUNTIF(T12:T20,0)=9,F21<>0,SUM(L21:L41)=0),E21&F21,0) | BA21: =IF(E21<=Leltar_iv!$Y$1,I21,0) -> 0
D22: =IF(AND(OR(Kiadas!C21<>Kiadas!C22,Kiadas!C22=1),SUM(Kiadas!L22:L42)<>0),YEAR(Kiadas!W22)&"/"&Kiadas!C22,"") | J22: =IF(AND(G22<>"",ISERROR(VLOOKUP(G22,Keszlet!$C$5:$H$200,6,FALSE))=FALSE),VLOOKUP(G22,Keszlet!$C$5:$H$200,6,FALSE),"") | K22: =IF(AND(G22<>"",ISERROR(VLOOKUP(G22,Keszlet!$C$5:$G$200,5,FALSE))=FALSE),VLOOKUP(G22,Keszlet!$C$5:$G$200,5,FALSE),"") | L22: =IF(AND(G22<>0,K22<>""),I22*K22,"") | T22: =IF(OR(E22<>0,COUNTIF(T13:T21,0)=9,F22<>0,SUM(L22:L42)=0),E22&F22,0) | BA22: =IF(E22<=Leltar_iv!$Y$1,I22,0) -> 0
... D200: =IF(AND(OR(Kiadas!C199<>Kiadas!C200,Kiadas!C200=1),SUM(Kiadas!L200:L220)<>0),YEAR(Kiadas!W200)&"/"&Kiadas!C200,"") | J200: =IF(AND(G200<>"",ISERROR(VLOOKUP(G200,Keszlet!$C$5:$H$200,6,FALSE))=FALSE),VLOOKUP(G200,Keszlet!$C$5:$H$200,6,FALSE),"") | K200: =IF(AND(G200<>"",ISERROR(VLOOKUP(G200,Keszlet!$C$5:$G$200,5,FALSE))=FALSE),VLOOKUP(G200,Keszlet!$C$5:$G$200,5,FALSE),"") | L200: =IF(AND(G200<>0,K200<>""),I200*K200,"") | T200: =IF(OR(E200<>0,COUNTIF(T191:T199,0)=9,F200<>0,SUM(L200:L220)=0),E200&F200,0) | BA200: =IF(E200<=Leltar_iv!$Y$1,I200,0) -> 0
D201: =IF(AND(OR(Kiadas!C200<>Kiadas!C201,Kiadas!C201=1),SUM(Kiadas!L201:L221)<>0),YEAR(Kiadas!W201)&"/"&Kiadas!C201,"") | J201: =IF(AND(H201<>"",ISERROR(VLOOKUP(H201,Keszlet!$C$5:$H$200,6,FALSE))=FALSE),VLOOKUP(H201,Keszlet!$C$5:$H$200,6,FALSE),"") | K201: =IF(AND(H201<>"",ISERROR(VLOOKUP(H201,Keszlet!$C$5:$G$200,5,FALSE))=FALSE),VLOOKUP(H201,Keszlet!$C$5:$G$200,5,FALSE),"") | L201: =IF(AND(H201<>0,K201<>""),I201*K201,"") | T201: =IF(OR(E201<>0,COUNTIF(T192:T200,0)=9,F201<>0,SUM(L201:L221)=0),E201&F201,0)
D202: =IF(AND(OR(Kiadas!C201<>Kiadas!C202,Kiadas!C202=1),SUM(Kiadas!L202:L222)<>0),YEAR(Kiadas!W202)&"/"&Kiadas!C202,"") | J202: =IF(AND(H202<>"",ISERROR(VLOOKUP(H202,Keszlet!$C$5:$H$200,6,FALSE))=FALSE),VLOOKUP(H202,Keszlet!$C$5:$H$200,6,FALSE),"") | K202: =IF(AND(H202<>"",ISERROR(VLOOKUP(H202,Keszlet!$C$5:$G$200,5,FALSE))=FALSE),VLOOKUP(H202,Keszlet!$C$5:$G$200,5,FALSE),"") | L202: =IF(AND(H202<>0,K202<>""),I202*K202,"") | T202: =IF(OR(E202<>0,COUNTIF(T193:T201,0)=9,F202<>0,SUM(L202:L222)=0),E202&F202,0)
D203: =IF(AND(OR(Kiadas!C202<>Kiadas!C203,Kiadas!C203=1),SUM(Kiadas!L203:L223)<>0),YEAR(Kiadas!W203)&"/"&Kiadas!C203,"") | J203: =IF(AND(H203<>"",ISERROR(VLOOKUP(H203,Keszlet!$C$5:$H$200,6,FALSE))=FALSE),VLOOKUP(H203,Keszlet!$C$5:$H$200,6,FALSE),"") | K203: =IF(AND(H203<>"",ISERROR(VLOOKUP(H203,Keszlet!$C$5:$G$200,5,FALSE))=FALSE),VLOOKUP(H203,Keszlet!$C$5:$G$200,5,FALSE),"") | L203: =IF(AND(H203<>0,K203<>""),I203*K203,"") | T203: =IF(OR(E203<>0,COUNTIF(T194:T202,0)=9,F203<>0,SUM(L203:L223)=0),E203&F203,0)
D204: =IF(AND(OR(Kiadas!C203<>Kiadas!C204,Kiadas!C204=1),SUM(Kiadas!L204:L224)<>0),YEAR(Kiadas!W204)&"/"&Kiadas!C204,"") | J204: =IF(AND(H204<>"",ISERROR(VLOOKUP(H204,Keszlet!$C$5:$H$200,6,FALSE))=FALSE),VLOOKUP(H204,Keszlet!$C$5:$H$200,6,FALSE),"") | K204: =IF(AND(H204<>"",ISERROR(VLOOKUP(H204,Keszlet!$C$5:$G$200,5,FALSE))=FALSE),VLOOKUP(H204,Keszlet!$C$5:$G$200,5,FALSE),"") | L204: =IF(AND(H204<>0,K204<>""),I204*K204,"") | T204: =IF(OR(E204<>0,COUNTIF(T195:T203,0)=9,F204<>0,SUM(L204:L224)=0),E204&F204,0)
D205: =IF(AND(OR(Kiadas!C204<>Kiadas!C205,Kiadas!C205=1),SUM(Kiadas!L205:L225)<>0),YEAR(Kiadas!W205)&"/"&Kiadas!C205,"") | J205: =IF(AND(H205<>"",ISERROR(VLOOKUP(H205,Keszlet!$C$5:$H$200,6,FALSE))=FALSE),VLOOKUP(H205,Keszlet!$C$5:$H$200,6,FALSE),"") | K205: =IF(AND(H205<>"",ISERROR(VLOOKUP(H205,Keszlet!$C$5:$G$200,5,FALSE))=FALSE),VLOOKUP(H205,Keszlet!$C$5:$G$200,5,FALSE),"") | L205: =IF(AND(H205<>0,K205<>""),I205*K205,"") | T205: =IF(OR(E205<>0,COUNTIF(T196:T204,0)=9,F205<>0,SUM(L205:L225)=0),E205&F205,0)
K206: =IF(H206<>0,I206*#REF!,"")
K207: =IF(H207<>0,I207*#REF!,"")
K208: =IF(H208<>0,I208*#REF!,"")
K209: =IF(H209<>0,I209*#REF!,"")
K210: =IF(H210<>0,I210*#REF!,"")
K211: =IF(H211<>0,I211*#REF!,"")
K212: =IF(H212<>0,I212*#REF!,"")
K213: =IF(H213<>0,I213*#REF!,"")
K214: =IF(H214<>0,I214*#REF!,"")
K215: =IF(H215<>0,I215*#REF!,"")
K216: =IF(H216<>0,I216*#REF!,"")
K217: =IF(H217<>0,I217*#REF!,"")
... K1000: =IF(H1000<>0,I1000*#REF!,"")

Sheet Kiadas
B1: kiseroiv | D1: =Keszlet!K1 -> 45658 | E1: =IF(MAX(E1006:E3000)>kkezd,MAX(E1006:E3000),kkezd) -> 45658 | X1: 55153
B2: =Kisero_iv!M2 -> b | D2: =Keszlet!K2 -> 55153
B3: =Kisero_iv!M3 -> k
B4: =Kisero_iv!N1 -> 1900
D5: Iratszám | E5: Dátum | F5: Kitől vettük be | G5: Anyag megnevezése | H5: Megjegyzés | I5: Mennyiség | J5: M.egység | K5: Egységár | L5: Érték
A6: =IF(COUNTIF($Y$6:Y6,Y6)=1,Y6,Y6+COUNTIF($Y$5:Y5,Y6)) -> 996 | B6: =IF(AND(Kisero_iv!$N$2=C6,Kisero_iv!$K$5=$B$2,SUM(I6:L10)<>0,$B$4=YEAR(W6)),B5+1,0) -> 0 | C6: =IF(YEAR(W5)<>YEAR(W6),1,IF(Bevetel!T6<>0,C5+1,C5)) -> 1 | D6: =Bevetel!D6 | E6: =Bevetel!E6 -> 0 | F6: =IF(Bevetel!F6<>0,Bevetel!F6,"") | G6: =IF(Bevetel!G6<>0,Bevetel!G6,"") | H6: =IF(Bevetel!H6<>0,Bevetel!H6,"") | I6: =Bevetel!I6 -> 0 | J6: =Bevetel!J6 | K6: =Bevetel!K6 | L6: =Bevetel!L6 | Q6: =VLOOKUP(G6,Keszlet!$C$5:$E$205,3,FALSE) -> 0 | T6: =IF(OR(E6<>0,COUNTIF(T1:T5,0)=5,F6<>"",SUM(L6:L26)=0),E6&F6,0) -> 0 | U6: =IF(F6<>"",F6,U5) -> 0 | W6: =IF(E6<>0,E6,W5) -> 0 | X6: =IF(G6=q,W6,$X$1) -> 55153 | Y6: =RANK(X6,$X$6:$X$10000,1) -> 996 | Z6: =IF(COUNTIF($Y$6:Y6,Y6)=1,Y6,Y6+COUNTIF($Y$5:Y5,Y6)) -> 996 | AD6: =IF(AND(C5<>C6,SUM(L6:L26)<>0,$B$4=YEAR(W6)),C6,"") | BA6: =IF(W6<=Leltar_iv!$Y$1,I6,0) -> 0
A7: =IF(COUNTIF($Y$6:Y7,Y7)=1,Y7,Y7+COUNTIF($Y$5:Y6,Y7)) -> 997 | B7: =IF(AND(Kisero_iv!$N$2=C7,Kisero_iv!$K$5=$B$2,SUM(I7:L11)<>0,$B$4=YEAR(W7)),B6+1,0) -> 0 | C7: =IF(YEAR(W6)<>YEAR(W7),1,IF(Bevetel!T7<>0,C6+1,C6)) -> 2 | D7: =Bevetel!D7 | E7: =Bevetel!E7 -> 0 | F7: =IF(Bevetel!F7<>0,Bevetel!F7,"") | G7: =IF(Bevetel!G7<>0,Bevetel!G7,"") | H7: =IF(Bevetel!H7<>0,Bevetel!H7,"") | I7: =Bevetel!I7 -> 0 | J7: =Bevetel!J7 | K7: =Bevetel!K7 | L7: =Bevetel!L7 | Q7: =VLOOKUP(G7,Keszlet!$C$5:$E$205,3,FALSE) -> 0 | T7: =IF(OR(E7<>0,COUNTIF(T2:T6,0)=5,F7<>"",SUM(L7:L27)=0),E7&F7,0) -> 0 | U7: =IF(F7<>"",F7,U6) -> 0 | W7: =IF(E7<>0,E7,W6) -> 0 | X7: =IF(G7=q,W7,$X$1) -> 55153 | Y7: =RANK(X7,$X$6:$X$10000,1) -> 996 | Z7: =IF(COUNTIF($Y$6:Y7,Y7)=1,Y7,Y7+COUNTIF($Y$5:Y6,Y7)) -> 997 | AD7: =IF(AND(C6<>C7,SUM(L7:L27)<>0,$B$4=YEAR(W7)),C7,"") | BA7: =IF(W7<=Leltar_iv!$Y$1,I7,0) -> 0
A8: =IF(COUNTIF($Y$6:Y8,Y8)=1,Y8,Y8+COUNTIF($Y$5:Y7,Y8)) -> 998 | B8: =IF(AND(Kisero_iv!$N$2=C8,Kisero_iv!$K$5=$B$2,SUM(I8:L12)<>0,$B$4=YEAR(W8)),B7+1,0) -> 0 | C8: =IF(YEAR(W7)<>YEAR(W8),1,IF(Bevetel!T8<>0,C7+1,C7)) -> 3 | D8: =Bevetel!D8 | E8: =Bevetel!E8 -> 0 | F8: =IF(Bevetel!F8<>0,Bevetel!F8,"") | G8: =IF(Bevetel!G8<>0,Bevetel!G8,"") | H8: =IF(Bevetel!H8<>0,Bevetel!H8,"") | I8: =Bevetel!I8 -> 0 | J8: =Bevetel!J8 | K8: =Bevetel!K8 | L8: =Bevetel!L8 | Q8: =VLOOKUP(G8,Keszlet!$C$5:$E$205,3,FALSE) -> 0 | T8: =IF(OR(E8<>0,COUNTIF(T3:T7,0)=5,F8<>"",SUM(L8:L28)=0),E8&F8,0) -> 0 | U8: =IF(F8<>"",F8,U7) -> 0 | W8: =IF(E8<>0,E8,W7) -> 0 | X8: =IF(G8=q,W8,$X$1) -> 55153 | Y8: =RANK(X8,$X$6:$X$10000,1) -> 996 | Z8: =IF(COUNTIF($Y$6:Y8,Y8)=1,Y8,Y8+COUNTIF($Y$5:Y7,Y8)) -> 998 | AD8: =IF(AND(C7<>C8,SUM(L8:L28)<>0,$B$4=YEAR(W8)),C8,"") | BA8: =IF(W8<=Leltar_iv!$Y$1,I8,0) -> 0
A9: =IF(COUNTIF($Y$6:Y9,Y9)=1,Y9,Y9+COUNTIF($Y$5:Y8,Y9)) -> 999 | B9: =IF(AND(Kisero_iv!$N$2=C9,Kisero_iv!$K$5=$B$2,SUM(I9:L13)<>0,$B$4=YEAR(W9)),B8+1,0) -> 0 | C9: =IF(YEAR(W8)<>YEAR(W9),1,IF(Bevetel!T9<>0,C8+1,C8)) -> 4 | D9: =Bevetel!D9 | E9: =Bevetel!E9 -> 0 | F9: =IF(Bevetel!F9<>0,Bevetel!F9,"") | G9: =IF(Bevetel!G9<>0,Bevetel!G9,"") | H9: =IF(Bevetel!H9<>0,Bevetel!H9,"") | I9: =Bevetel!I9 -> 0 | J9: =Bevetel!J9 | K9: =Bevetel!K9 | L9: =Bevetel!L9 | Q9: =VLOOKUP(G9,Keszlet!$C$5:$E$205,3,FALSE) -> 0 | T9: =IF(OR(E9<>0,COUNTIF(T4:T8,0)=5,F9<>"",SUM(L9:L29)=0),E9&F9,0) -> 0 | U9: =IF(F9<>"",F9,U8) -> 0 | W9: =IF(E9<>0,E9,W8) -> 0 | X9: =IF(G9=q,W9,$X$1) -> 55153 | Y9: =RANK(X9,$X$6:$X$10000,1) -> 996 | Z9: =IF(COUNTIF($Y$6:Y9,Y9)=1,Y9,Y9+COUNTIF($Y$5:Y8,Y9)) -> 999 | AD9: =IF(AND(C8<>C9,SUM(L9:L29)<>0,$B$4=YEAR(W9)),C9,"") | BA9: =IF(W9<=Leltar_iv!$Y$1,I9,0) -> 0
A10: =IF(COUNTIF($Y$6:Y10,Y10)=1,Y10,Y10+COUNTIF($Y$5:Y9,Y10)) -> 1000 | B10: =IF(AND(Kisero_iv!$N$2=C10,Kisero_iv!$K$5=$B$2,SUM(I10:L14)<>0,$B$4=YEAR(W10)),B9+1,0) -> 0 | C10: =IF(YEAR(W9)<>YEAR(W10),1,IF(Bevetel!T10<>0,C9+1,C9)) -> 5 | D10: =Bevetel!D10 | E10: =Bevetel!E10 -> 0 | F10: =IF(Bevetel!F10<>0,Bevetel!F10,"") | G10: =IF(Bevetel!G10<>0,Bevetel!G10,"") | H10: =IF(Bevetel!H10<>0,Bevetel!H10,"") | I10: =Bevetel!I10 -> 0 | J10: =Bevetel!J10 | K10: =Bevetel!K10 | L10: =Bevetel!L10 | Q10: =VLOOKUP(G10,Keszlet!$C$5:$E$205,3,FALSE) -> 0 | T10: =IF(OR(E10<>0,COUNTIF(T5:T9,0)=5,F10<>"",SUM(L10:L30)=0),E10&F10,0) -> 0 | U10: =IF(F10<>"",F10,U9) -> 0 | W10: =IF(E10<>0,E10,W9) -> 0 | X10: =IF(G10=q,W10,$X$1) -> 55153 | Y10: =RANK(X10,$X$6:$X$10000,1) -> 996 | Z10: =IF(COUNTIF($Y$6:Y10,Y10)=1,Y10,Y10+COUNTIF($Y$5:Y9,Y10)) -> 1000 | AD10: =IF(AND(C9<>C10,SUM(L10:L30)<>0,$B$4=YEAR(W10)),C10,"") | BA10: =IF(W10<=Leltar_iv!$Y$1,I10,0) -> 0
A11: =IF(COUNTIF($Y$6:Y11,Y11)=1,Y11,Y11+COUNTIF($Y$5:Y10,Y11)) -> 1001 | B11: =IF(AND(Kisero_iv!$N$2=C11,Kisero_iv!$K$5=$B$2,SUM(I11:L15)<>0,$B$4=YEAR(W11)),B10+1,0) -> 0 | C11: =IF(YEAR(W10)<>YEAR(W11),1,IF(Bevetel!T11<>0,C10+1,C10)) -> 6 | D11: =Bevetel!D11 | E11: =Bevetel!E11 -> 0 | F11: =IF(Bevetel!F11<>0,Bevetel!F11,"") | G11: =IF(Bevetel!G11<>0,Bevetel!G11,"") | H11: =IF(Bevetel!H11<>0,Bevetel!H11,"") | I11: =Bevetel!I11 -> 0 | J11: =Bevetel!J11 | K11: =Bevetel!K11 | L11: =Bevetel!L11 | Q11: =VLOOKUP(G11,Keszlet!$C$5:$E$205,3,FALSE) -> 0 | T11: =IF(OR(E11<>0,COUNTIF(T6:T10,0)=5,F11<>"",SUM(L11:L31)=0),E11&F11,0) -> 0 | U11: =IF(F11<>"",F11,U10) -> 0 | W11: =IF(E11<>0,E11,W10) -> 0 | X11: =IF(G11=q,W11,$X$1) -> 55153 | Y11: =RANK(X11,$X$6:$X$10000,1) -> 996 | Z11: =IF(COUNTIF($Y$6:Y11,Y11)=1,Y11,Y11+COUNTIF($Y$5:Y10,Y11)) -> 1001 | AD11: =IF(AND(C10<>C11,SUM(L11:L31)<>0,$B$4=YEAR(W11)),C11,"") | BA11: =IF(W11<=Leltar_iv!$Y$1,I11,0) -> 0
A12: =IF(COUNTIF($Y$6:Y12,Y12)=1,Y12,Y12+COUNTIF($Y$5:Y11,Y12)) -> 1002 | B12: =IF(AND(Kisero_iv!$N$2=C12,Kisero_iv!$K$5=$B$2,SUM(I12:L16)<>0,$B$4=YEAR(W12)),B11+1,0) -> 0 | C12: =IF(YEAR(W11)<>YEAR(W12),1,IF(Bevetel!T12<>0,C11+1,C11)) -> 7 | D12: =Bevetel!D12 | E12: =Bevetel!E12 -> 0 | F12: =IF(Bevetel!F12<>0,Bevetel!F12,"") | G12: =IF(Bevetel!G12<>0,Bevetel!G12,"") | H12: =IF(Bevetel!H12<>0,Bevetel!H12,"") | I12: =Bevetel!I12 -> 0 | J12: =Bevetel!J12 | K12: =Bevetel!K12 | L12: =Bevetel!L12 | Q12: =VLOOKUP(G12,Keszlet!$C$5:$E$205,3,FALSE) -> 0 | T12: =IF(OR(E12<>0,COUNTIF(T7:T11,0)=5,F12<>"",SUM(L12:L32)=0),E12&F12,0) -> 0 | U12: =IF(F12<>"",F12,U11) -> 0 | W12: =IF(E12<>0,E12,W11) -> 0 | X12: =IF(G12=q,W12,$X$1) -> 55153 | Y12: =RANK(X12,$X$6:$X$10000,1) -> 996 | Z12: =IF(COUNTIF($Y$6:Y12,Y12)=1,Y12,Y12+COUNTIF($Y$5:Y11,Y12)) -> 1002 | AD12: =IF(AND(C11<>C12,SUM(L12:L32)<>0,$B$4=YEAR(W12)),C12,"") | BA12: =IF(W12<=Leltar_iv!$Y$1,I12,0) -> 0
A13: =IF(COUNTIF($Y$6:Y13,Y13)=1,Y13,Y13+COUNTIF($Y$5:Y12,Y13)) -> 1003 | B13: =IF(AND(Kisero_iv!$N$2=C13,Kisero_iv!$K$5=$B$2,SUM(I13:L17)<>0,$B$4=YEAR(W13)),B12+1,0) -> 0 | C13: =IF(YEAR(W12)<>YEAR(W13),1,IF(Bevetel!T13<>0,C12+1,C12)) -> 8 | D13: =Bevetel!D13 | E13: =Bevetel!E13 -> 0 | F13: =IF(Bevetel!F13<>0,Bevetel!F13,"") | G13: =IF(Bevetel!G13<>0,Bevetel!G13,"") | H13: =IF(Bevetel!H13<>0,Bevetel!H13,"") | I13: =Bevetel!I13 -> 0 | J13: =Bevetel!J13 | K13: =Bevetel!K13 | L13: =Bevetel!L13 | Q13: =VLOOKUP(G13,Keszlet!$C$5:$E$205,3,FALSE) -> 0 | T13: =IF(OR(E13<>0,COUNTIF(T8:T12,0)=5,F13<>"",SUM(L13:L33)=0),E13&F13,0) -> 0 | U13: =IF(F13<>"",F13,U12) -> 0 | W13: =IF(E13<>0,E13,W12) -> 0 | X13: =IF(G13=q,W13,$X$1) -> 55153 | Y13: =RANK(X13,$X$6:$X$10000,1) -> 996 | Z13: =IF(COUNTIF($Y$6:Y13,Y13)=1,Y13,Y13+COUNTIF($Y$5:Y12,Y13)) -> 1003 | AD13: =IF(AND(C12<>C13,SUM(L13:L33)<>0,$B$4=YEAR(W13)),C13,"") | BA13: =IF(W13<=Leltar_iv!$Y$1,I13,0) -> 0
A14: =IF(COUNTIF($Y$6:Y14,Y14)=1,Y14,Y14+COUNTIF($Y$5:Y13,Y14)) -> 1004 | B14: =IF(AND(Kisero_iv!$N$2=C14,Kisero_iv!$K$5=$B$2,SUM(I14:L18)<>0,$B$4=YEAR(W14)),B13+1,0) -> 0 | C14: =IF(YEAR(W13)<>YEAR(W14),1,IF(Bevetel!T14<>0,C13+1,C13)) -> 9 | D14: =Bevetel!D14 | E14: =Bevetel!E14 -> 0 | F14: =IF(Bevetel!F14<>0,Bevetel!F14,"") | G14: =IF(Bevetel!G14<>0,Bevetel!G14,"") | H14: =IF(Bevetel!H14<>0,Bevetel!H14,"") | I14: =Bevetel!I14 -> 0 | J14: =Bevetel!J14 | K14: =Bevetel!K14 | L14: =Bevetel!L14 | Q14: =VLOOKUP(G14,Keszlet!$C$5:$E$205,3,FALSE) -> 0 | T14: =IF(OR(E14<>0,COUNTIF(T9:T13,0)=5,F14<>"",SUM(L14:L34)=0),E14&F14,0) -> 0 | U14: =IF(F14<>"",F14,U13) -> 0 | W14: =IF(E14<>0,E14,W13) -> 0 | X14: =IF(G14=q,W14,$X$1) -> 55153 | Y14: =RANK(X14,$X$6:$X$10000,1) -> 996 | Z14: =IF(COUNTIF($Y$6:Y14,Y14)=1,Y14,Y14+COUNTIF($Y$5:Y13,Y14)) -> 1004 | AD14: =IF(AND(C13<>C14,SUM(L14:L34)<>0,$B$4=YEAR(W14)),C14,"") | BA14: =IF(W14<=Leltar_iv!$Y$1,I14,0) -> 0
A15: =IF(COUNTIF($Y$6:Y15,Y15)=1,Y15,Y15+COUNTIF($Y$5:Y14,Y15)) -> 1005 | B15: =IF(AND(Kisero_iv!$N$2=C15,Kisero_iv!$K$5=$B$2,SUM(I15:L19)<>0,$B$4=YEAR(W15)),B14+1,0) -> 0 | C15: =IF(YEAR(W14)<>YEAR(W15),1,IF(Bevetel!T15<>0,C14+1,C14)) -> 10 | D15: =Bevetel!D15 | E15: =Bevetel!E15 -> 0 | F15: =IF(Bevetel!F15<>0,Bevetel!F15,"") | G15: =IF(Bevetel!G15<>0,Bevetel!G15,"") | H15: =IF(Bevetel!H15<>0,Bevetel!H15,"") | I15: =Bevetel!I15 -> 0 | J15: =Bevetel!J15 | K15: =Bevetel!K15 | L15: =Bevetel!L15 | Q15: =VLOOKUP(G15,Keszlet!$C$5:$E$205,3,FALSE) -> 0 | T15: =IF(OR(E15<>0,COUNTIF(T10:T14,0)=5,F15<>"",SUM(L15:L35)=0),E15&F15,0) -> 0 | U15: =IF(F15<>"",F15,U14) -> 0 | W15: =IF(E15<>0,E15,W14) -> 0 | X15: =IF(G15=q,W15,$X$1) -> 55153 | Y15: =RANK(X15,$X$6:$X$10000,1) -> 996 | Z15: =IF(COUNTIF($Y$6:Y15,Y15)=1,Y15,Y15+COUNTIF($Y$5:Y14,Y15)) -> 1005 | AD15: =IF(AND(C14<>C15,SUM(L15:L35)<>0,$B$4=YEAR(W15)),C15,"") | BA15: =IF(W15<=Leltar_iv!$Y$1,I15,0) -> 0
A16: =IF(COUNTIF($Y$6:Y16,Y16)=1,Y16,Y16+COUNTIF($Y$5:Y15,Y16)) -> 1006 | B16: =IF(AND(Kisero_iv!$N$2=C16,Kisero_iv!$K$5=$B$2,SUM(I16:L20)<>0,$B$4=YEAR(W16)),B15+1,0) -> 0 | C16: =IF(YEAR(W15)<>YEAR(W16),1,IF(Bevetel!T16<>0,C15+1,C15)) -> 11 | D16: =Bevetel!D16 | E16: =Bevetel!E16 -> 0 | F16: =IF(Bevetel!F16<>0,Bevetel!F16,"") | G16: =IF(Bevetel!G16<>0,Bevetel!G16,"") | H16: =IF(Bevetel!H16<>0,Bevetel!H16,"") | I16: =Bevetel!I16 -> 0 | J16: =Bevetel!J16 | K16: =Bevetel!K16 | L16: =Bevetel!L16 | Q16: =VLOOKUP(G16,Keszlet!$C$5:$E$205,3,FALSE) -> 0 | T16: =IF(OR(E16<>0,COUNTIF(T11:T15,0)=5,F16<>"",SUM(L16:L36)=0),E16&F16,0) -> 0 | U16: =IF(F16<>"",F16,U15) -> 0 | W16: =IF(E16<>0,E16,W15) -> 0 | X16: =IF(G16=q,W16,$X$1) -> 55153 | Y16: =RANK(X16,$X$6:$X$10000,1) -> 996 | Z16: =IF(COUNTIF($Y$6:Y16,Y16)=1,Y16,Y16+COUNTIF($Y$5:Y15,Y16)) -> 1006 | AD16: =IF(AND(C15<>C16,SUM(L16:L36)<>0,$B$4=YEAR(W16)),C16,"") | BA16: =IF(W16<=Leltar_iv!$Y$1,I16,0) -> 0
A17: =IF(COUNTIF($Y$6:Y17,Y17)=1,Y17,Y17+COUNTIF($Y$5:Y16,Y17)) -> 1007 | B17: =IF(AND(Kisero_iv!$N$2=C17,Kisero_iv!$K$5=$B$2,SUM(I17:L21)<>0,$B$4=YEAR(W17)),B16+1,0) -> 0 | C17: =IF(YEAR(W16)<>YEAR(W17),1,IF(Bevetel!T17<>0,C16+1,C16)) -> 12 | D17: =Bevetel!D17 | E17: =Bevetel!E17 -> 0 | F17: =IF(Bevetel!F17<>0,Bevetel!F17,"") | G17: =IF(Bevetel!G17<>0,Bevetel!G17,"") | H17: =IF(Bevetel!H17<>0,Bevetel!H17,"") | I17: =Bevetel!I17 -> 0 | J17: =Bevetel!J17 | K17: =Bevetel!K17 | L17: =Bevetel!L17 | Q17: =VLOOKUP(G17,Keszlet!$C$5:$E$205,3,FALSE) -> 0 | T17: =IF(OR(E17<>0,COUNTIF(T12:T16,0)=5,F17<>"",SUM(L17:L37)=0),E17&F17,0) -> 0 | U17: =IF(F17<>"",F17,U16) -> 0 | W17: =IF(E17<>0,E17,W16) -> 0 | X17: =IF(G17=q,W17,$X$1) -> 55153 | Y17: =RANK(X17,$X$6:$X$10000,1) -> 996 | Z17: =IF(COUNTIF($Y$6:Y17,Y17)=1,Y17,Y17+COUNTIF($Y$5:Y16,Y17)) -> 1007 | AD17: =IF(AND(C16<>C17,SUM(L17:L37)<>0,$B$4=YEAR(W17)),C17,"") | BA17: =IF(W17<=Leltar_iv!$Y$1,I17,0) -> 0
... A199: =IF(COUNTIF($Y$6:Y199,Y199)=1,Y199,Y199+COUNTIF($Y$5:Y198,Y199)) -> 1189 | B199: =IF(AND(Kisero_iv!$N$2=C199,Kisero_iv!$K$5=$B$2,SUM(I199:L203)<>0,$B$4=YEAR(W199)),B198+1,0) -> 0 | C199: =IF(YEAR(W198)<>YEAR(W199),1,IF(Bevetel!T199<>0,C198+1,C198)) -> 194 | D199: =Bevetel!D199 | E199: =Bevetel!E199 -> 0 | F199: =IF(Bevetel!F199<>0,Bevetel!F199,"") | G199: =IF(Bevetel!G199<>0,Bevetel!G199,"") | H199: =IF(Bevetel!H199<>0,Bevetel!H199,"") | I199: =Bevetel!I199 -> 0 | J199: =Bevetel!J199 | K199: =Bevetel!K199 | L199: =Bevetel!L199 | Q199: =VLOOKUP(G199,Keszlet!$C$5:$E$205,3,FALSE) -> 0 | T199: =IF(OR(E199<>0,COUNTIF(T194:T198,0)=5,F199<>"",SUM(L199:L219)=0),E199&F199,0) -> 0 | U199: =IF(F199<>"",F199,U198) -> 0 | W199: =IF(E199<>0,E199,W198) -> 0 | X199: =IF(G199=q,W199,$X$1) -> 55153 | Y199: =RANK(X199,$X$6:$X$10000,1) -> 996 | Z199: =IF(COUNTIF($Y$6:Y199,Y199)=1,Y199,Y199+COUNTIF($Y$5:Y198,Y199)) -> 1189 | AD199: =IF(AND(C198<>C199,SUM(L199:L219)<>0,$B$4=YEAR(W199)),C199,"") | BA199: =IF(W199<=Leltar_iv!$Y$1,I199,0) -> 0
A200: =IF(COUNTIF($Y$6:Y200,Y200)=1,Y200,Y200+COUNTIF($Y$5:Y199,Y200)) -> 1190 | B200: =IF(AND(Kisero_iv!$N$2=C200,Kisero_iv!$K$5=$B$2,SUM(I200:L204)<>0,$B$4=YEAR(W200)),B199+1,0) -> 0 | C200: =IF(YEAR(W199)<>YEAR(W200),1,IF(Bevetel!T200<>0,C199+1,C199)) -> 195 | D200: =Bevetel!D200 | E200: =Bevetel!E200 -> 0 | F200: =IF(Bevetel!F200<>0,Bevetel!F200,"") | G200: =IF(Bevetel!G200<>0,Bevetel!G200,"") | H200: =IF(Bevetel!H200<>0,Bevetel!H200,"") | I200: =Bevetel!I200 -> 0 | J200: =Bevetel!J200 | K200: =Bevetel!K200 | L200: =Bevetel!L200 | Q200: =VLOOKUP(G200,Keszlet!$C$5:$E$205,3,FALSE) -> 0 | T200: =IF(OR(E200<>0,COUNTIF(T195:T199,0)=5,F200<>"",SUM(L200:L220)=0),E200&F200,0) -> 0 | U200: =IF(F200<>"",F200,U199) -> 0 | W200: =IF(E200<>0,E200,W199) -> 0 | X200: =IF(G200=q,W200,$X$1) -> 55153 | Y200: =RANK(X200,$X$6:$X$10000,1) -> 996 | Z200: =IF(COUNTIF($Y$6:Y200,Y200)=1,Y200,Y200+COUNTIF($Y$5:Y199,Y200)) -> 1190 | AD200: =IF(AND(C199<>C200,SUM(L200:L220)<>0,$B$4=YEAR(W200)),C200,"")
C1004: =IF(T1004<>0,C1003+1,C1003) -> 0 | E1004: ANYAGRAKTÁR - KIADÁS
D1005: Iratszám | E1005: Dátum | F1005: Kinek adtuk ki | G1005: Anyag megnevezése | H1005: Megjegyzés | I1005: Mennyiség | J1005: M.egység | K1005: Egységár | L1005: Érték | M1005: Készlet
A1006: =IF(COUNTIF($Y$6:Y1006,Y1006)=1,Y1006,Y1006+COUNTIF($Y$5:Y1005,Y1006)) -> 1 | B1006: =IF(AND(Kisero_iv!$N$2=C1006,Kisero_iv!$K$5=$B$3,SUM(I1006:L1010)<>0,$B$4=YEAR(W1006)),B1005+1,0) -> 0 | C1006: =IF(YEAR(W1005)<>YEAR(W1006),1,IF(T1006<>0,C1005+1,C1005)) -> 1 | D1006: =IF(AND(OR(C1005<>C1006,C1006=1),SUM(L1006:L1026)<>0),YEAR(W1006)&"/"&C1006,"") | J1006: =IF(AND(G1006<>"",ISERROR(VLOOKUP(G1006,Keszlet!$C$5:$H$200,6,FALSE))=FALSE),VLOOKUP(G1006,Keszlet!$C$5:$H$200,6,FALSE),"") | K1006: =IF(AND(G1006<>"",ISERROR(VLOOKUP(G1006,Keszlet!$C$5:$G$200,5,FALSE))=FALSE),VLOOKUP(G1006,Keszlet!$C$5:$G$200,5,FALSE),"") | L1006: =IF(AND(G1006<>0,K1006<>""),I1006*K1006,"") | M1006: =IF(ISERROR(VLOOKUP(G1006,Keszlet!$C$5:$I$200,7,FALSE))=TRUE,"",IF(AND(J1005<>"",J1007=""),VLOOKUP(G1006,Keszlet!$C$5:$I$200,7,FALSE),"")) | Q1006: =VLOOKUP(G1006,Keszlet!$C$5:$E$205,3,FALSE) -> 0 | T1006: =IF(OR(E1006<>0,COUNTIF(T997:T1005,0)=9,F1006<>0,SUM(L1006:L1026)=0),E1006&F1006,0) | U1006: =IF(F1006<>"",F1006,U1005) -> 0 | W1006: =IF(E1006<>0,E1006,W1005) -> 0 | X1006: =IF(G1006=q,W1006,$X$1) -> 0 | Y1006: =RANK(X1006,$X$6:$X$10000,1) -> 1 | Z1006: =IF(COUNTIF($Y$6:Y1006,Y1006)=1,Y1006,Y1006+COUNTIF($Y$5:Y1005,Y1006)) -> 1 | AD1006: =IF(AND(OR(C1005<>C1006,YEAR(W1006)<>YEAR(W1005)),SUM(L1006:L1026)<>0,$B$4=YEAR(W1006)),C1006,"") | BA1006: =IF(W1006<=Leltar_iv!$Y$1,I1006,0) -> 0
A1007: =IF(COUNTIF($Y$6:Y1007,Y1007)=1,Y1007,Y1007+COUNTIF($Y$5:Y1006,Y1007)) -> 2 | B1007: =IF(AND(Kisero_iv!$N$2=C1007,Kisero_iv!$K$5=$B$3,SUM(I1007:L1011)<>0,$B$4=YEAR(W1007)),B1006+1,0) -> 0 | C1007: =IF(YEAR(W1006)<>YEAR(W1007),1,IF(T1007<>0,C1006+1,C1006)) -> 2 | D1007: =IF(AND(OR(C1006<>C1007,C1007=1),SUM(L1007:L1027)<>0),YEAR(W1007)&"/"&C1007,"") | J1007: =IF(AND(G1007<>"",ISERROR(VLOOKUP(G1007,Keszlet!$C$5:$H$200,6,FALSE))=FALSE),VLOOKUP(G1007,Keszlet!$C$5:$H$200,6,FALSE),"") | K1007: =IF(AND(G1007<>"",ISERROR(VLOOKUP(G1007,Keszlet!$C$5:$G$200,5,FALSE))=FALSE),VLOOKUP(G1007,Keszlet!$C$5:$G$200,5,FALSE),"") | L1007: =IF(AND(G1007<>0,K1007<>""),I1007*K1007,"") | M1007: =IF(ISERROR(VLOOKUP(G1007,Keszlet!$C$5:$I$200,7,FALSE))=TRUE,"",IF(AND(J1006<>"",J1008=""),VLOOKUP(G1007,Keszlet!$C$5:$I$200,7,FALSE),"")) | Q1007: =VLOOKUP(G1007,Keszlet!$C$5:$E$205,3,FALSE) -> 0 | T1007: =IF(OR(E1007<>0,COUNTIF(T998:T1006,0)=9,F1007<>0,SUM(L1007:L1027)=0),E1007&F1007,0) | U1007: =IF(F1007<>"",F1007,U1006) -> 0 | W1007: =IF(E1007<>0,E1007,W1006) -> 0 | X1007: =IF(G1007=q,W1007,$X$1) -> 0 | Y1007: =RANK(X1007,$X$6:$X$10000,1) -> 1 | Z1007: =IF(COUNTIF($Y$6:Y1007,Y1007)=1,Y1007,Y1007+COUNTIF($Y$5:Y1006,Y1007)) -> 2 | AD1007: =IF(AND(OR(C1006<>C1007,YEAR(W1007)<>YEAR(W1006)),SUM(L1007:L1027)<>0,$B$4=YEAR(W1007)),C1007,"") | BA1007: =IF(W1007<=Leltar_iv!$Y$1,I1007,0) -> 0
A1008: =IF(COUNTIF($Y$6:Y1008,Y1008)=1,Y1008,Y1008+COUNTIF($Y$5:Y1007,Y1008)) -> 3 | B1008: =IF(AND(Kisero_iv!$N$2=C1008,Kisero_iv!$K$5=$B$3,SUM(I1008:L1012)<>0,$B$4=YEAR(W1008)),B1007+1,0) -> 0 | C1008: =IF(YEAR(W1007)<>YEAR(W1008),1,IF(T1008<>0,C1007+1,C1007)) -> 3 | D1008: =IF(AND(OR(C1007<>C1008,C1008=1),SUM(L1008:L1028)<>0),YEAR(W1008)&"/"&C1008,"") | J1008: =IF(AND(G1008<>"",ISERROR(VLOOKUP(G1008,Keszlet!$C$5:$H$200,6,FALSE))=FALSE),VLOOKUP(G1008,Keszlet!$C$5:$H$200,6,FALSE),"") | K1008: =IF(AND(G1008<>"",ISERROR(VLOOKUP(G1008,Keszlet!$C$5:$G$200,5,FALSE))=FALSE),VLOOKUP(G1008,Keszlet!$C$5:$G$200,5,FALSE),"") | L1008: =IF(AND(G1008<>0,K1008<>""),I1008*K1008,"") | M1008: =IF(ISERROR(VLOOKUP(G1008,Keszlet!$C$5:$I$200,7,FALSE))=TRUE,"",IF(AND(J1007<>"",J1009=""),VLOOKUP(G1008,Keszlet!$C$5:$I$200,7,FALSE),"")) | Q1008: =VLOOKUP(G1008,Keszlet!$C$5:$E$205,3,FALSE) -> 0 | T1008: =IF(OR(E1008<>0,COUNTIF(T999:T1007,0)=9,F1008<>0,SUM(L1008:L1028)=0),E1008&F1008,0) | U1008: =IF(F1008<>"",F1008,U1007) -> 0 | W1008: =IF(E1008<>0,E1008,W1007) -> 0 | X1008: =IF(G1008=q,W1008,$X$1) -> 0 | Y1008: =RANK(X1008,$X$6:$X$10000,1) -> 1 | Z1008: =IF(COUNTIF($Y$6:Y1008,Y1008)=1,Y1008,Y1008+COUNTIF($Y$5:Y1007,Y1008)) -> 3 | AD1008: =IF(AND(OR(C1007<>C1008,YEAR(W1008)<>YEAR(W1007)),SUM(L1008:L1028)<>0,$B$4=YEAR(W1008)),C1008,"") | BA1008: =IF(W1008<=Leltar_iv!$Y$1,I1008,0) -> 0
A1009: =IF(COUNTIF($Y$6:Y1009,Y1009)=1,Y1009,Y1009+COUNTIF($Y$5:Y1008,Y1009)) -> 4 | B1009: =IF(AND(Kisero_iv!$N$2=C1009,Kisero_iv!$K$5=$B$3,SUM(I1009:L1013)<>0,$B$4=YEAR(W1009)),B1008+1,0) -> 0 | C1009: =IF(YEAR(W1008)<>YEAR(W1009),1,IF(T1009<>0,C1008+1,C1008)) -> 4 | D1009: =IF(AND(OR(C1008<>C1009,C1009=1),SUM(L1009:L1029)<>0),YEAR(W1009)&"/"&C1009,"") | J1009: =IF(AND(G1009<>"",ISERROR(VLOOKUP(G1009,Keszlet!$C$5:$H$200,6,FALSE))=FALSE),VLOOKUP(G1009,Keszlet!$C$5:$H$200,6,FALSE),"") | K1009: =IF(AND(G1009<>"",ISERROR(VLOOKUP(G1009,Keszlet!$C$5:$G$200,5,FALSE))=FALSE),VLOOKUP(G1009,Keszlet!$C$5:$G$200,5,FALSE),"") | L1009: =IF(AND(G1009<>0,K1009<>""),I1009*K1009,"") | M1009: =IF(ISERROR(VLOOKUP(G1009,Keszlet!$C$5:$I$200,7,FALSE))=TRUE,"",IF(AND(J1008<>"",J1010=""),VLOOKUP(G1009,Keszlet!$C$5:$I$200,7,FALSE),"")) | Q1009: =VLOOKUP(G1009,Keszlet!$C$5:$E$205,3,FALSE) -> 0 | T1009: =IF(OR(E1009<>0,COUNTIF(T1000:T1008,0)=9,F1009<>0,SUM(L1009:L1029)=0),E1009&F1009,0) | U1009: =IF(F1009<>"",F1009,U1008) -> 0 | W1009: =IF(E1009<>0,E1009,W1008) -> 0 | X1009: =IF(G1009=q,W1009,$X$1) -> 0 | Y1009: =RANK(X1009,$X$6:$X$10000,1) -> 1 | Z1009: =IF(COUNTIF($Y$6:Y1009,Y1009)=1,Y1009,Y1009+COUNTIF($Y$5:Y1008,Y1009)) -> 4 | AD1009: =IF(AND(OR(C1008<>C1009,YEAR(W1009)<>YEAR(W1008)),SUM(L1009:L1029)<>0,$B$4=YEAR(W1009)),C1009,"") | BA1009: =IF(W1009<=Leltar_iv!$Y$1,I1009,0) -> 0
A1010: =IF(COUNTIF($Y$6:Y1010,Y1010)=1,Y1010,Y1010+COUNTIF($Y$5:Y1009,Y1010)) -> 5 | B1010: =IF(AND(Kisero_iv!$N$2=C1010,Kisero_iv!$K$5=$B$3,SUM(I1010:L1014)<>0,$B$4=YEAR(W1010)),B1009+1,0) -> 0 | C1010: =IF(YEAR(W1009)<>YEAR(W1010),1,IF(T1010<>0,C1009+1,C1009)) -> 5 | D1010: =IF(AND(OR(C1009<>C1010,C1010=1),SUM(L1010:L1030)<>0),YEAR(W1010)&"/"&C1010,"") | J1010: =IF(AND(G1010<>"",ISERROR(VLOOKUP(G1010,Keszlet!$C$5:$H$200,6,FALSE))=FALSE),VLOOKUP(G1010,Keszlet!$C$5:$H$200,6,FALSE),"") | K1010: =IF(AND(G1010<>"",ISERROR(VLOOKUP(G1010,Keszlet!$C$5:$G$200,5,FALSE))=FALSE),VLOOKUP(G1010,Keszlet!$C$5:$G$200,5,FALSE),"") | L1010: =IF(AND(G1010<>0,K1010<>""),I1010*K1010,"") | M1010: =IF(ISERROR(VLOOKUP(G1010,Keszlet!$C$5:$I$200,7,FALSE))=TRUE,"",IF(AND(J1009<>"",J1011=""),VLOOKUP(G1010,Keszlet!$C$5:$I$200,7,FALSE),"")) | Q1010: =VLOOKUP(G1010,Keszlet!$C$5:$E$205,3,FALSE) -> 0 | T1010: =IF(OR(E1010<>0,COUNTIF(T1001:T1009,0)=9,F1010<>0,SUM(L1010:L1030)=0),E1010&F1010,0) | U1010: =IF(F1010<>"",F1010,U1009) -> 0 | W1010: =IF(E1010<>0,E1010,W1009) -> 0 | X1010: =IF(G1010=q,W1010,$X$1) -> 0 | Y1010: =RANK(X1010,$X$6:$X$10000,1) -> 1 | Z1010: =IF(COUNTIF($Y$6:Y1010,Y1010)=1,Y1010,Y1010+COUNTIF($Y$5:Y1009,Y1010)) -> 5 | AD1010: =IF(AND(OR(C1009<>C1010,YEAR(W1010)<>YEAR(W1009)),SUM(L1010:L1030)<>0,$B$4=YEAR(W1010)),C1010,"") | BA1010: =IF(W1010<=Leltar_iv!$Y$1,I1010,0) -> 0
A1011: =IF(COUNTIF($Y$6:Y1011,Y1011)=1,Y1011,Y1011+COUNTIF($Y$5:Y1010,Y1011)) -> 6 | B1011: =IF(AND(Kisero_iv!$N$2=C1011,Kisero_iv!$K$5=$B$3,SUM(I1011:L1015)<>0,$B$4=YEAR(W1011)),B1010+1,0) -> 0 | C1011: =IF(YEAR(W1010)<>YEAR(W1011),1,IF(T1011<>0,C1010+1,C1010)) -> 6 | D1011: =IF(AND(OR(C1010<>C1011,C1011=1),SUM(L1011:L1031)<>0),YEAR(W1011)&"/"&C1011,"") | J1011: =IF(AND(G1011<>"",ISERROR(VLOOKUP(G1011,Keszlet!$C$5:$H$200,6,FALSE))=FALSE),VLOOKUP(G1011,Keszlet!$C$5:$H$200,6,FALSE),"") | K1011: =IF(AND(G1011<>"",ISERROR(VLOOKUP(G1011,Keszlet!$C$5:$G$200,5,FALSE))=FALSE),VLOOKUP(G1011,Keszlet!$C$5:$G$200,5,FALSE),"") | L1011: =IF(AND(G1011<>0,K1011<>""),I1011*K1011,"") | M1011: =IF(ISERROR(VLOOKUP(G1011,Keszlet!$C$5:$I$200,7,FALSE))=TRUE,"",IF(AND(J1010<>"",J1012=""),VLOOKUP(G1011,Keszlet!$C$5:$I$200,7,FALSE),"")) | Q1011: =VLOOKUP(G1011,Keszlet!$C$5:$E$205,3,FALSE) -> 0 | T1011: =IF(OR(E1011<>0,COUNTIF(T1002:T1010,0)=9,F1011<>0,SUM(L1011:L1031)=0),E1011&F1011,0) | U1011: =IF(F1011<>"",F1011,U1010) -> 0 | W1011: =IF(E1011<>0,E1011,W1010) -> 0 | X1011: =IF(G1011=q,W1011,$X$1) -> 0 | Y1011: =RANK(X1011,$X$6:$X$10000,1) -> 1 | Z1011: =IF(COUNTIF($Y$6:Y1011,Y1011)=1,Y1011,Y1011+COUNTIF($Y$5:Y1010,Y1011)) -> 6 | AD1011: =IF(AND(OR(C1010<>C1011,YEAR(W1011)<>YEAR(W1010)),SUM(L1011:L1031)<>0,$B$4=YEAR(W1011)),C1011,"") | BA1011: =IF(W1011<=Leltar_iv!$Y$1,I1011,0) -> 0
A1012: =IF(COUNTIF($Y$6:Y1012,Y1012)=1,Y1012,Y1012+COUNTIF($Y$5:Y1011,Y1012)) -> 7 | B1012: =IF(AND(Kisero_iv!$N$2=C1012,Kisero_iv!$K$5=$B$3,SUM(I1012:L1016)<>0,$B$4=YEAR(W1012)),B1011+1,0) -> 0 | C1012: =IF(YEAR(W1011)<>YEAR(W1012),1,IF(T1012<>0,C1011+1,C1011)) -> 7 | D1012: =IF(AND(OR(C1011<>C1012,C1012=1),SUM(L1012:L1032)<>0),YEAR(W1012)&"/"&C1012,"") | J1012: =IF(AND(G1012<>"",ISERROR(VLOOKUP(G1012,Keszlet!$C$5:$H$200,6,FALSE))=FALSE),VLOOKUP(G1012,Keszlet!$C$5:$H$200,6,FALSE),"") | K1012: =IF(AND(G1012<>"",ISERROR(VLOOKUP(G1012,Keszlet!$C$5:$G$200,5,FALSE))=FALSE),VLOOKUP(G1012,Keszlet!$C$5:$G$200,5,FALSE),"") | L1012: =IF(AND(G1012<>0,K1012<>""),I1012*K1012,"") | M1012: =IF(ISERROR(VLOOKUP(G1012,Keszlet!$C$5:$I$200,7,FALSE))=TRUE,"",IF(AND(J1011<>"",J1013=""),VLOOKUP(G1012,Keszlet!$C$5:$I$200,7,FALSE),"")) | Q1012: =VLOOKUP(G1012,Keszlet!$C$5:$E$205,3,FALSE) -> 0 | T1012: =IF(OR(E1012<>0,COUNTIF(T1003:T1011,0)=9,F1012<>0,SUM(L1012:L1032)=0),E1012&F1012,0) | U1012: =IF(F1012<>"",F1012,U1011) -> 0 | W1012: =IF(E1012<>0,E1012,W1011) -> 0 | X1012: =IF(G1012=q,W1012,$X$1) -> 0 | Y1012: =RANK(X1012,$X$6:$X$10000,1) -> 1 | Z1012: =IF(COUNTIF($Y$6:Y1012,Y1012)=1,Y1012,Y1012+COUNTIF($Y$5:Y1011,Y1012)) -> 7 | AD1012: =IF(AND(OR(C1011<>C1012,YEAR(W1012)<>YEAR(W1011)),SUM(L1012:L1032)<>0,$B$4=YEAR(W1012)),C1012,"") | BA1012: =IF(W1012<=Leltar_iv!$Y$1,I1012,0) -> 0
A1013: =IF(COUNTIF($Y$6:Y1013,Y1013)=1,Y1013,Y1013+COUNTIF($Y$5:Y1012,Y1013)) -> 8 | B1013: =IF(AND(Kisero_iv!$N$2=C1013,Kisero_iv!$K$5=$B$3,SUM(I1013:L1017)<>0,$B$4=YEAR(W1013)),B1012+1,0) -> 0 | C1013: =IF(YEAR(W1012)<>YEAR(W1013),1,IF(T1013<>0,C1012+1,C1012)) -> 8 | D1013: =IF(AND(OR(C1012<>C1013,C1013=1),SUM(L1013:L1033)<>0),YEAR(W1013)&"/"&C1013,"") | J1013: =IF(AND(G1013<>"",ISERROR(VLOOKUP(G1013,Keszlet!$C$5:$H$200,6,FALSE))=FALSE),VLOOKUP(G1013,Keszlet!$C$5:$H$200,6,FALSE),"") | K1013: =IF(AND(G1013<>"",ISERROR(VLOOKUP(G1013,Keszlet!$C$5:$G$200,5,FALSE))=FALSE),VLOOKUP(G1013,Keszlet!$C$5:$G$200,5,FALSE),"") | L1013: =IF(AND(G1013<>0,K1013<>""),I1013*K1013,"") | M1013: =IF(ISERROR(VLOOKUP(G1013,Keszlet!$C$5:$I$200,7,FALSE))=TRUE,"",IF(AND(J1012<>"",J1014=""),VLOOKUP(G1013,Keszlet!$C$5:$I$200,7,FALSE),"")) | Q1013: =VLOOKUP(G1013,Keszlet!$C$5:$E$205,3,FALSE) -> 0 | T1013: =IF(OR(E1013<>0,COUNTIF(T1004:T1012,0)=9,F1013<>0,SUM(L1013:L1033)=0),E1013&F1013,0) | U1013: =IF(F1013<>"",F1013,U1012) -> 0 | W1013: =IF(E1013<>0,E1013,W1012) -> 0 | X1013: =IF(G1013=q,W1013,$X$1) -> 0 | Y1013: =RANK(X1013,$X$6:$X$10000,1) -> 1 | Z1013: =IF(COUNTIF($Y$6:Y1013,Y1013)=1,Y1013,Y1013+COUNTIF($Y$5:Y1012,Y1013)) -> 8 | AD1013: =IF(AND(OR(C1012<>C1013,YEAR(W1013)<>YEAR(W1012)),SUM(L1013:L1033)<>0,$B$4=YEAR(W1013)),C1013,"") | BA1013: =IF(W1013<=Leltar_iv!$Y$1,I1013,0) -> 0
A1014: =IF(COUNTIF($Y$6:Y1014,Y1014)=1,Y1014,Y1014+COUNTIF($Y$5:Y1013,Y1014)) -> 9 | B1014: =IF(AND(Kisero_iv!$N$2=C1014,Kisero_iv!$K$5=$B$3,SUM(I1014:L1018)<>0,$B$4=YEAR(W1014)),B1013+1,0) -> 0 | C1014: =IF(YEAR(W1013)<>YEAR(W1014),1,IF(T1014<>0,C1013+1,C1013)) -> 9 | D1014: =IF(AND(OR(C1013<>C1014,C1014=1),SUM(L1014:L1034)<>0),YEAR(W1014)&"/"&C1014,"") | J1014: =IF(AND(G1014<>"",ISERROR(VLOOKUP(G1014,Keszlet!$C$5:$H$200,6,FALSE))=FALSE),VLOOKUP(G1014,Keszlet!$C$5:$H$200,6,FALSE),"") | K1014: =IF(AND(G1014<>"",ISERROR(VLOOKUP(G1014,Keszlet!$C$5:$G$200,5,FALSE))=FALSE),VLOOKUP(G1014,Keszlet!$C$5:$G$200,5,FALSE),"") | L1014: =IF(AND(G1014<>0,K1014<>""),I1014*K1014,"") | M1014: =IF(ISERROR(VLOOKUP(G1014,Keszlet!$C$5:$I$200,7,FALSE))=TRUE,"",IF(AND(J1013<>"",J1015=""),VLOOKUP(G1014,Keszlet!$C$5:$I$200,7,FALSE),"")) | Q1014: =VLOOKUP(G1014,Keszlet!$C$5:$E$205,3,FALSE) -> 0 | T1014: =IF(OR(E1014<>0,COUNTIF(T1005:T1013,0)=9,F1014<>0,SUM(L1014:L1034)=0),E1014&F1014,0) | U1014: =IF(F1014<>"",F1014,U1013) -> 0 | W1014: =IF(E1014<>0,E1014,W1013) -> 0 | X1014: =IF(G1014=q,W1014,$X$1) -> 0 | Y1014: =RANK(X1014,$X$6:$X$10000,1) -> 1 | Z1014: =IF(COUNTIF($Y$6:Y1014,Y1014)=1,Y1014,Y1014+COUNTIF($Y$5:Y1013,Y1014)) -> 9 | AD1014: =IF(AND(OR(C1013<>C1014,YEAR(W1014)<>YEAR(W1013)),SUM(L1014:L1034)<>0,$B$4=YEAR(W1014)),C1014,"") | BA1014: =IF(W1014<=Leltar_iv!$Y$1,I1014,0) -> 0
A1015: =IF(COUNTIF($Y$6:Y1015,Y1015)=1,Y1015,Y1015+COUNTIF($Y$5:Y1014,Y1015)) -> 10 | B1015: =IF(AND(Kisero_iv!$N$2=C1015,Kisero_iv!$K$5=$B$3,SUM(I1015:L1019)<>0,$B$4=YEAR(W1015)),B1014+1,0) -> 0 | C1015: =IF(YEAR(W1014)<>YEAR(W1015),1,IF(T1015<>0,C1014+1,C1014)) -> 10 | D1015: =IF(AND(OR(C1014<>C1015,C1015=1),SUM(L1015:L1035)<>0),YEAR(W1015)&"/"&C1015,"") | J1015: =IF(AND(G1015<>"",ISERROR(VLOOKUP(G1015,Keszlet!$C$5:$H$200,6,FALSE))=FALSE),VLOOKUP(G1015,Keszlet!$C$5:$H$200,6,FALSE),"") | K1015: =IF(AND(G1015<>"",ISERROR(VLOOKUP(G1015,Keszlet!$C$5:$G$200,5,FALSE))=FALSE),VLOOKUP(G1015,Keszlet!$C$5:$G$200,5,FALSE),"") | L1015: =IF(AND(G1015<>0,K1015<>""),I1015*K1015,"") | M1015: =IF(ISERROR(VLOOKUP(G1015,Keszlet!$C$5:$I$200,7,FALSE))=TRUE,"",IF(AND(J1014<>"",J1016=""),VLOOKUP(G1015,Keszlet!$C$5:$I$200,7,FALSE),"")) | Q1015: =VLOOKUP(G1015,Keszlet!$C$5:$E$205,3,FALSE) -> 0 | T1015: =IF(OR(E1015<>0,COUNTIF(T1006:T1014,0)=9,F1015<>0,SUM(L1015:L1035)=0),E1015&F1015,0) | U1015: =IF(F1015<>"",F1015,U1014) -> 0 | W1015: =IF(E1015<>0,E1015,W1014) -> 0 | X1015: =IF(G1015=q,W1015,$X$1) -> 0 | Y1015: =RANK(X1015,$X$6:$X$10000,1) -> 1 | Z1015: =IF(COUNTIF($Y$6:Y1015,Y1015)=1,Y1015,Y1015+COUNTIF($Y$5:Y1014,Y1015)) -> 10 | AD1015: =IF(AND(OR(C1014<>C1015,YEAR(W1015)<>YEAR(W1014)),SUM(L1015:L1035)<>0,$B$4=YEAR(W1015)),C1015,"") | BA1015: =IF(W1015<=Leltar_iv!$Y$1,I1015,0) -> 0
A1016: =IF(COUNTIF($Y$6:Y1016,Y1016)=1,Y1016,Y1016+COUNTIF($Y$5:Y1015,Y1016)) -> 11 | B1016: =IF(AND(Kisero_iv!$N$2=C1016,Kisero_iv!$K$5=$B$3,SUM(I1016:L1020)<>0,$B$4=YEAR(W1016)),B1015+1,0) -> 0 | C1016: =IF(YEAR(W1015)<>YEAR(W1016),1,IF(T1016<>0,C1015+1,C1015)) -> 11 | D1016: =IF(AND(OR(C1015<>C1016,C1016=1),SUM(L1016:L1036)<>0),YEAR(W1016)&"/"&C1016,"") | J1016: =IF(AND(G1016<>"",ISERROR(VLOOKUP(G1016,Keszlet!$C$5:$H$200,6,FALSE))=FALSE),VLOOKUP(G1016,Keszlet!$C$5:$H$200,6,FALSE),"") | K1016: =IF(AND(G1016<>"",ISERROR(VLOOKUP(G1016,Keszlet!$C$5:$G$200,5,FALSE))=FALSE),VLOOKUP(G1016,Keszlet!$C$5:$G$200,5,FALSE),"") | L1016: =IF(AND(G1016<>0,K1016<>""),I1016*K1016,"") | M1016: =IF(ISERROR(VLOOKUP(G1016,Keszlet!$C$5:$I$200,7,FALSE))=TRUE,"",IF(AND(J1015<>"",J1017=""),VLOOKUP(G1016,Keszlet!$C$5:$I$200,7,FALSE),"")) | Q1016: =VLOOKUP(G1016,Keszlet!$C$5:$E$205,3,FALSE) -> 0 | T1016: =IF(OR(E1016<>0,COUNTIF(T1007:T1015,0)=9,F1016<>0,SUM(L1016:L1036)=0),E1016&F1016,0) | U1016: =IF(F1016<>"",F1016,U1015) -> 0 | W1016: =IF(E1016<>0,E1016,W1015) -> 0 | X1016: =IF(G1016=q,W1016,$X$1) -> 0 | Y1016: =RANK(X1016,$X$6:$X$10000,1) -> 1 | Z1016: =IF(COUNTIF($Y$6:Y1016,Y1016)=1,Y1016,Y1016+COUNTIF($Y$5:Y1015,Y1016)) -> 11 | AD1016: =IF(AND(OR(C1015<>C1016,YEAR(W1016)<>YEAR(W1015)),SUM(L1016:L1036)<>0,$B$4=YEAR(W1016)),C1016,"") | BA1016: =IF(W1016<=Leltar_iv!$Y$1,I1016,0) -> 0
A1017: =IF(COUNTIF($Y$6:Y1017,Y1017)=1,Y1017,Y1017+COUNTIF($Y$5:Y1016,Y1017)) -> 12 | B1017: =IF(AND(Kisero_iv!$N$2=C1017,Kisero_iv!$K$5=$B$3,SUM(I1017:L1021)<>0,$B$4=YEAR(W1017)),B1016+1,0) -> 0 | C1017: =IF(YEAR(W1016)<>YEAR(W1017),1,IF(T1017<>0,C1016+1,C1016)) -> 12 | D1017: =IF(AND(OR(C1016<>C1017,C1017=1),SUM(L1017:L1037)<>0),YEAR(W1017)&"/"&C1017,"") | J1017: =IF(AND(G1017<>"",ISERROR(VLOOKUP(G1017,Keszlet!$C$5:$H$200,6,FALSE))=FALSE),VLOOKUP(G1017,Keszlet!$C$5:$H$200,6,FALSE),"") | K1017: =IF(AND(G1017<>"",ISERROR(VLOOKUP(G1017,Keszlet!$C$5:$G$200,5,FALSE))=FALSE),VLOOKUP(G1017,Keszlet!$C$5:$G$200,5,FALSE),"") | L1017: =IF(AND(G1017<>0,K1017<>""),I1017*K1017,"") | M1017: =IF(ISERROR(VLOOKUP(G1017,Keszlet!$C$5:$I$200,7,FALSE))=TRUE,"",IF(AND(J1016<>"",J1018=""),VLOOKUP(G1017,Keszlet!$C$5:$I$200,7,FALSE),"")) | Q1017: =VLOOKUP(G1017,Keszlet!$C$5:$E$205,3,FALSE) -> 0 | T1017: =IF(OR(E1017<>0,COUNTIF(T1008:T1016,0)=9,F1017<>0,SUM(L1017:L1037)=0),E1017&F1017,0) | U1017: =IF(F1017<>"",F1017,U1016) -> 0 | W1017: =IF(E1017<>0,E1017,W1016) -> 0 | X1017: =IF(G1017=q,W1017,$X$1) -> 0 | Y1017: =RANK(X1017,$X$6:$X$10000,1) -> 1 | Z1017: =IF(COUNTIF($Y$6:Y1017,Y1017)=1,Y1017,Y1017+COUNTIF($Y$5:Y1016,Y1017)) -> 12 | AD1017: =IF(AND(OR(C1016<>C1017,YEAR(W1017)<>YEAR(W1016)),SUM(L1017:L1037)<>0,$B$4=YEAR(W1017)),C1017,"") | BA1017: =IF(W1017<=Leltar_iv!$Y$1,I1017,0) -> 0
... A2000: =IF(COUNTIF($Y$6:Y2000,Y2000)=1,Y2000,Y2000+COUNTIF($Y$5:Y1999,Y2000)) -> 995 | B2000: =IF(AND(Kisero_iv!$N$2=C2000,Kisero_iv!$K$5=$B$3,SUM(I2000:L2004)<>0,$B$4=YEAR(W2000)),B1999+1,0) -> 0 | C2000: =IF(YEAR(W1999)<>YEAR(W2000),1,IF(T2000<>0,C1999+1,C1999)) -> 995 | D2000: =IF(AND(OR(C1999<>C2000,C2000=1),SUM(L2000:L2020)<>0),YEAR(W2000)&"/"&C2000,"") | J2000: =IF(AND(G2000<>"",ISERROR(VLOOKUP(G2000,Keszlet!$C$5:$H$200,6,FALSE))=FALSE),VLOOKUP(G2000,Keszlet!$C$5:$H$200,6,FALSE),"") | K2000: =IF(AND(G2000<>"",ISERROR(VLOOKUP(G2000,Keszlet!$C$5:$G$200,5,FALSE))=FALSE),VLOOKUP(G2000,Keszlet!$C$5:$G$200,5,FALSE),"") | L2000: =IF(AND(G2000<>0,K2000<>""),I2000*K2000,"") | M2000: =IF(ISERROR(VLOOKUP(G2000,Keszlet!$C$5:$I$200,7,FALSE))=TRUE,"",IF(AND(J1999<>"",J2001=""),VLOOKUP(G2000,Keszlet!$C$5:$I$200,7,FALSE),"")) | Q2000: =VLOOKUP(G2000,Keszlet!$C$5:$E$205,3,FALSE) -> 0 | T2000: =IF(OR(E2000<>0,COUNTIF(T1991:T1999,0)=9,F2000<>0,SUM(L2000:L2020)=0),E2000&F2000,0) | U2000: =IF(F2000<>"",F2000,U1999) -> 0 | W2000: =IF(E2000<>0,E2000,W1999) -> 0 | X2000: =IF(G2000=q,W2000,$X$1) -> 0 | Y2000: =RANK(X2000,$X$6:$X$10000,1) -> 1 | Z2000: =IF(COUNTIF($Y$6:Y2000,Y2000)=1,Y2000,Y2000+COUNTIF($Y$5:Y1999,Y2000)) -> 995 | AD2000: =IF(AND(OR(C1999<>C2000,YEAR(W2000)<>YEAR(W1999)),SUM(L2000:L2020)<>0,$B$4=YEAR(W2000)),C2000,"") | BA2000: =IF(W2000<=Leltar_iv!$Y$1,I2000,0) -> 0

Sheet Kisero_iv
C1: A jobboldali, zöld cellában lehet váltani a Bevételezési bizonylat és az Anyagraktári kiadási utalvány között. | E1: Anyagraktári kiadási utalvány | J1: a a | N1: =IF(G2<>0,G2,YEAR(O1)) -> 1900 | O1: =MAX(Kiadas!W6:W2000) -> 0
C2: A jobboldali cellában lehet megadni az évet. Ha a cella üres, akkor a legutolsó felkönyvelt évet lehet nyomtatni. | J2: a a a | K2: Bevételezési bizonylat | L2: Átadó: | M2: b | N2: =IF(G3<>0,G3,N5) -> 0 | O2: =MAX(Kiadas!AD6:AD200) -> 0
C3: A jobboldali cellában lehet megadni a listázni kívánt lap számát. Ha a cella üres, akkor a legutolsó lapot nyomtatja | J3: a a | K3: Anyagraktári kiadási utalvány | L3: Átvevő: | M3: k | N3: Összesen | O3: =MAX(Kiadas!AD1006:AD10000) -> 0
C4: =Keszlet!G3 -> 0 | K4: =IF(E1<>"",E1,K3) -> Anyagraktári kiadási utalvány | N4: =MAX(Kiadas!B6:B10000) -> 0
G5: ="Szám: "&N1&" / "&N2 -> Szám: 1900 / 0 | K5: =VLOOKUP(K4,K2:M3,3,FALSE) -> k | N5: =VLOOKUP(K4,K2:O3,5,FALSE) -> 0
C6: =K4 -> Anyagraktári kiadási utalvány
C7: =VLOOKUP(K4,K2:L3,2,FALSE) -> Átvevő:
C8: =IF(C11<>"",VLOOKUP(C11,Kiadas!$B$6:$W$10000,20,FALSE),"")
T9: Anyag megnevezése
C10: Sz. | D10: =IF(S10=10,T9,T10) -> Anyag megnevezése | E10: Mennyiség | F10: Egységár | G10: Összesen | S10: =COUNTIF(S11:S20,"") -> 10 | T10: Anyag megnevezése / Megjegyzés
C11: =IF(N11<=$N$4,N11,"") | D11: =IF(C11<>"",TRIM(T11&" "&S11),"") | E11: =IF(C11<>"",K11&" "&L11,"") | F11: =IF(C11<>"",VLOOKUP(C11,Kiadas!$B$6:$L$10000,10,FALSE),"") | G11: =IF(C11<>"",K11*F11,IF(C10<>"",0,"")) -> 0 | K11: =IF(C11<>"",VLOOKUP(C11,Kiadas!$B$6:$L$10000,8,FALSE),"") | L11: =VLOOKUP(U11,Keszlet!$C$5:$H$200,6,FALSE) -> #N/A | N11: 1 | S11: =IF(C11<>"",IF(VLOOKUP(C11,Kiadas!$B$6:$L$10000,7,FALSE)<>0," / "&VLOOKUP(C11,Kiadas!$B$6:$L$10000,7,FALSE),""),"") | T11: =VLOOKUP(U11,Keszlet!$C$5:$E$205,3,FALSE)&IF(VLOOKUP(U11,Keszlet!$C$5:$F$205,4,FALSE)<>0," - "&VLOOKUP(U11,Keszlet!$C$5:$F$205,4,FALSE),"") | U11: =IF(C11<>"",IF(VLOOKUP(C11,Kiadas!$B$6:$Q$10000,6,FALSE)<>0,VLOOKUP(C11,Kiadas!$B$6:$Q$10000,6,FALSE),""),"")
C12: =IF(N12<=$N$4,N12,"") | D12: =IF(C12<>"",TRIM(T12&" "&S12),"") | E12: =IF(C12<>"",K12&" "&L12,"") | F12: =IF(C12<>"",VLOOKUP(C12,Kiadas!$B$6:$L$10000,10,FALSE),IF(C11<>"",$N$3,"")) | G12: =IF(C12<>"",K12*F12,IF(C11<>"",SUM($G$11:G11),"")) | K12: =IF(C12<>"",VLOOKUP(C12,Kiadas!$B$6:$L$10000,8,FALSE),"") | L12: =VLOOKUP(U12,Keszlet!$C$5:$H$200,6,FALSE) -> #N/A | N12: 2 | S12: =IF(C12<>"",IF(VLOOKUP(C12,Kiadas!$B$6:$L$10000,7,FALSE)<>0," / "&VLOOKUP(C12,Kiadas!$B$6:$L$10000,7,FALSE),""),"") | T12: =VLOOKUP(U12,Keszlet!$C$5:$E$205,3,FALSE)&IF(VLOOKUP(U12,Keszlet!$C$5:$F$205,4,FALSE)<>0," - "&VLOOKUP(U12,Keszlet!$C$5:$F$205,4,FALSE),"") | U12: =IF(C12<>"",IF(VLOOKUP(C12,Kiadas!$B$6:$Q$10000,6,FALSE)<>0,VLOOKUP(C12,Kiadas!$B$6:$Q$10000,6,FALSE),""),"")
C13: =IF(N13<=$N$4,N13,"") | D13: =IF(C13<>"",TRIM(T13&" "&S13),"") | E13: =IF(C13<>"",K13&" "&L13,"") | F13: =IF(C13<>"",VLOOKUP(C13,Kiadas!$B$6:$L$10000,10,FALSE),IF(C12<>"",$N$3,"")) | G13: =IF(C13<>"",K13*F13,IF(C12<>"",SUM($G$11:G12),"")) | K13: =IF(C13<>"",VLOOKUP(C13,Kiadas!$B$6:$L$10000,8,FALSE),"") | L13: =VLOOKUP(U13,Keszlet!$C$5:$H$200,6,FALSE) -> #N/A | N13: 3 | S13: =IF(C13<>"",IF(VLOOKUP(C13,Kiadas!$B$6:$L$10000,7,FALSE)<>0," / "&VLOOKUP(C13,Kiadas!$B$6:$L$10000,7,FALSE),""),"") | T13: =VLOOKUP(U13,Keszlet!$C$5:$E$205,3,FALSE)&IF(VLOOKUP(U13,Keszlet!$C$5:$F$205,4,FALSE)<>0," - "&VLOOKUP(U13,Keszlet!$C$5:$F$205,4,FALSE),"") | U13: =IF(C13<>"",IF(VLOOKUP(C13,Kiadas!$B$6:$Q$10000,6,FALSE)<>0,VLOOKUP(C13,Kiadas!$B$6:$Q$10000,6,FALSE),""),"")
C14: =IF(N14<=$N$4,N14,"") | D14: =IF(C14<>"",TRIM(T14&" "&S14),"") | E14: =IF(C14<>"",K14&" "&L14,"") | F14: =IF(C14<>"",VLOOKUP(C14,Kiadas!$B$6:$L$10000,10,FALSE),IF(C13<>"",$N$3,"")) | G14: =IF(C14<>"",K14*F14,IF(C13<>"",SUM($G$11:G13),"")) | K14: =IF(C14<>"",VLOOKUP(C14,Kiadas!$B$6:$L$10000,8,FALSE),"") | L14: =VLOOKUP(U14,Keszlet!$C$5:$H$200,6,FALSE) -> #N/A | N14: 4 | S14: =IF(C14<>"",IF(VLOOKUP(C14,Kiadas!$B$6:$L$10000,7,FALSE)<>0," / "&VLOOKUP(C14,Kiadas!$B$6:$L$10000,7,FALSE),""),"") | T14: =VLOOKUP(U14,Keszlet!$C$5:$E$205,3,FALSE)&IF(VLOOKUP(U14,Keszlet!$C$5:$F$205,4,FALSE)<>0," - "&VLOOKUP(U14,Keszlet!$C$5:$F$205,4,FALSE),"") | U14: =IF(C14<>"",IF(VLOOKUP(C14,Kiadas!$B$6:$Q$10000,6,FALSE)<>0,VLOOKUP(C14,Kiadas!$B$6:$Q$10000,6,FALSE),""),"")
C15: =IF(N15<=$N$4,N15,"") | D15: =IF(C15<>"",TRIM(T15&" "&S15),"") | E15: =IF(C15<>"",K15&" "&L15,"") | F15: =IF(C15<>"",VLOOKUP(C15,Kiadas!$B$6:$L$10000,10,FALSE),IF(C14<>"",$N$3,"")) | G15: =IF(C15<>"",K15*F15,IF(C14<>"",SUM($G$11:G14),"")) | K15: =IF(C15<>"",VLOOKUP(C15,Kiadas!$B$6:$L$10000,8,FALSE),"") | L15: =VLOOKUP(U15,Keszlet!$C$5:$H$200,6,FALSE) -> #N/A | N15: 5 | S15: =IF(C15<>"",IF(VLOOKUP(C15,Kiadas!$B$6:$L$10000,7,FALSE)<>0," / "&VLOOKUP(C15,Kiadas!$B$6:$L$10000,7,FALSE),""),"") | T15: =VLOOKUP(U15,Keszlet!$C$5:$E$205,3,FALSE)&IF(VLOOKUP(U15,Keszlet!$C$5:$F$205,4,FALSE)<>0," - "&VLOOKUP(U15,Keszlet!$C$5:$F$205,4,FALSE),"") | U15: =IF(C15<>"",IF(VLOOKUP(C15,Kiadas!$B$6:$Q$10000,6,FALSE)<>0,VLOOKUP(C15,Kiadas!$B$6:$Q$10000,6,FALSE),""),"")
