Workbook
Name IktNy: Nyomtathato_iktato!$A$6:INDEX(Nyomtathato_iktato!$F:$F,Nyomtathato_iktato!$N$1)
Name IratNy: Irattari_leltar!$A$6:INDEX(Irattari_leltar!$F:$F,Irattari_leltar!$K$1)
Name Nevek: Iktato!$AD$1:$AD$13

Sheet Iktato
B1: =Nyomtathato_iktato!I1 -> 2025 | C1: =Irattari_leltar!I2 -> Levelezés | F1: =R2 -> IDE KELL BEÍRNI AZ EGYHÁZKÖZSÉG NEVÉT | R1: AZ EGYHÁZKÖZSÉG NEVÉT AZ "Iktató" MUNKALAPON LEHET KITÖLTENI | V1: t | W1: x | Y1: =Irattari_leltar!I1 -> 2025 | Z1: 46023 | AD1: Levelezés | AE1: a | AF1: Levelezés (egyházkerületi, egyházmegyei, egyházközségi, világi hatóságokkal, magánszemélyekkel) | AG1: 1 - | AH1: 1 | AI1: Válasz
E2: Helyi iktató szám | F2: Érkezés /küldés dátuma | G2: Küldő iktató száma | H2: Küldő keltezése | I2: Cím Kitől/Kinek | J2: Tárgykivonat | K2: Iratgyűjtő | L2: Lapok száma | M2: Ha válasz | N2: Megjegyzés | O2: Hivatkozás címe | P2: Iratgyűjtő száma | Q2: Iratgyűjtői sor száma | R2: IDE KELL BEÍRNI AZ EGYHÁZKÖZSÉG NEVÉT | Y2: =MAX($Z$1,F3:F10000) -> 46023 | Z2: 45657 | AD2: Anya- és családkönyvi levelezés | AE2: b | AF2: Anya- és családkönyvi levelezés és adatvédelmi nyilatkozatok | AG2: 2 - | AH2: 2
B3: =IF($B$1=YEAR(F3),B2+1,B2) -> 0 | C3: =IF(AND($C$1=K3,$Y$1=YEAR(F3)),C2+1,C2) -> 0 | D3: 1 | E3: =IF(D3<>"",D3&" - "&YEAR(F3),"") -> 1 - 1900 | H3: =IF(G3<>"",F3,"") | P3: =IF(OR(T3=0,RIGHT(T3,1)=$W$1),"",VLOOKUP(K3,$AD$1:$AK$15,5,FALSE)) | Q3: =IF(OR(T3=0,RIGHT(T3,1)=$W$1),"",COUNTIF($T$3:T3,T3)) | S3: =IF(AND($C$1=K3,$Y$1=YEAR(F3)),C3,0) -> 0 | T3: =IF(F3=0,0,YEAR(F3)&VLOOKUP(K3,$AD$1:$AE$15,2,FALSE)) -> 0 | V3: =IF(AND(YEAR(F3)=$Y$1,K3=$C$1,L3&$V$1<>$V$1),L3,IF(AND(YEAR(F3)=$Y$1,K3=$C$1),1,0)) -> 0 | Y3: =IF(M3<>$AI$1,$Y$2,F2) -> 46023 | AD3: Jelentések | AE3: d | AF3: Jelentések | AG3: 3 - | AH3: 3
B4: =IF($B$1=YEAR(F4),B3+1,B3) -> 0 | C4: =IF(AND($C$1=K4,$Y$1=YEAR(F4)),C3+1,C3) -> 0 | D4: =IF(F4<>0,IF(YEAR(F4)<>YEAR(F3),1,IF(M4=$AI$1,D3,D3+1)),"") | E4: =IF(D4<>"",D4&" - "&YEAR(F4),"") | H4: =IF(G4<>"",F4,"") | P4: =IF(OR(T4=0,RIGHT(T4,1)=$W$1),"",VLOOKUP(K4,$AD$1:$AK$15,5,FALSE)) | Q4: =IF(OR(T4=0,RIGHT(T4,1)=$W$1),"",COUNTIF($T$3:T4,T4)) | S4: =IF(AND($C$1=K4,$Y$1=YEAR(F4)),C4,0) -> 0 | T4: =IF(F4=0,0,YEAR(F4)&VLOOKUP(K4,$AD$1:$AE$15,2,FALSE)) -> 0 | V4: =IF(AND(YEAR(F4)=$Y$1,K4=$C$1,L4&$V$1<>$V$1),L4,IF(AND(YEAR(F4)=$Y$1,K4=$C$1),1,0)) -> 0 | Y4: =IF(M4<>$AI$1,$Y$2,F3) -> 46023 | AD4: Választók névjegyzéke | AE4: e | AF4: Választók névjegyzéke | AG4: 4 - | AH4: 4
B5: =IF($B$1=YEAR(F5),B4+1,B4) -> 0 | C5: =IF(AND($C$1=K5,$Y$1=YEAR(F5)),C4+1,C4) -> 0 | D5: =IF(F5<>0,IF(YEAR(F5)<>YEAR(F4),1,IF(M5=$AI$1,D4,D4+1)),"") | E5: =IF(D5<>"",D5&" - "&YEAR(F5),"") | H5: =IF(G5<>"",F5,"") | P5: =IF(OR(T5=0,RIGHT(T5,1)=$W$1),"",VLOOKUP(K5,$AD$1:$AK$15,5,FALSE)) | Q5: =IF(OR(T5=0,RIGHT(T5,1)=$W$1),"",COUNTIF($T$3:T5,T5)) | S5: =IF(AND($C$1=K5,$Y$1=YEAR(F5)),C5,0) -> 0 | T5: =IF(F5=0,0,YEAR(F5)&VLOOKUP(K5,$AD$1:$AE$15,2,FALSE)) -> 0 | V5: =IF(AND(YEAR(F5)=$Y$1,K5=$C$1,L5&$V$1<>$V$1),L5,IF(AND(YEAR(F5)=$Y$1,K5=$C$1),1,0)) -> 0 | Y5: =IF(M5<>$AI$1,$Y$2,F4) -> 46023 | AD5: Vagyonleltári jelentések | AE5: f | AF5: Vagyonleltári jelentések, leltárívek, selejtezési jegyzőkönyvek | AG5: 6/1 - | AH5: 6/1.
B6: =IF($B$1=YEAR(F6),B5+1,B5) -> 0 | C6: =IF(AND($C$1=K6,$Y$1=YEAR(F6)),C5+1,C5) -> 0 | D6: =IF(F6<>0,IF(YEAR(F6)<>YEAR(F5),1,IF(M6=$AI$1,D5,D5+1)),"") | E6: =IF(D6<>"",D6&" - "&YEAR(F6),"") | H6: =IF(G6<>"",F6,"") | P6: =IF(OR(T6=0,RIGHT(T6,1)=$W$1),"",VLOOKUP(K6,$AD$1:$AK$15,5,FALSE)) | Q6: =IF(OR(T6=0,RIGHT(T6,1)=$W$1),"",COUNTIF($T$3:T6,T6)) | S6: =IF(AND($C$1=K6,$Y$1=YEAR(F6)),C6,0) -> 0 | T6: =IF(F6=0,0,YEAR(F6)&VLOOKUP(K6,$AD$1:$AE$15,2,FALSE)) -> 0 | V6: =IF(AND(YEAR(F6)=$Y$1,K6=$C$1,L6&$V$1<>$V$1),L6,IF(AND(YEAR(F6)=$Y$1,K6=$C$1),1,0)) -> 0 | Y6: =IF(M6<>$AI$1,$Y$2,F5) -> 46023 | AD6: Ingatlanadók, felértékelések … | AE6: g | AF6: Ingatlanadók, felértékelések, kockázatfelmérések, biztosítások | AG6: 6/2 - | AH6: 6/4.
B7: =IF($B$1=YEAR(F7),B6+1,B6) -> 0 | C7: =IF(AND($C$1=K7,$Y$1=YEAR(F7)),C6+1,C6) -> 0 | D7: =IF(F7<>0,IF(YEAR(F7)<>YEAR(F6),1,IF(M7=$AI$1,D6,D6+1)),"") | E7: =IF(D7<>"",D7&" - "&YEAR(F7),"") | H7: =IF(G7<>"",F7,"") | P7: =IF(OR(T7=0,RIGHT(T7,1)=$W$1),"",VLOOKUP(K7,$AD$1:$AK$15,5,FALSE)) | Q7: =IF(OR(T7=0,RIGHT(T7,1)=$W$1),"",COUNTIF($T$3:T7,T7)) | S7: =IF(AND($C$1=K7,$Y$1=YEAR(F7)),C7,0) -> 0 | T7: =IF(F7=0,0,YEAR(F7)&VLOOKUP(K7,$AD$1:$AE$15,2,FALSE)) -> 0 | V7: =IF(AND(YEAR(F7)=$Y$1,K7=$C$1,L7&$V$1<>$V$1),L7,IF(AND(YEAR(F7)=$Y$1,K7=$C$1),1,0)) -> 0 | Y7: =IF(M7<>$AI$1,$Y$2,F6) -> 46023 | AD7: Költségvetések, számadások | AE7: h | AF7: Költségvetések, költségvetés-módosítások, számadások | AG7: 8 - | AH7: 8
B8: =IF($B$1=YEAR(F8),B7+1,B7) -> 0 | C8: =IF(AND($C$1=K8,$Y$1=YEAR(F8)),C7+1,C7) -> 0 | D8: =IF(F8<>0,IF(YEAR(F8)<>YEAR(F7),1,IF(M8=$AI$1,D7,D7+1)),"") | E8: =IF(D8<>"",D8&" - "&YEAR(F8),"") | H8: =IF(G8<>"",F8,"") | P8: =IF(OR(T8=0,RIGHT(T8,1)=$W$1),"",VLOOKUP(K8,$AD$1:$AK$15,5,FALSE)) | Q8: =IF(OR(T8=0,RIGHT(T8,1)=$W$1),"",COUNTIF($T$3:T8,T8)) | S8: =IF(AND($C$1=K8,$Y$1=YEAR(F8)),C8,0) -> 0 | T8: =IF(F8=0,0,YEAR(F8)&VLOOKUP(K8,$AD$1:$AE$15,2,FALSE)) -> 0 | V8: =IF(AND(YEAR(F8)=$Y$1,K8=$C$1,L8&$V$1<>$V$1),L8,IF(AND(YEAR(F8)=$Y$1,K8=$C$1),1,0)) -> 0 | Y8: =IF(M8<>$AI$1,$Y$2,F7) -> 46023 | AD8: Bérleti szerződések | AE8: i | AF8: Bérleti szerződések | AG8: 13/1 - | AH8: 13/1.
B9: =IF($B$1=YEAR(F9),B8+1,B8) -> 0 | C9: =IF(AND($C$1=K9,$Y$1=YEAR(F9)),C8+1,C8) -> 0 | D9: =IF(F9<>0,IF(YEAR(F9)<>YEAR(F8),1,IF(M9=$AI$1,D8,D8+1)),"") | E9: =IF(D9<>"",D9&" - "&YEAR(F9),"") | H9: =IF(G9<>"",F9,"") | P9: =IF(OR(T9=0,RIGHT(T9,1)=$W$1),"",VLOOKUP(K9,$AD$1:$AK$15,5,FALSE)) | Q9: =IF(OR(T9=0,RIGHT(T9,1)=$W$1),"",COUNTIF($T$3:T9,T9)) | S9: =IF(AND($C$1=K9,$Y$1=YEAR(F9)),C9,0) -> 0 | T9: =IF(F9=0,0,YEAR(F9)&VLOOKUP(K9,$AD$1:$AE$15,2,FALSE)) -> 0 | V9: =IF(AND(YEAR(F9)=$Y$1,K9=$C$1,L9&$V$1<>$V$1),L9,IF(AND(YEAR(F9)=$Y$1,K9=$C$1),1,0)) -> 0 | Y9: =IF(M9<>$AI$1,$Y$2,F8) -> 46023 | AD9: Közüzemi szerzdődések … | AE9: j | AF9: Közüzemi szerződések (energia, telekommunikáció, víz és csatoma) | AG9: 13/2 - | AH9: 13/2.
B10: =IF($B$1=YEAR(F10),B9+1,B9) -> 0 | C10: =IF(AND($C$1=K10,$Y$1=YEAR(F10)),C9+1,C9) -> 0 | D10: =IF(F10<>0,IF(YEAR(F10)<>YEAR(F9),1,IF(M10=$AI$1,D9,D9+1)),"") | E10: =IF(D10<>"",D10&" - "&YEAR(F10),"") | H10: =IF(G10<>"",F10,"") | P10: =IF(OR(T10=0,RIGHT(T10,1)=$W$1),"",VLOOKUP(K10,$AD$1:$AK$15,5,FALSE)) | Q10: =IF(OR(T10=0,RIGHT(T10,1)=$W$1),"",COUNTIF($T$3:T10,T10)) | S10: =IF(AND($C$1=K10,$Y$1=YEAR(F10)),C10,0) -> 0 | T10: =IF(F10=0,0,YEAR(F10)&VLOOKUP(K10,$AD$1:$AE$15,2,FALSE)) -> 0 | V10: =IF(AND(YEAR(F10)=$Y$1,K10=$C$1,L10&$V$1<>$V$1),L10,IF(AND(YEAR(F10)=$Y$1,K10=$C$1),1,0)) -> 0 | Y10: =IF(M10<>$AI$1,$Y$2,F9) -> 46023 | AD10: Szolgáltatási és támogatási szerz. … | AE10: k | AF10: Szolgáltatási és támogatási szerződések | AG10: 13/3 - | AH10: 13/3.
B11: =IF($B$1=YEAR(F11),B10+1,B10) -> 0 | C11: =IF(AND($C$1=K11,$Y$1=YEAR(F11)),C10+1,C10) -> 0 | D11: =IF(F11<>0,IF(YEAR(F11)<>YEAR(F10),1,IF(M11=$AI$1,D10,D10+1)),"") | E11: =IF(D11<>"",D11&" - "&YEAR(F11),"") | H11: =IF(G11<>"",F11,"") | P11: =IF(OR(T11=0,RIGHT(T11,1)=$W$1),"",VLOOKUP(K11,$AD$1:$AK$15,5,FALSE)) | Q11: =IF(OR(T11=0,RIGHT(T11,1)=$W$1),"",COUNTIF($T$3:T11,T11)) | S11: =IF(AND($C$1=K11,$Y$1=YEAR(F11)),C11,0) -> 0 | T11: =IF(F11=0,0,YEAR(F11)&VLOOKUP(K11,$AD$1:$AE$15,2,FALSE)) -> 0 | V11: =IF(AND(YEAR(F11)=$Y$1,K11=$C$1,L11&$V$1<>$V$1),L11,IF(AND(YEAR(F11)=$Y$1,K11=$C$1),1,0)) -> 0 | Y11: =IF(M11<>$AI$1,$Y$2,F10) -> 46023 | AD11: Pályázatok | AE11: l | AF11: Pályázatok | AG11: 14 - | AH11: 14
B12: =IF($B$1=YEAR(F12),B11+1,B11) -> 0 | C12: =IF(AND($C$1=K12,$Y$1=YEAR(F12)),C11+1,C11) -> 0 | D12: =IF(F12<>0,IF(YEAR(F12)<>YEAR(F11),1,IF(M12=$AI$1,D11,D11+1)),"") | E12: =IF(D12<>"",D12&" - "&YEAR(F12),"") | H12: =IF(G12<>"",F12,"") | P12: =IF(OR(T12=0,RIGHT(T12,1)=$W$1),"",VLOOKUP(K12,$AD$1:$AK$15,5,FALSE)) | Q12: =IF(OR(T12=0,RIGHT(T12,1)=$W$1),"",COUNTIF($T$3:T12,T12)) | S12: =IF(AND($C$1=K12,$Y$1=YEAR(F12)),C12,0) -> 0 | T12: =IF(F12=0,0,YEAR(F12)&VLOOKUP(K12,$AD$1:$AE$15,2,FALSE)) -> 0 | V12: =IF(AND(YEAR(F12)=$Y$1,K12=$C$1,L12&$V$1<>$V$1),L12,IF(AND(YEAR(F12)=$Y$1,K12=$C$1),1,0)) -> 0 | Y12: =IF(M12<>$AI$1,$Y$2,F11) -> 46023 | AD12: Ellenőrzési jegyzőkönyvek … | AE12: m | AF12: Ellenőrzési jegyzőkönyvek (belső, gazdasági bizottsági és felsőbb hatósági) | AG12: 15 - | AH12: 15
B13: =IF($B$1=YEAR(F13),B12+1,B12) -> 0 | C13: =IF(AND($C$1=K13,$Y$1=YEAR(F13)),C12+1,C12) -> 0 | D13: =IF(F13<>0,IF(YEAR(F13)<>YEAR(F12),1,IF(M13=$AI$1,D12,D12+1)),"") | E13: =IF(D13<>"",D13&" - "&YEAR(F13),"") | H13: =IF(G13<>"",F13,"") | P13: =IF(OR(T13=0,RIGHT(T13,1)=$W$1),"",VLOOKUP(K13,$AD$1:$AK$15,5,FALSE)) | Q13: =IF(OR(T13=0,RIGHT(T13,1)=$W$1),"",COUNTIF($T$3:T13,T13)) | S13: =IF(AND($C$1=K13,$Y$1=YEAR(F13)),C13,0) -> 0 | T13: =IF(F13=0,0,YEAR(F13)&VLOOKUP(K13,$AD$1:$AE$15,2,FALSE)) -> 0 | V13: =IF(AND(YEAR(F13)=$Y$1,K13=$C$1,L13&$V$1<>$V$1),L13,IF(AND(YEAR(F13)=$Y$1,K13=$C$1),1,0)) -> 0 | Y13: =IF(M13<>$AI$1,$Y$2,F12) -> 46023 | AD13: Temetőügyek | AE13: n | AF13: Temetőügyek | AG13: 17 - | AH13: 17
B14: =IF($B$1=YEAR(F14),B13+1,B13) -> 0 | C14: =IF(AND($C$1=K14,$Y$1=YEAR(F14)),C13+1,C13) -> 0 | D14: =IF(F14<>0,IF(YEAR(F14)<>YEAR(F13),1,IF(M14=$AI$1,D13,D13+1)),"") | E14: =IF(D14<>"",D14&" - "&YEAR(F14),"") | H14: =IF(G14<>"",F14,"") | P14: =IF(OR(T14=0,RIGHT(T14,1)=$W$1),"",VLOOKUP(K14,$AD$1:$AK$15,5,FALSE)) | Q14: =IF(OR(T14=0,RIGHT(T14,1)=$W$1),"",COUNTIF($T$3:T14,T14)) | S14: =IF(AND($C$1=K14,$Y$1=YEAR(F14)),C14,0) -> 0 | T14: =IF(F14=0,0,YEAR(F14)&VLOOKUP(K14,$AD$1:$AE$15,2,FALSE)) -> 0 | V14: =IF(AND(YEAR(F14)=$Y$1,K14=$C$1,L14&$V$1<>$V$1),L14,IF(AND(YEAR(F14)=$Y$1,K14=$C$1),1,0)) -> 0 | Y14: =IF(M14<>$AI$1,$Y$2,F13) -> 46023 | AD14: 0 | AE14: x | AH14: =$AJ$1&$AJ$2
B15: =IF($B$1=YEAR(F15),B14+1,B14) -> 0 | C15: =IF(AND($C$1=K15,$Y$1=YEAR(F15)),C14+1,C14) -> 0 | D15: =IF(F15<>0,IF(YEAR(F15)<>YEAR(F14),1,IF(M15=$AI$1,D14,D14+1)),"") | E15: =IF(D15<>"",D15&" - "&YEAR(F15),"") | H15: =IF(G15<>"",F15,"") | P15: =IF(OR(T15=0,RIGHT(T15,1)=$W$1),"",VLOOKUP(K15,$AD$1:$AK$15,5,FALSE)) | Q15: =IF(OR(T15=0,RIGHT(T15,1)=$W$1),"",COUNTIF($T$3:T15,T15)) | S15: =IF(AND($C$1=K15,$Y$1=YEAR(F15)),C15,0) -> 0 | T15: =IF(F15=0,0,YEAR(F15)&VLOOKUP(K15,$AD$1:$AE$15,2,FALSE)) -> 0 | V15: =IF(AND(YEAR(F15)=$Y$1,K15=$C$1,L15&$V$1<>$V$1),L15,IF(AND(YEAR(F15)=$Y$1,K15=$C$1),1,0)) -> 0 | Y15: =IF(M15<>$AI$1,$Y$2,F14) -> 46023 | AD15: =$AJ$1&$AJ$2 | AE15: x | AH15: =$AJ$1&$AJ$2
B16: =IF($B$1=YEAR(F16),B15+1,B15) -> 0 | C16: =IF(AND($C$1=K16,$Y$1=YEAR(F16)),C15+1,C15) -> 0 | D16: =IF(F16<>0,IF(YEAR(F16)<>YEAR(F15),1,IF(M16=$AI$1,D15,D15+1)),"") | E16: =IF(D16<>"",D16&" - "&YEAR(F16),"") | H16: =IF(G16<>"",F16,"") | P16: =IF(OR(T16=0,RIGHT(T16,1)=$W$1),"",VLOOKUP(K16,$AD$1:$AK$15,5,FALSE)) | Q16: =IF(OR(T16=0,RIGHT(T16,1)=$W$1),"",COUNTIF($T$3:T16,T16)) | S16: =IF(AND($C$1=K16,$Y$1=YEAR(F16)),C16,0) -> 0 | T16: =IF(F16=0,0,YEAR(F16)&VLOOKUP(K16,$AD$1:$AE$15,2,FALSE)) -> 0 | V16: =IF(AND(YEAR(F16)=$Y$1,K16=$C$1,L16&$V$1<>$V$1),L16,IF(AND(YEAR(F16)=$Y$1,K16=$C$1),1,0)) -> 0 | Y16: =IF(M16<>$AI$1,$Y$2,F15) -> 46023
B17: =IF($B$1=YEAR(F17),B16+1,B16) -> 0 | C17: =IF(AND($C$1=K17,$Y$1=YEAR(F17)),C16+1,C16) -> 0 | D17: =IF(F17<>0,IF(YEAR(F17)<>YEAR(F16),1,IF(M17=$AI$1,D16,D16+1)),"") | E17: =IF(D17<>"",D17&" - "&YEAR(F17),"") | H17: =IF(G17<>"",F17,"") | P17: =IF(OR(T17=0,RIGHT(T17,1)=$W$1),"",VLOOKUP(K17,$AD$1:$AK$15,5,FALSE)) | Q17: =IF(OR(T17=0,RIGHT(T17,1)=$W$1),"",COUNTIF($T$3:T17,T17)) | S17: =IF(AND($C$1=K17,$Y$1=YEAR(F17)),C17,0) -> 0 | T17: =IF(F17=0,0,YEAR(F17)&VLOOKUP(K17,$AD$1:$AE$15,2,FALSE)) -> 0 | V17: =IF(AND(YEAR(F17)=$Y$1,K17=$C$1,L17&$V$1<>$V$1),L17,IF(AND(YEAR(F17)=$Y$1,K17=$C$1),1,0)) -> 0 | Y17: =IF(M17<>$AI$1,$Y$2,F16) -> 46023
B18: =IF($B$1=YEAR(F18),B17+1,B17) -> 0 | C18: =IF(AND($C$1=K18,$Y$1=YEAR(F18)),C17+1,C17) -> 0 | D18: =IF(F18<>0,IF(YEAR(F18)<>YEAR(F17),1,IF(M18=$AI$1,D17,D17+1)),"") | E18: =IF(D18<>"",D18&" - "&YEAR(F18),"") | H18: =IF(G18<>"",F18,"") | P18: =IF(OR(T18=0,RIGHT(T18,1)=$W$1),"",VLOOKUP(K18,$AD$1:$AK$15,5,FALSE)) | Q18: =IF(OR(T18=0,RIGHT(T18,1)=$W$1),"",COUNTIF($T$3:T18,T18)) | S18: =IF(AND($C$1=K18,$Y$1=YEAR(F18)),C18,0) -> 0 | T18: =IF(F18=0,0,YEAR(F18)&VLOOKUP(K18,$AD$1:$AE$15,2,FALSE)) -> 0 | V18: =IF(AND(YEAR(F18)=$Y$1,K18=$C$1,L18&$V$1<>$V$1),L18,IF(AND(YEAR(F18)=$Y$1,K18=$C$1),1,0)) -> 0 | Y18: =IF(M18<>$AI$1,$Y$2,F17) -> 46023
B19: =IF($B$1=YEAR(F19),B18+1,B18) -> 0 | C19: =IF(AND($C$1=K19,$Y$1=YEAR(F19)),C18+1,C18) -> 0 | D19: =IF(F19<>0,IF(YEAR(F19)<>YEAR(F18),1,IF(M19=$AI$1,D18,D18+1)),"") | E19: =IF(D19<>"",D19&" - "&YEAR(F19),"") | H19: =IF(G19<>"",F19,"") | P19: =IF(OR(T19=0,RIGHT(T19,1)=$W$1),"",VLOOKUP(K19,$AD$1:$AK$15,5,FALSE)) | Q19: =IF(OR(T19=0,RIGHT(T19,1)=$W$1),"",COUNTIF($T$3:T19,T19)) | S19: =IF(AND($C$1=K19,$Y$1=YEAR(F19)),C19,0) -> 0 | T19: =IF(F19=0,0,YEAR(F19)&VLOOKUP(K19,$AD$1:$AE$15,2,FALSE)) -> 0 | V19: =IF(AND(YEAR(F19)=$Y$1,K19=$C$1,L19&$V$1<>$V$1),L19,IF(AND(YEAR(F19)=$Y$1,K19=$C$1),1,0)) -> 0 | Y19: =IF(M19<>$AI$1,$Y$2,F18) -> 46023
B20: =IF($B$1=YEAR(F20),B19+1,B19) -> 0 | C20: =IF(AND($C$1=K20,$Y$1=YEAR(F20)),C19+1,C19) -> 0 | D20: =IF(F20<>0,IF(YEAR(F20)<>YEAR(F19),1,IF(M20=$AI$1,D19,D19+1)),"") | E20: =IF(D20<>"",D20&" - "&YEAR(F20),"") | H20: =IF(G20<>"",F20,"") | P20: =IF(OR(T20=0,RIGHT(T20,1)=$W$1),"",VLOOKUP(K20,$AD$1:$AK$15,5,FALSE)) | Q20: =IF(OR(T20=0,RIGHT(T20,1)=$W$1),"",COUNTIF($T$3:T20,T20)) | S20: =IF(AND($C$1=K20,$Y$1=YEAR(F20)),C20,0) -> 0 | T20: =IF(F20=0,0,YEAR(F20)&VLOOKUP(K20,$AD$1:$AE$15,2,FALSE)) -> 0 | V20: =IF(AND(YEAR(F20)=$Y$1,K20=$C$1,L20&$V$1<>$V$1),L20,IF(AND(YEAR(F20)=$Y$1,K20=$C$1),1,0)) -> 0 | Y20: =IF(M20<>$AI$1,$Y$2,F19) -> 46023
B21: =IF($B$1=YEAR(F21),B20+1,B20) -> 0 | C21: =IF(AND($C$1=K21,$Y$1=YEAR(F21)),C20+1,C20) -> 0 | D21: =IF(F21<>0,IF(YEAR(F21)<>YEAR(F20),1,IF(M21=$AI$1,D20,D20+1)),"") | E21: =IF(D21<>"",D21&" - "&YEAR(F21),"") | H21: =IF(G21<>"",F21,"") | P21: =IF(OR(T21=0,RIGHT(T21,1)=$W$1),"",VLOOKUP(K21,$AD$1:$AK$15,5,FALSE)) | Q21: =IF(OR(T21=0,RIGHT(T21,1)=$W$1),"",COUNTIF($T$3:T21,T21)) | S21: =IF(AND($C$1=K21,$Y$1=YEAR(F21)),C21,0) -> 0 | T21: =IF(F21=0,0,YEAR(F21)&VLOOKUP(K21,$AD$1:$AE$15,2,FALSE)) -> 0 | V21: =IF(AND(YEAR(F21)=$Y$1,K21=$C$1,L21&$V$1<>$V$1),L21,IF(AND(YEAR(F21)=$Y$1,K21=$C$1),1,0)) -> 0 | Y21: =IF(M21<>$AI$1,$Y$2,F20) -> 46023
B22: =IF($B$1=YEAR(F22),B21+1,B21) -> 0 | C22: =IF(AND($C$1=K22,$Y$1=YEAR(F22)),C21+1,C21) -> 0 | D22: =IF(F22<>0,IF(YEAR(F22)<>YEAR(F21),1,IF(M22=$AI$1,D21,D21+1)),"") | E22: =IF(D22<>"",D22&" - "&YEAR(F22),"") | H22: =IF(G22<>"",F22,"") | P22: =IF(OR(T22=0,RIGHT(T22,1)=$W$1),"",VLOOKUP(K22,$AD$1:$AK$15,5,FALSE)) | Q22: =IF(OR(T22=0,RIGHT(T22,1)=$W$1),"",COUNTIF($T$3:T22,T22)) | S22: =IF(AND($C$1=K22,$Y$1=YEAR(F22)),C22,0) -> 0 | T22: =IF(F22=0,0,YEAR(F22)&VLOOKUP(K22,$AD$1:$AE$15,2,FALSE)) -> 0 | V22: =IF(AND(YEAR(F22)=$Y$1,K22=$C$1,L22&$V$1<>$V$1),L22,IF(AND(YEAR(F22)=$Y$1,K22=$C$1),1,0)) -> 0 | Y22: =IF(M22<>$AI$1,$Y$2,F21) -> 46023
B23: =IF($B$1=YEAR(F23),B22+1,B22) -> 0 | C23: =IF(AND($C$1=K23,$Y$1=YEAR(F23)),C22+1,C22) -> 0 | D23: =IF(F23<>0,IF(YEAR(F23)<>YEAR(F22),1,IF(M23=$AI$1,D22,D22+1)),"") | E23: =IF(D23<>"",D23&" - "&YEAR(F23),"") | H23: =IF(G23<>"",F23,"") | P23: =IF(OR(T23=0,RIGHT(T23,1)=$W$1),"",VLOOKUP(K23,$AD$1:$AK$15,5,FALSE)) | Q23: =IF(OR(T23=0,RIGHT(T23,1)=$W$1),"",COUNTIF($T$3:T23,T23)) | S23: =IF(AND($C$1=K23,$Y$1=YEAR(F23)),C23,0) -> 0 | T23: =IF(F23=0,0,YEAR(F23)&VLOOKUP(K23,$AD$1:$AE$15,2,FALSE)) -> 0 | V23: =IF(AND(YEAR(F23)=$Y$1,K23=$C$1,L23&$V$1<>$V$1),L23,IF(AND(YEAR(F23)=$Y$1,K23=$C$1),1,0)) -> 0 | Y23: =IF(M23<>$AI$1,$Y$2,F22) -> 46023
B24: =IF($B$1=YEAR(F24),B23+1,B23) -> 0 | C24: =IF(AND($C$1=K24,$Y$1=YEAR(F24)),C23+1,C23) -> 0 | D24: =IF(F24<>0,IF(YEAR(F24)<>YEAR(F23),1,IF(M24=$AI$1,D23,D23+1)),"") | E24: =IF(D24<>"",D24&" - "&YEAR(F24),"") | H24: =IF(G24<>"",F24,"") | P24: =IF(OR(T24=0,RIGHT(T24,1)=$W$1),"",VLOOKUP(K24,$AD$1:$AK$15,5,FALSE)) | Q24: =IF(OR(T24=0,RIGHT(T24,1)=$W$1),"",COUNTIF($T$3:T24,T24)) | S24: =IF(AND($C$1=K24,$Y$1=YEAR(F24)),C24,0) -> 0 | T24: =IF(F24=0,0,YEAR(F24)&VLOOKUP(K24,$AD$1:$AE$15,2,FALSE)) -> 0 | V24: =IF(AND(YEAR(F24)=$Y$1,K24=$C$1,L24&$V$1<>$V$1),L24,IF(AND(YEAR(F24)=$Y$1,K24=$C$1),1,0)) -> 0 | Y24: =IF(M24<>$AI$1,$Y$2,F23) -> 46023
B25: =IF($B$1=YEAR(F25),B24+1,B24) -> 0 | C25: =IF(AND($C$1=K25,$Y$1=YEAR(F25)),C24+1,C24) -> 0 | D25: =IF(F25<>0,IF(YEAR(F25)<>YEAR(F24),1,IF(M25=$AI$1,D24,D24+1)),"") | E25: =IF(D25<>"",D25&" - "&YEAR(F25),"") | H25: =IF(G25<>"",F25,"") | P25: =IF(OR(T25=0,RIGHT(T25,1)=$W$1),"",VLOOKUP(K25,$AD$1:$AK$15,5,FALSE)) | Q25: =IF(OR(T25=0,RIGHT(T25,1)=$W$1),"",COUNTIF($T$3:T25,T25)) | S25: =IF(AND($C$1=K25,$Y$1=YEAR(F25)),C25,0) -> 0 | T25: =IF(F25=0,0,YEAR(F25)&VLOOKUP(K25,$AD$1:$AE$15,2,FALSE)) -> 0 | V25: =IF(AND(YEAR(F25)=$Y$1,K25=$C$1,L25&$V$1<>$V$1),L25,IF(AND(YEAR(F25)=$Y$1,K25=$C$1),1,0)) -> 0 | Y25: =IF(M25<>$AI$1,$Y$2,F24) -> 46023
B26: =IF($B$1=YEAR(F26),B25+1,B25) -> 0 | C26: =IF(AND($C$1=K26,$Y$1=YEAR(F26)),C25+1,C25) -> 0 | D26: =IF(F26<>0,IF(YEAR(F26)<>YEAR(F25),1,IF(M26=$AI$1,D25,D25+1)),"") | E26: =IF(D26<>"",D26&" - "&YEAR(F26),"") | H26: =IF(G26<>"",F26,"") | P26: =IF(OR(T26=0,RIGHT(T26,1)=$W$1),"",VLOOKUP(K26,$AD$1:$AK$15,5,FALSE)) | Q26: =IF(OR(T26=0,RIGHT(T26,1)=$W$1),"",COUNTIF($T$3:T26,T26)) | S26: =IF(AND($C$1=K26,$Y$1=YEAR(F26)),C26,0) -> 0 | T26: =IF(F26=0,0,YEAR(F26)&VLOOKUP(K26,$AD$1:$AE$15,2,FALSE)) -> 0 | V26: =IF(AND(YEAR(F26)=$Y$1,K26=$C$1,L26&$V$1<>$V$1),L26,IF(AND(YEAR(F26)=$Y$1,K26=$C$1),1,0)) -> 0 | Y26: =IF(M26<>$AI$1,$Y$2,F25) -> 46023
B27: =IF($B$1=YEAR(F27),B26+1,B26) -> 0 | C27: =IF(AND($C$1=K27,$Y$1=YEAR(F27)),C26+1,C26) -> 0 | D27: =IF(F27<>0,IF(YEAR(F27)<>YEAR(F26),1,IF(M27=$AI$1,D26,D26+1)),"") | E27: =IF(D27<>"",D27&" - "&YEAR(F27),"") | H27: =IF(G27<>"",F27,"") | P27: =IF(OR(T27=0,RIGHT(T27,1)=$W$1),"",VLOOKUP(K27,$AD$1:$AK$15,5,FALSE)) | Q27: =IF(OR(T27=0,RIGHT(T27,1)=$W$1),"",COUNTIF($T$3:T27,T27)) | S27: =IF(AND($C$1=K27,$Y$1=YEAR(F27)),C27,0) -> 0 | T27: =IF(F27=0,0,YEAR(F27)&VLOOKUP(K27,$AD$1:$AE$15,2,FALSE)) -> 0 | V27: =IF(AND(YEAR(F27)=$Y$1,K27=$C$1,L27&$V$1<>$V$1),L27,IF(AND(YEAR(F27)=$Y$1,K27=$C$1),1,0)) -> 0 | Y27: =IF(M27<>$AI$1,$Y$2,F26) -> 46023
... B5000: =IF($B$1=YEAR(F5000),B4999+1,B4999) -> 0 | C5000: =IF(AND($C$1=K5000,$Y$1=YEAR(F5000)),C4999+1,C4999) -> 0 | D5000: =IF(F5000<>0,IF(YEAR(F5000)<>YEAR(F4999),1,IF(M5000=$AI$1,D4999,D4999+1)),"") | E5000: =IF(D5000<>"",D5000&" - "&YEAR(F5000),"") | H5000: =IF(G5000<>"",F5000,"") | P5000: =IF(OR(T5000=0,RIGHT(T5000,1)=$W$1),"",VLOOKUP(K5000,$AD$1:$AK$15,5,FALSE)) | Q5000: =IF(OR(T5000=0,RIGHT(T5000,1)=$W$1),"",COUNTIF($T$3:T5000,T5000)) | S5000: =IF(AND($C$1=K5000,$Y$1=YEAR(F5000)),C5000,0) -> 0 | T5000: =IF(F5000=0,0,YEAR(F5000)&VLOOKUP(K5000,$AD$1:$AE$15,2,FALSE)) -> 0 | V5000: =IF(AND(YEAR(F5000)=$Y$1,K5000=$C$1,L5000&$V$1<>$V$1),L5000,IF(AND(YEAR(F5000)=$Y$1,K5000=$C$1),1,0)) -> 0 | Y5000: =IF(M5000<>$AI$1,$Y$2,F4999) -> 46023

Sheet Irattari_leltar
A1: A sormagasságok helyes beállításáért nyomtatás előtt az 1-es fölötti, az A-tól balra levő négyzetre kell kattintani, utána kétszer az 1 és 2 kettő közötti elválasztó vonalra. | D1: A jobboldali, zöld cellába lehet beírni az évszámot | G1: 2025 | I1: =IF(OR(G1=0,G1=""),YEAR(I7),G1) -> 2025 | K1: =L1+10 -> 10 | L1: =MAX(Iktato!C3:C10000) -> 0
D2: A jobboldali, zöld cella lenyílójából lehet kiválasztani az iratgyűjtő nevét. | G2: Levelezés | I2: =IF(OR(G2=0,G2="",ISERROR(VLOOKUP(G2,Iktato!$AD$1:$AF$13,3,FALSE))=TRUE),Iktato!AD1,G2) -> Levelezés | L2: =ROUNDUP(L1/300,0) -> 0 | M2: Ezen a leltáríven összesen
D3: =IF(L2>1,M2&L2&M3&I3&M4,"") | H3: A A | I3: =IF(OR(G3=0,G3="",G3>L2),1,G3) -> 1 | L3: =ROUNDDOWN(L1/40,0) -> 0 | M3: lap van. Ebből jelenleg a
M4: . látszik. A jobboldali, zöld cellában lehet megadni a listázni kívánt lapszámot.
A6: =IF(Iktato!F1=Iktato!R2,Iktato!R1,Iktato!F1) -> AZ EGYHÁZKÖZSÉG NEVÉT AZ "Iktató" MUNKALAPON LEHET KITÖLTENI
A7: =IF(ISERROR(VLOOKUP(I2,Iktato!$AD$1:$AF$13,3,FALSE))=FALSE,VLOOKUP(I2,Iktato!$AD$1:$AF$13,3,FALSE),"") -> Levelezés (egyházkerületi, egyházmegyei, egyházközségi, világi hatóságokkal, magánszemélyekkel) | I7: =TODAY() -> 46026
A8: =I8&I1&J8 -> 1 - 2025. számú iratgyűjtő | I8: =VLOOKUP(I2,Iktato!$AD$1:$AG$14,4,FALSE) -> 1 - | J8: . számú iratgyűjtő
K9: ="<="&H10 -> <=0 | L9: =SUMIF(Iktato!$S$3:$S$10000,K9,Iktato!$V$3:$V$10000) -> 0
A10: S. sz. | B10: Ikt. sz. | C10: Dátum | D10: Küldő Cimzett | E10: Tárgy | F10: Lap szám | H10: =ROUND(SUM(I3,-1)*300,0) -> 0 | K10: =L9 -> 0
A11: =IF(H11<=$L$1,H11,"") | B11: =IF(H11<=$L$1,VLOOKUP(H11,Iktato!$C$3:$O$10000,2,FALSE),"") | C11: =IF(H11<=$L$1,VLOOKUP(H11,Iktato!$C$3:$O$10000,4,FALSE),"") | D11: =TRIM(IF(H11<=$L$1,VLOOKUP(H11,Iktato!$C$3:$O$10000,7,FALSE),"")) | E11: =TRIM(IF(H11<=$L$1,VLOOKUP(H11,Iktato!$C$3:$O$10000,8,FALSE),"")) | F11: =IF(H11<=$L$1,J11,"") | H11: =H10+1 -> 1 | J11: =IF(L11<>0,IF(K11<>K10+1,K10+1&"-"&K11,K11),J10) -> 0 | K11: =SUM($L$9,$L$11:L11) -> 0 | L11: =SUMIF(Iktato!$S$3:$S$10000,H11,Iktato!$V$3:$V$10000) -> 0
A12: =IF(H12<=$L$1,H12,"") | B12: =IF(H12<=$L$1,VLOOKUP(H12,Iktato!$C$3:$O$10000,2,FALSE),"") | C12: =IF(H12<=$L$1,VLOOKUP(H12,Iktato!$C$3:$O$10000,4,FALSE),"") | D12: =TRIM(IF(H12<=$L$1,VLOOKUP(H12,Iktato!$C$3:$O$10000,7,FALSE),"")) | E12: =TRIM(IF(H12<=$L$1,VLOOKUP(H12,Iktato!$C$3:$O$10000,8,FALSE),"")) | F12: =IF(H12<=$L$1,J12,"") | H12: =H11+1 -> 2 | J12: =IF(L12<>0,IF(K12<>K11+1,K11+1&"-"&K12,K12),J11) -> 0 | K12: =SUM($L$9,$L$11:L12) -> 0 | L12: =SUMIF(Iktato!$S$3:$S$10000,H12,Iktato!$V$3:$V$10000) -> 0
A13: =IF(H13<=$L$1,H13,"") | B13: =IF(H13<=$L$1,VLOOKUP(H13,Iktato!$C$3:$O$10000,2,FALSE),"") | C13: =IF(H13<=$L$1,VLOOKUP(H13,Iktato!$C$3:$O$10000,4,FALSE),"") | D13: =TRIM(IF(H13<=$L$1,VLOOKUP(H13,Iktato!$C$3:$O$10000,7,FALSE),"")) | E13: =TRIM(IF(H13<=$L$1,VLOOKUP(H13,Iktato!$C$3:$O$10000,8,FALSE),"")) | F13: =IF(H13<=$L$1,J13,"") | H13: =H12+1 -> 3 | J13: =IF(L13<>0,IF(K13<>K12+1,K12+1&"-"&K13,K13),J12) -> 0 | K13: =SUM($L$9,$L$11:L13) -> 0 | L13: =SUMIF(Iktato!$S$3:$S$10000,H13,Iktato!$V$3:$V$10000) -> 0
A14: =IF(H14<=$L$1,H14,"") | B14: =IF(H14<=$L$1,VLOOKUP(H14,Iktato!$C$3:$O$10000,2,FALSE),"") | C14: =IF(H14<=$L$1,VLOOKUP(H14,Iktato!$C$3:$O$10000,4,FALSE),"") | D14: =TRIM(IF(H14<=$L$1,VLOOKUP(H14,Iktato!$C$3:$O$10000,7,FALSE),"")) | E14: =TRIM(IF(H14<=$L$1,VLOOKUP(H14,Iktato!$C$3:$O$10000,8,FALSE),"")) | F14: =IF(H14<=$L$1,J14,"") | H14: =H13+1 -> 4 | J14: =IF(L14<>0,IF(K14<>K13+1,K13+1&"-"&K14,K14),J13) -> 0 | K14: =SUM($L$9,$L$11:L14) -> 0 | L14: =SUMIF(Iktato!$S$3:$S$10000,H14,Iktato!$V$3:$V$10000) -> 0
A15: =IF(H15<=$L$1,H15,"") | B15: =IF(H15<=$L$1,VLOOKUP(H15,Iktato!$C$3:$O$10000,2,FALSE),"") | C15: =IF(H15<=$L$1,VLOOKUP(H15,Iktato!$C$3:$O$10000,4,FALSE),"") | D15: =TRIM(IF(H15<=$L$1,VLOOKUP(H15,Iktato!$C$3:$O$10000,7,FALSE),"")) | E15: =TRIM(IF(H15<=$L$1,VLOOKUP(H15,Iktato!$C$3:$O$10000,8,FALSE),"")) | F15: =IF(H15<=$L$1,J15,"") | H15: =H14+1 -> 5 | J15: =IF(L15<>0,IF(K15<>K14+1,K14+1&"-"&K15,K15),J14) -> 0 | K15: =SUM($L$9,$L$11:L15) -> 0 | L15: =SUMIF(Iktato!$S$3:$S$10000,H15,Iktato!$V$3:$V$10000) -> 0
A16: =IF(H16<=$L$1,H16,"") | B16: =IF(H16<=$L$1,VLOOKUP(H16,Iktato!$C$3:$O$10000,2,FALSE),"") | C16: =IF(H16<=$L$1,VLOOKUP(H16,Iktato!$C$3:$O$10000,4,FALSE),"") | D16: =TRIM(IF(H16<=$L$1,VLOOKUP(H16,Iktato!$C$3:$O$10000,7,FALSE),"")) | E16: =TRIM(IF(H16<=$L$1,VLOOKUP(H16,Iktato!$C$3:$O$10000,8,FALSE),"")) | F16: =IF(H16<=$L$1,J16,"") | H16: =H15+1 -> 6 | J16: =IF(L16<>0,IF(K16<>K15+1,K15+1&"-"&K16,K16),J15) -> 0 | K16: =SUM($L$9,$L$11:L16) -> 0 | L16: =SUMIF(Iktato!$S$3:$S$10000,H16,Iktato!$V$3:$V$10000) -> 0
A17: =IF(H17<=$L$1,H17,"") | B17: =IF(H17<=$L$1,VLOOKUP(H17,Iktato!$C$3:$O$10000,2,FALSE),"") | C17: =IF(H17<=$L$1,VLOOKUP(H17,Iktato!$C$3:$O$10000,4,FALSE),"") | D17: =TRIM(IF(H17<=$L$1,VLOOKUP(H17,Iktato!$C$3:$O$10000,7,FALSE),"")) | E17: =TRIM(IF(H17<=$L$1,VLOOKUP(H17,Iktato!$C$3:$O$10000,8,FALSE),"")) | F17: =IF(H17<=$L$1,J17,"") | H17: =H16+1 -> 7 | J17: =IF(L17<>0,IF(K17<>K16+1,K16+1&"-"&K17,K17),J16) -> 0 | K17: =SUM($L$9,$L$11:L17) -> 0 | L17: =SUMIF(Iktato!$S$3:$S$10000,H17,Iktato!$V$3:$V$10000) -> 0
A18: =IF(H18<=$L$1,H18,"") | B18: =IF(H18<=$L$1,VLOOKUP(H18,Iktato!$C$3:$O$10000,2,FALSE),"") | C18: =IF(H18<=$L$1,VLOOKUP(H18,Iktato!$C$3:$O$10000,4,FALSE),"") | D18: =TRIM(IF(H18<=$L$1,VLOOKUP(H18,Iktato!$C$3:$O$10000,7,FALSE),"")) | E18: =TRIM(IF(H18<=$L$1,VLOOKUP(H18,Iktato!$C$3:$O$10000,8,FALSE),"")) | F18: =IF(H18<=$L$1,J18,"") | H18: =H17+1 -> 8 | J18: =IF(L18<>0,IF(K18<>K17+1,K17+1&"-"&K18,K18),J17) -> 0 | K18: =SUM($L$9,$L$11:L18) -> 0 | L18: =SUMIF(Iktato!$S$3:$S$10000,H18,Iktato!$V$3:$V$10000) -> 0
A19: =IF(H19<=$L$1,H19,"") | B19: =IF(H19<=$L$1,VLOOKUP(H19,Iktato!$C$3:$O$10000,2,FALSE),"") | C19: =IF(H19<=$L$1,VLOOKUP(H19,Iktato!$C$3:$O$10000,4,FALSE),"") | D19: =TRIM(IF(H19<=$L$1,VLOOKUP(H19,Iktato!$C$3:$O$10000,7,FALSE),"")) | E19: =TRIM(IF(H19<=$L$1,VLOOKUP(H19,Iktato!$C$3:$O$10000,8,FALSE),"")) | F19: =IF(H19<=$L$1,J19,"") | H19: =H18+1 -> 9 | J19: =IF(L19<>0,IF(K19<>K18+1,K18+1&"-"&K19,K19),J18) -> 0 | K19: =SUM($L$9,$L$11:L19) -> 0 | L19: =SUMIF(Iktato!$S$3:$S$10000,H19,Iktato!$V$3:$V$10000) -> 0
A20: =IF(H20<=$L$1,H20,"") | B20: =IF(H20<=$L$1,VLOOKUP(H20,Iktato!$C$3:$O$10000,2,FALSE),"") | C20: =IF(H20<=$L$1,VLOOKUP(H20,Iktato!$C$3:$O$10000,4,FALSE),"") | D20: =TRIM(IF(H20<=$L$1,VLOOKUP(H20,Iktato!$C$3:$O$10000,7,FALSE),"")) | E20: =TRIM(IF(H20<=$L$1,VLOOKUP(H20,Iktato!$C$3:$O$10000,8,FALSE),"")) | F20: =IF(H20<=$L$1,J20,"") | H20: =H19+1 -> 10 | J20: =IF(L20<>0,IF(K20<>K19+1,K19+1&"-"&K20,K20),J19) -> 0 | K20: =SUM($L$9,$L$11:L20) -> 0 | L20: =SUMIF(Iktato!$S$3:$S$10000,H20,Iktato!$V$3:$V$10000) -> 0
A21: =IF(H21<=$L$1,H21,"") | B21: =IF(H21<=$L$1,VLOOKUP(H21,Iktato!$C$3:$O$10000,2,FALSE),"") | C21: =IF(H21<=$L$1,VLOOKUP(H21,Iktato!$C$3:$O$10000,4,FALSE),"") | D21: =TRIM(IF(H21<=$L$1,VLOOKUP(H21,Iktato!$C$3:$O$10000,7,FALSE),"")) | E21: =TRIM(IF(H21<=$L$1,VLOOKUP(H21,Iktato!$C$3:$O$10000,8,FALSE),"")) | F21: =IF(H21<=$L$1,J21,"") | H21: =H20+1 -> 11 | J21: =IF(L21<>0,IF(K21<>K20+1,K20+1&"-"&K21,K21),J20) -> 0 | K21: =SUM($L$9,$L$11:L21) -> 0 | L21: =SUMIF(Iktato!$S$3:$S$10000,H21,Iktato!$V$3:$V$10000) -> 0
A22: =IF(H22<=$L$1,H22,"") | B22: =IF(H22<=$L$1,VLOOKUP(H22,Iktato!$C$3:$O$10000,2,FALSE),"") | C22: =IF(H22<=$L$1,VLOOKUP(H22,Iktato!$C$3:$O$10000,4,FALSE),"") | D22: =TRIM(IF(H22<=$L$1,VLOOKUP(H22,Iktato!$C$3:$O$10000,7,FALSE),"")) | E22: =TRIM(IF(H22<=$L$1,VLOOKUP(H22,Iktato!$C$3:$O$10000,8,FALSE),"")) | F22: =IF(H22<=$L$1,J22,"") | H22: =H21+1 -> 12 | J22: =IF(L22<>0,IF(K22<>K21+1,K21+1&"-"&K22,K22),J21) -> 0 | K22: =SUM($L$9,$L$11:L22) -> 0 | L22: =SUMIF(Iktato!$S$3:$S$10000,H22,Iktato!$V$3:$V$10000) -> 0
... A311: =IF(H311<=$L$1,H311,"") | B311: =IF(H311<=$L$1,VLOOKUP(H311,Iktato!$C$3:$O$10000,2,FALSE),"") | C311: =IF(H311<=$L$1,VLOOKUP(H311,Iktato!$C$3:$O$10000,4,FALSE),"") | D311: =TRIM(IF(H311<=$L$1,VLOOKUP(H311,Iktato!$C$3:$O$10000,7,FALSE),"")) | E311: =TRIM(IF(H311<=$L$1,VLOOKUP(H311,Iktato!$C$3:$O$10000,8,FALSE),"")) | F311: =IF(H311<=$L$1,J311,"") | H311: =H310+1 -> 301 | J311: =IF(L311<>0,IF(K311<>K310+1,K310+1&"-"&K311,K311),J310) -> 0 | K311: =SUM($L$9,$L$11:L311) -> 0 | L311: =SUMIF(Iktato!$S$3:$S$10000,H311,Iktato!$V$3:$V$10000) -> 0

Sheet Nyomtathato_iktato
A1: A sormagasságok helyes beállításáért nyomtatás előtt az 1-es fölötti, az A-tól balra levő négyzetre kell kattintani, utána kétszer az 1 és 2 kettő közötti elválasztó vonalra. | D1: A jobboldali, zöld cellába lehet beírni az évszámot | F1: 2025 | I1: =IF(OR(F1=0,F1=""),YEAR(I2),F1) -> 2025 | K1: =IF(OR(F2=0,F2="",F2>M2),1,F2) -> 1 | M1: =MAX(Iktato!B3:B10000) -> 0 | N1: =M1+10 -> 10
D2: =IF(M2>1,K2&M2&K3&K1&K4,"") | I2: =Iktato!Y2 -> 46023 | J2: a a | K2: Ebben az iktatóban összesen | M2: =ROUNDUP(M1/400,0) -> 0
K3: lap van. Ebből jelenleg a
K4: . látszik. A jobboldali, zöld cellában lehet megadni a listázni kívánt lapszámot.
A6: =IF(Iktato!F1=Iktato!R2,Iktato!R1,Iktato!F1) -> AZ EGYHÁZKÖZSÉG NEVÉT AZ "Iktató" MUNKALAPON LEHET KITÖLTENI
A7: IKTATOTT IRATOK
A8: =I1 -> 2025
A10: Ikt. sz. | B10: Dátum | C10: Beadvány száma és kelte | D10: Cím | E10: Tárgykivonat | F10: Irattári jele | I10: =SUM(K1,-1)*400 -> 0 | M10: / | R10: .
A11: =IF($M$1>=I11,J11,"") | B11: =IF($M$1>=I11,VLOOKUP(I11,Iktato!$B$3:$L$10000,5,FALSE),"") | C11: =TRIM(IF(AND(P11&Q11<>"",$M$1>=I11),P11&"-"&R11&$R$10&S11&$R$10&T11&$R$10,"")) | D11: =TRIM(IF($M$1>=I11,IF(VLOOKUP(I11,Iktato!$B$3:$L$10000,8,FALSE)<>0,VLOOKUP(I11,Iktato!$B$3:$L$10000,8,FALSE),""),"")) | E11: =TRIM(IF($M$1>=I11,IF(VLOOKUP(I11,Iktato!$B$3:$L$10000,9,FALSE)<>0,VLOOKUP(I11,Iktato!$B$3:$L$10000,9,FALSE),""),"")) | F11: =TRIM(IF($M$1>=I11,M11&$M$10&N11,"")) | I11: =I10+1 -> 1 | J11: =IF(K10<>K11,K11,"") | K11: =IF($M$1>=I11,VLOOKUP(I11,Iktato!$B$3:$L$10000,3,FALSE),"") | M11: =IF($M$1>=I11,IF(VLOOKUP(I11,Iktato!$B$3:$P$10000,15,FALSE)<>0,VLOOKUP(I11,Iktato!$B$3:$P$10000,15,FALSE),""),"") | N11: =IF($M$1>=I11,IF(VLOOKUP(I11,Iktato!$B$3:$Q$10000,16,FALSE)<>0,VLOOKUP(I11,Iktato!$B$3:$Q$10000,16,FALSE),""),"") | P11: =TRIM(IF($M$1>=I11,IF(VLOOKUP(I11,Iktato!$B$3:$L$10000,6,FALSE)<>0,VLOOKUP(I11,Iktato!$B$3:$L$10000,6,FALSE),""),"")) | Q11: =TRIM(IF($M$1>=I11,IF(VLOOKUP(I11,Iktato!$B$3:$L$10000,7,FALSE)<>0,VLOOKUP(I11,Iktato!$B$3:$L$10000,7,FALSE),""),"")) | R11: =IF(Q11<>"",YEAR(Q11),"") | S11: =IF(Q11<>"",MONTH(Q11),"") | T11: =IF(Q11<>"",DAY(Q11),"")
A12: =IF($M$1>=I12,J12,"") | B12: =IF($M$1>=I12,VLOOKUP(I12,Iktato!$B$3:$L$10000,5,FALSE),"") | C12: =TRIM(IF(AND(P12&Q12<>"",$M$1>=I12),P12&"-"&R12&$R$10&S12&$R$10&T12&$R$10,"")) | D12: =TRIM(IF($M$1>=I12,IF(VLOOKUP(I12,Iktato!$B$3:$L$10000,8,FALSE)<>0,VLOOKUP(I12,Iktato!$B$3:$L$10000,8,FALSE),""),"")) | E12: =TRIM(IF($M$1>=I12,IF(VLOOKUP(I12,Iktato!$B$3:$L$10000,9,FALSE)<>0,VLOOKUP(I12,Iktato!$B$3:$L$10000,9,FALSE),""),"")) | F12: =TRIM(IF($M$1>=I12,M12&$M$10&N12,"")) | I12: =I11+1 -> 2 | J12: =IF(K11<>K12,K12,"") | K12: =IF($M$1>=I12,VLOOKUP(I12,Iktato!$B$3:$L$10000,3,FALSE),"") | M12: =IF($M$1>=I12,IF(VLOOKUP(I12,Iktato!$B$3:$P$10000,15,FALSE)<>0,VLOOKUP(I12,Iktato!$B$3:$P$10000,15,FALSE),""),"") | N12: =IF($M$1>=I12,IF(VLOOKUP(I12,Iktato!$B$3:$Q$10000,16,FALSE)<>0,VLOOKUP(I12,Iktato!$B$3:$Q$10000,16,FALSE),""),"") | P12: =TRIM(IF($M$1>=I12,IF(VLOOKUP(I12,Iktato!$B$3:$L$10000,6,FALSE)<>0,VLOOKUP(I12,Iktato!$B$3:$L$10000,6,FALSE),""),"")) | Q12: =TRIM(IF($M$1>=I12,IF(VLOOKUP(I12,Iktato!$B$3:$L$10000,7,FALSE)<>0,VLOOKUP(I12,Iktato!$B$3:$L$10000,7,FALSE),""),"")) | R12: =IF(Q12<>"",YEAR(Q12),"") | S12: =IF(Q12<>"",MONTH(Q12),"") | T12: =IF(Q12<>"",DAY(Q12),"")
A13: =IF($M$1>=I13,J13,"") | B13: =IF($M$1>=I13,VLOOKUP(I13,Iktato!$B$3:$L$10000,5,FALSE),"") | C13: =TRIM(IF(AND(P13&Q13<>"",$M$1>=I13),P13&"-"&R13&$R$10&S13&$R$10&T13&$R$10,"")) | D13: =TRIM(IF($M$1>=I13,IF(VLOOKUP(I13,Iktato!$B$3:$L$10000,8,FALSE)<>0,VLOOKUP(I13,Iktato!$B$3:$L$10000,8,FALSE),""),"")) | E13: =TRIM(IF($M$1>=I13,IF(VLOOKUP(I13,Iktato!$B$3:$L$10000,9,FALSE)<>0,VLOOKUP(I13,Iktato!$B$3:$L$10000,9,FALSE),""),"")) | F13: =TRIM(IF($M$1>=I13,M13&$M$10&N13,"")) | I13: =I12+1 -> 3 | J13: =IF(K12<>K13,K13,"") | K13: =IF($M$1>=I13,VLOOKUP(I13,Iktato!$B$3:$L$10000,3,FALSE),"") | M13: =IF($M$1>=I13,IF(VLOOKUP(I13,Iktato!$B$3:$P$10000,15,FALSE)<>0,VLOOKUP(I13,Iktato!$B$3:$P$10000,15,FALSE),""),"") | N13: =IF($M$1>=I13,IF(VLOOKUP(I13,Iktato!$B$3:$Q$10000,16,FALSE)<>0,VLOOKUP(I13,Iktato!$B$3:$Q$10000,16,FALSE),""),"") | P13: =TRIM(IF($M$1>=I13,IF(VLOOKUP(I13,Iktato!$B$3:$L$10000,6,FALSE)<>0,VLOOKUP(I13,Iktato!$B$3:$L$10000,6,FALSE),""),"")) | Q13: =TRIM(IF($M$1>=I13,IF(VLOOKUP(I13,Iktato!$B$3:$L$10000,7,FALSE)<>0,VLOOKUP(I13,Iktato!$B$3:$L$10000,7,FALSE),""),"")) | R13: =IF(Q13<>"",YEAR(Q13),"") | S13: =IF(Q13<>"",MONTH(Q13),"") | T13: =IF(Q13<>"",DAY(Q13),"")
A14: =IF($M$1>=I14,J14,"") | B14: =IF($M$1>=I14,VLOOKUP(I14,Iktato!$B$3:$L$10000,5,FALSE),"") | C14: =TRIM(IF(AND(P14&Q14<>"",$M$1>=I14),P14&"-"&R14&$R$10&S14&$R$10&T14&$R$10,"")) | D14: =TRIM(IF($M$1>=I14,IF(VLOOKUP(I14,Iktato!$B$3:$L$10000,8,FALSE)<>0,VLOOKUP(I14,Iktato!$B$3:$L$10000,8,FALSE),""),"")) | E14: =TRIM(IF($M$1>=I14,IF(VLOOKUP(I14,Iktato!$B$3:$L$10000,9,FALSE)<>0,VLOOKUP(I14,Iktato!$B$3:$L$10000,9,FALSE),""),"")) | F14: =TRIM(IF($M$1>=I14,M14&$M$10&N14,"")) | I14: =I13+1 -> 4 | J14: =IF(K13<>K14,K14,"") | K14: =IF($M$1>=I14,VLOOKUP(I14,Iktato!$B$3:$L$10000,3,FALSE),"") | M14: =IF($M$1>=I14,IF(VLOOKUP(I14,Iktato!$B$3:$P$10000,15,FALSE)<>0,VLOOKUP(I14,Iktato!$B$3:$P$10000,15,FALSE),""),"") | N14: =IF($M$1>=I14,IF(VLOOKUP(I14,Iktato!$B$3:$Q$10000,16,FALSE)<>0,VLOOKUP(I14,Iktato!$B$3:$Q$10000,16,FALSE),""),"") | P14: =TRIM(IF($M$1>=I14,IF(VLOOKUP(I14,Iktato!$B$3:$L$10000,6,FALSE)<>0,VLOOKUP(I14,Iktato!$B$3:$L$10000,6,FALSE),""),"")) | Q14: =TRIM(IF($M$1>=I14,IF(VLOOKUP(I14,Iktato!$B$3:$L$10000,7,FALSE)<>0,VLOOKUP(I14,Iktato!$B$3:$L$10000,7,FALSE),""),"")) | R14: =IF(Q14<>"",YEAR(Q14),"") | S14: =IF(Q14<>"",MONTH(Q14),"") | T14: =IF(Q14<>"",DAY(Q14),"")
A15: =IF($M$1>=I15,J15,"") | B15: =IF($M$1>=I15,VLOOKUP(I15,Iktato!$B$3:$L$10000,5,FALSE),"") | C15: =TRIM(IF(AND(P15&Q15<>"",$M$1>=I15),P15&"-"&R15&$R$10&S15&$R$10&T15&$R$10,"")) | D15: =TRIM(IF($M$1>=I15,IF(VLOOKUP(I15,Iktato!$B$3:$L$10000,8,FALSE)<>0,VLOOKUP(I15,Iktato!$B$3:$L$10000,8,FALSE),""),"")) | E15: =TRIM(IF($M$1>=I15,IF(VLOOKUP(I15,Iktato!$B$3:$L$10000,9,FALSE)<>0,VLOOKUP(I15,Iktato!$B$3:$L$10000,9,FALSE),""),"")) | F15: =TRIM(IF($M$1>=I15,M15&$M$10&N15,"")) | I15: =I14+1 -> 5 | J15: =IF(K14<>K15,K15,"") | K15: =IF($M$1>=I15,VLOOKUP(I15,Iktato!$B$3:$L$10000,3,FALSE),"") | M15: =IF($M$1>=I15,IF(VLOOKUP(I15,Iktato!$B$3:$P$10000,15,FALSE)<>0,VLOOKUP(I15,Iktato!$B$3:$P$10000,15,FALSE),""),"") | N15: =IF($M$1>=I15,IF(VLOOKUP(I15,Iktato!$B$3:$Q$10000,16,FALSE)<>0,VLOOKUP(I15,Iktato!$B$3:$Q$10000,16,FALSE),""),"") | P15: =TRIM(IF($M$1>=I15,IF(VLOOKUP(I15,Iktato!$B$3:$L$10000,6,FALSE)<>0,VLOOKUP(I15,Iktato!$B$3:$L$10000,6,FALSE),""),"")) | Q15: =TRIM(IF($M$1>=I15,IF(VLOOKUP(I15,Iktato!$B$3:$L$10000,7,FALSE)<>0,VLOOKUP(I15,Iktato!$B$3:$L$10000,7,FALSE),""),"")) | R15: =IF(Q15<>"",YEAR(Q15),"") | S15: =IF(Q15<>"",MONTH(Q15),"") | T15: =IF(Q15<>"",DAY(Q15),"")
A16: =IF($M$1>=I16,J16,"") | B16: =IF($M$1>=I16,VLOOKUP(I16,Iktato!$B$3:$L$10000,5,FALSE),"") | C16: =TRIM(IF(AND(P16&Q16<>"",$M$1>=I16),P16&"-"&R16&$R$10&S16&$R$10&T16&$R$10,"")) | D16: =TRIM(IF($M$1>=I16,IF(VLOOKUP(I16,Iktato!$B$3:$L$10000,8,FALSE)<>0,VLOOKUP(I16,Iktato!$B$3:$L$10000,8,FALSE),""),"")) | E16: =TRIM(IF($M$1>=I16,IF(VLOOKUP(I16,Iktato!$B$3:$L$10000,9,FALSE)<>0,VLOOKUP(I16,Iktato!$B$3:$L$10000,9,FALSE),""),"")) | F16: =TRIM(IF($M$1>=I16,M16&$M$10&N16,"")) | I16: =I15+1 -> 6 | J16: =IF(K15<>K16,K16,"") | K16: =IF($M$1>=I16,VLOOKUP(I16,Iktato!$B$3:$L$10000,3,FALSE),"") | M16: =IF($M$1>=I16,IF(VLOOKUP(I16,Iktato!$B$3:$P$10000,15,FALSE)<>0,VLOOKUP(I16,Iktato!$B$3:$P$10000,15,FALSE),""),"") | N16: =IF($M$1>=I16,IF(VLOOKUP(I16,Iktato!$B$3:$Q$10000,16,FALSE)<>0,VLOOKUP(I16,Iktato!$B$3:$Q$10000,16,FALSE),""),"") | P16: =TRIM(IF($M$1>=I16,IF(VLOOKUP(I16,Iktato!$B$3:$L$10000,6,FALSE)<>0,VLOOKUP(I16,Iktato!$B$3:$L$10000,6,FALSE),""),"")) | Q16: =TRIM(IF($M$1>=I16,IF(VLOOKUP(I16,Iktato!$B$3:$L$10000,7,FALSE)<>0,VLOOKUP(I16,Iktato!$B$3:$L$10000,7,FALSE),""),"")) | R16: =IF(Q16<>"",YEAR(Q16),"") | S16: =IF(Q16<>"",MONTH(Q16),"") | T16: =IF(Q16<>"",DAY(Q16),"")
A17: =IF($M$1>=I17,J17,"") | B17: =IF($M$1>=I17,VLOOKUP(I17,Iktato!$B$3:$L$10000,5,FALSE),"") | C17: =TRIM(IF(AND(P17&Q17<>"",$M$1>=I17),P17&"-"&R17&$R$10&S17&$R$10&T17&$R$10,"")) | D17: =TRIM(IF($M$1>=I17,IF(VLOOKUP(I17,Iktato!$B$3:$L$10000,8,FALSE)<>0,VLOOKUP(I17,Iktato!$B$3:$L$10000,8,FALSE),""),"")) | E17: =TRIM(IF($M$1>=I17,IF(VLOOKUP(I17,Iktato!$B$3:$L$10000,9,FALSE)<>0,VLOOKUP(I17,Iktato!$B$3:$L$10000,9,FALSE),""),"")) | F17: =TRIM(IF($M$1>=I17,M17&$M$10&N17,"")) | I17: =I16+1 -> 7 | J17: =IF(K16<>K17,K17,"") | K17: =IF($M$1>=I17,VLOOKUP(I17,Iktato!$B$3:$L$10000,3,FALSE),"") | M17: =IF($M$1>=I17,IF(VLOOKUP(I17,Iktato!$B$3:$P$10000,15,FALSE)<>0,VLOOKUP(I17,Iktato!$B$3:$P$10000,15,FALSE),""),"") | N17: =IF($M$1>=I17,IF(VLOOKUP(I17,Iktato!$B$3:$Q$10000,16,FALSE)<>0,VLOOKUP(I17,Iktato!$B$3:$Q$10000,16,FALSE),""),"") | P17: =TRIM(IF($M$1>=I17,IF(VLOOKUP(I17,Iktato!$B$3:$L$10000,6,FALSE)<>0,VLOOKUP(I17,Iktato!$B$3:$L$10000,6,FALSE),""),"")) | Q17: =TRIM(IF($M$1>=I17,IF(VLOOKUP(I17,Iktato!$B$3:$L$10000,7,FALSE)<>0,VLOOKUP(I17,Iktato!$B$3:$L$10000,7,FALSE),""),"")) | R17: =IF(Q17<>"",YEAR(Q17),"") | S17: =IF(Q17<>"",MONTH(Q17),"") | T17: =IF(Q17<>"",DAY(Q17),"")
A18: =IF($M$1>=I18,J18,"") | B18: =IF($M$1>=I18,VLOOKUP(I18,Iktato!$B$3:$L$10000,5,FALSE),"") | C18: =TRIM(IF(AND(P18&Q18<>"",$M$1>=I18),P18&"-"&R18&$R$10&S18&$R$10&T18&$R$10,"")) | D18: =TRIM(IF($M$1>=I18,IF(VLOOKUP(I18,Iktato!$B$3:$L$10000,8,FALSE)<>0,VLOOKUP(I18,Iktato!$B$3:$L$10000,8,FALSE),""),"")) | E18: =TRIM(IF($M$1>=I18,IF(VLOOKUP(I18,Iktato!$B$3:$L$10000,9,FALSE)<>0,VLOOKUP(I18,Iktato!$B$3:$L$10000,9,FALSE),""),"")) | F18: =TRIM(IF($M$1>=I18,M18&$M$10&N18,"")) | I18: =I17+1 -> 8 | J18: =IF(K17<>K18,K18,"") | K18: =IF($M$1>=I18,VLOOKUP(I18,Iktato!$B$3:$L$10000,3,FALSE),"") | M18: =IF($M$1>=I18,IF(VLOOKUP(I18,Iktato!$B$3:$P$10000,15,FALSE)<>0,VLOOKUP(I18,Iktato!$B$3:$P$10000,15,FALSE),""),"") | N18: =IF($M$1>=I18,IF(VLOOKUP(I18,Iktato!$B$3:$Q$10000,16,FALSE)<>0,VLOOKUP(I18,Iktato!$B$3:$Q$10000,16,FALSE),""),"") | P18: =TRIM(IF($M$1>=I18,IF(VLOOKUP(I18,Iktato!$B$3:$L$10000,6,FALSE)<>0,VLOOKUP(I18,Iktato!$B$3:$L$10000,6,FALSE),""),"")) | Q18: =TRIM(IF($M$1>=I18,IF(VLOOKUP(I18,Iktato!$B$3:$L$10000,7,FALSE)<>0,VLOOKUP(I18,Iktato!$B$3:$L$10000,7,FALSE),""),"")) | R18: =IF(Q18<>"",YEAR(Q18),"") | S18: =IF(Q18<>"",MONTH(Q18),"") | T18: =IF(Q18<>"",DAY(Q18),"")
A19: =IF($M$1>=I19,J19,"") | B19: =IF($M$1>=I19,VLOOKUP(I19,Iktato!$B$3:$L$10000,5,FALSE),"") | C19: =TRIM(IF(AND(P19&Q19<>"",$M$1>=I19),P19&"-"&R19&$R$10&S19&$R$10&T19&$R$10,"")) | D19: =TRIM(IF($M$1>=I19,IF(VLOOKUP(I19,Iktato!$B$3:$L$10000,8,FALSE)<>0,VLOOKUP(I19,Iktato!$B$3:$L$10000,8,FALSE),""),"")) | E19: =TRIM(IF($M$1>=I19,IF(VLOOKUP(I19,Iktato!$B$3:$L$10000,9,FALSE)<>0,VLOOKUP(I19,Iktato!$B$3:$L$10000,9,FALSE),""),"")) | F19: =TRIM(IF($M$1>=I19,M19&$M$10&N19,"")) | I19: =I18+1 -> 9 | J19: =IF(K18<>K19,K19,"") | K19: =IF($M$1>=I19,VLOOKUP(I19,Iktato!$B$3:$L$10000,3,FALSE),"") | M19: =IF($M$1>=I19,IF(VLOOKUP(I19,Iktato!$B$3:$P$10000,15,FALSE)<>0,VLOOKUP(I19,Iktato!$B$3:$P$10000,15,FALSE),""),"") | N19: =IF($M$1>=I19,IF(VLOOKUP(I19,Iktato!$B$3:$Q$10000,16,FALSE)<>0,VLOOKUP(I19,Iktato!$B$3:$Q$10000,16,FALSE),""),"") | P19: =TRIM(IF($M$1>=I19,IF(VLOOKUP(I19,Iktato!$B$3:$L$10000,6,FALSE)<>0,VLOOKUP(I19,Iktato!$B$3:$L$10000,6,FALSE),""),"")) | Q19: =TRIM(IF($M$1>=I19,IF(VLOOKUP(I19,Iktato!$B$3:$L$10000,7,FALSE)<>0,VLOOKUP(I19,Iktato!$B$3:$L$10000,7,FALSE),""),"")) | R19: =IF(Q19<>"",YEAR(Q19),"") | S19: =IF(Q19<>"",MONTH(Q19),"") | T19: =IF(Q19<>"",DAY(Q19),"")
A20: =IF($M$1>=I20,J20,"") | B20: =IF($M$1>=I20,VLOOKUP(I20,Iktato!$B$3:$L$10000,5,FALSE),"") | C20: =TRIM(IF(AND(P20&Q20<>"",$M$1>=I20),P20&"-"&R20&$R$10&S20&$R$10&T20&$R$10,"")) | D20: =TRIM(IF($M$1>=I20,IF(VLOOKUP(I20,Iktato!$B$3:$L$10000,8,FALSE)<>0,VLOOKUP(I20,Iktato!$B$3:$L$10000,8,FALSE),""),"")) | E20: =TRIM(IF($M$1>=I20,IF(VLOOKUP(I20,Iktato!$B$3:$L$10000,9,FALSE)<>0,VLOOKUP(I20,Iktato!$B$3:$L$10000,9,FALSE),""),"")) | F20: =TRIM(IF($M$1>=I20,M20&$M$10&N20,"")) | I20: =I19+1 -> 10 | J20: =IF(K19<>K20,K20,"") | K20: =IF($M$1>=I20,VLOOKUP(I20,Iktato!$B$3:$L$10000,3,FALSE),"") | M20: =IF($M$1>=I20,IF(VLOOKUP(I20,Iktato!$B$3:$P$10000,15,FALSE)<>0,VLOOKUP(I20,Iktato!$B$3:$P$10000,15,FALSE),""),"") | N20: =IF($M$1>=I20,IF(VLOOKUP(I20,Iktato!$B$3:$Q$10000,16,FALSE)<>0,VLOOKUP(I20,Iktato!$B$3:$Q$10000,16,FALSE),""),"") | P20: =TRIM(IF($M$1>=I20,IF(VLOOKUP(I20,Iktato!$B$3:$L$10000,6,FALSE)<>0,VLOOKUP(I20,Iktato!$B$3:$L$10000,6,FALSE),""),"")) | Q20: =TRIM(IF($M$1>=I20,IF(VLOOKUP(I20,Iktato!$B$3:$L$10000,7,FALSE)<>0,VLOOKUP(I20,Iktato!$B$3:$L$10000,7,FALSE),""),"")) | R20: =IF(Q20<>"",YEAR(Q20),"") | S20: =IF(Q20<>"",MONTH(Q20),"") | T20: =IF(Q20<>"",DAY(Q20),"")
A21: =IF($M$1>=I21,J21,"") | B21: =IF($M$1>=I21,VLOOKUP(I21,Iktato!$B$3:$L$10000,5,FALSE),"") | C21: =TRIM(IF(AND(P21&Q21<>"",$M$1>=I21),P21&"-"&R21&$R$10&S21&$R$10&T21&$R$10,"")) | D21: =TRIM(IF($M$1>=I21,IF(VLOOKUP(I21,Iktato!$B$3:$L$10000,8,FALSE)<>0,VLOOKUP(I21,Iktato!$B$3:$L$10000,8,FALSE),""),"")) | E21: =TRIM(IF($M$1>=I21,IF(VLOOKUP(I21,Iktato!$B$3:$L$10000,9,FALSE)<>0,VLOOKUP(I21,Iktato!$B$3:$L$10000,9,FALSE),""),"")) | F21: =TRIM(IF($M$1>=I21,M21&$M$10&N21,"")) | I21: =I20+1 -> 11 | J21: =IF(K20<>K21,K21,"") | K21: =IF($M$1>=I21,VLOOKUP(I21,Iktato!$B$3:$L$10000,3,FALSE),"") | M21: =IF($M$1>=I21,IF(VLOOKUP(I21,Iktato!$B$3:$P$10000,15,FALSE)<>0,VLOOKUP(I21,Iktato!$B$3:$P$10000,15,FALSE),""),"") | N21: =IF($M$1>=I21,IF(VLOOKUP(I21,Iktato!$B$3:$Q$10000,16,FALSE)<>0,VLOOKUP(I21,Iktato!$B$3:$Q$10000,16,FALSE),""),"") | P21: =TRIM(IF($M$1>=I21,IF(VLOOKUP(I21,Iktato!$B$3:$L$10000,6,FALSE)<>0,VLOOKUP(I21,Iktato!$B$3:$L$10000,6,FALSE),""),"")) | Q21: =TRIM(IF($M$1>=I21,IF(VLOOKUP(I21,Iktato!$B$3:$L$10000,7,FALSE)<>0,VLOOKUP(I21,Iktato!$B$3:$L$10000,7,FALSE),""),"")) | R21: =IF(Q21<>"",YEAR(Q21),"") | S21: =IF(Q21<>"",MONTH(Q21),"") | T21: =IF(Q21<>"",DAY(Q21),"")
A22: =IF($M$1>=I22,J22,"") | B22: =IF($M$1>=I22,VLOOKUP(I22,Iktato!$B$3:$L$10000,5,FALSE),"") | C22: =TRIM(IF(AND(P22&Q22<>"",$M$1>=I22),P22&"-"&R22&$R$10&S22&$R$10&T22&$R$10,"")) | D22: =TRIM(IF($M$1>=I22,IF(VLOOKUP(I22,Iktato!$B$3:$L$10000,8,FALSE)<>0,VLOOKUP(I22,Iktato!$B$3:$L$10000,8,FALSE),""),"")) | E22: =TRIM(IF($M$1>=I22,IF(VLOOKUP(I22,Iktato!$B$3:$L$10000,9,FALSE)<>0,VLOOKUP(I22,Iktato!$B$3:$L$10000,9,FALSE),""),"")) | F22: =TRIM(IF($M$1>=I22,M22&$M$10&N22,"")) | I22: =I21+1 -> 12 | J22: =IF(K21<>K22,K22,"") | K22: =IF($M$1>=I22,VLOOKUP(I22,Iktato!$B$3:$L$10000,3,FALSE),"") | M22: =IF($M$1>=I22,IF(VLOOKUP(I22,Iktato!$B$3:$P$10000,15,FALSE)<>0,VLOOKUP(I22,Iktato!$B$3:$P$10000,15,FALSE),""),"") | N22: =IF($M$1>=I22,IF(VLOOKUP(I22,Iktato!$B$3:$Q$10000,16,FALSE)<>0,VLOOKUP(I22,Iktato!$B$3:$Q$10000,16,FALSE),""),"") | P22: =TRIM(IF($M$1>=I22,IF(VLOOKUP(I22,Iktato!$B$3:$L$10000,6,FALSE)<>0,VLOOKUP(I22,Iktato!$B$3:$L$10000,6,FALSE),""),"")) | Q22: =TRIM(IF($M$1>=I22,IF(VLOOKUP(I22,Iktato!$B$3:$L$10000,7,FALSE)<>0,VLOOKUP(I22,Iktato!$B$3:$L$10000,7,FALSE),""),"")) | R22: =IF(Q22<>"",YEAR(Q22),"") | S22: =IF(Q22<>"",MONTH(Q22),"") | T22: =IF(Q22<>"",DAY(Q22),"")
... A411: =IF($M$1>=I411,J411,"") | B411: =IF($M$1>=I411,VLOOKUP(I411,Iktato!$B$3:$L$10000,5,FALSE),"") | C411: =TRIM(IF(AND(P411&Q411<>"",$M$1>=I411),P411&"-"&R411&$R$10&S411&$R$10&T411&$R$10,"")) | D411: =TRIM(IF($M$1>=I411,IF(VLOOKUP(I411,Iktato!$B$3:$L$10000,8,FALSE)<>0,VLOOKUP(I411,Iktato!$B$3:$L$10000,8,FALSE),""),"")) | E411: =TRIM(IF($M$1>=I411,IF(VLOOKUP(I411,Iktato!$B$3:$L$10000,9,FALSE)<>0,VLOOKUP(I411,Iktato!$B$3:$L$10000,9,FALSE),""),"")) | F411: =TRIM(IF($M$1>=I411,M411&$M$10&N411,"")) | I411: =I410+1 -> 401 | J411: =IF(K410<>K411,K411,"") | K411: =IF($M$1>=I411,VLOOKUP(I411,Iktato!$B$3:$L$10000,3,FALSE),"") | M411: =IF($M$1>=I411,IF(VLOOKUP(I411,Iktato!$B$3:$P$10000,15,FALSE)<>0,VLOOKUP(I411,Iktato!$B$3:$P$10000,15,FALSE),""),"") | N411: =IF($M$1>=I411,IF(VLOOKUP(I411,Iktato!$B$3:$Q$10000,16,FALSE)<>0,VLOOKUP(I411,Iktato!$B$3:$Q$10000,16,FALSE),""),"") | P411: =TRIM(IF($M$1>=I411,IF(VLOOKUP(I411,Iktato!$B$3:$L$10000,6,FALSE)<>0,VLOOKUP(I411,Iktato!$B$3:$L$10000,6,FALSE),""),"")) | Q411: =TRIM(IF($M$1>=I411,IF(VLOOKUP(I411,Iktato!$B$3:$L$10000,7,FALSE)<>0,VLOOKUP(I411,Iktato!$B$3:$L$10000,7,FALSE),""),"")) | R411: =IF(Q411<>"",YEAR(Q411),"") | S411: =IF(Q411<>"",MONTH(Q411),"") | T411: =IF(Q411<>"",DAY(Q411),"")

Sheet Ugykorjegyzek_2024tol
B1: Egyházközségi ügykörjegyzék 2024-től - B. szálas iratok | G1: Ebben az oszlopban található ügykörhöz tartozó iratokat iktatjuk, ezek a ügyköri megnevezések érhetőek el a lenyílóban. A többi iratot iktató szám nélkül fűzzük le a megfelelő iratgyűjtőbe.
B3: Szám | D3: Ügykör megnevezése | G3: Rövid megnevezés a lenyílóba
B4: 1 | D4: Levelezés (egyházkerületi, egyházmegyei, egyházközségi, világi hatóságokkal, magánszemélyekkel) | E4: É.Á. | G4: Levelezés
B5: 2 | D5: Anya- és családkönyvi levelezés és adatvédelmi nyilatkozatok | E5: F. Á. | G5: Anya- és családkönyvi levelezés
B6: 3 | D6: Jelentések | E6: F. Á. | G6: Jelentések
B7: 4 | D7: Választók névjegyzéke | E7: F. Á. | G7: Választók névjegyzéke
B8: 5 | D8: Egyházi alkalmazottak személyi iratgyűjtői | E8: F. Á.
B9: 6 | D9: Leltári ügyek
C10: 6/1. | D10: Vagyonleltári jelentések, leltárívek, selejtezési jegyzőkönyvek | E10: É. Á. | G10: Vagyonleltári jelentések
C11: 6/2. | D11: Birtokívek, birtoklevelek, telekkönyvi kivonatok, adóazonosítókivonat („cod fiscal”), gépkocsik törzskönyve | E11: F. Á
C12: 6/3. | D12: Alapeszközök nyilvántartó lapjai | E12: F. Á.
C13: 6/4. | D13: Ingatlanadók, felértékelések, kockázatfelmérések, biztosítások | E13: F. Á. | G13: Ingatlanadók, felértékelések …
C14: 6/5. | D14: Részvények és banki kötvények | E14: F. Á.
C15: 6/6. | D15: Pecsétnyomók nyilvántartása | E15: F. Á.
C16: 6/7. | D16: Anyagraktári ügyek | E16: F. Á.
B17: 7 | D17: Műemlékek, műkincsek, történeti értékű tárgyak | E17: F. Á.
B18: 8 | D18: Költségvetések, költségvetés-módosítások, számadások | E18: F. Á. | G18: Költségvetések, számadások
B19: 9 | D19: Pénzügyi igazoló iratok
C20: 9/1. | D20: Pénztári igazoló iratok (készpénz): kifizetési bizonylat (nyugta), számla, pénztárnapló („kasszakönyv”), kifizetést kísérő irat | E20: É. Á.
C21: 9/2. | D21: Banki igazoló iratok: átutalási szelvény, számla, számlakivonat, banknapló, megrendelőlap | E21: É. Á.
B22: 10 | D22: Csoportnapló | E22: É. Á.
B23: 11 | D23: Fizetési jegyzékek | E23: F. Á
B24: 12 | D24: Munkavédelem, tűzvédelem | E24: F. Á.
B25: 13 | D25: Szerződések
C26: 13 1. | D26: Bérleti szerződések | E26: F. Á. | G26: Bérleti szerződések
C27: 13 2. | D27: Közüzemi szerződések (energia, telekommunikáció, víz és csatoma) | E27: F. Á. | G27: Közüzemi szerzdődések …
C28: 13 3. | D28: Szolgáltatási és támogatási szerződések | E28: F. Á. | G28: Szolgáltatási és támogatási szerz. …
B29: 14 | D29: Pályázatok | E29: F. Á. | G29: Pályázatok
B30: 15 | D30: Ellenőrzési jegyzőkönyvek (belső, gazdasági bizottsági és felsőbb hatósági) | E30: F. Á. | G30: Ellenőrzési jegyzőkönyvek …
B31: 16 | D31: Egyházközségi egyesületek és alapítványok – statútuma, hivatalos adatai, bírósági kivonatok | E31: F. Á.
B32: 17 | D32: Temetőügyek | E32: F. Á. | G32: Temetőügyek
B33: 18 | D33: Gyülekezeti kiadványok, aprónyomtatványok, rendezvények dokumentumai | E33: F. Á.
B35: Megjegyzés:
B36: F.Á. – folyamatosan állandó (folyamatosan vezetjük, amíg az irattartó megtelik)
B37: É.Á. – évente állandó (évente lezárjuk az iratmennyiségtől függetlenül)
B40: Egyházközségi ügykörjegyzék 2024-től - A. kötetes anyag
B42: Szám | D42: Ügykör megnevezése
B43: I. | D43: Presbiteri gyűlések jegyzőkönyvei
B44: II. | D44: Közgyűlési jegyzőkönyvek
B45: III. | D45: Anyakönyvek
...

Sheet Szinek
B2: Védett cella, nem szerkeszthető
B3: Védelem nélküli cella, ide lehet írni
B4: Világosszürke sor - kapott levelek
B5: Világoskék sor: válaszlevél, az előző sorral azonos iktatószámmal
B6: Zöld sor: következő év - az előző sorhoz képest, az iktatószám előlről kezdődik.
