Workbook
Name DeDu: #REF!
Name evek: Adatlap!$C$1:$M$1
Name NaploNy: #REF!:INDEX(#REF!,#REF!)
Name Szolgalatok: #REF!

Sheet Adatlap
A1: Az áthúzás, kivágás, másolás, beillesztés lehetőségeket ne használd. Ha valamit rossz helyre írtál, töröld ki és írd újra a megfelelő helyre. | C1: 2026 | D1: =C1+1 -> 2027 | E1: =D1+1 -> 2028 | F1: =E1+1 -> 2029 | G1: =F1+1 -> 2030 | H1: =G1+1 -> 2031 | I1: =H1+1 -> 2032 | J1: =I1+1 -> 2033 | K1: =J1+1 -> 2034 | L1: =K1+1 -> 2035 | M1: Összesen | AA1: Brassói | AB1: Főgondnok
B2: Egyházmegye | D2: 2 | E2: 3 | F2: 4 | G2: 5 | H2: 6 | I2: 7 | J2: 8 | K2: 9 | L2: 10 | M2: 11 | N2: =IF(COUNTA(C51:L51)<>0,COUNTA(C51:L51),1) -> 1 | AA2: Dési | AB2: Gondnok
B3: Egyházközség neve (Református Egyházközség nélkül) | AA3: Erdővidéki
B4: Lelkipásztor | D4: =IF(C4<>0,C4,"") | E4: =IF(D4<>0,D4,"") | F4: =IF(E4<>0,E4,"") | G4: =IF(F4<>0,F4,"") | H4: =IF(G4<>0,G4,"") | I4: =IF(H4<>0,H4,"") | J4: =IF(I4<>0,I4,"") | K4: =IF(J4<>0,J4,"") | L4: =IF(K4<>0,K4,"") | AA4: Görgényi
B5: Főgondnok/Gondnok | D5: =IF(C5<>0,C5,"") | E5: =IF(D5<>0,D5,"") | F5: =IF(E5<>0,E5,"") | G5: =IF(F5<>0,F5,"") | H5: =IF(G5<>0,G5,"") | I5: =IF(H5<>0,H5,"") | J5: =IF(I5<>0,I5,"") | K5: =IF(J5<>0,J5,"") | L5: =IF(K5<>0,K5,"") | AA5: Hunyadi
B6: Presbiteri gyűlés dátuma | AA6: Kalotaszegi
B7: Határozat száma | AA7: Kézdi-Orbai
B8: Közgyűlés dátuma | AA8: Kolozsvári
B9: Határozat száma | AA9: Küküllői
B10: Egyházközségi iktatószám | AA10: Marosi
A11: I. Adatok a lélekszámról | AA11: Maros-Mezőségi
A12: 1. | B12: Az_előző_évi_lélekszám: férfi | D12: =SUM(C12,C14,-C16,C18,-C21,C24,-C26,-C28) -> 0 | E12: =SUM(D12,D14,-D16,D18,-D21,D24,-D26,-D28) -> 0 | F12: =SUM(E12,E14,-E16,E18,-E21,E24,-E26,-E28) -> 0 | G12: =SUM(F12,F14,-F16,F18,-F21,F24,-F26,-F28) -> 0 | H12: =SUM(G12,G14,-G16,G18,-G21,G24,-G26,-G28) -> 0 | I12: =SUM(H12,H14,-H16,H18,-H21,H24,-H26,-H28) -> 0 | J12: =SUM(I12,I14,-I16,I18,-I21,I24,-I26,-I28) -> 0 | K12: =SUM(J12,J14,-J16,J18,-J21,J24,-J26,-J28) -> 0 | L12: =SUM(K12,K14,-K16,K18,-K21,K24,-K26,-K28) -> 0 | M12: =C12 -> 0 | AA12: Nagyenyedi
B13: nő | D13: =SUM(C13,C15,-C17,C19,-C22,C25,-C27,-C29) -> 0 | E13: =SUM(D13,D15,-D17,D19,-D22,D25,-D27,-D29) -> 0 | F13: =SUM(E13,E15,-E17,E19,-E22,E25,-E27,-E29) -> 0 | G13: =SUM(F13,F15,-F17,F19,-F22,F25,-F27,-F29) -> 0 | H13: =SUM(G13,G15,-G17,G19,-G22,G25,-G27,-G29) -> 0 | I13: =SUM(H13,H15,-H17,H19,-H22,H25,-H27,-H29) -> 0 | J13: =SUM(I13,I15,-I17,I19,-I22,I25,-I27,-I29) -> 0 | K13: =SUM(J13,J15,-J17,J19,-J22,J25,-J27,-J29) -> 0 | L13: =SUM(K13,K15,-K17,K19,-K22,K25,-K27,-K29) -> 0 | M13: =C13 -> 0 | AA13: Sepsi
A14: 2. | B14: Keresztelésben_részesült: férfi | M14: =SUM(C14:L14) -> 0 | AA14: Székelyudvarhelyi
B15: nő | M15: =SUM(C15:L15) -> 0 | AA15: Tordai
A16: 3. | B16: Eltemettetett: férfi | M16: =SUM(C16:L16) -> 0 | AA16: Töltsd ki az egyházmegye nevét!
B17: nő | M17: =SUM(C17:L17) -> 0
A18: 6. | B18: Egyházunkba_tért: férfi | M18: =SUM(C18:L18) -> 0
B19: nő | M19: =SUM(C19:L19) -> 0
B20: Milyen felekezetből:
A21: 7. | B21: Egyházunkból_kitért: férfi | M21: =SUM(C21:L21) -> 0
B22: nő | M22: =SUM(C22:L22) -> 0
B23: Milyen felekezetbe:
A24: 8. | B24: Beköltözött_az_egyházközségbe: férfi | M24: =SUM(C24:L24) -> 0
B25: nő | M25: =SUM(C25:L25) -> 0
A26: 9. | B26: Kiköltözött_más_egyházközségbe: férfi | M26: =SUM(C26:L26) -> 0
B27: nő | M27: =SUM(C27:L27) -> 0
A28: 10. | B28: Kiköltözött_külföldre: férfi | M28: =SUM(C28:L28) -> 0
B29: nő | M29: =SUM(C29:L29) -> 0
A30: 14. | B30: A gyülekezet választói névjegyzékében szereplő tagjainak száma:
A31: 15. | B31: Az egyházfenntartás személyenkénti éves meghatározott összege:
A32: 16. | B32: Azon felnőtt egyháztagok száma, akik 5 vagy annál több éve nem fizetik az egyházfenntartói járulékot:
A33: 17. | B33: Gyülekezet lélekszámában jelentős (10 személynél több), más nemzetiségű egyháztagok száma: Román
B34: Német
B35: Roma
B36: Más (kérjük megnevezni)
B37: más tagok száma
A38: 18. | B38: Külföldön élő egyháztagok száma, akik életvitelszerűen külföldön élnek, vagy évi több mint 6 hónapot külföldön tartózkodnak:
A39: 19. | B39: Más településen élő egyháztagok száma:
A40: 20. | B40: Más gyülekezetben is tagságot vállaló egyháztagok száma:
...

Sheet Jelentes
A1: 2026 | D1: A baloldali zöld cellába kell beírni a listázni kívánt év számát. | R1: =IF(ISERROR(HLOOKUP(A1,Adatlap!D1:M2,2,FALSE))=TRUE,1,HLOOKUP(A1,Adatlap!D1:M2,2,FALSE)) -> 1 | S1: lej. | AB1: b | AD1: 1 | AE1: 1-én | AF1: . január
A2: Erdélyi Református Egyházkerület | AA2: a a | AB2: c | AD2: 2 | AE2: 2-án | AF2: . február
A3: =R3&" Református Egyházmegye" -> Református Egyházmegye | R3: =IF(Adatlap!C2<>0,Adatlap!C2,"") | AA3: a a | AB3: d | AD3: 3 | AE3: 3-án | AF3: . március
A4: ="Egyházközségi iktatószám: "&IF($Q4<>0,$Q4,"___________") -> Egyházközségi iktatószám: ___________ | Q4: {=INDEX(Adatlap!$C$1:$M$215,V4,$R$1)} -> 0 | V4: =ROW(Adatlap!$B$10) -> 10 | AA4: a a a | AB4: f | AD4: 4 | AE4: 4-én | AF4: . április
A5: Egyházmegyei iktatószám: _________ | N5: Esperes | AA5: a a | AB5: g | AD5: 5 | AE5: 5-én | AF5: . május
AB6: h | AD6: 6 | AE6: 6-án | AF6: . június
AB7: j | AD7: 7 | AE7: 7-én | AF7: . július
AB8: k | AD8: 8 | AE8: 8-án | AF8: . augusztus
A9: LELKÉSZI JELENTÉS | AA9: a a | AB9: l | AD9: 9 | AE9: 9-én | AF9: . szeptember
A10: =CLEAN(UPPER(S10&" "&R10&" REFORMÁTUS EGYHÁZKÖZSÉG")) -> A _________________________ REFORMÁTUS EGYHÁZKÖZSÉG | R10: =IF(Adatlap!C3<>0,Adatlap!C3,"_________________________") -> _________________________ | S10: =IF(ISERROR(VLOOKUP(LOWER(LEFT(R10,1)),AB1:AC19,2,FALSE)),"AZ","A") -> A | AA10: a a | AB10: m | AD10: 10 | AE10: 10-én | AF10: . október
A11: =IF($Q11<>0,$Q11,"")&". ÉVI ÉLETÉRŐL" -> 2026. ÉVI ÉLETÉRŐL | Q11: {=INDEX(Adatlap!$C$1:$M$215,V11,$R$1)} -> 2026 | V11: =ROW(Adatlap!$A$1) -> 1 | AA11: a a | AB11: n | AD11: 11 | AE11: 11-én | AF11: . november
AB12: p | AD12: 12 | AE12: 12-én | AF12: . december
A13: ="Tárgyalta a presbitérium a "&S13&T13&U13&" tartott gyűlésén "&IF($R13<>0,$R13,"_____")&". szám alatt." -> Tárgyalta a presbitérium a _____________ tartott gyűlésén _____. szám alatt. | Q13: {=INDEX(Adatlap!$C$1:$M$215,V13,$R$1)} -> 0 | R13: {=INDEX(Adatlap!$C$1:$M$215,W13,$R$1)} -> 0 | S13: =IF($Q13<>0,YEAR($Q$13),"_____________") -> _____________ | T13: =IF($Q13<>0,VLOOKUP(MONTH($Q$13),AD1:AF12,3,FALSE),"") | U13: =IF($Q13<>0,VLOOKUP(DAY($Q$13),AD1:AF32,2,FALSE),"") | V13: =ROW(Adatlap!$B$6) -> 6 | W13: =ROW(Adatlap!$B$7) -> 7 | AA13: a a | AB13: q | AD13: 13 | AE13: 13-án
A14: ="Tárgyalta az egyházközségi közgyűlés a "&S14&T14&U14&" tartott gyűlésén "&IF($R14<>0,$R14,"_____")&". szám alatt." -> Tárgyalta az egyházközségi közgyűlés a _____________ tartott gyűlésén _____. szám alatt. | Q14: {=INDEX(Adatlap!$C$1:$M$215,V14,$R$1)} -> 0 | R14: {=INDEX(Adatlap!$C$1:$M$215,W14,$R$1)} -> 0 | S14: =IF($Q14<>0,YEAR($Q$14),"_____________") -> _____________ | T14: =IF($Q14<>0,VLOOKUP(MONTH($Q$14),AD1:AF12,3,FALSE),"") | U14: =IF($Q14<>0,VLOOKUP(DAY($Q$14),AD1:AF33,2,FALSE),"") | V14: =ROW(Adatlap!$B$8) -> 8 | W14: =ROW(Adatlap!$B$9) -> 9 | AA14: a a | AB14: r | AD14: 14 | AE14: 14-én
C15: =IF($Q15<>0,$Q15,"") | L15: =IF($R15<>0,$R15,"") | Q15: {=INDEX(Adatlap!$C$1:$M$215,V15,$R$1)} -> 0 | R15: {=INDEX(Adatlap!$C$1:$M$215,W15,$R$1)} -> 0 | V15: =ROW(Adatlap!$B$4) -> 4 | W15: =ROW(Adatlap!$B$5) -> 5 | AB15: s | AD15: 15 | AE15: 15-én
C16: Lelkipásztor | L16: =IF(Adatlap!B5<>0,Adatlap!B5,"Gondnok") -> Főgondnok/Gondnok | AB16: t | AD16: 16 | AE16: 16-án
AB17: v | AD17: 17 | AE17: 17-én
N18: v 1.0a | AB18: z | AD18: 18 | AE18: 18-án
A19: I. Adatok a lélekszámról | AA19: a a a | AB19: _ | AD19: 19 | AE19: 19-én
A20: 1. | B20: Az előző évi lélekszám: | H20: férfi: | I20: =IF($Q20<>0,$Q20,"") | J20: nő: | K20: =IF($R20<>0,$R20,"") | L20: együtt: | N20: =SUM(I20,K20) -> 0 | Q20: {=INDEX(Adatlap!$C$1:$M$215,V20,$R$1)} -> 0 | R20: {=INDEX(Adatlap!$C$1:$M$215,W20,$R$1)} -> 0 | V20: =ROW(Adatlap!$B$12) -> 12 | W20: =ROW(Adatlap!$B$13) -> 13 | AD20: 20 | AE20: 20-án
A21: 2. | B21: Keresztelésben részesült: | H21: férfi: | I21: =IF($Q21<>0,$Q21,"") | J21: nő: | K21: =IF($R21<>0,$R21,"") | L21: együtt: | N21: =SUM(I21,K21) -> 0 | Q21: {=INDEX(Adatlap!$C$1:$M$215,V21,$R$1)} -> 0 | R21: {=INDEX(Adatlap!$C$1:$M$215,W21,$R$1)} -> 0 | V21: =ROW(Adatlap!$B$14) -> 14 | W21: =ROW(Adatlap!$B$15) -> 15 | AD21: 21 | AE21: 21-én
A22: 3. | B22: Eltemettetett: | H22: férfi: | I22: =IF($Q22<>0,$Q22,"") | J22: nő: | K22: =IF($R22<>0,$R22,"") | L22: együtt: | N22: =SUM(I22,K22) -> 0 | Q22: {=INDEX(Adatlap!$C$1:$M$215,V22,$R$1)} -> 0 | R22: {=INDEX(Adatlap!$C$1:$M$215,W22,$R$1)} -> 0 | V22: =ROW(Adatlap!$B$16) -> 16 | W22: =ROW(Adatlap!$B$17) -> 17 | AD22: 22 | AE22: 22-én
A23: 4. | B23: Természetes szaporulat: | L23: együtt: | N23: =IF(N21>N22,SUM(N21,-N22),"") | AD23: 23 | AE23: 23-án
A24: 5. | B24: Természetes apadás: | L24: együtt: | N24: =IF(N22>N21,SUM(N22,-N21),"") | AD24: 24 | AE24: 24-én
A25: 6. | B25: Egyházunkba tért: | H25: férfi: | I25: =IF($Q25<>0,$Q25,"") | J25: nő: | K25: =IF($R25<>0,$R25,"") | L25: együtt: | N25: =SUM(I25,K25) -> 0 | Q25: {=INDEX(Adatlap!$C$1:$M$215,V25,$R$1)} -> 0 | R25: {=INDEX(Adatlap!$C$1:$M$215,W25,$R$1)} -> 0 | V25: =ROW(Adatlap!$B$18) -> 18 | W25: =ROW(Adatlap!$B$19) -> 19 | AD25: 25 | AE25: 25-én
B26: Milyen felekezetből: | E26: =IF(Q26<>0,Q26,"") | Q26: {=INDEX(Adatlap!$C$1:$M$215,V26,$R$1)} -> 0 | V26: =ROW(Adatlap!$B$20) -> 20 | AD26: 26 | AE26: 26-án
A27: 7. | B27: Egyházunkból kitért: | H27: férfi: | I27: =IF($Q27<>0,$Q27,"") | J27: nő: | K27: =IF($R27<>0,$R27,"") | L27: együtt: | N27: =SUM(I27,K27) -> 0 | Q27: {=INDEX(Adatlap!$C$1:$M$215,V27,$R$1)} -> 0 | R27: {=INDEX(Adatlap!$C$1:$M$215,W27,$R$1)} -> 0 | V27: =ROW(Adatlap!$B$21) -> 21 | W27: =ROW(Adatlap!$B$22) -> 22 | AD27: 27 | AE27: 27-én
B28: Milyen felekezetbe: | E28: =IF(Q28<>0,Q28,"") | Q28: {=INDEX(Adatlap!$C$1:$M$215,V28,$R$1)} -> 0 | V28: =ROW(Adatlap!$B$23) -> 23 | AD28: 28 | AE28: 28-án
A29: 8. | B29: Beköltözött az egyházközségbe: | H29: férfi: | I29: =IF($Q29<>0,$Q29,"") | J29: nő: | K29: =IF($R29<>0,$R29,"") | L29: együtt: | N29: =SUM(I29,K29) -> 0 | Q29: {=INDEX(Adatlap!$C$1:$M$215,V29,$R$1)} -> 0 | R29: {=INDEX(Adatlap!$C$1:$M$215,W29,$R$1)} -> 0 | V29: =ROW(Adatlap!$B$24) -> 24 | W29: =ROW(Adatlap!$B$25) -> 25 | AD29: 29 | AE29: 29-én
A30: 9. | B30: Kiköltözött más egyházközségbe: | H30: férfi: | I30: =IF($Q30<>0,$Q30,"") | J30: nő: | K30: =IF($R30<>0,$R30,"") | L30: együtt: | N30: =SUM(I30,K30) -> 0 | Q30: {=INDEX(Adatlap!$C$1:$M$215,V30,$R$1)} -> 0 | R30: {=INDEX(Adatlap!$C$1:$M$215,W30,$R$1)} -> 0 | V30: =ROW(Adatlap!$B$26) -> 26 | W30: =ROW(Adatlap!$B$27) -> 27 | AD30: 30 | AE30: 30-án
A31: 10. | B31: Kiköltözött külföldre: | H31: férfi: | I31: =IF($Q31<>0,$Q31,"") | J31: nő: | K31: =IF($R31<>0,$R31,"") | L31: együtt: | N31: =SUM(I31,K31) -> 0 | Q31: {=INDEX(Adatlap!$C$1:$M$215,V31,$R$1)} -> 0 | R31: {=INDEX(Adatlap!$C$1:$M$215,W31,$R$1)} -> 0 | V31: =ROW(Adatlap!$B$28) -> 28 | W31: =ROW(Adatlap!$B$29) -> 29 | AD31: 31 | AE31: 31-én
A32: 11. | B32: Általános szaporulat: | L32: együtt: | N32: =IF(N34>N20,SUM(N34,-N20),"") | AD32: 0
A33: 12. | B33: Általános apadás: | L33: együtt: | N33: =IF(N20>N34,SUM(N20,-N34),"")
A34: 13. | B34: A gyülekezet lélekszáma dec. 31-én: | H34: férfi: | I34: =SUM(Q20,Q21,-Q22,Q25,-Q27,Q29,-Q30,-Q31) -> 0 | J34: nő: | K34: =SUM(R20,R21,-R22,R25,-R27,R29,-R30,-R31) -> 0 | L34: együtt: | N34: =SUM(I34,K34) -> 0
A35: 14. | B35: ="A gyülekezet választói névjegyzékében szereplő tagjainak száma: "&IF($Q35<>0,$Q35,"") -> A gyülekezet választói névjegyzékében szereplő tagjainak száma: | Q35: {=INDEX(Adatlap!$C$1:$M$215,V35,$R$1)} -> 0 | V35: =ROW(Adatlap!$B$30) -> 30
A36: 15. | B36: ="Az egyházfenntartás személyenkénti éves meghatározott összege: "&IF($Q36<>0,$Q36&$S$1,"") -> Az egyházfenntartás személyenkénti éves meghatározott összege: | Q36: {=INDEX(Adatlap!$C$1:$M$215,V36,$R$1)} -> 0 | V36: =ROW(Adatlap!$B$31) -> 31
A37: 16. | B37: ="Azon felnőtt egyháztagok száma, akik 5 vagy annál több éve nem fizetik az egyházfenntartói járulékot: "&IF($Q37<>0,$Q37,"") -> Azon felnőtt egyháztagok száma, akik 5 vagy annál több éve nem fizetik az egyházfenntartói járulékot: | Q37: {=INDEX(Adatlap!$C$1:$M$215,V37,$R$1)} -> 0 | V37: =ROW(Adatlap!$B$32) -> 32 | AA37: a a
A38: 17. | B38: ="Gyülekezet lélekszámában jelentős (10 személynél több), más nemzetiségű egyháztagok száma: (román, német, roma stb.): "&IF($Q38<>0,$Q38,"") -> Gyülekezet lélekszámában jelentős (10 személynél több), más nemzetiségű egyháztagok száma: (román, német, roma stb.): | Q38: =SUM(Q39:S39,U39) -> 0 | AA38: a a
B39: ="Román: "&IF($Q39<>0,$Q39,"") -> Román: | E39: ="Német: "&IF($R39<>0,$R39,"") -> Német: | G39: ="Roma: "&IF($S39<>0,$S39,"") -> Roma: | J39: =IF($T39<>0,$T39&":","")&" "&IF($U39<>0,$U39,"") | Q39: {=INDEX(Adatlap!$C$1:$M$215,V39,$R$1)} -> 0 | R39: {=INDEX(Adatlap!$C$1:$M$215,W39,$R$1)} -> 0 | S39: {=INDEX(Adatlap!$C$1:$M$215,X39,$R$1)} -> 0 | T39: {=INDEX(Adatlap!$C$1:$M$215,Y39,$R$1)} -> 0 | U39: {=INDEX(Adatlap!$C$1:$M$215,Z39,$R$1)} -> 0 | V39: =ROW(Adatlap!$B$33) -> 33 | W39: =ROW(Adatlap!$B$34) -> 34 | X39: =ROW(Adatlap!$B$35) -> 35 | Y39: =ROW(Adatlap!$B$36) -> 36 | Z39: =ROW(Adatlap!$B$37) -> 37
A40: 18. | B40: ="Külföldön élő egyháztagok száma, akik életvitelszerűen külföldön élnek, vagy évi több mint 6 hónapot külföldön tartózkodnak: "&IF($Q40<>0,$Q40,"") -> Külföldön élő egyháztagok száma, akik életvitelszerűen külföldön élnek, vagy évi több mint 6 hónapot külföldön tartózkodnak: | Q40: {=INDEX(Adatlap!$C$1:$M$215,V40,$R$1)} -> 0 | V40: =ROW(Adatlap!$B$38) -> 38 | AA40: a a
...

Sheet Sugo_lelkeszi jelenteshez
B1: Súgó a lelkészi jelentés kitöltéséhez.
B2: Jelen lelkészi jelentés űrlapot az Igazgatótanács a 2025. október 8-án tartott ülésén 65/2025. szám alatt fogadta el. Az új űrlap két változatban érhető el, egyszerű űrlapként, és egybeépítve a digitális munkanaplóval. Jelen lelkészi jelentés 2026-tól kötelező. A lelkészi jelentés 2026-tól kezdődőleg magába foglalja a lélekszámjelentést, az építési-javítási jelentést, és a diakóniai jelentést. A felsorolt jelentéseket nem kell külön elkészíteni, leadni. | P2: a a a a a
B3: Új fejezetek a korábbi jelentéshez képest: IV. Belmissziós tevékenységek; VI. Szeretetszolgálat; VIII. Ingatlanok
B4: Fejezeteken belül új sorok is kerültek be a jelentésbe.
B6: A papíron leadandó lelkészi jelentést a "Jelentés" munkalapon lehet kinyomtatni. Ezen a lapon nem lehet megváltoztatni az adatokat.
B7: Adatokat bevinni a jelentésbe az csak az "Adatlap" munkalapokon lehet, az ide bevitt adatokat dolgozza fel és rendszerezi a "Jelentés" munkalap. | H7: a a
B8: Az "Adalap" munkalap 10 kitölthető oszlopot tartalmaz, 10 év jelentését lehet bevezetni.
B9: A "Jelentés" munkalap fejlécén ki lehet választani a nyomtatáshoz az évszámot, vagy az összesítő lehetőséget.
B10: Az "Adatlap" színeiről:
C11: Fejezeteket elválasztó sor, nem módosítható | E11: a a
C12: Képletet, vagy magyarázatot tartalmazó cella, nem módosítható | E12: a a
C13: Kitölthető cella | E13: a a
C14: Világosszürke cella, korlátozott adatbeviteli lehetőség, csak a lenyílóban található lehetőségekből lehet választani. | E14: a a
C17: Fejléc/évszám
C18: Egyházmegye | D18: Az egyházmegye nevét a lenyílóból lehet kiválasztani
C19: Egyházközség neve (Református Egyházközség nélkül) | D19: Az egyházközség nevét egyszer kell beírni, "Református Egyházközség nélkül"
C20: Lelkipásztor | D20: Lelkipásztor neve, egyszer kell beírni, átveszi a következő év, de rá lehet javítani lelkipásztor csere esetében.
C21: Főgondnok/Gondnok | D21: Ki lehet választani a gondnok / főgondnok lehetőséget
C22: Presbiteri gyűlés dátuma | D22: Dátum írható
C23: Határozat száma
C24: Közgyűlés dátuma | D24: Dátum írható
C25: Határozat száma
C26: Egyházközségi iktatószám
B27: I. Adatok a lélekszámról
B28: 1. | C28: Az_előző_évi_lélekszám: férfi | D28: Egész szám írható be. A kezdés évében kell beírni, a későbbi éveknél képlet számolja ki a kezdő lélekszámot
C29: nő | D29: Egész szám írható be. A kezdés évében kell beírni, a későbbi éveknél képlet számolja ki a kezdő lélekszámot
B30: 2. | C30: Keresztelésben_részesült: férfi | D30: Az adatokat a digitális munkanaplóból, a "Szolgálati_alkalmak" lapról veszi át. ("F. keresztelő" szolgálatok száma)
C31: nő | D31: Az adatokat a digitális munkanaplóból, a "Szolgálati_alkalmak" lapról veszi át. ("N. keresztelő" szolgálatok száma)
B32: 3. | C32: Eltemettetett: férfi | D32: Az adatokat a digitális munkanaplóból, a "Szolgálati_alkalmak" lapról veszi át. ("F. temetés" szolgálatok száma)
C33: nő | D33: Az adatokat a digitális munkanaplóból, a "Szolgálati_alkalmak" lapról veszi át. ("N. temetés" szolgálatok száma)
B34: 6. | C34: Egyházunkba_tért: férfi | D34: Egész szám írható be.
C35: nő | D35: Egész szám írható be.
C36: Milyen felekezetből: | D36: Szöveg írható be, max. 200 karakter
B37: 7. | C37: Egyházunkból_kitért: férfi | D37: Egész szám írható be.
C38: nő | D38: Egész szám írható be.
C39: Milyen felekezetbe: | D39: Szöveg írható be, max. 200 karakter
B40: 8. | C40: Beköltözött_az_egyházközségbe: férfi | D40: Egész szám írható be.
C41: nő | D41: Egész szám írható be.
B42: 9. | C42: Kiköltözött_más_egyházközségbe: férfi | D42: Egész szám írható be.
C43: nő | D43: Egész szám írható be.
...
