Workbook
Name DeDu: Szolgalati_alkalmak!$AB$1:$AB$3
Name evek: Adatlap!$C$1:$M$1
Name NaploNy: Nyomtathato_munkanaplo!$A$3:INDEX(Nyomtathato_munkanaplo!$K:$K,Nyomtathato_munkanaplo!$P$1)
Name Szolgalatok: Szolgalati_alkalmak!$BA$3:$BA$41

Sheet Szolgalati_alkalmak
B1: =Nyomtathato_munkanaplo!Q1 -> 2026 | D1: =Adatlap!C3&" Református Egyházközség" -> Református Egyházközség | T1: Az áthúzás, kivágás, másolás, beillesztés lehetőségeket ne használd. | Y1: =DATE(Adatlap!C1,1,1) -> 46023 | Z1: =MAX(Z4,Z10000) -> 1 | AB1: Du. | BB1: It száma | BD1: It összesen | BE1: részt vett de | BH1: részt vett du | BM1: Statisztika de | BP1: Statisztika du | BS1: Bűnbánati hetek száma | BT1: =IF(BU1=7,42,36) -> 36
D2: Szolgálati alkalmak | T2: Ha valamit rossz helyre írtál, töröld ki és írd újra a megfelelő helyre. | Y2: 1 | AB2: De.2 | BB2: de | BC2: du | BE2: de férfi | BF2: de nő | BG2: Összesen | BH2: du férfi | BI2: du nő | BM2: Férfi | BN2: Nő | BO2: Összesen | BP2: Férfi | BQ2: Nő | BR2: Összesen | BS2: Úrvacsorák száma | BT2: =IF(ISNUMBER(BU2)=TRUE,BU2,0) -> 0
D3: S.sz. | E3: Dátum | F3: Szolgálat jellege | G3: Du. | H3: Férfi | I3: Nő | J3: Bibliaolvasás | K3: Alapige | L3: 1. ének | M3: 2. ének | N3: 3. ének | O3: 4. ének | P3: 5. ének | Q3: 6. ének | R3: Szolgált | S3: Perselypénz | T3: Megjegyzés | AA3: De | AB3: Du.2 | AZ3: 1 | BA3: Vasárnapi i.t. | BB3: =COUNTIF($AA$4:$AA$10000,BA3) -> 0 | BC3: =COUNTIF($AB$4:$AB$10000,BA3) -> 0 | BE3: =SUMIF($AA$4:$AA$10000,BA3,$H$4:$H$10000) -> 0 | BF3: =SUMIF($AA$4:$AA$10000,BA3,$I$4:$I$10000) -> 0 | BG3: =SUM(BE3:BF3) -> 0 | BH3: =SUMIF($AB$4:$AB$10000,BA3,$H$4:$H$10000) -> 0 | BI3: =SUMIF($AB$4:$AB$10000,BA3,$I$4:$I$10000) -> 0 | BJ3: =SUM(BH3:BI3) -> 0 | BO3: =IF(BB3<>0,ROUND(BG3/BB3,2),"") | BR3: =IF(BC3<>0,ROUND(BJ3/BC3,2),"")
B4: =IF($B$1=YEAR(Z4),D4,0) -> 0 | D4: 1 | Z4: =IF(CONCATENATE(F4,F5,F6,F7,F8,F9)<>"",IF(AND(E4<>0,ISNUMBER(E4)=TRUE),E4,Z3),$Y$2) -> 1 | AC4: =YEAR(Z4)&F4&G4 -> 1900 | AZ4: 2 | BA4: Ünnepi i.t. | BB4: =COUNTIF($AA$4:$AA$10000,BA4) -> 0 | BC4: =COUNTIF($AB$4:$AB$10000,BA4) -> 0 | BE4: =SUMIF($AA$4:$AA$10000,BA4,$H$4:$H$10000) -> 0 | BF4: =SUMIF($AA$4:$AA$10000,BA4,$I$4:$I$10000) -> 0 | BG4: =SUM(BE4:BF4) -> 0 | BH4: =SUMIF($AB$4:$AB$10000,BA4,$H$4:$H$10000) -> 0 | BI4: =SUMIF($AB$4:$AB$10000,BA4,$I$4:$I$10000) -> 0 | BJ4: =SUM(BH4:BI4) -> 0 | BO4: =IF(BB4<>0,ROUND(BG4/BB4,2),"") | BR4: =IF(BC4<>0,ROUND(BJ4/BC4,2),"")
B5: =IF($B$1=YEAR(Z5),D5,0) -> 0 | D5: =IF(Z5<>$Y$2,IF(YEAR(Z5)=YEAR(Z4),D4+1,1),"") | Z5: =IF(CONCATENATE(F5,F6,F7,F8,F9,F10)<>"",IF(AND(E5<>0,ISNUMBER(E5)=TRUE),E5,Z4),$Y$2) -> 1 | AC5: =YEAR(Z5)&F5&G5 -> 1900 | AZ5: 3 | BA5: Bűnbánati i.t. | BB5: =COUNTIF($AA$4:$AA$10000,BA5) -> 0 | BC5: =COUNTIF($AB$4:$AB$10000,BA5) -> 0 | BE5: =SUMIF($AA$4:$AA$10000,BA5,$H$4:$H$10000) -> 0 | BF5: =SUMIF($AA$4:$AA$10000,BA5,$I$4:$I$10000) -> 0 | BG5: =SUM(BE5:BF5) -> 0 | BH5: =SUMIF($AB$4:$AB$10000,BA5,$H$4:$H$10000) -> 0 | BI5: =SUMIF($AB$4:$AB$10000,BA5,$I$4:$I$10000) -> 0 | BJ5: =SUM(BH5:BI5) -> 0 | BO5: =IF(BB5<>0,ROUND(BG5/BB5,2),"") | BR5: =IF(BC5<>0,ROUND(BJ5/BC5,2),"")
B6: =IF($B$1=YEAR(Z6),D6,0) -> 0 | D6: =IF(Z6<>$Y$2,IF(YEAR(Z6)=YEAR(Z5),D5+1,1),"") | Z6: =IF(CONCATENATE(F6,F7,F8,F9,F10,F11)<>"",IF(AND(E6<>0,ISNUMBER(E6)=TRUE),E6,Z5),$Y$2) -> 1 | AC6: =YEAR(Z6)&F6&G6 -> 1900 | AZ6: 4 | BA6: Hétköznapi i.t. | BB6: =COUNTIF($AA$4:$AA$10000,BA6) -> 0 | BC6: =COUNTIF($AB$4:$AB$10000,BA6) -> 0 | BE6: =SUMIF($AA$4:$AA$10000,BA6,$H$4:$H$10000) -> 0 | BF6: =SUMIF($AA$4:$AA$10000,BA6,$I$4:$I$10000) -> 0 | BH6: =SUMIF($AB$4:$AB$10000,BA6,$H$4:$H$10000) -> 0 | BI6: =SUMIF($AB$4:$AB$10000,BA6,$I$4:$I$10000) -> 0 | BM6: =SUM(BE6,BH6,BE7,BH7) -> 0 | BN6: =SUM(BF6,BI6,BF7,BI7) -> 0 | BP6: =IF(BT2<>0,ROUND(BM6/BT2,2),"") | BQ6: =IF(BT2<>0,ROUND(BN6/BT2,2),"") | BR6: =IF(BC6<>0,ROUND(BJ6/BC6,2),"")
B7: =IF($B$1=YEAR(Z7),D7,0) -> 0 | D7: =IF(Z7<>$Y$2,IF(YEAR(Z7)=YEAR(Z6),D6+1,1),"") | Z7: =IF(CONCATENATE(F7,F8,F9,F10,F11,F12)<>"",IF(AND(E7<>0,ISNUMBER(E7)=TRUE),E7,Z6),$Y$2) -> 1 | AC7: =YEAR(Z7)&F7&G7 -> 1900 | AZ7: 5 | BA7: Úrvacsora templomban | BB7: =COUNTIF($AA$4:$AA$10000,BA7) -> 0 | BC7: =COUNTIF($AB$4:$AB$10000,BA7) -> 0 | BE7: =SUMIF($AA$4:$AA$10000,BA7,$H$4:$H$10000) -> 0 | BF7: =SUMIF($AA$4:$AA$10000,BA7,$I$4:$I$10000) -> 0 | BH7: =SUMIF($AB$4:$AB$10000,BA7,$H$4:$H$10000) -> 0 | BI7: =SUMIF($AB$4:$AB$10000,BA7,$I$4:$I$10000) -> 0
B8: =IF($B$1=YEAR(Z8),D8,0) -> 0 | D8: =IF(Z8<>$Y$2,IF(YEAR(Z8)=YEAR(Z7),D7+1,1),"") | Z8: =IF(CONCATENATE(F8,F9,F10,F11,F12,F13)<>"",IF(AND(E8<>0,ISNUMBER(E8)=TRUE),E8,Z7),$Y$2) -> 1 | AC8: =YEAR(Z8)&F8&G8 -> 1900 | AZ8: 6 | BA8: Betegúrvacsora | BB8: =COUNTIF($AA$4:$AA$10000,BA8) -> 0 | BC8: =COUNTIF($AB$4:$AB$10000,BA8) -> 0 | BD8: =SUM(BB8:BC8) -> 0 | BE8: =SUMIF($AA$4:$AA$10000,BA8,$H$4:$H$10000) -> 0 | BF8: =SUMIF($AA$4:$AA$10000,BA8,$I$4:$I$10000) -> 0 | BG8: =SUM(BE8:BF8) -> 0 | BH8: =SUMIF($AB$4:$AB$10000,BA8,$H$4:$H$10000) -> 0 | BI8: =SUMIF($AB$4:$AB$10000,BA8,$I$4:$I$10000) -> 0 | BJ8: =SUM(BH8:BI8) -> 0 | BO8: =IF(SUM(BD8:BD11)<>0,ROUND(SUM(BG8:BG11,BJ8:BJ11)/SUM(BD8:BD11),2),"")
B9: =IF($B$1=YEAR(Z9),D9,0) -> 0 | D9: =IF(Z9<>$Y$2,IF(YEAR(Z9)=YEAR(Z8),D8+1,1),"") | Z9: =IF(CONCATENATE(F9,F10,F11,F12,F13,F14)<>"",IF(AND(E9<>0,ISNUMBER(E9)=TRUE),E9,Z8),$Y$2) -> 1 | AC9: =YEAR(Z9)&F9&G9 -> 1900 | AZ9: 7 | BA9: Felnőtt bibliaóra | BB9: =COUNTIF($AA$4:$AA$10000,BA9) -> 0 | BC9: =COUNTIF($AB$4:$AB$10000,BA9) -> 0 | BD9: =SUM(BB9:BC9) -> 0 | BE9: =SUMIF($AA$4:$AA$10000,BA9,$H$4:$H$10000) -> 0 | BF9: =SUMIF($AA$4:$AA$10000,BA9,$I$4:$I$10000) -> 0 | BG9: =SUM(BE9:BF9) -> 0 | BH9: =SUMIF($AB$4:$AB$10000,BA9,$H$4:$H$10000) -> 0 | BI9: =SUMIF($AB$4:$AB$10000,BA9,$I$4:$I$10000) -> 0 | BJ9: =SUM(BH9:BI9) -> 0
B10: =IF($B$1=YEAR(Z10),D10,0) -> 0 | D10: =IF(Z10<>$Y$2,IF(YEAR(Z10)=YEAR(Z9),D9+1,1),"") | Z10: =IF(CONCATENATE(F10,F11,F12,F13,F14,F15)<>"",IF(AND(E10<>0,ISNUMBER(E10)=TRUE),E10,Z9),$Y$2) -> 1 | AC10: =YEAR(Z10)&F10&G10 -> 1900 | AZ10: 8 | BA10: Ifj. vagy IKE bibliaóra | BB10: =COUNTIF($AA$4:$AA$10000,BA10) -> 0 | BC10: =COUNTIF($AB$4:$AB$10000,BA10) -> 0 | BD10: =SUM(BB10:BC10) -> 0 | BE10: =SUMIF($AA$4:$AA$10000,BA10,$H$4:$H$10000) -> 0 | BF10: =SUMIF($AA$4:$AA$10000,BA10,$I$4:$I$10000) -> 0 | BG10: =SUM(BE10:BF10) -> 0 | BH10: =SUMIF($AB$4:$AB$10000,BA10,$H$4:$H$10000) -> 0 | BI10: =SUMIF($AB$4:$AB$10000,BA10,$I$4:$I$10000) -> 0 | BJ10: =SUM(BH10:BI10) -> 0
B11: =IF($B$1=YEAR(Z11),D11,0) -> 0 | D11: =IF(Z11<>$Y$2,IF(YEAR(Z11)=YEAR(Z10),D10+1,1),"") | Z11: =IF(CONCATENATE(F11,F12,F13,F14,F15,F16)<>"",IF(AND(E11<>0,ISNUMBER(E11)=TRUE),E11,Z10),$Y$2) -> 1 | AC11: =YEAR(Z11)&F11&G11 -> 1900 | AZ11: 9 | BA11: Presbiteri bibliaóra | BB11: =COUNTIF($AA$4:$AA$10000,BA11) -> 0 | BC11: =COUNTIF($AB$4:$AB$10000,BA11) -> 0 | BD11: =SUM(BB11:BC11) -> 0 | BE11: =SUMIF($AA$4:$AA$10000,BA11,$H$4:$H$10000) -> 0 | BF11: =SUMIF($AA$4:$AA$10000,BA11,$I$4:$I$10000) -> 0 | BG11: =SUM(BE11:BF11) -> 0 | BH11: =SUMIF($AB$4:$AB$10000,BA11,$H$4:$H$10000) -> 0 | BI11: =SUMIF($AB$4:$AB$10000,BA11,$I$4:$I$10000) -> 0 | BJ11: =SUM(BH11:BI11) -> 0
B12: =IF($B$1=YEAR(Z12),D12,0) -> 0 | D12: =IF(Z12<>$Y$2,IF(YEAR(Z12)=YEAR(Z11),D11+1,1),"") | Z12: =IF(CONCATENATE(F12,F13,F14,F15,F16,F17)<>"",IF(AND(E12<>0,ISNUMBER(E12)=TRUE),E12,Z11),$Y$2) -> 1 | AC12: =YEAR(Z12)&F12&G12 -> 1900 | AZ12: 10 | BA12: Nőszöv. bibliaóra | BB12: =COUNTIF($AA$4:$AA$10000,BA12) -> 0 | BC12: =COUNTIF($AB$4:$AB$10000,BA12) -> 0 | BD12: =SUM(BB12:BC12) -> 0 | BE12: =SUMIF($AA$4:$AA$10000,BA12,$H$4:$H$10000) -> 0 | BF12: =SUMIF($AA$4:$AA$10000,BA12,$I$4:$I$10000) -> 0 | BH12: =SUMIF($AB$4:$AB$10000,BA12,$H$4:$H$10000) -> 0 | BI12: =SUMIF($AB$4:$AB$10000,BA12,$I$4:$I$10000) -> 0
B13: =IF($B$1=YEAR(Z13),D13,0) -> 0 | D13: =IF(Z13<>$Y$2,IF(YEAR(Z13)=YEAR(Z12),D12+1,1),"") | Z13: =IF(CONCATENATE(F13,F14,F15,F16,F17,F18)<>"",IF(AND(E13<>0,ISNUMBER(E13)=TRUE),E13,Z12),$Y$2) -> 1 | AC13: =YEAR(Z13)&F13&G13 -> 1900 | AZ13: 11 | BA13: Házasok bibliaórája | BB13: =COUNTIF($AA$4:$AA$10000,BA13) -> 0 | BC13: =COUNTIF($AB$4:$AB$10000,BA13) -> 0 | BD13: =SUM(BB13:BC13) -> 0 | BE13: =SUMIF($AA$4:$AA$10000,BA13,$H$4:$H$10000) -> 0 | BF13: =SUMIF($AA$4:$AA$10000,BA13,$I$4:$I$10000) -> 0 | BH13: =SUMIF($AB$4:$AB$10000,BA13,$H$4:$H$10000) -> 0 | BI13: =SUMIF($AB$4:$AB$10000,BA13,$I$4:$I$10000) -> 0
B14: =IF($B$1=YEAR(Z14),D14,0) -> 0 | D14: =IF(Z14<>$Y$2,IF(YEAR(Z14)=YEAR(Z13),D13+1,1),"") | Z14: =IF(CONCATENATE(F14,F15,F16,F17,F18,F19)<>"",IF(AND(E14<>0,ISNUMBER(E14)=TRUE),E14,Z13),$Y$2) -> 1 | AC14: =YEAR(Z14)&F14&G14 -> 1900 | AZ14: 12 | BA14: Más bibliaóra 1 | BB14: =COUNTIF($AA$4:$AA$10000,BA14) -> 0 | BC14: =COUNTIF($AB$4:$AB$10000,BA14) -> 0 | BD14: =SUM(BB14:BC14) -> 0 | BE14: =SUMIF($AA$4:$AA$10000,BA14,$H$4:$H$10000) -> 0 | BF14: =SUMIF($AA$4:$AA$10000,BA14,$I$4:$I$10000) -> 0 | BH14: =SUMIF($AB$4:$AB$10000,BA14,$H$4:$H$10000) -> 0 | BI14: =SUMIF($AB$4:$AB$10000,BA14,$I$4:$I$10000) -> 0
B15: =IF($B$1=YEAR(Z15),D15,0) -> 0 | D15: =IF(Z15<>$Y$2,IF(YEAR(Z15)=YEAR(Z14),D14+1,1),"") | Z15: =IF(CONCATENATE(F15,F16,F17,F18,F19,F20)<>"",IF(AND(E15<>0,ISNUMBER(E15)=TRUE),E15,Z14),$Y$2) -> 1 | AC15: =YEAR(Z15)&F15&G15 -> 1900 | AZ15: 13 | BA15: Más bibliaóra 2 | BB15: =COUNTIF($AA$4:$AA$10000,BA15) -> 0 | BC15: =COUNTIF($AB$4:$AB$10000,BA15) -> 0 | BD15: =SUM(BB15:BC15) -> 0 | BE15: =SUMIF($AA$4:$AA$10000,BA15,$H$4:$H$10000) -> 0 | BF15: =SUMIF($AA$4:$AA$10000,BA15,$I$4:$I$10000) -> 0 | BH15: =SUMIF($AB$4:$AB$10000,BA15,$H$4:$H$10000) -> 0 | BI15: =SUMIF($AB$4:$AB$10000,BA15,$I$4:$I$10000) -> 0
B16: =IF($B$1=YEAR(Z16),D16,0) -> 0 | D16: =IF(Z16<>$Y$2,IF(YEAR(Z16)=YEAR(Z15),D15+1,1),"") | Z16: =IF(CONCATENATE(F16,F17,F18,F19,F20,F21)<>"",IF(AND(E16<>0,ISNUMBER(E16)=TRUE),E16,Z15),$Y$2) -> 1 | AC16: =YEAR(Z16)&F16&G16 -> 1900 | AZ16: 14 | BA16: F. keresztelő | BB16: =COUNTIF($AA$4:$AA$10000,BA16) -> 0 | BC16: =COUNTIF($AB$4:$AB$10000,BA16) -> 0 | BD16: =SUM(BB16:BC16) -> 0 | BE16: =SUMIF($AA$4:$AA$10000,BA16,$H$4:$H$10000) -> 0 | BF16: =SUMIF($AA$4:$AA$10000,BA16,$I$4:$I$10000) -> 0 | BH16: =SUMIF($AB$4:$AB$10000,BA16,$H$4:$H$10000) -> 0 | BI16: =SUMIF($AB$4:$AB$10000,BA16,$I$4:$I$10000) -> 0
B17: =IF($B$1=YEAR(Z17),D17,0) -> 0 | D17: =IF(Z17<>$Y$2,IF(YEAR(Z17)=YEAR(Z16),D16+1,1),"") | Z17: =IF(CONCATENATE(F17,F18,F19,F20,F21,F22)<>"",IF(AND(E17<>0,ISNUMBER(E17)=TRUE),E17,Z16),$Y$2) -> 1 | AC17: =YEAR(Z17)&F17&G17 -> 1900 | AZ17: 15 | BA17: N. keresztelő | BB17: =COUNTIF($AA$4:$AA$10000,BA17) -> 0 | BC17: =COUNTIF($AB$4:$AB$10000,BA17) -> 0 | BD17: =SUM(BB17:BC17) -> 0 | BE17: =SUMIF($AA$4:$AA$10000,BA17,$H$4:$H$10000) -> 0 | BF17: =SUMIF($AA$4:$AA$10000,BA17,$I$4:$I$10000) -> 0 | BH17: =SUMIF($AB$4:$AB$10000,BA17,$H$4:$H$10000) -> 0 | BI17: =SUMIF($AB$4:$AB$10000,BA17,$I$4:$I$10000) -> 0
B18: =IF($B$1=YEAR(Z18),D18,0) -> 0 | D18: =IF(Z18<>$Y$2,IF(YEAR(Z18)=YEAR(Z17),D17+1,1),"") | Z18: =IF(CONCATENATE(F18,F19,F20,F21,F22,F23)<>"",IF(AND(E18<>0,ISNUMBER(E18)=TRUE),E18,Z17),$Y$2) -> 1 | AC18: =YEAR(Z18)&F18&G18 -> 1900 | AZ18: 16 | BA18: Keresztelői felkészítő | BB18: =COUNTIF($AA$4:$AA$10000,BA18) -> 0 | BC18: =COUNTIF($AB$4:$AB$10000,BA18) -> 0 | BD18: =SUM(BB18:BC18) -> 0 | BE18: =SUMIF($AA$4:$AA$10000,BA18,$H$4:$H$10000) -> 0 | BF18: =SUMIF($AA$4:$AA$10000,BA18,$I$4:$I$10000) -> 0 | BH18: =SUMIF($AB$4:$AB$10000,BA18,$H$4:$H$10000) -> 0 | BI18: =SUMIF($AB$4:$AB$10000,BA18,$I$4:$I$10000) -> 0
B19: =IF($B$1=YEAR(Z19),D19,0) -> 0 | D19: =IF(Z19<>$Y$2,IF(YEAR(Z19)=YEAR(Z18),D18+1,1),"") | Z19: =IF(CONCATENATE(F19,F20,F21,F22,F23,F24)<>"",IF(AND(E19<>0,ISNUMBER(E19)=TRUE),E19,Z18),$Y$2) -> 1 | AC19: =YEAR(Z19)&F19&G19 -> 1900 | AZ19: 17 | BA19: F. temetés | BB19: =COUNTIF($AA$4:$AA$10000,BA19) -> 0 | BC19: =COUNTIF($AB$4:$AB$10000,BA19) -> 0 | BD19: =SUM(BB19:BC19) -> 0 | BE19: =SUMIF($AA$4:$AA$10000,BA19,$H$4:$H$10000) -> 0 | BF19: =SUMIF($AA$4:$AA$10000,BA19,$I$4:$I$10000) -> 0 | BH19: =SUMIF($AB$4:$AB$10000,BA19,$H$4:$H$10000) -> 0 | BI19: =SUMIF($AB$4:$AB$10000,BA19,$I$4:$I$10000) -> 0
B20: =IF($B$1=YEAR(Z20),D20,0) -> 0 | D20: =IF(Z20<>$Y$2,IF(YEAR(Z20)=YEAR(Z19),D19+1,1),"") | Z20: =IF(CONCATENATE(F20,F21,F22,F23,F24,F25)<>"",IF(AND(E20<>0,ISNUMBER(E20)=TRUE),E20,Z19),$Y$2) -> 1 | AC20: =YEAR(Z20)&F20&G20 -> 1900 | AZ20: 18 | BA20: N. temetés | BB20: =COUNTIF($AA$4:$AA$10000,BA20) -> 0 | BC20: =COUNTIF($AB$4:$AB$10000,BA20) -> 0 | BD20: =SUM(BB20:BC20) -> 0 | BE20: =SUMIF($AA$4:$AA$10000,BA20,$H$4:$H$10000) -> 0 | BF20: =SUMIF($AA$4:$AA$10000,BA20,$I$4:$I$10000) -> 0 | BG20: =SUM(BE20:BF20) -> 0 | BH20: =SUMIF($AB$4:$AB$10000,BA20,$H$4:$H$10000) -> 0 | BI20: =SUMIF($AB$4:$AB$10000,BA20,$I$4:$I$10000) -> 0 | BJ20: =SUM(BH20:BI20) -> 0 | BO20: =IF(BB20<>0,ROUND(BG20/BB20,2),"") | BR20: =IF(BC20<>0,ROUND(BJ20/BC20,2),"")
B21: =IF($B$1=YEAR(Z21),D21,0) -> 0 | D21: =IF(Z21<>$Y$2,IF(YEAR(Z21)=YEAR(Z20),D20+1,1),"") | Z21: =IF(CONCATENATE(F21,F22,F23,F24,F25,F26)<>"",IF(AND(E21<>0,ISNUMBER(E21)=TRUE),E21,Z20),$Y$2) -> 1 | AC21: =YEAR(Z21)&F21&G21 -> 1900 | AZ21: 19 | BA21: Virrasztó | BB21: =COUNTIF($AA$4:$AA$10000,BA21) -> 0 | BC21: =COUNTIF($AB$4:$AB$10000,BA21) -> 0 | BD21: =SUM(BB21:BC21) -> 0 | BE21: =SUMIF($AA$4:$AA$10000,BA21,$H$4:$H$10000) -> 0 | BF21: =SUMIF($AA$4:$AA$10000,BA21,$I$4:$I$10000) -> 0 | BG21: =SUM(BE21:BF21) -> 0 | BH21: =SUMIF($AB$4:$AB$10000,BA21,$H$4:$H$10000) -> 0 | BI21: =SUMIF($AB$4:$AB$10000,BA21,$I$4:$I$10000) -> 0 | BJ21: =SUM(BH21:BI21) -> 0 | BO21: =IF(BD21<>0,ROUND(SUM(BG21,BJ21)/BD21,2),"") | BR21: =IF(BC21<>0,ROUND(BJ21/BC21,2),"")
B22: =IF($B$1=YEAR(Z22),D22,0) -> 0 | D22: =IF(Z22<>$Y$2,IF(YEAR(Z22)=YEAR(Z21),D21+1,1),"") | Z22: =IF(CONCATENATE(F22,F23,F24,F25,F26,F27)<>"",IF(AND(E22<>0,ISNUMBER(E22)=TRUE),E22,Z21),$Y$2) -> 1 | AC22: =YEAR(Z22)&F22&G22 -> 1900 | AZ22: 20 | BA22: Azonos esketés | BB22: =COUNTIF($AA$4:$AA$10000,BA22) -> 0 | BC22: =COUNTIF($AB$4:$AB$10000,BA22) -> 0 | BE22: =SUMIF($AA$4:$AA$10000,BA22,$H$4:$H$10000) -> 0 | BF22: =SUMIF($AA$4:$AA$10000,BA22,$I$4:$I$10000) -> 0 | BG22: =SUM(BE22:BF22) -> 0 | BH22: =SUMIF($AB$4:$AB$10000,BA22,$H$4:$H$10000) -> 0 | BI22: =SUMIF($AB$4:$AB$10000,BA22,$I$4:$I$10000) -> 0 | BJ22: =SUM(BH22:BI22) -> 0 | BO22: =IF(BB22<>0,ROUND(BG22/BB22,2),"") | BR22: =IF(BC22<>0,ROUND(BJ22/BC22,2),"")
B23: =IF($B$1=YEAR(Z23),D23,0) -> 0 | D23: =IF(Z23<>$Y$2,IF(YEAR(Z23)=YEAR(Z22),D22+1,1),"") | Z23: =IF(CONCATENATE(F23,F24,F25,F26,F27,F28)<>"",IF(AND(E23<>0,ISNUMBER(E23)=TRUE),E23,Z22),$Y$2) -> 1 | AC23: =YEAR(Z23)&F23&G23 -> 1900 | AZ23: 21 | BA23: Vegyes esketés | BB23: =COUNTIF($AA$4:$AA$10000,BA23) -> 0 | BC23: =COUNTIF($AB$4:$AB$10000,BA23) -> 0 | BE23: =SUMIF($AA$4:$AA$10000,BA23,$H$4:$H$10000) -> 0 | BF23: =SUMIF($AA$4:$AA$10000,BA23,$I$4:$I$10000) -> 0 | BG23: =SUM(BE23:BF23) -> 0 | BH23: =SUMIF($AB$4:$AB$10000,BA23,$H$4:$H$10000) -> 0 | BI23: =SUMIF($AB$4:$AB$10000,BA23,$I$4:$I$10000) -> 0 | BJ23: =SUM(BH23:BI23) -> 0 | BO23: =IF(BB23<>0,ROUND(BG23/BB23,2),"") | BR23: =IF(BC23<>0,ROUND(BJ23/BC23,2),"")
B24: =IF($B$1=YEAR(Z24),D24,0) -> 0 | D24: =IF(Z24<>$Y$2,IF(YEAR(Z24)=YEAR(Z23),D23+1,1),"") | Z24: =IF(CONCATENATE(F24,F25,F26,F27,F28,F29)<>"",IF(AND(E24<>0,ISNUMBER(E24)=TRUE),E24,Z23),$Y$2) -> 1 | AC24: =YEAR(Z24)&F24&G24 -> 1900 | AZ24: 22 | BA24: Jegyesbeszélgetés | BB24: =COUNTIF($AA$4:$AA$10000,BA24) -> 0 | BC24: =COUNTIF($AB$4:$AB$10000,BA24) -> 0 | BE24: =SUMIF($AA$4:$AA$10000,BA24,$H$4:$H$10000) -> 0 | BF24: =SUMIF($AA$4:$AA$10000,BA24,$I$4:$I$10000) -> 0 | BG24: =SUM(BE24:BF24) -> 0 | BH24: =SUMIF($AB$4:$AB$10000,BA24,$H$4:$H$10000) -> 0 | BI24: =SUMIF($AB$4:$AB$10000,BA24,$I$4:$I$10000) -> 0 | BJ24: =SUM(BH24:BI24) -> 0 | BO24: =IF(BB24<>0,ROUND(BG24/BB24,2),"") | BR24: =IF(BC24<>0,ROUND(BJ24/BC24,2),"")
B25: =IF($B$1=YEAR(Z25),D25,0) -> 0 | D25: =IF(Z25<>$Y$2,IF(YEAR(Z25)=YEAR(Z24),D24+1,1),"") | Z25: =IF(CONCATENATE(F25,F26,F27,F28,F29,F30)<>"",IF(AND(E25<>0,ISNUMBER(E25)=TRUE),E25,Z24),$Y$2) -> 1 | AC25: =YEAR(Z25)&F25&G25 -> 1900 | AZ25: 23 | BA25: Digitális alkalmak | BB25: =COUNTIF($AA$4:$AA$10000,BA25) -> 0 | BC25: =COUNTIF($AB$4:$AB$10000,BA25) -> 0 | BE25: =SUMIF($AA$4:$AA$10000,BA25,$H$4:$H$10000) -> 0 | BF25: =SUMIF($AA$4:$AA$10000,BA25,$I$4:$I$10000) -> 0 | BG25: =SUM(BE25:BF25) -> 0 | BH25: =SUMIF($AB$4:$AB$10000,BA25,$H$4:$H$10000) -> 0 | BI25: =SUMIF($AB$4:$AB$10000,BA25,$I$4:$I$10000) -> 0 | BJ25: =SUM(BH25:BI25) -> 0 | BO25: =IF(BB25<>0,ROUND(BG25/BB25,2),"") | BR25: =IF(BC25<>0,ROUND(BJ25/BC25,2),"")
B26: =IF($B$1=YEAR(Z26),D26,0) -> 0 | D26: =IF(Z26<>$Y$2,IF(YEAR(Z26)=YEAR(Z25),D25+1,1),"") | Z26: =IF(CONCATENATE(F26,F27,F28,F29,F30,F31)<>"",IF(AND(E26<>0,ISNUMBER(E26)=TRUE),E26,Z25),$Y$2) -> 1 | AC26: =YEAR(Z26)&F26&G26 -> 1900 | AZ26: 24 | BA26: Imahét | BB26: =COUNTIF($AA$4:$AA$10000,BA26) -> 0 | BC26: =COUNTIF($AB$4:$AB$10000,BA26) -> 0 | BE26: =SUMIF($AA$4:$AA$10000,BA26,$H$4:$H$10000) -> 0 | BF26: =SUMIF($AA$4:$AA$10000,BA26,$I$4:$I$10000) -> 0 | BG26: =SUM(BE26:BF26) -> 0 | BH26: =SUMIF($AB$4:$AB$10000,BA26,$H$4:$H$10000) -> 0 | BI26: =SUMIF($AB$4:$AB$10000,BA26,$I$4:$I$10000) -> 0 | BJ26: =SUM(BH26:BI26) -> 0 | BO26: =IF(BB26<>0,ROUND(BG26/BB26,2),"") | BR26: =IF(BC26<>0,ROUND(BJ26/BC26,2),"")
B27: =IF($B$1=YEAR(Z27),D27,0) -> 0 | D27: =IF(Z27<>$Y$2,IF(YEAR(Z27)=YEAR(Z26),D26+1,1),"") | Z27: =IF(CONCATENATE(F27,F28,F29,F30,F31,F32)<>"",IF(AND(E27<>0,ISNUMBER(E27)=TRUE),E27,Z26),$Y$2) -> 1 | AC27: =YEAR(Z27)&F27&G27 -> 1900 | AZ27: 25 | BA27: Húsvét I. it. | BB27: =COUNTIF($AA$4:$AA$10000,BA27) -> 0 | BC27: =COUNTIF($AB$4:$AB$10000,BA27) -> 0 | BE27: =SUMIF($AA$4:$AA$10000,BA27,$H$4:$H$10000) -> 0 | BF27: =SUMIF($AA$4:$AA$10000,BA27,$I$4:$I$10000) -> 0 | BG27: =SUM(BE27:BF27) -> 0 | BH27: =SUMIF($AB$4:$AB$10000,BA27,$H$4:$H$10000) -> 0 | BI27: =SUMIF($AB$4:$AB$10000,BA27,$I$4:$I$10000) -> 0 | BJ27: =SUM(BH27:BI27) -> 0 | BO27: =IF(BB27<>0,ROUND(BG27/BB27,2),"") | BR27: =IF(BC27<>0,ROUND(BJ27/BC27,2),"")
B28: =IF($B$1=YEAR(Z28),D28,0) -> 0 | D28: =IF(Z28<>$Y$2,IF(YEAR(Z28)=YEAR(Z27),D27+1,1),"") | Z28: =IF(CONCATENATE(F28,F29,F30,F31,F32,F33)<>"",IF(AND(E28<>0,ISNUMBER(E28)=TRUE),E28,Z27),$Y$2) -> 1 | AC28: =YEAR(Z28)&F28&G28 -> 1900 | AZ28: 26 | BA28: Húsvét II. it. | BB28: =COUNTIF($AA$4:$AA$10000,BA28) -> 0 | BC28: =COUNTIF($AB$4:$AB$10000,BA28) -> 0 | BE28: =SUMIF($AA$4:$AA$10000,BA28,$H$4:$H$10000) -> 0 | BF28: =SUMIF($AA$4:$AA$10000,BA28,$I$4:$I$10000) -> 0 | BG28: =SUM(BE28:BF28) -> 0 | BH28: =SUMIF($AB$4:$AB$10000,BA28,$H$4:$H$10000) -> 0 | BI28: =SUMIF($AB$4:$AB$10000,BA28,$I$4:$I$10000) -> 0 | BJ28: =SUM(BH28:BI28) -> 0 | BO28: =IF(BB28<>0,ROUND(BG28/BB28,2),"") | BR28: =IF(BC28<>0,ROUND(BJ28/BC28,2),"")
B29: =IF($B$1=YEAR(Z29),D29,0) -> 0 | D29: =IF(Z29<>$Y$2,IF(YEAR(Z29)=YEAR(Z28),D28+1,1),"") | Z29: =IF(CONCATENATE(F29,F30,F31,F32,F33,F34)<>"",IF(AND(E29<>0,ISNUMBER(E29)=TRUE),E29,Z28),$Y$2) -> 1 | AC29: =YEAR(Z29)&F29&G29 -> 1900 | AZ29: 27 | BA29: Húsvét III. it. | BB29: =COUNTIF($AA$4:$AA$10000,BA29) -> 0 | BC29: =COUNTIF($AB$4:$AB$10000,BA29) -> 0 | BE29: =SUMIF($AA$4:$AA$10000,BA29,$H$4:$H$10000) -> 0 | BF29: =SUMIF($AA$4:$AA$10000,BA29,$I$4:$I$10000) -> 0 | BG29: =SUM(BE29:BF29) -> 0 | BH29: =SUMIF($AB$4:$AB$10000,BA29,$H$4:$H$10000) -> 0 | BI29: =SUMIF($AB$4:$AB$10000,BA29,$I$4:$I$10000) -> 0 | BJ29: =SUM(BH29:BI29) -> 0 | BO29: =IF(BB29<>0,ROUND(BG29/BB29,2),"") | BR29: =IF(BC29<>0,ROUND(BJ29/BC29,2),"")
B30: =IF($B$1=YEAR(Z30),D30,0) -> 0 | D30: =IF(Z30<>$Y$2,IF(YEAR(Z30)=YEAR(Z29),D29+1,1),"") | Z30: =IF(CONCATENATE(F30,F31,F32,F33,F34,F35)<>"",IF(AND(E30<>0,ISNUMBER(E30)=TRUE),E30,Z29),$Y$2) -> 1 | AC30: =YEAR(Z30)&F30&G30 -> 1900 | AZ30: 28 | BA30: Pünkösd I. it. | BB30: =COUNTIF($AA$4:$AA$10000,BA30) -> 0 | BC30: =COUNTIF($AB$4:$AB$10000,BA30) -> 0 | BE30: =SUMIF($AA$4:$AA$10000,BA30,$H$4:$H$10000) -> 0 | BF30: =SUMIF($AA$4:$AA$10000,BA30,$I$4:$I$10000) -> 0 | BG30: =SUM(BE30:BF30) -> 0 | BH30: =SUMIF($AB$4:$AB$10000,BA30,$H$4:$H$10000) -> 0 | BI30: =SUMIF($AB$4:$AB$10000,BA30,$I$4:$I$10000) -> 0 | BJ30: =SUM(BH30:BI30) -> 0 | BO30: =IF(BB30<>0,ROUND(BG30/BB30,2),"") | BR30: =IF(BC30<>0,ROUND(BJ30/BC30,2),"")
B31: =IF($B$1=YEAR(Z31),D31,0) -> 0 | D31: =IF(Z31<>$Y$2,IF(YEAR(Z31)=YEAR(Z30),D30+1,1),"") | Z31: =IF(CONCATENATE(F31,F32,F33,F34,F35,F36)<>"",IF(AND(E31<>0,ISNUMBER(E31)=TRUE),E31,Z30),$Y$2) -> 1 | AC31: =YEAR(Z31)&F31&G31 -> 1900 | AZ31: 29 | BA31: Pünkösd II. it. | BB31: =COUNTIF($AA$4:$AA$10000,BA31) -> 0 | BC31: =COUNTIF($AB$4:$AB$10000,BA31) -> 0 | BD31: =SUM(BB31:BC31) -> 0 | BE31: =SUMIF($AA$4:$AA$10000,BA31,$H$4:$H$10000) -> 0 | BF31: =SUMIF($AA$4:$AA$10000,BA31,$I$4:$I$10000) -> 0 | BG31: =SUM(BE31:BF31) -> 0 | BH31: =SUMIF($AB$4:$AB$10000,BA31,$H$4:$H$10000) -> 0 | BI31: =SUMIF($AB$4:$AB$10000,BA31,$I$4:$I$10000) -> 0 | BJ31: =SUM(BH31:BI31) -> 0 | BO31: =IF(BD31<>0,ROUND(SUM(BG31,BJ31)/BD31,2),"")
B32: =IF($B$1=YEAR(Z32),D32,0) -> 0 | D32: =IF(Z32<>$Y$2,IF(YEAR(Z32)=YEAR(Z31),D31+1,1),"") | Z32: =IF(CONCATENATE(F32,F33,F34,F35,F36,F37)<>"",IF(AND(E32<>0,ISNUMBER(E32)=TRUE),E32,Z31),$Y$2) -> 1 | AC32: =YEAR(Z32)&F32&G32 -> 1900 | AZ32: 30 | BA32: Pünkösd III. it. | BB32: =COUNTIF($AA$4:$AA$10000,BA32) -> 0 | BC32: =COUNTIF($AB$4:$AB$10000,BA32) -> 0 | BD32: =SUM(BB32:BC32) -> 0 | BE32: =SUMIF($AA$4:$AA$10000,BA32,$H$4:$H$10000) -> 0 | BF32: =SUMIF($AA$4:$AA$10000,BA32,$I$4:$I$10000) -> 0 | BG32: =SUM(BE32:BF32) -> 0 | BH32: =SUMIF($AB$4:$AB$10000,BA32,$H$4:$H$10000) -> 0 | BI32: =SUMIF($AB$4:$AB$10000,BA32,$I$4:$I$10000) -> 0 | BJ32: =SUM(BH32:BI32) -> 0 | BO32: =IF(BD32<>0,ROUND(SUM(BG32,BJ32)/BD32,2),"")
B33: =IF($B$1=YEAR(Z33),D33,0) -> 0 | D33: =IF(Z33<>$Y$2,IF(YEAR(Z33)=YEAR(Z32),D32+1,1),"") | Z33: =IF(CONCATENATE(F33,F34,F35,F36,F37,F38)<>"",IF(AND(E33<>0,ISNUMBER(E33)=TRUE),E33,Z32),$Y$2) -> 1 | AC33: =YEAR(Z33)&F33&G33 -> 1900 | AZ33: 31 | BA33: Karácsony I. it. | BB33: =COUNTIF($AA$4:$AA$10000,BA33) -> 0 | BC33: =COUNTIF($AB$4:$AB$10000,BA33) -> 0 | BD33: =SUM(BB33:BC33) -> 0 | BE33: =SUMIF($AA$4:$AA$10000,BA33,$H$4:$H$10000) -> 0 | BF33: =SUMIF($AA$4:$AA$10000,BA33,$I$4:$I$10000) -> 0 | BG33: =SUM(BE33:BF33) -> 0 | BH33: =SUMIF($AB$4:$AB$10000,BA33,$H$4:$H$10000) -> 0 | BI33: =SUMIF($AB$4:$AB$10000,BA33,$I$4:$I$10000) -> 0 | BJ33: =SUM(BH33:BI33) -> 0 | BO33: =IF(BD33<>0,ROUND(SUM(BG33,BJ33)/BD33,2),"")
B34: =IF($B$1=YEAR(Z34),D34,0) -> 0 | D34: =IF(Z34<>$Y$2,IF(YEAR(Z34)=YEAR(Z33),D33+1,1),"") | Z34: =IF(CONCATENATE(F34,F35,F36,F37,F38,F39)<>"",IF(AND(E34<>0,ISNUMBER(E34)=TRUE),E34,Z33),$Y$2) -> 1 | AC34: =YEAR(Z34)&F34&G34 -> 1900 | AZ34: 32 | BA34: Karácsony II. it.
B35: =IF($B$1=YEAR(Z35),D35,0) -> 0 | D35: =IF(Z35<>$Y$2,IF(YEAR(Z35)=YEAR(Z34),D34+1,1),"") | Z35: =IF(CONCATENATE(F35,F36,F37,F38,F39,F40)<>"",IF(AND(E35<>0,ISNUMBER(E35)=TRUE),E35,Z34),$Y$2) -> 1 | AC35: =YEAR(Z35)&F35&G35 -> 1900 | AZ35: 33 | BA35: Karácsony III. it.
B36: =IF($B$1=YEAR(Z36),D36,0) -> 0 | D36: =IF(Z36<>$Y$2,IF(YEAR(Z36)=YEAR(Z35),D35+1,1),"") | Z36: =IF(CONCATENATE(F36,F37,F38,F39,F40,F41)<>"",IF(AND(E36<>0,ISNUMBER(E36)=TRUE),E36,Z35),$Y$2) -> 1 | AC36: =YEAR(Z36)&F36&G36 -> 1900 | AZ36: 34 | BA36: Vallásos ünnepély
B37: =IF($B$1=YEAR(Z37),D37,0) -> 0 | D37: =IF(Z37<>$Y$2,IF(YEAR(Z37)=YEAR(Z36),D36+1,1),"") | Z37: =IF(CONCATENATE(F37,F38,F39,F40,F41,F42)<>"",IF(AND(E37<>0,ISNUMBER(E37)=TRUE),E37,Z36),$Y$2) -> 1 | AC37: =YEAR(Z37)&F37&G37 -> 1900 | AZ37: 35 | BA37: Szeretetvendégség
B38: =IF($B$1=YEAR(Z38),D38,0) -> 0 | D38: =IF(Z38<>$Y$2,IF(YEAR(Z38)=YEAR(Z37),D37+1,1),"") | Z38: =IF(CONCATENATE(F38,F39,F40,F41,F42,F43)<>"",IF(AND(E38<>0,ISNUMBER(E38)=TRUE),E38,Z37),$Y$2) -> 1 | AC38: =YEAR(Z38)&F38&G38 -> 1900 | AZ38: 36 | BA38: Egyéb szolgálat
B39: =IF($B$1=YEAR(Z39),D39,0) -> 0 | D39: =IF(Z39<>$Y$2,IF(YEAR(Z39)=YEAR(Z38),D38+1,1),"") | Z39: =IF(CONCATENATE(F39,F40,F41,F42,F43,F44)<>"",IF(AND(E39<>0,ISNUMBER(E39)=TRUE),E39,Z38),$Y$2) -> 1 | AC39: =YEAR(Z39)&F39&G39 -> 1900 | AZ39: 37 | BA39: Presbiteri felkészítő
B40: =IF($B$1=YEAR(Z40),D40,0) -> 0 | D40: =IF(Z40<>$Y$2,IF(YEAR(Z40)=YEAR(Z39),D39+1,1),"") | Z40: =IF(CONCATENATE(F40,F41,F42,F43,F44,F45)<>"",IF(AND(E40<>0,ISNUMBER(E40)=TRUE),E40,Z39),$Y$2) -> 1 | AC40: =YEAR(Z40)&F40&G40 -> 1900
...

Sheet Katekezis
D1: =Szolgalati_alkalmak!D1 -> Református Egyházközség | V1: 1 | Y1: =Szolgalati_alkalmak!Y1 -> 46023
D2: A katekézis munkanaplója
D3: Sor szám | E3: Dátum | F3: Katekézis jellege | G3: Részt vett | H3: Tananyag | I3: Persely pénz | J3: A katekézist tartotta | K3: Megjegyzés | AA3: Vallásóra 1. csoport
D4: =IF(W4<>$V$1,IF(YEAR(W4)=YEAR(W3),D3+1,1),"") | W4: =IF(CONCATENATE(F4,F5,F6,F7,F8,F9)<>"",IF(AND(E4<>0,ISNUMBER(E4)=TRUE),E4,W3),$V$1) -> 1 | AA4: Elsőéves konf. felkészítő | AC4: =YEAR(W4)&F4 -> 1900
D5: =IF(W5<>$V$1,IF(YEAR(W5)=YEAR(W4),D4+1,1),"") | W5: =IF(CONCATENATE(F5,F6,F7,F8,F9,F10)<>"",IF(AND(E5<>0,ISNUMBER(E5)=TRUE),E5,W4),$V$1) -> 1 | AA5: Másodéves konf. felkészítő | AC5: =YEAR(W5)&F5 -> 1900
D6: =IF(W6<>$V$1,IF(YEAR(W6)=YEAR(W5),D5+1,1),"") | W6: =IF(CONCATENATE(F6,F7,F8,F9,F10,F11)<>"",IF(AND(E6<>0,ISNUMBER(E6)=TRUE),E6,W5),$V$1) -> 1 | AA6: Gyermekistentisztelet | AC6: =YEAR(W6)&F6 -> 1900
D7: =IF(W7<>$V$1,IF(YEAR(W7)=YEAR(W6),D6+1,1),"") | W7: =IF(CONCATENATE(F7,F8,F9,F10,F11,F12)<>"",IF(AND(E7<>0,ISNUMBER(E7)=TRUE),E7,W6),$V$1) -> 1 | AA7: Vasárnapi iskola | AC7: =YEAR(W7)&F7 -> 1900
D8: =IF(W8<>$V$1,IF(YEAR(W8)=YEAR(W7),D7+1,1),"") | W8: =IF(CONCATENATE(F8,F9,F10,F11,F12,F13)<>"",IF(AND(E8<>0,ISNUMBER(E8)=TRUE),E8,W7),$V$1) -> 1 | AA8: Vallásóra 2. csoport | AC8: =YEAR(W8)&F8 -> 1900
D9: =IF(W9<>$V$1,IF(YEAR(W9)=YEAR(W8),D8+1,1),"") | W9: =IF(CONCATENATE(F9,F10,F11,F12,F13,F14)<>"",IF(AND(E9<>0,ISNUMBER(E9)=TRUE),E9,W8),$V$1) -> 1 | AA9: Vallásóra 3. csoport | AC9: =YEAR(W9)&F9 -> 1900
D10: =IF(W10<>$V$1,IF(YEAR(W10)=YEAR(W9),D9+1,1),"") | W10: =IF(CONCATENATE(F10,F11,F12,F13,F14,F15)<>"",IF(AND(E10<>0,ISNUMBER(E10)=TRUE),E10,W9),$V$1) -> 1 | AA10: Vallásóra 4. csoport | AC10: =YEAR(W10)&F10 -> 1900
D11: =IF(W11<>$V$1,IF(YEAR(W11)=YEAR(W10),D10+1,1),"") | W11: =IF(CONCATENATE(F11,F12,F13,F14,F15,F16)<>"",IF(AND(E11<>0,ISNUMBER(E11)=TRUE),E11,W10),$V$1) -> 1 | AA11: Vallásóra 5. csoport | AC11: =YEAR(W11)&F11 -> 1900
D12: =IF(W12<>$V$1,IF(YEAR(W12)=YEAR(W11),D11+1,1),"") | W12: =IF(CONCATENATE(F12,F13,F14,F15,F16,F17)<>"",IF(AND(E12<>0,ISNUMBER(E12)=TRUE),E12,W11),$V$1) -> 1 | AA12: VBH - Vakációs Bibliahét | AC12: =YEAR(W12)&F12 -> 1900
D13: =IF(W13<>$V$1,IF(YEAR(W13)=YEAR(W12),D12+1,1),"") | W13: =IF(CONCATENATE(F13,F14,F15,F16,F17,F18)<>"",IF(AND(E13<>0,ISNUMBER(E13)=TRUE),E13,W12),$V$1) -> 1 | AA13: Egyéb foglalkozás | AC13: =YEAR(W13)&F13 -> 1900
D14: =IF(W14<>$V$1,IF(YEAR(W14)=YEAR(W13),D13+1,1),"") | W14: =IF(CONCATENATE(F14,F15,F16,F17,F18,F19)<>"",IF(AND(E14<>0,ISNUMBER(E14)=TRUE),E14,W13),$V$1) -> 1 | AC14: =YEAR(W14)&F14 -> 1900
D15: =IF(W15<>$V$1,IF(YEAR(W15)=YEAR(W14),D14+1,1),"") | W15: =IF(CONCATENATE(F15,F16,F17,F18,F19,F20)<>"",IF(AND(E15<>0,ISNUMBER(E15)=TRUE),E15,W14),$V$1) -> 1 | AC15: =YEAR(W15)&F15 -> 1900
D16: =IF(W16<>$V$1,IF(YEAR(W16)=YEAR(W15),D15+1,1),"") | W16: =IF(CONCATENATE(F16,F17,F18,F19,F20,F21)<>"",IF(AND(E16<>0,ISNUMBER(E16)=TRUE),E16,W15),$V$1) -> 1 | AC16: =YEAR(W16)&F16 -> 1900
D17: =IF(W17<>$V$1,IF(YEAR(W17)=YEAR(W16),D16+1,1),"") | W17: =IF(CONCATENATE(F17,F18,F19,F20,F21,F22)<>"",IF(AND(E17<>0,ISNUMBER(E17)=TRUE),E17,W16),$V$1) -> 1 | AC17: =YEAR(W17)&F17 -> 1900
D18: =IF(W18<>$V$1,IF(YEAR(W18)=YEAR(W17),D17+1,1),"") | W18: =IF(CONCATENATE(F18,F19,F20,F21,F22,F23)<>"",IF(AND(E18<>0,ISNUMBER(E18)=TRUE),E18,W17),$V$1) -> 1 | AC18: =YEAR(W18)&F18 -> 1900
D19: =IF(W19<>$V$1,IF(YEAR(W19)=YEAR(W18),D18+1,1),"") | W19: =IF(CONCATENATE(F19,F20,F21,F22,F23,F24)<>"",IF(AND(E19<>0,ISNUMBER(E19)=TRUE),E19,W18),$V$1) -> 1 | AC19: =YEAR(W19)&F19 -> 1900
D20: =IF(W20<>$V$1,IF(YEAR(W20)=YEAR(W19),D19+1,1),"") | W20: =IF(CONCATENATE(F20,F21,F22,F23,F24,F25)<>"",IF(AND(E20<>0,ISNUMBER(E20)=TRUE),E20,W19),$V$1) -> 1 | AC20: =YEAR(W20)&F20 -> 1900
D21: =IF(W21<>$V$1,IF(YEAR(W21)=YEAR(W20),D20+1,1),"") | W21: =IF(CONCATENATE(F21,F22,F23,F24,F25,F26)<>"",IF(AND(E21<>0,ISNUMBER(E21)=TRUE),E21,W20),$V$1) -> 1 | AC21: =YEAR(W21)&F21 -> 1900
D22: =IF(W22<>$V$1,IF(YEAR(W22)=YEAR(W21),D21+1,1),"") | W22: =IF(CONCATENATE(F22,F23,F24,F25,F26,F27)<>"",IF(AND(E22<>0,ISNUMBER(E22)=TRUE),E22,W21),$V$1) -> 1 | AC22: =YEAR(W22)&F22 -> 1900
D23: =IF(W23<>$V$1,IF(YEAR(W23)=YEAR(W22),D22+1,1),"") | W23: =IF(CONCATENATE(F23,F24,F25,F26,F27,F28)<>"",IF(AND(E23<>0,ISNUMBER(E23)=TRUE),E23,W22),$V$1) -> 1 | AC23: =YEAR(W23)&F23 -> 1900
D24: =IF(W24<>$V$1,IF(YEAR(W24)=YEAR(W23),D23+1,1),"") | W24: =IF(CONCATENATE(F24,F25,F26,F27,F28,F29)<>"",IF(AND(E24<>0,ISNUMBER(E24)=TRUE),E24,W23),$V$1) -> 1 | AC24: =YEAR(W24)&F24 -> 1900
D25: =IF(W25<>$V$1,IF(YEAR(W25)=YEAR(W24),D24+1,1),"") | W25: =IF(CONCATENATE(F25,F26,F27,F28,F29,F30)<>"",IF(AND(E25<>0,ISNUMBER(E25)=TRUE),E25,W24),$V$1) -> 1 | AC25: =YEAR(W25)&F25 -> 1900
... D5000: =IF(W5000<>$V$1,IF(YEAR(W5000)=YEAR(W4999),D4999+1,1),"") | W5000: =IF(CONCATENATE(F5000,F5001,F5002,F5003,F5004,F5005)<>"",IF(AND(E5000<>0,ISNUMBER(E5000)=TRUE),E5000,W4999),$V$1) -> 1 | AC5000: =YEAR(W5000)&F5000 -> 1900

Sheet Csaladlatogatas
D1: =Szolgalati_alkalmak!D1 -> Református Egyházközség | V1: 1 | W1: =Szolgalati_alkalmak!AA1 -> 0 | Y1: =Szolgalati_alkalmak!Y1 -> 46023 | AA1: CsL
D2: Családlátogatási-beteglátogatási munkanapló | AA2: BL
D3: Sor szám | E3: Dátum | F3: CsL BL | G3: A meglátogatott család neve | H3: A meglátogatott család címe | I3: Jelen volt | J3: Jegyzet (Olvasott bibliai rész, ének, egyéb)
D4: =IF(W4<>$V$1,IF(YEAR(W4)=YEAR(W3),D3+1,1),"") | W4: =IF(CONCATENATE(F4,F5,F6,F7,F8,F9)<>"",IF(AND(E4<>0,ISNUMBER(E4)=TRUE),E4,W3),$V$1) -> 1 | AC4: =YEAR(W4)&F4 -> 1900
D5: =IF(W5<>$V$1,IF(YEAR(W5)=YEAR(W4),D4+1,1),"") | W5: =IF(CONCATENATE(F5,F6,F7,F8,F9,F10)<>"",IF(AND(E5<>0,ISNUMBER(E5)=TRUE),E5,W4),$V$1) -> 1 | AC5: =YEAR(W5)&F5 -> 1900
D6: =IF(W6<>$V$1,IF(YEAR(W6)=YEAR(W5),D5+1,1),"") | W6: =IF(CONCATENATE(F6,F7,F8,F9,F10,F11)<>"",IF(AND(E6<>0,ISNUMBER(E6)=TRUE),E6,W5),$V$1) -> 1 | AC6: =YEAR(W6)&F6 -> 1900
D7: =IF(W7<>$V$1,IF(YEAR(W7)=YEAR(W6),D6+1,1),"") | W7: =IF(CONCATENATE(F7,F8,F9,F10,F11,F12)<>"",IF(AND(E7<>0,ISNUMBER(E7)=TRUE),E7,W6),$V$1) -> 1 | AC7: =YEAR(W7)&F7 -> 1900
D8: =IF(W8<>$V$1,IF(YEAR(W8)=YEAR(W7),D7+1,1),"") | W8: =IF(CONCATENATE(F8,F9,F10,F11,F12,F13)<>"",IF(AND(E8<>0,ISNUMBER(E8)=TRUE),E8,W7),$V$1) -> 1 | AC8: =YEAR(W8)&F8 -> 1900
D9: =IF(W9<>$V$1,IF(YEAR(W9)=YEAR(W8),D8+1,1),"") | W9: =IF(CONCATENATE(F9,F10,F11,F12,F13,F14)<>"",IF(AND(E9<>0,ISNUMBER(E9)=TRUE),E9,W8),$V$1) -> 1 | AC9: =YEAR(W9)&F9 -> 1900
D10: =IF(W10<>$V$1,IF(YEAR(W10)=YEAR(W9),D9+1,1),"") | W10: =IF(CONCATENATE(F10,F11,F12,F13,F14,F15)<>"",IF(AND(E10<>0,ISNUMBER(E10)=TRUE),E10,W9),$V$1) -> 1 | AC10: =YEAR(W10)&F10 -> 1900
D11: =IF(W11<>$V$1,IF(YEAR(W11)=YEAR(W10),D10+1,1),"") | W11: =IF(CONCATENATE(F11,F12,F13,F14,F15,F16)<>"",IF(AND(E11<>0,ISNUMBER(E11)=TRUE),E11,W10),$V$1) -> 1 | AC11: =YEAR(W11)&F11 -> 1900
D12: =IF(W12<>$V$1,IF(YEAR(W12)=YEAR(W11),D11+1,1),"") | W12: =IF(CONCATENATE(F12,F13,F14,F15,F16,F17)<>"",IF(AND(E12<>0,ISNUMBER(E12)=TRUE),E12,W11),$V$1) -> 1 | AC12: =YEAR(W12)&F12 -> 1900
D13: =IF(W13<>$V$1,IF(YEAR(W13)=YEAR(W12),D12+1,1),"") | W13: =IF(CONCATENATE(F13,F14,F15,F16,F17,F18)<>"",IF(AND(E13<>0,ISNUMBER(E13)=TRUE),E13,W12),$V$1) -> 1 | AC13: =YEAR(W13)&F13 -> 1900
D14: =IF(W14<>$V$1,IF(YEAR(W14)=YEAR(W13),D13+1,1),"") | W14: =IF(CONCATENATE(F14,F15,F16,F17,F18,F19)<>"",IF(AND(E14<>0,ISNUMBER(E14)=TRUE),E14,W13),$V$1) -> 1 | AC14: =YEAR(W14)&F14 -> 1900
D15: =IF(W15<>$V$1,IF(YEAR(W15)=YEAR(W14),D14+1,1),"") | W15: =IF(CONCATENATE(F15,F16,F17,F18,F19,F20)<>"",IF(AND(E15<>0,ISNUMBER(E15)=TRUE),E15,W14),$V$1) -> 1 | AC15: =YEAR(W15)&F15 -> 1900
... D5000: =IF(W5000<>$V$1,IF(YEAR(W5000)=YEAR(W4999),D4999+1,1),"") | W5000: =IF(CONCATENATE(F5000,F5001,F5002,F5003,F5004,F5005)<>"",IF(AND(E5000<>0,ISNUMBER(E5000)=TRUE),E5000,W4999),$V$1) -> 1 | AC5000: =YEAR(W5000)&F5000 -> 1900
W5001: =E5001 -> 0 | X5001: =IF(YEAR(W5001)=$W$1,F5001,"")
W5002: =E5002 -> 0 | X5002: =IF(YEAR(W5002)=$W$1,F5002,"")
W5003: =E5003 -> 0 | X5003: =IF(YEAR(W5003)=$W$1,F5003,"")
W5004: =E5004 -> 0 | X5004: =IF(YEAR(W5004)=$W$1,F5004,"")
W5005: =E5005 -> 0 | X5005: =IF(YEAR(W5005)=$W$1,F5005,"")
W5006: =E5006 -> 0 | X5006: =IF(YEAR(W5006)=$W$1,F5006,"")
W5007: =E5007 -> 0 | X5007: =IF(YEAR(W5007)=$W$1,F5007,"")
W5008: =E5008 -> 0 | X5008: =IF(YEAR(W5008)=$W$1,F5008,"")
W5009: =E5009 -> 0 | X5009: =IF(YEAR(W5009)=$W$1,F5009,"")
W5010: =E5010 -> 0 | X5010: =IF(YEAR(W5010)=$W$1,F5010,"")
W5011: =E5011 -> 0 | X5011: =IF(YEAR(W5011)=$W$1,F5011,"")
W5012: =E5012 -> 0 | X5012: =IF(YEAR(W5012)=$W$1,F5012,"")
... W6000: =E6000 -> 0 | X6000: =IF(YEAR(W6000)=$W$1,F6000,"")

Sheet Adatlap
A1: Az áthúzás, kivágás, másolás, beillesztés lehetőségeket ne használd. Ha valamit rossz helyre írtál, töröld ki és írd újra a megfelelő helyre. | C1: 2026 | D1: =C1+1 -> 2027 | E1: =D1+1 -> 2028 | F1: =E1+1 -> 2029 | G1: =F1+1 -> 2030 | H1: =G1+1 -> 2031 | I1: =H1+1 -> 2032 | J1: =I1+1 -> 2033 | K1: =J1+1 -> 2034 | L1: =K1+1 -> 2035 | M1: Összesen | N1: =MAX(Szolgalati_alkalmak!E4:E8000) -> 0 | P1: =C1 -> 2026 | Q1: =D1 -> 2027 | R1: =E1 -> 2028 | S1: =F1 -> 2029 | T1: =G1 -> 2030 | U1: =H1 -> 2031 | V1: =I1 -> 2032 | W1: =J1 -> 2033 | ... Y1: =L1 -> 2035 | AA1: Brassói | AB1: Főgondnok
B2: Egyházmegye | D2: 2 | E2: 3 | F2: 4 | G2: 5 | H2: 6 | I2: 7 | J2: 8 | K2: 9 | L2: 10 | M2: 11 | N2: =IF(ISERROR(HLOOKUP(YEAR(N1),C1:L2,2,FALSE))=TRUE,1,HLOOKUP(YEAR(N1),C1:L2,2,FALSE)) -> 1 | O2: Du. | AA2: Dési | AB2: Gondnok
B3: Egyházközség neve (Református Egyházközség nélkül) | O3: De.2 | AA3: Erdővidéki
B4: Lelkipásztor | D4: =IF(C4<>0,C4,"") | E4: =IF(D4<>0,D4,"") | F4: =IF(E4<>0,E4,"") | G4: =IF(F4<>0,F4,"") | H4: =IF(G4<>0,G4,"") | I4: =IF(H4<>0,H4,"") | J4: =IF(I4<>0,I4,"") | K4: =IF(J4<>0,J4,"") | L4: =IF(K4<>0,K4,"") | O4: Du.2 | AA4: Görgényi
B5: Főgondnok/Gondnok | D5: =IF(C5<>0,C5,"") | E5: =IF(D5<>0,D5,"") | F5: =IF(E5<>0,E5,"") | G5: =IF(F5<>0,F5,"") | H5: =IF(G5<>0,G5,"") | I5: =IF(H5<>0,H5,"") | J5: =IF(I5<>0,I5,"") | K5: =IF(J5<>0,J5,"") | L5: =IF(K5<>0,K5,"") | AA5: Hunyadi
B6: Presbiteri gyűlés dátuma | AA6: Kalotaszegi
B7: Határozat száma | AA7: Kézdi-Orbai
B8: Közgyűlés dátuma | AA8: Kolozsvári
B9: Határozat száma | AA9: Küküllői
B10: Egyházközségi iktatószám | AA10: Marosi
A11: I. Adatok a lélekszámról | AA11: Maros-Mezőségi
A12: 1. | B12: Az_előző_évi_lélekszám: férfi | D12: =SUM(C12,C14,-C16,C18,-C21,C24,-C26,-C28) -> 0 | E12: =SUM(D12,D14,-D16,D18,-D21,D24,-D26,-D28) -> 0 | F12: =SUM(E12,E14,-E16,E18,-E21,E24,-E26,-E28) -> 0 | G12: =SUM(F12,F14,-F16,F18,-F21,F24,-F26,-F28) -> 0 | H12: =SUM(G12,G14,-G16,G18,-G21,G24,-G26,-G28) -> 0 | I12: =SUM(H12,H14,-H16,H18,-H21,H24,-H26,-H28) -> 0 | J12: =SUM(I12,I14,-I16,I18,-I21,I24,-I26,-I28) -> 0 | K12: =SUM(J12,J14,-J16,J18,-J21,J24,-J26,-J28) -> 0 | L12: =SUM(K12,K14,-K16,K18,-K21,K24,-K26,-K28) -> 0 | M12: =C12 -> 0 | AA12: Nagyenyedi
B13: nő | D13: =SUM(C13,C15,-C17,C19,-C22,C25,-C27,-C29) -> 0 | E13: =SUM(D13,D15,-D17,D19,-D22,D25,-D27,-D29) -> 0 | F13: =SUM(E13,E15,-E17,E19,-E22,E25,-E27,-E29) -> 0 | G13: =SUM(F13,F15,-F17,F19,-F22,F25,-F27,-F29) -> 0 | H13: =SUM(G13,G15,-G17,G19,-G22,G25,-G27,-G29) -> 0 | I13: =SUM(H13,H15,-H17,H19,-H22,H25,-H27,-H29) -> 0 | J13: =SUM(I13,I15,-I17,I19,-I22,I25,-I27,-I29) -> 0 | K13: =SUM(J13,J15,-J17,J19,-J22,J25,-J27,-J29) -> 0 | L13: =SUM(K13,K15,-K17,K19,-K22,K25,-K27,-K29) -> 0 | M13: =C13 -> 0 | AA13: Sepsi
A14: 2. | B14: Keresztelésben_részesült: férfi | C14: =P14 -> 0 | D14: =Q14 -> 0 | E14: =R14 -> 0 | F14: =S14 -> 0 | G14: =T14 -> 0 | H14: =U14 -> 0 | I14: =V14 -> 0 | J14: =W14 -> 0 | ... L14: =Y14 -> 0 | M14: =SUM(C14:L14) -> 0 | N14: F. keresztelő | P14: =SUM(COUNTIF(Szolgalati_alkalmak!$AC$4:$AC$8000,$P$1&$N14),COUNTIF(Szolgalati_alkalmak!$AC$4:$AC$8000,$P$1&$N14&$O$2),COUNTIF(Szolgalati_alkalmak!$AC$4:$AC$8000,$P$1&$N14&$O$3),COUNTIF(Szolgalati_alkalmak!$AC$4:$AC$8000,$P$1&$N14&$O$4)) -> 0 | Q14: =SUM(COUNTIF(Szolgalati_alkalmak!$AC$4:$AC$8000,$Q$1&$N14),COUNTIF(Szolgalati_alkalmak!$AC$4:$AC$8000,$Q$1&$N14&$O$2),COUNTIF(Szolgalati_alkalmak!$AC$4:$AC$8000,$Q$1&$N14&$O$3),COUNTIF(Szolgalati_alkalmak!$AC$4:$AC$8000,$Q$1&$N14&$O$4)) -> 0 | R14: =SUM(COUNTIF(Szolgalati_alkalmak!$AC$4:$AC$8000,$R$1&$N14),COUNTIF(Szolgalati_alkalmak!$AC$4:$AC$8000,$R$1&$N14&$O$2),COUNTIF(Szolgalati_alkalmak!$AC$4:$AC$8000,$R$1&$N14&$O$3),COUNTIF(Szolgalati_alkalmak!$AC$4:$AC$8000,$R$1&$N14&$O$4)) -> 0 | S14: =SUM(COUNTIF(Szolgalati_alkalmak!$AC$4:$AC$8000,$S$1&$N14),COUNTIF(Szolgalati_alkalmak!$AC$4:$AC$8000,$S$1&$N14&$O$2),COUNTIF(Szolgalati_alkalmak!$AC$4:$AC$8000,$S$1&$N14&$O$3),COUNTIF(Szolgalati_alkalmak!$AC$4:$AC$8000,$S$1&$N14&$O$4)) -> 0 | T14: =SUM(COUNTIF(Szolgalati_alkalmak!$AC$4:$AC$8000,$T$1&$N14),COUNTIF(Szolgalati_alkalmak!$AC$4:$AC$8000,$T$1&$N14&$O$2),COUNTIF(Szolgalati_alkalmak!$AC$4:$AC$8000,$T$1&$N14&$O$3),COUNTIF(Szolgalati_alkalmak!$AC$4:$AC$8000,$T$1&$N14&$O$4)) -> 0 | U14: =SUM(COUNTIF(Szolgalati_alkalmak!$AC$4:$AC$8000,$U$1&$N14),COUNTIF(Szolgalati_alkalmak!$AC$4:$AC$8000,$U$1&$N14&$O$2),COUNTIF(Szolgalati_alkalmak!$AC$4:$AC$8000,$U$1&$N14&$O$3),COUNTIF(Szolgalati_alkalmak!$AC$4:$AC$8000,$U$1&$N14&$O$4)) -> 0 | V14: =SUM(COUNTIF(Szolgalati_alkalmak!$AC$4:$AC$8000,$V$1&$N14),COUNTIF(Szolgalati_alkalmak!$AC$4:$AC$8000,$V$1&$N14&$O$2),COUNTIF(Szolgalati_alkalmak!$AC$4:$AC$8000,$V$1&$N14&$O$3),COUNTIF(Szolgalati_alkalmak!$AC$4:$AC$8000,$V$1&$N14&$O$4)) -> 0 | W14: =SUM(COUNTIF(Szolgalati_alkalmak!$AC$4:$AC$8000,$W$1&$N14),COUNTIF(Szolgalati_alkalmak!$AC$4:$AC$8000,$W$1&$N14&$O$2),COUNTIF(Szolgalati_alkalmak!$AC$4:$AC$8000,$W$1&$N14&$O$3),COUNTIF(Szolgalati_alkalmak!$AC$4:$AC$8000,$W$1&$N14&$O$4)) -> 0 | X14: =SUM(COUNTIF(Szolgalati_alkalmak!$AC$4:$AC$8000,$X$1&$N14),COUNTIF(Szolgalati_alkalmak!$AC$4:$AC$8000,$X$1&$N14&$O$2),COUNTIF(Szolgalati_alkalmak!$AC$4:$AC$8000,$X$1&$N14&$O$3),COUNTIF(Szolgalati_alkalmak!$AC$4:$AC$8000,$X$1&$N14&$O$4)) -> 0 | Y14: =SUM(COUNTIF(Szolgalati_alkalmak!$AC$4:$AC$8000,$Y$1&$N14),COUNTIF(Szolgalati_alkalmak!$AC$4:$AC$8000,$Y$1&$N14&$O$2),COUNTIF(Szolgalati_alkalmak!$AC$4:$AC$8000,$Y$1&$N14&$O$3),COUNTIF(Szolgalati_alkalmak!$AC$4:$AC$8000,$Y$1&$N14&$O$4)) -> 0 | AA14: Székelyudvarhelyi
B15: nő | C15: =P15 -> 0 | D15: =Q15 -> 0 | E15: =R15 -> 0 | F15: =S15 -> 0 | G15: =T15 -> 0 | H15: =U15 -> 0 | I15: =V15 -> 0 | J15: =W15 -> 0 | ... L15: =Y15 -> 0 | M15: =SUM(C15:L15) -> 0 | N15: N. keresztelő | P15: =SUM(COUNTIF(Szolgalati_alkalmak!$AC$4:$AC$8000,$P$1&$N15),COUNTIF(Szolgalati_alkalmak!$AC$4:$AC$8000,$P$1&$N15&$O$2),COUNTIF(Szolgalati_alkalmak!$AC$4:$AC$8000,$P$1&$N15&$O$3),COUNTIF(Szolgalati_alkalmak!$AC$4:$AC$8000,$P$1&$N15&$O$4)) -> 0 | Q15: =SUM(COUNTIF(Szolgalati_alkalmak!$AC$4:$AC$8000,$Q$1&$N15),COUNTIF(Szolgalati_alkalmak!$AC$4:$AC$8000,$Q$1&$N15&$O$2),COUNTIF(Szolgalati_alkalmak!$AC$4:$AC$8000,$Q$1&$N15&$O$3),COUNTIF(Szolgalati_alkalmak!$AC$4:$AC$8000,$Q$1&$N15&$O$4)) -> 0 | R15: =SUM(COUNTIF(Szolgalati_alkalmak!$AC$4:$AC$8000,$R$1&$N15),COUNTIF(Szolgalati_alkalmak!$AC$4:$AC$8000,$R$1&$N15&$O$2),COUNTIF(Szolgalati_alkalmak!$AC$4:$AC$8000,$R$1&$N15&$O$3),COUNTIF(Szolgalati_alkalmak!$AC$4:$AC$8000,$R$1&$N15&$O$4)) -> 0 | S15: =SUM(COUNTIF(Szolgalati_alkalmak!$AC$4:$AC$8000,$S$1&$N15),COUNTIF(Szolgalati_alkalmak!$AC$4:$AC$8000,$S$1&$N15&$O$2),COUNTIF(Szolgalati_alkalmak!$AC$4:$AC$8000,$S$1&$N15&$O$3),COUNTIF(Szolgalati_alkalmak!$AC$4:$AC$8000,$S$1&$N15&$O$4)) -> 0 | T15: =SUM(COUNTIF(Szolgalati_alkalmak!$AC$4:$AC$8000,$T$1&$N15),COUNTIF(Szolgalati_alkalmak!$AC$4:$AC$8000,$T$1&$N15&$O$2),COUNTIF(Szolgalati_alkalmak!$AC$4:$AC$8000,$T$1&$N15&$O$3),COUNTIF(Szolgalati_alkalmak!$AC$4:$AC$8000,$T$1&$N15&$O$4)) -> 0 | U15: =SUM(COUNTIF(Szolgalati_alkalmak!$AC$4:$AC$8000,$U$1&$N15),COUNTIF(Szolgalati_alkalmak!$AC$4:$AC$8000,$U$1&$N15&$O$2),COUNTIF(Szolgalati_alkalmak!$AC$4:$AC$8000,$U$1&$N15&$O$3),COUNTIF(Szolgalati_alkalmak!$AC$4:$AC$8000,$U$1&$N15&$O$4)) -> 0 | V15: =SUM(COUNTIF(Szolgalati_alkalmak!$AC$4:$AC$8000,$V$1&$N15),COUNTIF(Szolgalati_alkalmak!$AC$4:$AC$8000,$V$1&$N15&$O$2),COUNTIF(Szolgalati_alkalmak!$AC$4:$AC$8000,$V$1&$N15&$O$3),COUNTIF(Szolgalati_alkalmak!$AC$4:$AC$8000,$V$1&$N15&$O$4)) -> 0 | W15: =SUM(COUNTIF(Szolgalati_alkalmak!$AC$4:$AC$8000,$W$1&$N15),COUNTIF(Szolgalati_alkalmak!$AC$4:$AC$8000,$W$1&$N15&$O$2),COUNTIF(Szolgalati_alkalmak!$AC$4:$AC$8000,$W$1&$N15&$O$3),COUNTIF(Szolgalati_alkalmak!$AC$4:$AC$8000,$W$1&$N15&$O$4)) -> 0 | X15: =SUM(COUNTIF(Szolgalati_alkalmak!$AC$4:$AC$8000,$X$1&$N15),COUNTIF(Szolgalati_alkalmak!$AC$4:$AC$8000,$X$1&$N15&$O$2),COUNTIF(Szolgalati_alkalmak!$AC$4:$AC$8000,$X$1&$N15&$O$3),COUNTIF(Szolgalati_alkalmak!$AC$4:$AC$8000,$X$1&$N15&$O$4)) -> 0 | Y15: =SUM(COUNTIF(Szolgalati_alkalmak!$AC$4:$AC$8000,$Y$1&$N15),COUNTIF(Szolgalati_alkalmak!$AC$4:$AC$8000,$Y$1&$N15&$O$2),COUNTIF(Szolgalati_alkalmak!$AC$4:$AC$8000,$Y$1&$N15&$O$3),COUNTIF(Szolgalati_alkalmak!$AC$4:$AC$8000,$Y$1&$N15&$O$4)) -> 0 | AA15: Tordai
A16: 3. | B16: Eltemettetett: férfi | C16: =P16 -> 0 | D16: =Q16 -> 0 | E16: =R16 -> 0 | F16: =S16 -> 0 | G16: =T16 -> 0 | H16: =U16 -> 0 | I16: =V16 -> 0 | J16: =W16 -> 0 | ... L16: =Y16 -> 0 | M16: =SUM(C16:L16) -> 0 | N16: F. temetés | P16: =SUM(COUNTIF(Szolgalati_alkalmak!$AC$4:$AC$8000,$P$1&$N16),COUNTIF(Szolgalati_alkalmak!$AC$4:$AC$8000,$P$1&$N16&$O$2),COUNTIF(Szolgalati_alkalmak!$AC$4:$AC$8000,$P$1&$N16&$O$3),COUNTIF(Szolgalati_alkalmak!$AC$4:$AC$8000,$P$1&$N16&$O$4)) -> 0 | Q16: =SUM(COUNTIF(Szolgalati_alkalmak!$AC$4:$AC$8000,$Q$1&$N16),COUNTIF(Szolgalati_alkalmak!$AC$4:$AC$8000,$Q$1&$N16&$O$2),COUNTIF(Szolgalati_alkalmak!$AC$4:$AC$8000,$Q$1&$N16&$O$3),COUNTIF(Szolgalati_alkalmak!$AC$4:$AC$8000,$Q$1&$N16&$O$4)) -> 0 | R16: =SUM(COUNTIF(Szolgalati_alkalmak!$AC$4:$AC$8000,$R$1&$N16),COUNTIF(Szolgalati_alkalmak!$AC$4:$AC$8000,$R$1&$N16&$O$2),COUNTIF(Szolgalati_alkalmak!$AC$4:$AC$8000,$R$1&$N16&$O$3),COUNTIF(Szolgalati_alkalmak!$AC$4:$AC$8000,$R$1&$N16&$O$4)) -> 0 | S16: =SUM(COUNTIF(Szolgalati_alkalmak!$AC$4:$AC$8000,$S$1&$N16),COUNTIF(Szolgalati_alkalmak!$AC$4:$AC$8000,$S$1&$N16&$O$2),COUNTIF(Szolgalati_alkalmak!$AC$4:$AC$8000,$S$1&$N16&$O$3),COUNTIF(Szolgalati_alkalmak!$AC$4:$AC$8000,$S$1&$N16&$O$4)) -> 0 | T16: =SUM(COUNTIF(Szolgalati_alkalmak!$AC$4:$AC$8000,$T$1&$N16),COUNTIF(Szolgalati_alkalmak!$AC$4:$AC$8000,$T$1&$N16&$O$2),COUNTIF(Szolgalati_alkalmak!$AC$4:$AC$8000,$T$1&$N16&$O$3),COUNTIF(Szolgalati_alkalmak!$AC$4:$AC$8000,$T$1&$N16&$O$4)) -> 0 | U16: =SUM(COUNTIF(Szolgalati_alkalmak!$AC$4:$AC$8000,$U$1&$N16),COUNTIF(Szolgalati_alkalmak!$AC$4:$AC$8000,$U$1&$N16&$O$2),COUNTIF(Szolgalati_alkalmak!$AC$4:$AC$8000,$U$1&$N16&$O$3),COUNTIF(Szolgalati_alkalmak!$AC$4:$AC$8000,$U$1&$N16&$O$4)) -> 0 | V16: =SUM(COUNTIF(Szolgalati_alkalmak!$AC$4:$AC$8000,$V$1&$N16),COUNTIF(Szolgalati_alkalmak!$AC$4:$AC$8000,$V$1&$N16&$O$2),COUNTIF(Szolgalati_alkalmak!$AC$4:$AC$8000,$V$1&$N16&$O$3),COUNTIF(Szolgalati_alkalmak!$AC$4:$AC$8000,$V$1&$N16&$O$4)) -> 0 | W16: =SUM(COUNTIF(Szolgalati_alkalmak!$AC$4:$AC$8000,$W$1&$N16),COUNTIF(Szolgalati_alkalmak!$AC$4:$AC$8000,$W$1&$N16&$O$2),COUNTIF(Szolgalati_alkalmak!$AC$4:$AC$8000,$W$1&$N16&$O$3),COUNTIF(Szolgalati_alkalmak!$AC$4:$AC$8000,$W$1&$N16&$O$4)) -> 0 | X16: =SUM(COUNTIF(Szolgalati_alkalmak!$AC$4:$AC$8000,$X$1&$N16),COUNTIF(Szolgalati_alkalmak!$AC$4:$AC$8000,$X$1&$N16&$O$2),COUNTIF(Szolgalati_alkalmak!$AC$4:$AC$8000,$X$1&$N16&$O$3),COUNTIF(Szolgalati_alkalmak!$AC$4:$AC$8000,$X$1&$N16&$O$4)) -> 0 | Y16: =SUM(COUNTIF(Szolgalati_alkalmak!$AC$4:$AC$8000,$Y$1&$N16),COUNTIF(Szolgalati_alkalmak!$AC$4:$AC$8000,$Y$1&$N16&$O$2),COUNTIF(Szolgalati_alkalmak!$AC$4:$AC$8000,$Y$1&$N16&$O$3),COUNTIF(Szolgalati_alkalmak!$AC$4:$AC$8000,$Y$1&$N16&$O$4)) -> 0 | AA16: Töltsd ki az egyházmegye nevét!
B17: nő | C17: =P17 -> 0 | D17: =Q17 -> 0 | E17: =R17 -> 0 | F17: =S17 -> 0 | G17: =T17 -> 0 | H17: =U17 -> 0 | I17: =V17 -> 0 | J17: =W17 -> 0 | ... L17: =Y17 -> 0 | M17: =SUM(C17:L17) -> 0 | N17: N. temetés | P17: =SUM(COUNTIF(Szolgalati_alkalmak!$AC$4:$AC$8000,$P$1&$N17),COUNTIF(Szolgalati_alkalmak!$AC$4:$AC$8000,$P$1&$N17&$O$2),COUNTIF(Szolgalati_alkalmak!$AC$4:$AC$8000,$P$1&$N17&$O$3),COUNTIF(Szolgalati_alkalmak!$AC$4:$AC$8000,$P$1&$N17&$O$4)) -> 0 | Q17: =SUM(COUNTIF(Szolgalati_alkalmak!$AC$4:$AC$8000,$Q$1&$N17),COUNTIF(Szolgalati_alkalmak!$AC$4:$AC$8000,$Q$1&$N17&$O$2),COUNTIF(Szolgalati_alkalmak!$AC$4:$AC$8000,$Q$1&$N17&$O$3),COUNTIF(Szolgalati_alkalmak!$AC$4:$AC$8000,$Q$1&$N17&$O$4)) -> 0 | R17: =SUM(COUNTIF(Szolgalati_alkalmak!$AC$4:$AC$8000,$R$1&$N17),COUNTIF(Szolgalati_alkalmak!$AC$4:$AC$8000,$R$1&$N17&$O$2),COUNTIF(Szolgalati_alkalmak!$AC$4:$AC$8000,$R$1&$N17&$O$3),COUNTIF(Szolgalati_alkalmak!$AC$4:$AC$8000,$R$1&$N17&$O$4)) -> 0 | S17: =SUM(COUNTIF(Szolgalati_alkalmak!$AC$4:$AC$8000,$S$1&$N17),COUNTIF(Szolgalati_alkalmak!$AC$4:$AC$8000,$S$1&$N17&$O$2),COUNTIF(Szolgalati_alkalmak!$AC$4:$AC$8000,$S$1&$N17&$O$3),COUNTIF(Szolgalati_alkalmak!$AC$4:$AC$8000,$S$1&$N17&$O$4)) -> 0 | T17: =SUM(COUNTIF(Szolgalati_alkalmak!$AC$4:$AC$8000,$T$1&$N17),COUNTIF(Szolgalati_alkalmak!$AC$4:$AC$8000,$T$1&$N17&$O$2),COUNTIF(Szolgalati_alkalmak!$AC$4:$AC$8000,$T$1&$N17&$O$3),COUNTIF(Szolgalati_alkalmak!$AC$4:$AC$8000,$T$1&$N17&$O$4)) -> 0 | U17: =SUM(COUNTIF(Szolgalati_alkalmak!$AC$4:$AC$8000,$U$1&$N17),COUNTIF(Szolgalati_alkalmak!$AC$4:$AC$8000,$U$1&$N17&$O$2),COUNTIF(Szolgalati_alkalmak!$AC$4:$AC$8000,$U$1&$N17&$O$3),COUNTIF(Szolgalati_alkalmak!$AC$4:$AC$8000,$U$1&$N17&$O$4)) -> 0 | V17: =SUM(COUNTIF(Szolgalati_alkalmak!$AC$4:$AC$8000,$V$1&$N17),COUNTIF(Szolgalati_alkalmak!$AC$4:$AC$8000,$V$1&$N17&$O$2),COUNTIF(Szolgalati_alkalmak!$AC$4:$AC$8000,$V$1&$N17&$O$3),COUNTIF(Szolgalati_alkalmak!$AC$4:$AC$8000,$V$1&$N17&$O$4)) -> 0 | W17: =SUM(COUNTIF(Szolgalati_alkalmak!$AC$4:$AC$8000,$W$1&$N17),COUNTIF(Szolgalati_alkalmak!$AC$4:$AC$8000,$W$1&$N17&$O$2),COUNTIF(Szolgalati_alkalmak!$AC$4:$AC$8000,$W$1&$N17&$O$3),COUNTIF(Szolgalati_alkalmak!$AC$4:$AC$8000,$W$1&$N17&$O$4)) -> 0 | X17: =SUM(COUNTIF(Szolgalati_alkalmak!$AC$4:$AC$8000,$X$1&$N17),COUNTIF(Szolgalati_alkalmak!$AC$4:$AC$8000,$X$1&$N17&$O$2),COUNTIF(Szolgalati_alkalmak!$AC$4:$AC$8000,$X$1&$N17&$O$3),COUNTIF(Szolgalati_alkalmak!$AC$4:$AC$8000,$X$1&$N17&$O$4)) -> 0 | Y17: =SUM(COUNTIF(Szolgalati_alkalmak!$AC$4:$AC$8000,$Y$1&$N17),COUNTIF(Szolgalati_alkalmak!$AC$4:$AC$8000,$Y$1&$N17&$O$2),COUNTIF(Szolgalati_alkalmak!$AC$4:$AC$8000,$Y$1&$N17&$O$3),COUNTIF(Szolgalati_alkalmak!$AC$4:$AC$8000,$Y$1&$N17&$O$4)) -> 0
A18: 6. | B18: Egyházunkba_tért: férfi | M18: =SUM(C18:L18) -> 0
B19: nő | M19: =SUM(C19:L19) -> 0
B20: Milyen felekezetből:
A21: 7. | B21: Egyházunkból_kitért: férfi | M21: =SUM(C21:L21) -> 0
B22: nő | M22: =SUM(C22:L22) -> 0
B23: Milyen felekezetbe:
A24: 8. | B24: Beköltözött_az_egyházközségbe: férfi | M24: =SUM(C24:L24) -> 0
B25: nő | M25: =SUM(C25:L25) -> 0
A26: 9. | B26: Kiköltözött_más_egyházközségbe: férfi | M26: =SUM(C26:L26) -> 0
B27: nő | M27: =SUM(C27:L27) -> 0
A28: 10. | B28: Kiköltözött_külföldre: férfi | M28: =SUM(C28:L28) -> 0
B29: nő | M29: =SUM(C29:L29) -> 0
A30: 14. | B30: A gyülekezet választói névjegyzékében szereplő tagjainak száma:
A31: 15. | B31: Az egyházfenntartás személyenkénti éves meghatározott összege:
A32: 16. | B32: Azon felnőtt egyháztagok száma, akik 5 vagy annál több éve nem fizetik az egyházfenntartói járulékot:
A33: 17. | B33: Gyülekezet lélekszámában jelentős (10 személynél több), más nemzetiségű egyháztagok száma: Román
B34: Német
B35: Roma
B36: Más (kérjük megnevezni)
B37: más tagok száma
A38: 18. | B38: Külföldön élő egyháztagok száma, akik életvitelszerűen külföldön élnek, vagy évi több mint 6 hónapot külföldön tartózkodnak:
A39: 19. | B39: Más településen élő egyháztagok száma:
A40: 20. | B40: Más gyülekezetben is tagságot vállaló egyháztagok száma:
...

Sheet Jelentes
A1: 2026 | D1: A baloldali zöld cellába kell beírni a listázni kívánt év számát. | R1: =IF(ISERROR(HLOOKUP(A1,Adatlap!D1:M2,2,FALSE))=TRUE,1,HLOOKUP(A1,Adatlap!D1:M2,2,FALSE)) -> 1 | S1: lej. | AB1: b | AD1: 1 | AE1: 1-én | AF1: . január
A2: Erdélyi Református Egyházkerület | AA2: a a | AB2: c | AD2: 2 | AE2: 2-án | AF2: . február
A3: =R3&" Református Egyházmegye" -> Református Egyházmegye | R3: =IF(Adatlap!C2<>0,Adatlap!C2,"") | AA3: a a | AB3: d | AD3: 3 | AE3: 3-án | AF3: . március
A4: ="Egyházközségi iktatószám: "&IF($Q4<>0,$Q4,"___________") -> Egyházközségi iktatószám: ___________ | Q4: {=INDEX(Adatlap!$C$1:$M$215,V4,$R$1)} -> 0 | V4: =ROW(Adatlap!$B$10) -> 10 | AA4: a a a | AB4: f | AD4: 4 | AE4: 4-én | AF4: . április
A5: Egyházmegyei iktatószám: _________ | N5: Esperes | AA5: a a | AB5: g | AD5: 5 | AE5: 5-én | AF5: . május
AB6: h | AD6: 6 | AE6: 6-án | AF6: . június
AB7: j | AD7: 7 | AE7: 7-én | AF7: . július
AB8: k | AD8: 8 | AE8: 8-án | AF8: . augusztus
A9: LELKÉSZI JELENTÉS | AA9: a a | AB9: l | AD9: 9 | AE9: 9-én | AF9: . szeptember
A10: =CLEAN(UPPER(S10&" "&R10&" REFORMÁTUS EGYHÁZKÖZSÉG")) -> A _________________________ REFORMÁTUS EGYHÁZKÖZSÉG | R10: =IF(Adatlap!C3<>0,Adatlap!C3,"_________________________") -> _________________________ | S10: =IF(ISERROR(VLOOKUP(LOWER(LEFT(R10,1)),AB1:AC19,2,FALSE)),"AZ","A") -> A | AA10: a a | AB10: m | AD10: 10 | AE10: 10-én | AF10: . október
A11: =IF($Q11<>0,$Q11,"")&". ÉVI ÉLETÉRŐL" -> 2026. ÉVI ÉLETÉRŐL | Q11: {=INDEX(Adatlap!$C$1:$M$215,V11,$R$1)} -> 2026 | V11: =ROW(Adatlap!$A$1) -> 1 | AA11: a a | AB11: n | AD11: 11 | AE11: 11-én | AF11: . november
AB12: p | AD12: 12 | AE12: 12-én | AF12: . december
A13: ="Tárgyalta a presbitérium a "&S13&T13&U13&" tartott gyűlésén "&IF($R13<>0,$R13,"_____")&". szám alatt." -> Tárgyalta a presbitérium a _____________ tartott gyűlésén _____. szám alatt. | Q13: {=INDEX(Adatlap!$C$1:$M$215,V13,$R$1)} -> 0 | R13: {=INDEX(Adatlap!$C$1:$M$215,W13,$R$1)} -> 0 | S13: =IF($Q13<>0,YEAR($Q$13),"_____________") -> _____________ | T13: =IF($Q13<>0,VLOOKUP(MONTH($Q$13),AD1:AF12,3,FALSE),"") | U13: =IF($Q13<>0,VLOOKUP(DAY($Q$13),AD1:AF32,2,FALSE),"") | V13: =ROW(Adatlap!$B$6) -> 6 | W13: =ROW(Adatlap!$B$7) -> 7 | AA13: a a | AB13: q | AD13: 13 | AE13: 13-án
A14: ="Tárgyalta az egyházközségi közgyűlés a "&S14&T14&U14&" tartott gyűlésén "&IF($R14<>0,$R14,"_____")&". szám alatt." -> Tárgyalta az egyházközségi közgyűlés a _____________ tartott gyűlésén _____. szám alatt. | Q14: {=INDEX(Adatlap!$C$1:$M$215,V14,$R$1)} -> 0 | R14: {=INDEX(Adatlap!$C$1:$M$215,W14,$R$1)} -> 0 | S14: =IF($Q14<>0,YEAR($Q$14),"_____________") -> _____________ | T14: =IF($Q14<>0,VLOOKUP(MONTH($Q$14),AD1:AF12,3,FALSE),"") | U14: =IF($Q14<>0,VLOOKUP(DAY($Q$14),AD1:AF33,2,FALSE),"") | V14: =ROW(Adatlap!$B$8) -> 8 | W14: =ROW(Adatlap!$B$9) -> 9 | AA14: a a | AB14: r | AD14: 14 | AE14: 14-én
C15: =IF($Q15<>0,$Q15,"") | L15: =IF($R15<>0,$R15,"") | Q15: {=INDEX(Adatlap!$C$1:$M$215,V15,$R$1)} -> 0 | R15: {=INDEX(Adatlap!$C$1:$M$215,W15,$R$1)} -> 0 | V15: =ROW(Adatlap!$B$4) -> 4 | W15: =ROW(Adatlap!$B$5) -> 5 | AB15: s | AD15: 15 | AE15: 15-én
C16: Lelkipásztor | L16: =IF(Adatlap!B5<>0,Adatlap!B5,"Gondnok") -> Főgondnok/Gondnok | AB16: t | AD16: 16 | AE16: 16-án
AB17: v | AD17: 17 | AE17: 17-én
N18: v 1.0b | AB18: z | AD18: 18 | AE18: 18-án
A19: I. Adatok a lélekszámról | AA19: a a a | AB19: _ | AD19: 19 | AE19: 19-én
A20: 1. | B20: Az előző évi lélekszám: | H20: férfi: | I20: =IF($Q20<>0,$Q20,"") | J20: nő: | K20: =IF($R20<>0,$R20,"") | L20: együtt: | N20: =SUM(I20,K20) -> 0 | Q20: {=INDEX(Adatlap!$C$1:$M$215,V20,$R$1)} -> 0 | R20: {=INDEX(Adatlap!$C$1:$M$215,W20,$R$1)} -> 0 | V20: =ROW(Adatlap!$B$12) -> 12 | W20: =ROW(Adatlap!$B$13) -> 13 | AD20: 20 | AE20: 20-án
A21: 2. | B21: Keresztelésben részesült: | H21: férfi: | I21: =IF($Q21<>0,$Q21,"") | J21: nő: | K21: =IF($R21<>0,$R21,"") | L21: együtt: | N21: =SUM(I21,K21) -> 0 | Q21: {=INDEX(Adatlap!$C$1:$M$215,V21,$R$1)} -> 0 | R21: {=INDEX(Adatlap!$C$1:$M$215,W21,$R$1)} -> 0 | V21: =ROW(Adatlap!$B$14) -> 14 | W21: =ROW(Adatlap!$B$15) -> 15 | AD21: 21 | AE21: 21-én
A22: 3. | B22: Eltemettetett: | H22: férfi: | I22: =IF($Q22<>0,$Q22,"") | J22: nő: | K22: =IF($R22<>0,$R22,"") | L22: együtt: | N22: =SUM(I22,K22) -> 0 | Q22: {=INDEX(Adatlap!$C$1:$M$215,V22,$R$1)} -> 0 | R22: {=INDEX(Adatlap!$C$1:$M$215,W22,$R$1)} -> 0 | V22: =ROW(Adatlap!$B$16) -> 16 | W22: =ROW(Adatlap!$B$17) -> 17 | AD22: 22 | AE22: 22-én
A23: 4. | B23: Természetes szaporulat: | L23: együtt: | N23: =IF(N21>N22,SUM(N21,-N22),"") | AD23: 23 | AE23: 23-án
A24: 5. | B24: Természetes apadás: | L24: együtt: | N24: =IF(N22>N21,SUM(N22,-N21),"") | AD24: 24 | AE24: 24-én
A25: 6. | B25: Egyházunkba tért: | H25: férfi: | I25: =IF($Q25<>0,$Q25,"") | J25: nő: | K25: =IF($R25<>0,$R25,"") | L25: együtt: | N25: =SUM(I25,K25) -> 0 | Q25: {=INDEX(Adatlap!$C$1:$M$215,V25,$R$1)} -> 0 | R25: {=INDEX(Adatlap!$C$1:$M$215,W25,$R$1)} -> 0 | V25: =ROW(Adatlap!$B$18) -> 18 | W25: =ROW(Adatlap!$B$19) -> 19 | AD25: 25 | AE25: 25-én
B26: Milyen felekezetből: | E26: =IF(Q26<>0,Q26,"") | Q26: {=INDEX(Adatlap!$C$1:$M$215,V26,$R$1)} -> 0 | V26: =ROW(Adatlap!$B$20) -> 20 | AD26: 26 | AE26: 26-án
A27: 7. | B27: Egyházunkból kitért: | H27: férfi: | I27: =IF($Q27<>0,$Q27,"") | J27: nő: | K27: =IF($R27<>0,$R27,"") | L27: együtt: | N27: =SUM(I27,K27) -> 0 | Q27: {=INDEX(Adatlap!$C$1:$M$215,V27,$R$1)} -> 0 | R27: {=INDEX(Adatlap!$C$1:$M$215,W27,$R$1)} -> 0 | V27: =ROW(Adatlap!$B$21) -> 21 | W27: =ROW(Adatlap!$B$22) -> 22 | AD27: 27 | AE27: 27-én
B28: Milyen felekezetbe: | E28: =IF(Q28<>0,Q28,"") | Q28: {=INDEX(Adatlap!$C$1:$M$215,V28,$R$1)} -> 0 | V28: =ROW(Adatlap!$B$23) -> 23 | AD28: 28 | AE28: 28-án
A29: 8. | B29: Beköltözött az egyházközségbe: | H29: férfi: | I29: =IF($Q29<>0,$Q29,"") | J29: nő: | K29: =IF($R29<>0,$R29,"") | L29: együtt: | N29: =SUM(I29,K29) -> 0 | Q29: {=INDEX(Adatlap!$C$1:$M$215,V29,$R$1)} -> 0 | R29: {=INDEX(Adatlap!$C$1:$M$215,W29,$R$1)} -> 0 | V29: =ROW(Adatlap!$B$24) -> 24 | W29: =ROW(Adatlap!$B$25) -> 25 | AD29: 29 | AE29: 29-én
A30: 9. | B30: Kiköltözött más egyházközségbe: | H30: férfi: | I30: =IF($Q30<>0,$Q30,"") | J30: nő: | K30: =IF($R30<>0,$R30,"") | L30: együtt: | N30: =SUM(I30,K30) -> 0 | Q30: {=INDEX(Adatlap!$C$1:$M$215,V30,$R$1)} -> 0 | R30: {=INDEX(Adatlap!$C$1:$M$215,W30,$R$1)} -> 0 | V30: =ROW(Adatlap!$B$26) -> 26 | W30: =ROW(Adatlap!$B$27) -> 27 | AD30: 30 | AE30: 30-án
A31: 10. | B31: Kiköltözött külföldre: | H31: férfi: | I31: =IF($Q31<>0,$Q31,"") | J31: nő: | K31: =IF($R31<>0,$R31,"") | L31: együtt: | N31: =SUM(I31,K31) -> 0 | Q31: {=INDEX(Adatlap!$C$1:$M$215,V31,$R$1)} -> 0 | R31: {=INDEX(Adatlap!$C$1:$M$215,W31,$R$1)} -> 0 | V31: =ROW(Adatlap!$B$28) -> 28 | W31: =ROW(Adatlap!$B$29) -> 29 | AD31: 31 | AE31: 31-én
A32: 11. | B32: Általános szaporulat: | L32: együtt: | N32: =IF(N34>N20,SUM(N34,-N20),"") | AD32: 0
A33: 12. | B33: Általános apadás: | L33: együtt: | N33: =IF(N20>N34,SUM(N20,-N34),"")
A34: 13. | B34: A gyülekezet lélekszáma dec. 31-én: | H34: férfi: | I34: =SUM(Q20,Q21,-Q22,Q25,-Q27,Q29,-Q30,-Q31) -> 0 | J34: nő: | K34: =SUM(R20,R21,-R22,R25,-R27,R29,-R30,-R31) -> 0 | L34: együtt: | N34: =SUM(I34,K34) -> 0
A35: 14. | B35: ="A gyülekezet választói névjegyzékében szereplő tagjainak száma: "&IF($Q35<>0,$Q35,"") -> A gyülekezet választói névjegyzékében szereplő tagjainak száma: | Q35: {=INDEX(Adatlap!$C$1:$M$215,V35,$R$1)} -> 0 | V35: =ROW(Adatlap!$B$30) -> 30
A36: 15. | B36: ="Az egyházfenntartás személyenkénti éves meghatározott összege: "&IF($Q36<>0,$Q36&$S$1,"") -> Az egyházfenntartás személyenkénti éves meghatározott összege: | Q36: {=INDEX(Adatlap!$C$1:$M$215,V36,$R$1)} -> 0 | V36: =ROW(Adatlap!$B$31) -> 31
A37: 16. | B37: ="Azon felnőtt egyháztagok száma, akik 5 vagy annál több éve nem fizetik az egyházfenntartói járulékot: "&IF($Q37<>0,$Q37,"") -> Azon felnőtt egyháztagok száma, akik 5 vagy annál több éve nem fizetik az egyházfenntartói járulékot: | Q37: {=INDEX(Adatlap!$C$1:$M$215,V37,$R$1)} -> 0 | V37: =ROW(Adatlap!$B$32) -> 32 | AA37: a a
A38: 17. | B38: ="Gyülekezet lélekszámában jelentős (10 személynél több), más nemzetiségű egyháztagok száma: (román, német, roma stb.): "&IF($Q38<>0,$Q38,"") -> Gyülekezet lélekszámában jelentős (10 személynél több), más nemzetiségű egyháztagok száma: (román, német, roma stb.): | Q38: =SUM(Q39:S39,U39) -> 0 | AA38: a a
B39: ="Román: "&IF($Q39<>0,$Q39,"") -> Román: | E39: ="Német: "&IF($R39<>0,$R39,"") -> Német: | G39: ="Roma: "&IF($S39<>0,$S39,"") -> Roma: | J39: =IF($T39<>0,$T39&":","")&" "&IF($U39<>0,$U39,"") | Q39: {=INDEX(Adatlap!$C$1:$M$215,V39,$R$1)} -> 0 | R39: {=INDEX(Adatlap!$C$1:$M$215,W39,$R$1)} -> 0 | S39: {=INDEX(Adatlap!$C$1:$M$215,X39,$R$1)} -> 0 | T39: {=INDEX(Adatlap!$C$1:$M$215,Y39,$R$1)} -> 0 | U39: {=INDEX(Adatlap!$C$1:$M$215,Z39,$R$1)} -> 0 | V39: =ROW(Adatlap!$B$33) -> 33 | W39: =ROW(Adatlap!$B$34) -> 34 | X39: =ROW(Adatlap!$B$35) -> 35 | Y39: =ROW(Adatlap!$B$36) -> 36 | Z39: =ROW(Adatlap!$B$37) -> 37
A40: 18. | B40: ="Külföldön élő egyháztagok száma, akik életvitelszerűen külföldön élnek, vagy évi több mint 6 hónapot külföldön tartózkodnak: "&IF($Q40<>0,$Q40,"") -> Külföldön élő egyháztagok száma, akik életvitelszerűen külföldön élnek, vagy évi több mint 6 hónapot külföldön tartózkodnak: | Q40: {=INDEX(Adatlap!$C$1:$M$215,V40,$R$1)} -> 0 | V40: =ROW(Adatlap!$B$38) -> 38 | AA40: a a
...

Sheet Nyomtathato_munkanaplo
A1: A jobboldali, zöld cellába lehet beírni az évszámot: | K1: 2026 | N1: =IF(OR(K2=0,K2="",K2>O2),1,K2) -> 1 | O1: =MAX(Szolgalati_alkalmak!B4:B10000) -> 0 | P1: =MATCH(MAX(A7:A406),A1:A406,0) -> #N/A | Q1: =IF(OR(K1=0,K1=""),YEAR(Q2),K1) -> 2026 | T1: Ebben a munkanaplóban összesen | U1: . látszik. A jobboldali, zöld cellában lehet megadni a kövektekező (vagy előző) 400 sor listázását (1 , 2, 3 stb számok beírásával) | AB1: ;
A2: =IF(O2>1,T1&O1&T2&U2&U1,"") | N2: a a | O2: =ROUNDUP(O1/400,0) -> 0 | Q2: =TODAY() -> 46029 | T2: sor van. Ebből jelenleg a | U2: =IF(N1=1,"1 - 400",IF(N1=2,"401 - "&O1,"801 - "&O1)) -> 1 - 400
A3: =Szolgalati_alkalmak!D1 -> Református Egyházközség
A4: =TRIM(O4&Q1) -> Szolgálati munkanapló - 2026 | O4: Szolgálati munkanapló -
A5: Sz. | B5: Dátum | C5: Szolgálat jellege | D5: Bibliaolvasás | E5: Alapige | F5: Énekek | G5: Részt vett | I5: Szolgált | J5: P. pénz | K5: Jegyzet
G6: Férfi | H6: Nő | O6: =SUM(N1,-1)*400 -> 0
